[2022-06-01T01:02:35.148] _slurm_rpc_submit_batch_job: JobId=42802 InitPrio=19758 usec=589
[2022-06-01T01:02:36.012] sched: Allocate JobId=42802 NodeList=gpu05 #CPUs=32 Partition=gpu-v100s
[2022-06-01T01:02:52.084] _slurm_rpc_kill_job: REQUEST_KILL_JOB JobId=42802 uid 548200045
[2022-06-01T01:17:06.607] _job_complete: JobId=42784 WEXITSTATUS 0
[2022-06-01T01:17:06.607] _job_complete: JobId=42784 done
[2022-06-01T04:05:04.581] _job_complete: JobId=42801 WEXITSTATUS 2
[2022-06-01T04:05:04.586] _job_complete: JobId=42801 done
[2022-06-01T07:14:56.037] _slurm_rpc_submit_batch_job: JobId=42803 InitPrio=19758 usec=707
[2022-06-01T07:14:56.632] sched: Allocate JobId=42803 NodeList=gpu05 #CPUs=32 Partition=gpu-v100s
[2022-06-01T07:15:35.447] _slurm_rpc_kill_job: REQUEST_KILL_JOB JobId=42803 uid 548200045
[2022-06-01T07:15:39.036] _slurm_rpc_submit_batch_job: JobId=42804 InitPrio=19758 usec=409
[2022-06-01T07:15:39.684] sched: Allocate JobId=42804 NodeList=gpu05 #CPUs=32 Partition=gpu-v100s
[2022-06-01T08:10:51.458] _job_complete: JobId=42720 WEXITSTATUS 0
[2022-06-01T08:10:51.458] _job_complete: JobId=42720 done
[2022-06-01T08:55:12.708] _slurm_rpc_submit_batch_job: JobId=42805 InitPrio=19205 usec=541
[2022-06-01T08:55:12.868] sched: Allocate JobId=42805 NodeList=cpu04 #CPUs=64 Partition=cpu-opteron
[2022-06-01T09:10:33.650] _slurm_rpc_submit_batch_job: JobId=42806 InitPrio=20861 usec=386
[2022-06-01T09:10:34.641] sched: Allocate JobId=42806 NodeList=cpu01 #CPUs=1 Partition=cpu-opteron
[2022-06-01T09:10:36.953] _job_complete: JobId=42806 WEXITSTATUS 1
[2022-06-01T09:10:36.954] _job_complete: JobId=42806 done
[2022-06-01T09:11:17.069] _slurm_rpc_submit_batch_job: JobId=42807 InitPrio=20861 usec=374
[2022-06-01T09:11:17.689] sched: Allocate JobId=42807 NodeList=cpu01 #CPUs=1 Partition=cpu-opteron
[2022-06-01T09:11:20.396] _job_complete: JobId=42807 WEXITSTATUS 1
[2022-06-01T09:11:20.396] _job_complete: JobId=42807 done
[2022-06-01T09:16:23.166] _slurm_rpc_submit_batch_job: JobId=42808 InitPrio=20861 usec=331
[2022-06-01T09:16:23.309] sched: Allocate JobId=42808 NodeList=cpu01 #CPUs=1 Partition=cpu-opteron
[2022-06-01T09:16:55.690] _slurm_rpc_submit_batch_job: JobId=42809 InitPrio=20861 usec=408
[2022-06-01T09:16:56.360] sched: Allocate JobId=42809 NodeList=cpu01 #CPUs=1 Partition=cpu-opteron
[2022-06-01T09:28:29.792] _job_complete: JobId=42808 WEXITSTATUS 0
[2022-06-01T09:28:29.793] _job_complete: JobId=42808 done
[2022-06-01T09:28:44.482] _job_complete: JobId=42809 WEXITSTATUS 0
[2022-06-01T09:28:44.482] _job_complete: JobId=42809 done
[2022-06-01T09:36:15.587] _slurm_rpc_submit_batch_job: JobId=42810 InitPrio=21292 usec=404
[2022-06-01T09:59:44.733] _slurm_rpc_submit_batch_job: JobId=42811 InitPrio=21292 usec=423
[2022-06-01T10:01:26.241] _slurm_rpc_submit_batch_job: JobId=42812 InitPrio=20861 usec=482
[2022-06-01T10:01:26.899] sched: Allocate JobId=42812 NodeList=cpu01 #CPUs=1 Partition=cpu-opteron
[2022-06-01T10:01:40.298] _job_complete: JobId=42812 WEXITSTATUS 0
[2022-06-01T10:01:40.298] _job_complete: JobId=42812 done
[2022-06-01T10:01:41.298] _slurm_rpc_kill_job: REQUEST_KILL_JOB JobId=42812 uid 548200029
[2022-06-01T10:01:56.416] _slurm_rpc_submit_batch_job: JobId=42813 InitPrio=20861 usec=465
[2022-06-01T10:01:56.938] sched: Allocate JobId=42813 NodeList=cpu01 #CPUs=1 Partition=cpu-opteron
[2022-06-01T10:02:06.026] _job_complete: JobId=42813 WEXITSTATUS 0
[2022-06-01T10:02:06.026] _job_complete: JobId=42813 done
[2022-06-01T10:02:31.002] _slurm_rpc_submit_batch_job: JobId=42814 InitPrio=20861 usec=497
[2022-06-01T10:02:31.275] sched: Allocate JobId=42814 NodeList=cpu01 #CPUs=1 Partition=cpu-opteron
[2022-06-01T10:02:46.578] _slurm_rpc_submit_batch_job: JobId=42815 InitPrio=20861 usec=403
[2022-06-01T10:02:47.298] sched: Allocate JobId=42815 NodeList=cpu01 #CPUs=1 Partition=cpu-opteron
[2022-06-01T10:02:51.463] _job_complete: JobId=42815 WEXITSTATUS 0
[2022-06-01T10:02:51.463] _job_complete: JobId=42815 done
[2022-06-01T10:03:02.959] _job_complete: JobId=42814 WEXITSTATUS 0
[2022-06-01T10:03:02.959] _job_complete: JobId=42814 done
[2022-06-01T10:38:04.131] _slurm_rpc_submit_batch_job: JobId=42816 InitPrio=20854 usec=488
[2022-06-01T10:38:04.154] sched: Allocate JobId=42816 NodeList=cpu01 #CPUs=1 Partition=cpu-opteron
[2022-06-01T10:38:17.793] _job_complete: JobId=42816 WEXITSTATUS 0
[2022-06-01T10:38:17.793] _job_complete: JobId=42816 done
[2022-06-01T10:38:45.587] _slurm_rpc_submit_batch_job: JobId=42817 InitPrio=20854 usec=408
[2022-06-01T10:38:46.210] sched: Allocate JobId=42817 NodeList=cpu01 #CPUs=1 Partition=cpu-opteron
[2022-06-01T10:38:47.350] _job_complete: JobId=42817 WEXITSTATUS 1
[2022-06-01T10:38:47.350] _job_complete: JobId=42817 done
[2022-06-01T10:39:01.172] _slurm_rpc_submit_batch_job: JobId=42818 InitPrio=20854 usec=425
[2022-06-01T10:39:01.232] sched: Allocate JobId=42818 NodeList=cpu01 #CPUs=1 Partition=cpu-opteron
[2022-06-01T10:39:02.347] _job_complete: JobId=42818 WEXITSTATUS 1
[2022-06-01T10:39:02.348] _job_complete: JobId=42818 done
[2022-06-01T10:39:14.832] _slurm_rpc_submit_batch_job: JobId=42819 InitPrio=20828 usec=492
[2022-06-01T10:39:15.254] sched: Allocate JobId=42819 NodeList=cpu01 #CPUs=4 Partition=cpu-opteron
[2022-06-01T10:39:20.444] _job_complete: JobId=42819 WEXITSTATUS 0
[2022-06-01T10:39:20.444] _job_complete: JobId=42819 done
[2022-06-01T10:39:24.178] _slurm_rpc_kill_job: REQUEST_KILL_JOB JobId=42819 uid 548200029
[2022-06-01T10:39:44.678] _slurm_rpc_submit_batch_job: JobId=42820 InitPrio=20836 usec=417
[2022-06-01T10:39:45.296] sched: Allocate JobId=42820 NodeList=cpu01 #CPUs=3 Partition=cpu-opteron
[2022-06-01T10:39:49.014] _job_complete: JobId=42820 WEXITSTATUS 0
[2022-06-01T10:39:49.014] _job_complete: JobId=42820 done
[2022-06-01T10:39:58.277] _slurm_rpc_submit_batch_job: JobId=42821 InitPrio=20854 usec=355
[2022-06-01T10:39:58.316] sched: Allocate JobId=42821 NodeList=cpu01 #CPUs=1 Partition=cpu-opteron
[2022-06-01T10:40:18.635] _job_complete: JobId=42821 WEXITSTATUS 0
[2022-06-01T10:40:18.635] _job_complete: JobId=42821 done
[2022-06-01T10:53:15.257] sched: _slurm_rpc_allocate_resources JobId=42822 NodeList=(null) usec=54752
[2022-06-01T10:53:15.868] sched: Allocate JobId=42822 NodeList=cpu03 #CPUs=1 Partition=cpu-opteron
[2022-06-01T10:54:26.160] _job_complete: JobId=42822 WEXITSTATUS 0
[2022-06-01T10:54:26.161] _job_complete: JobId=42822 done
[2022-06-01T12:36:24.685] _slurm_rpc_submit_batch_job: JobId=42823 InitPrio=20846 usec=505
[2022-06-01T12:36:25.308] sched: Allocate JobId=42823 NodeList=cpu01 #CPUs=1 Partition=cpu-opteron
[2022-06-01T12:36:26.150] _job_complete: JobId=42823 WEXITSTATUS 1
[2022-06-01T12:36:26.150] _job_complete: JobId=42823 done
[2022-06-01T13:00:59.941] _slurm_rpc_submit_batch_job: JobId=42824 InitPrio=20846 usec=384
[2022-06-01T13:01:00.020] sched: Allocate JobId=42824 NodeList=cpu01 #CPUs=1 Partition=cpu-opteron
[2022-06-01T13:01:32.427] _job_complete: JobId=42824 WEXITSTATUS 0
[2022-06-01T13:01:32.427] _job_complete: JobId=42824 done
[2022-06-01T13:23:58.920] sched: _slurm_rpc_allocate_resources JobId=42825 NodeList=(null) usec=28647
[2022-06-01T13:23:59.707] sched: Allocate JobId=42825 NodeList=cpu03 #CPUs=1 Partition=cpu-opteron
[2022-06-01T13:28:30.230] _slurm_rpc_kill_job: REQUEST_KILL_JOB JobId=42788 uid 548200029
[2022-06-01T13:28:35.685] _slurm_rpc_kill_job: REQUEST_KILL_JOB JobId=42785 uid 548200029
[2022-06-01T13:32:46.194] _get_job_parts: invalid partition specified: cpu-standard
[2022-06-01T13:32:46.194] _slurm_rpc_submit_batch_job: Invalid partition name specified
[2022-06-01T13:36:09.122] _slurm_rpc_submit_batch_job: JobId=42826 InitPrio=20717 usec=759
[2022-06-01T13:36:38.367] _slurm_rpc_kill_job: REQUEST_KILL_JOB JobId=42826 uid 548200029
[2022-06-01T13:37:18.847] _slurm_rpc_submit_batch_job: JobId=42827 InitPrio=20820 usec=889
[2022-06-01T13:37:19.158] sched: Allocate JobId=42827 NodeList=gpu01 #CPUs=4 Partition=gpu-k10
[2022-06-01T13:39:12.863] _slurm_rpc_kill_job: REQUEST_KILL_JOB JobId=42708 uid 548200029
[2022-06-01T13:40:41.623] _slurm_rpc_submit_batch_job: JobId=42828 InitPrio=20717 usec=634
[2022-06-01T13:40:42.494] sched: Allocate JobId=42828 NodeList=gpu03 #CPUs=16 Partition=gpu-k10
[2022-06-01T13:41:12.928] _slurm_rpc_kill_job: REQUEST_KILL_JOB JobId=42704 uid 548200029
[2022-06-01T13:43:09.407] _slurm_rpc_submit_batch_job: JobId=42829 InitPrio=20717 usec=463
[2022-06-01T13:44:23.982] _get_job_parts: invalid partition specified: cpu-standard
[2022-06-01T13:44:23.982] _slurm_rpc_allocate_resources: Invalid partition name specified 
[2022-06-01T13:44:35.944] sched: _slurm_rpc_allocate_resources JobId=42830 NodeList=(null) usec=641
[2022-06-01T13:44:35.989] sched: Allocate JobId=42830 NodeList=cpu03 #CPUs=1 Partition=cpu-opteron
[2022-06-01T13:44:52.370] _job_complete: JobId=42830 WEXITSTATUS 0
[2022-06-01T13:44:52.371] _job_complete: JobId=42830 done
[2022-06-01T13:45:37.722] _slurm_rpc_kill_job: REQUEST_KILL_JOB JobId=42828 uid 548200029
[2022-06-01T13:45:39.624] sched: Allocate JobId=42829 NodeList=gpu03 #CPUs=16 Partition=gpu-k10
[2022-06-01T13:45:42.322] _slurm_rpc_submit_batch_job: JobId=42831 InitPrio=20717 usec=521
[2022-06-01T13:50:21.916] job_step_signal: JobId=42825 StepId=0 not found
[2022-06-01T13:50:21.917] _job_complete: JobId=42825 WTERMSIG 126
[2022-06-01T13:50:21.917] _job_complete: JobId=42825 cancelled by interactive user
[2022-06-01T13:50:21.917] _job_complete: JobId=42825 done
[2022-06-01T13:57:10.676] _slurm_rpc_kill_job: REQUEST_KILL_JOB JobId=42827 uid 548200029
[2022-06-01T13:57:12.599] sched: Allocate JobId=42831 NodeList=gpu01 #CPUs=16 Partition=gpu-k10
[2022-06-01T13:57:26.755] _slurm_rpc_submit_batch_job: JobId=42832 InitPrio=20820 usec=583
[2022-06-01T13:57:48.216] _slurm_rpc_kill_job: REQUEST_KILL_JOB JobId=42831 uid 548200029
[2022-06-01T13:57:50.129] sched: Allocate JobId=42832 NodeList=gpu01 #CPUs=4 Partition=gpu-k10
[2022-06-01T13:58:14.465] _slurm_rpc_submit_batch_job: JobId=42833 InitPrio=20820 usec=531
[2022-06-01T13:58:14.591] sched: Allocate JobId=42833 NodeList=gpu01 #CPUs=4 Partition=gpu-k10
[2022-06-01T14:43:22.655] _job_complete: JobId=42805 WEXITSTATUS 2
[2022-06-01T14:43:22.660] _job_complete: JobId=42805 done
[2022-06-01T15:01:41.966] _job_complete: JobId=42799 WEXITSTATUS 2
[2022-06-01T15:01:41.967] _job_complete: JobId=42799 done
[2022-06-01T15:12:23.290] error: This association 187(account='free', user='lobbeytan', partition='(null)') does not have access to qos long
[2022-06-01T15:12:23.291] _slurm_rpc_submit_batch_job: Invalid qos specification
[2022-06-01T15:12:37.315] _job_create: exceeded association/QOS limit for user 548300564: AssocGrpCpuLimit
[2022-06-01T15:12:37.315] _slurm_rpc_submit_batch_job: Job violates accounting/QOS policy (job submit limit, user's size and/or time limits)
[2022-06-01T15:12:48.448] error: This association 194(account='free', user='tingweijing', partition='(null)') does not have access to qos normal
[2022-06-01T15:12:48.448] _slurm_rpc_submit_batch_job: Invalid qos specification
[2022-06-01T15:12:54.891] error: This association 194(account='free', user='tingweijing', partition='(null)') does not have access to qos long
[2022-06-01T15:12:54.891] _slurm_rpc_submit_batch_job: Invalid qos specification
[2022-06-01T15:12:58.128] error: This association 186(account='free', user='f4ww4z', partition='(null)') does not have access to qos long
[2022-06-01T15:12:58.128] _slurm_rpc_submit_batch_job: Invalid qos specification
[2022-06-01T15:13:07.140] _job_create: exceeded association/QOS limit for user 548300556: AssocGrpCpuLimit
[2022-06-01T15:13:07.140] _slurm_rpc_submit_batch_job: Job violates accounting/QOS policy (job submit limit, user's size and/or time limits)
[2022-06-01T15:13:17.233] error: This association 186(account='free', user='f4ww4z', partition='(null)') does not have access to qos long
[2022-06-01T15:13:17.233] _slurm_rpc_submit_batch_job: Invalid qos specification
[2022-06-01T15:13:46.163] error: This association 186(account='free', user='f4ww4z', partition='(null)') does not have access to qos long
[2022-06-01T15:13:46.163] _slurm_rpc_submit_batch_job: Invalid qos specification
[2022-06-01T15:14:00.192] _job_create: exceeded association/QOS limit for user 548300558: AssocGrpCpuLimit
[2022-06-01T15:14:00.192] _slurm_rpc_submit_batch_job: Job violates accounting/QOS policy (job submit limit, user's size and/or time limits)
[2022-06-01T15:14:31.538] error: This association 186(account='free', user='f4ww4z', partition='(null)') does not have access to qos long
[2022-06-01T15:14:31.538] _slurm_rpc_submit_batch_job: Invalid qos specification
[2022-06-01T15:14:41.978] _job_create: exceeded association/QOS limit for user 548300556: AssocGrpCpuLimit
[2022-06-01T15:14:41.978] _slurm_rpc_submit_batch_job: Job violates accounting/QOS policy (job submit limit, user's size and/or time limits)
[2022-06-01T15:14:48.874] error: This association 188(account='free', user='xinpeng', partition='(null)') does not have access to qos normal
[2022-06-01T15:14:48.874] _slurm_rpc_submit_batch_job: Invalid qos specification
[2022-06-01T15:15:07.128] _job_create: exceeded association/QOS limit for user 548300564: AssocGrpCpuLimit
[2022-06-01T15:15:07.128] _slurm_rpc_submit_batch_job: Job violates accounting/QOS policy (job submit limit, user's size and/or time limits)
[2022-06-01T15:15:16.925] _job_create: exceeded association/QOS limit for user 548300558: AssocGrpCpuLimit
[2022-06-01T15:15:16.926] _slurm_rpc_submit_batch_job: Job violates accounting/QOS policy (job submit limit, user's size and/or time limits)
[2022-06-01T15:15:31.645] _slurm_rpc_submit_batch_job: JobId=42834 InitPrio=68334 usec=537
[2022-06-01T15:15:32.260] sched: Allocate JobId=42834 NodeList=cpu03 #CPUs=4 Partition=cpu-opteron
[2022-06-01T15:15:47.186] _slurm_rpc_submit_batch_job: JobId=42835 InitPrio=68334 usec=426
[2022-06-01T15:15:47.280] sched: Allocate JobId=42835 NodeList=cpu03 #CPUs=4 Partition=cpu-opteron
[2022-06-01T15:15:47.605] _job_complete: JobId=42835 WEXITSTATUS 1
[2022-06-01T15:15:47.605] _job_complete: JobId=42835 done
[2022-06-01T15:15:53.099] _job_create: exceeded association/QOS limit for user 548300558: AssocGrpCpuLimit
[2022-06-01T15:15:53.099] _slurm_rpc_submit_batch_job: Job violates accounting/QOS policy (job submit limit, user's size and/or time limits)
[2022-06-01T15:16:03.938] _slurm_rpc_submit_batch_job: JobId=42836 InitPrio=68334 usec=404
[2022-06-01T15:16:04.307] sched: Allocate JobId=42836 NodeList=cpu03 #CPUs=4 Partition=cpu-opteron
[2022-06-01T15:16:04.455] error: This association 196(account='free', user='aznul', partition='(null)') does not have access to qos long
[2022-06-01T15:16:04.455] _slurm_rpc_submit_batch_job: Invalid qos specification
[2022-06-01T15:16:06.259] _job_complete: JobId=42836 WEXITSTATUS 2
[2022-06-01T15:16:06.259] _job_complete: JobId=42836 done
[2022-06-01T15:16:09.246] _slurm_rpc_submit_batch_job: JobId=42837 InitPrio=24032 usec=428
[2022-06-01T15:16:09.266] sched: Allocate JobId=42837 NodeList=cpu01 #CPUs=16 Partition=cpu-opteron
[2022-06-01T15:16:18.767] _slurm_rpc_submit_batch_job: JobId=42838 InitPrio=26795 usec=16505
[2022-06-01T15:16:19.374] sched: Allocate JobId=42838 NodeList=cpu10 #CPUs=16 Partition=cpu-opteron
[2022-06-01T15:17:06.753] error: This association 196(account='free', user='aznul', partition='(null)') does not have access to qos long
[2022-06-01T15:17:06.753] _slurm_rpc_submit_batch_job: Invalid qos specification
[2022-06-01T15:17:18.651] _slurm_rpc_submit_batch_job: JobId=42839 InitPrio=68334 usec=450
[2022-06-01T15:17:19.529] sched: Allocate JobId=42839 NodeList=cpu03 #CPUs=4 Partition=cpu-opteron
[2022-06-01T15:17:22.995] _slurm_rpc_kill_job: REQUEST_KILL_JOB JobId=42834 uid 548300556
[2022-06-01T15:18:06.354] _job_create: exceeded association/QOS limit for user 548300558: AssocGrpCpuLimit
[2022-06-01T15:18:06.354] _slurm_rpc_submit_batch_job: Job violates accounting/QOS policy (job submit limit, user's size and/or time limits)
[2022-06-01T15:18:13.227] _slurm_rpc_submit_batch_job: JobId=42840 InitPrio=29660 usec=399
[2022-06-01T15:18:13.554] sched: Allocate JobId=42840 NodeList=cpu03 #CPUs=4 Partition=cpu-opteron
[2022-06-01T15:18:15.060] _slurm_rpc_submit_batch_job: JobId=42841 InitPrio=68334 usec=420
[2022-06-01T15:18:16.604] sched: Allocate JobId=42841 NodeList=cpu03 #CPUs=4 Partition=cpu-opteron
[2022-06-01T15:18:44.543] _slurm_rpc_submit_batch_job: JobId=42842 InitPrio=31870 usec=442
[2022-06-01T15:18:44.601] sched: Allocate JobId=42842 NodeList=gpu02 #CPUs=4 Partition=gpu-titan
[2022-06-01T15:18:51.956] _slurm_rpc_submit_batch_job: JobId=42843 InitPrio=30212 usec=474
[2022-06-01T15:18:53.601] sched: Allocate JobId=42843 NodeList=cpu03 #CPUs=4 Partition=cpu-opteron
[2022-06-01T15:18:54.816] _slurm_rpc_submit_batch_job: JobId=42844 InitPrio=24032 usec=408
[2022-06-01T15:18:56.605] sched: Allocate JobId=42844 NodeList=cpu01 #CPUs=16 Partition=cpu-opteron
[2022-06-01T15:19:20.349] _job_complete: JobId=42838 WEXITSTATUS 0
[2022-06-01T15:19:20.349] _job_complete: JobId=42838 done
[2022-06-01T15:19:32.646] _job_create: exceeded association/QOS limit for user 548300565: AssocGrpCpuLimit
[2022-06-01T15:19:32.646] _slurm_rpc_submit_batch_job: Job violates accounting/QOS policy (job submit limit, user's size and/or time limits)
[2022-06-01T15:19:54.359] _slurm_rpc_kill_job: REQUEST_KILL_JOB JobId=42842 uid 548300558
[2022-06-01T15:20:20.100] _job_complete: JobId=42839 WEXITSTATUS 0
[2022-06-01T15:20:20.100] _job_complete: JobId=42839 done
[2022-06-01T15:20:34.804] _slurm_rpc_submit_batch_job: JobId=42845 InitPrio=68334 usec=456
[2022-06-01T15:20:35.361] _slurm_rpc_submit_batch_job: JobId=42846 InitPrio=68334 usec=417
[2022-06-01T15:20:35.752] sched: Allocate JobId=42845 NodeList=cpu03 #CPUs=4 Partition=cpu-opteron
[2022-06-01T15:20:35.819] sched: Allocate JobId=42846 NodeList=cpu03 #CPUs=4 Partition=cpu-opteron
[2022-06-01T15:20:41.312] _slurm_rpc_submit_batch_job: JobId=42847 InitPrio=68334 usec=409
[2022-06-01T15:20:41.821] sched: Allocate JobId=42847 NodeList=cpu03 #CPUs=4 Partition=cpu-opteron
[2022-06-01T15:20:49.670] _slurm_rpc_kill_job: REQUEST_KILL_JOB JobId=42843 uid 548300556
[2022-06-01T15:21:14.213] _job_complete: JobId=42840 WEXITSTATUS 0
[2022-06-01T15:21:14.213] _job_complete: JobId=42840 done
[2022-06-01T15:21:17.312] _job_complete: JobId=42841 WEXITSTATUS 0
[2022-06-01T15:21:17.312] _job_complete: JobId=42841 done
[2022-06-01T15:21:26.712] _slurm_rpc_submit_batch_job: JobId=42848 InitPrio=33251 usec=499
[2022-06-01T15:21:26.828] sched: Allocate JobId=42848 NodeList=cpu03 #CPUs=4 Partition=cpu-opteron
[2022-06-01T15:21:33.477] _slurm_rpc_submit_batch_job: JobId=42849 InitPrio=68334 usec=808
[2022-06-01T15:21:33.837] sched: Allocate JobId=42849 NodeList=cpu03 #CPUs=4 Partition=cpu-opteron
[2022-06-01T15:21:37.152] _slurm_rpc_submit_batch_job: JobId=42850 InitPrio=30212 usec=483
[2022-06-01T15:21:37.844] sched: Allocate JobId=42850 NodeList=cpu03 #CPUs=4 Partition=cpu-opteron
[2022-06-01T15:21:48.302] _job_complete: JobId=42850 WEXITSTATUS 0
[2022-06-01T15:21:48.302] _job_complete: JobId=42850 done
[2022-06-01T15:21:50.616] _slurm_rpc_submit_batch_job: JobId=42851 InitPrio=24032 usec=480
[2022-06-01T15:21:50.864] sched: Allocate JobId=42851 NodeList=cpu10 #CPUs=16 Partition=cpu-opteron
[2022-06-01T15:22:47.340] _slurm_rpc_submit_batch_job: JobId=42852 InitPrio=29936 usec=467
[2022-06-01T15:22:48.089] sched: Allocate JobId=42852 NodeList=gpu02 #CPUs=4 Partition=gpu-titan
[2022-06-01T15:23:36.277] _job_complete: JobId=42845 WEXITSTATUS 0
[2022-06-01T15:23:36.277] _job_complete: JobId=42845 done
[2022-06-01T15:23:36.348] _job_complete: JobId=42846 WEXITSTATUS 0
[2022-06-01T15:23:36.348] _job_complete: JobId=42846 done
[2022-06-01T15:23:42.340] _job_complete: JobId=42847 WEXITSTATUS 0
[2022-06-01T15:23:42.340] _job_complete: JobId=42847 done
[2022-06-01T15:23:47.319] error: Invalid qos (sharp)
[2022-06-01T15:23:47.319] _slurm_rpc_submit_batch_job: Invalid qos specification
[2022-06-01T15:24:27.316] _job_complete: JobId=42848 WEXITSTATUS 0
[2022-06-01T15:24:27.316] _job_complete: JobId=42848 done
[2022-06-01T15:24:33.423] _slurm_rpc_submit_batch_job: JobId=42853 InitPrio=68334 usec=426
[2022-06-01T15:24:34.311] sched: Allocate JobId=42853 NodeList=cpu03 #CPUs=4 Partition=cpu-opteron
[2022-06-01T15:24:34.311] _job_complete: JobId=42849 WEXITSTATUS 0
[2022-06-01T15:24:34.311] _job_complete: JobId=42849 done
[2022-06-01T15:25:01.036] _slurm_rpc_submit_batch_job: JobId=42854 InitPrio=24032 usec=389
[2022-06-01T15:25:01.275] sched: Allocate JobId=42854 NodeList=cpu10 #CPUs=16 Partition=cpu-opteron
[2022-06-01T15:25:35.318] _slurm_rpc_submit_batch_job: JobId=42855 InitPrio=68334 usec=472
[2022-06-01T15:25:35.426] sched: Allocate JobId=42855 NodeList=cpu03 #CPUs=4 Partition=cpu-opteron
[2022-06-01T15:25:48.409] _job_complete: JobId=42852 WEXITSTATUS 0
[2022-06-01T15:25:48.409] _job_complete: JobId=42852 done
[2022-06-01T15:25:51.237] _get_job_parts: invalid partition specified: opteron
[2022-06-01T15:25:51.237] _slurm_rpc_submit_batch_job: Invalid partition name specified
[2022-06-01T15:26:05.553] _slurm_rpc_submit_batch_job: JobId=42856 InitPrio=29936 usec=447
[2022-06-01T15:26:06.367] sched: Allocate JobId=42856 NodeList=cpu03 #CPUs=4 Partition=cpu-opteron
[2022-06-01T15:26:10.999] _slurm_rpc_submit_batch_job: JobId=42857 InitPrio=68334 usec=433
[2022-06-01T15:26:11.447] sched: Allocate JobId=42857 NodeList=cpu04 #CPUs=4 Partition=cpu-opteron
[2022-06-01T15:26:30.407] _slurm_rpc_submit_batch_job: JobId=42858 InitPrio=32422 usec=409
[2022-06-01T15:26:31.404] sched: Allocate JobId=42858 NodeList=cpu03 #CPUs=4 Partition=cpu-opteron
[2022-06-01T15:27:07.016] error: This association 199(account='free', user='hass', partition='(null)') does not have access to qos long
[2022-06-01T15:27:07.017] _slurm_rpc_submit_batch_job: Invalid qos specification
[2022-06-01T15:27:31.362] _job_create: exceeded association/QOS limit for user 548300569: AssocGrpCpuLimit
[2022-06-01T15:27:31.362] _slurm_rpc_submit_batch_job: Job violates accounting/QOS policy (job submit limit, user's size and/or time limits)
[2022-06-01T15:27:32.042] _slurm_rpc_submit_batch_job: JobId=42859 InitPrio=31317 usec=359
[2022-06-01T15:27:32.596] sched: Allocate JobId=42859 NodeList=cpu03 #CPUs=4 Partition=cpu-opteron
[2022-06-01T15:27:34.800] _job_complete: JobId=42853 WEXITSTATUS 0
[2022-06-01T15:27:34.800] _job_complete: JobId=42853 done
[2022-06-01T15:27:48.768] _job_create: exceeded association/QOS limit for user 548300563: AssocGrpCpuLimit
[2022-06-01T15:27:48.769] _slurm_rpc_submit_batch_job: Job violates accounting/QOS policy (job submit limit, user's size and/or time limits)
[2022-06-01T15:27:59.204] _slurm_rpc_submit_batch_job: JobId=42860 InitPrio=24032 usec=425
[2022-06-01T15:27:59.641] sched: Allocate JobId=42860 NodeList=cpu04 #CPUs=16 Partition=cpu-opteron
[2022-06-01T15:28:06.499] _slurm_rpc_submit_batch_job: JobId=42861 InitPrio=68334 usec=439
[2022-06-01T15:28:06.737] sched: Allocate JobId=42861 NodeList=cpu03 #CPUs=4 Partition=cpu-opteron
[2022-06-01T15:28:07.059] _job_complete: JobId=42861 WEXITSTATUS 0
[2022-06-01T15:28:07.059] _job_complete: JobId=42861 done
[2022-06-01T15:28:31.948] _slurm_rpc_submit_batch_job: JobId=42862 InitPrio=68334 usec=428
[2022-06-01T15:28:32.685] sched: Allocate JobId=42862 NodeList=cpu03 #CPUs=4 Partition=cpu-opteron
[2022-06-01T15:28:36.536] _job_complete: JobId=42855 WEXITSTATUS 0
[2022-06-01T15:28:36.536] _job_complete: JobId=42855 done
[2022-06-01T15:28:54.640] error: This association 201(account='free', user='liew.wei.shiung', partition='(null)') does not have access to qos long
[2022-06-01T15:28:54.640] _slurm_rpc_submit_batch_job: Invalid qos specification
[2022-06-01T15:29:03.744] _slurm_rpc_kill_job: REQUEST_KILL_JOB JobId=42857 uid 548300570
[2022-06-01T15:29:06.907] _job_complete: JobId=42856 WEXITSTATUS 0
[2022-06-01T15:29:06.907] _job_complete: JobId=42856 done
[2022-06-01T15:29:10.221] _get_job_parts: invalid partition specified: cpu-titan
[2022-06-01T15:29:10.221] _slurm_rpc_submit_batch_job: Invalid partition name specified
[2022-06-01T15:29:13.794] _job_create: exceeded association/QOS limit for user 548300563: AssocGrpCpuLimit
[2022-06-01T15:29:13.794] _slurm_rpc_submit_batch_job: Job violates accounting/QOS policy (job submit limit, user's size and/or time limits)
[2022-06-01T15:29:31.996] _job_complete: JobId=42858 WEXITSTATUS 0
[2022-06-01T15:29:31.996] _job_complete: JobId=42858 done
[2022-06-01T15:29:47.004] _slurm_rpc_submit_batch_job: JobId=42863 InitPrio=33251 usec=458
[2022-06-01T15:29:47.791] sched: Allocate JobId=42863 NodeList=cpu04 #CPUs=4 Partition=cpu-opteron
[2022-06-01T15:30:18.119] error: This association 201(account='free', user='liew.wei.shiung', partition='(null)') does not have access to qos long
[2022-06-01T15:30:18.119] _slurm_rpc_submit_batch_job: Invalid qos specification
[2022-06-01T15:30:33.121] _job_complete: JobId=42859 WEXITSTATUS 0
[2022-06-01T15:30:33.121] _job_complete: JobId=42859 done
[2022-06-01T15:30:48.716] _slurm_rpc_submit_batch_job: JobId=42864 InitPrio=32699 usec=423
[2022-06-01T15:30:48.878] sched: Allocate JobId=42864 NodeList=gpu02 #CPUs=4 Partition=gpu-titan
[2022-06-01T15:30:49.141] _job_complete: JobId=42864 WEXITSTATUS 0
[2022-06-01T15:30:49.141] _job_complete: JobId=42864 done
[2022-06-01T15:30:51.759] _slurm_rpc_submit_batch_job: JobId=42865 InitPrio=31594 usec=460
[2022-06-01T15:30:53.889] sched: Allocate JobId=42865 NodeList=gpu02 #CPUs=4 Partition=gpu-titan
[2022-06-01T15:31:03.799] _slurm_rpc_submit_batch_job: JobId=42866 InitPrio=30212 usec=500
[2022-06-01T15:31:03.902] sched: Allocate JobId=42866 NodeList=cpu03 #CPUs=4 Partition=cpu-opteron
[2022-06-01T15:31:27.874] _slurm_rpc_kill_job: REQUEST_KILL_JOB JobId=42804 uid 548300563
[2022-06-01T15:31:27.874] error: Security violation, REQUEST_KILL_JOB RPC for JobId=42804 from uid 548300563
[2022-06-01T15:31:27.874] _slurm_rpc_kill_job: job_str_signal() uid=548300563 JobId=42804 sig=9 returned: Access/permission denied
[2022-06-01T15:31:33.200] _job_complete: JobId=42862 WEXITSTATUS 0
[2022-06-01T15:31:33.200] _job_complete: JobId=42862 done
[2022-06-01T15:31:37.672] error: This association 201(account='free', user='liew.wei.shiung', partition='(null)') does not have access to qos long
[2022-06-01T15:31:37.672] _slurm_rpc_submit_batch_job: Invalid qos specification
[2022-06-01T15:32:34.779] _slurm_rpc_submit_batch_job: JobId=42867 InitPrio=25137 usec=420
[2022-06-01T15:32:35.215] sched: Allocate JobId=42867 NodeList=cpu04 #CPUs=16 Partition=cpu-opteron
[2022-06-01T15:32:39.926] _slurm_rpc_submit_batch_job: JobId=42868 InitPrio=32422 usec=428
[2022-06-01T15:32:40.185] sched: Allocate JobId=42868 NodeList=cpu03 #CPUs=4 Partition=cpu-opteron
[2022-06-01T15:32:48.305] _job_complete: JobId=42863 WEXITSTATUS 0
[2022-06-01T15:32:48.305] _job_complete: JobId=42863 done
[2022-06-01T15:33:40.532] _slurm_rpc_kill_job: REQUEST_KILL_JOB JobId=42868 uid 548300569
[2022-06-01T15:33:54.265] _job_complete: JobId=42865 WEXITSTATUS 0
[2022-06-01T15:33:54.265] _job_complete: JobId=42865 done
[2022-06-01T15:34:04.450] _job_complete: JobId=42866 WEXITSTATUS 0
[2022-06-01T15:34:04.450] _job_complete: JobId=42866 done
[2022-06-01T15:34:06.344] _slurm_rpc_submit_batch_job: JobId=42869 InitPrio=24032 usec=428
[2022-06-01T15:34:07.308] sched: Allocate JobId=42869 NodeList=cpu04 #CPUs=16 Partition=cpu-opteron
[2022-06-01T15:34:55.928] _slurm_rpc_submit_batch_job: JobId=42870 InitPrio=31594 usec=433
[2022-06-01T15:34:56.378] sched: Allocate JobId=42870 NodeList=cpu04 #CPUs=4 Partition=cpu-opteron
[2022-06-01T15:35:35.649] _job_complete: JobId=42867 WEXITSTATUS 0
[2022-06-01T15:35:35.649] _job_complete: JobId=42867 done
[2022-06-01T15:37:56.860] _job_complete: JobId=42870 WEXITSTATUS 0
[2022-06-01T15:37:56.860] _job_complete: JobId=42870 done
[2022-06-01T15:40:47.840] _slurm_rpc_submit_batch_job: JobId=42871 InitPrio=20846 usec=443
[2022-06-01T15:40:48.024] sched: Allocate JobId=42871 NodeList=cpu04 #CPUs=1 Partition=cpu-opteron
[2022-06-01T15:42:09.144] _job_complete: JobId=42871 WEXITSTATUS 0
[2022-06-01T15:42:09.144] _job_complete: JobId=42871 done
[2022-06-01T15:42:43.373] _slurm_rpc_submit_batch_job: JobId=42872 InitPrio=19891 usec=2207
[2022-06-01T15:42:44.264] sched: Allocate JobId=42872 NodeList=cpu12 #CPUs=48 Partition=cpu-epyc
[2022-06-01T15:43:58.835] _slurm_rpc_submit_batch_job: JobId=42873 InitPrio=19754 usec=483
[2022-06-01T15:43:59.357] sched: Allocate JobId=42873 NodeList=cpu07 #CPUs=64 Partition=cpu-opteron
[2022-06-01T15:44:25.399] _job_complete: JobId=42872 WEXITSTATUS 1
[2022-06-01T15:44:25.399] _job_complete: JobId=42872 done
[2022-06-01T15:57:44.436] _slurm_rpc_submit_batch_job: JobId=42874 InitPrio=23825 usec=509
[2022-06-01T15:58:03.587] error: This association 187(account='free', user='lobbeytan', partition='(null)') does not have access to qos normal
[2022-06-01T15:58:03.587] _slurm_rpc_submit_batch_job: Invalid qos specification
[2022-06-01T15:59:32.537] sched: Updated reservation=AI_Training users=jitkang,wktang,zati,f4ww4z,lobbeytan,xinpeng,loojh666,jamesong22,roland,nerv_zmg,rayedbw,tingweijing,shahreeza,aznul,huiszeli,nuruljpr,jackmin,ayhamalomari,jasonyang429,stephen.khor,hass,sawsn nodes=cpu03,gpu[02,04] cores=96 licenses=(null) tres=cpu=128 watts=4294967294 start=2022-06-01T10:00:00 end=2022-06-01T18:00:00 MaxStartDelay=
[2022-06-01T15:59:33.003] sched: Allocate JobId=42874 NodeList=gpu04 #CPUs=8 Partition=gpu-k40c
[2022-06-01T15:59:44.416] error: This association 187(account='free', user='lobbeytan', partition='(null)') does not have access to qos normal
[2022-06-01T15:59:44.416] _slurm_rpc_submit_batch_job: Invalid qos specification
[2022-06-01T16:00:08.161] _slurm_rpc_submit_batch_job: JobId=42875 InitPrio=31041 usec=487
[2022-06-01T16:00:09.044] sched: Allocate JobId=42875 NodeList=gpu04 #CPUs=4 Partition=gpu-k40c
[2022-06-01T16:00:11.443] _job_complete: JobId=42875 WEXITSTATUS 1
[2022-06-01T16:00:11.444] _job_complete: JobId=42875 done
[2022-06-01T16:00:38.401] _job_complete: JobId=42874 WEXITSTATUS 0
[2022-06-01T16:00:38.402] _job_complete: JobId=42874 done
[2022-06-01T16:01:35.056] _slurm_rpc_submit_batch_job: JobId=42876 InitPrio=26863 usec=509
[2022-06-01T16:07:05.452] _slurm_rpc_submit_batch_job: JobId=42877 InitPrio=26863 usec=468
[2022-06-01T16:10:50.854] _slurm_rpc_submit_batch_job: JobId=42878 InitPrio=31041 usec=645
[2022-06-01T16:10:53.160] sched: Allocate JobId=42878 NodeList=gpu04 #CPUs=4 Partition=gpu-k40c
[2022-06-01T16:10:54.108] _job_complete: JobId=42878 WEXITSTATUS 1
[2022-06-01T16:10:54.109] _job_complete: JobId=42878 done
[2022-06-01T16:15:51.812] _slurm_rpc_submit_batch_job: JobId=42879 InitPrio=23895 usec=458
[2022-06-01T16:15:53.712] sched: Allocate JobId=42879 NodeList=cpu13 #CPUs=32 Partition=cpu-epyc
[2022-06-01T17:26:47.956] Time limit exhausted for JobId=41981
[2022-06-01T18:00:29.810] sched/backfill: _start_job: Started JobId=42876 in gpu-k40c on gpu04
[2022-06-01T18:00:29.811] sched/backfill: _start_job: Started JobId=42877 in gpu-titan on gpu02
[2022-06-01T18:00:29.827] sched/backfill: _start_job: Started JobId=42810 in gpu-k40c on gpu04
[2022-06-01T18:00:32.016] _job_complete: JobId=42876 WEXITSTATUS 1
[2022-06-01T18:00:32.016] _job_complete: JobId=42876 done
[2022-06-01T18:00:32.294] _job_complete: JobId=42877 WEXITSTATUS 1
[2022-06-01T18:00:32.295] _job_complete: JobId=42877 done
[2022-06-01T18:00:32.413] sched: Allocate JobId=42811 NodeList=gpu04 #CPUs=16 Partition=gpu-k40c
[2022-06-01T18:00:42.091] _job_complete: JobId=42811 WEXITSTATUS 0
[2022-06-01T18:00:42.092] _job_complete: JobId=42811 done
[2022-06-01T19:18:36.023] _slurm_rpc_submit_batch_job: JobId=42880 InitPrio=19338 usec=626
[2022-06-01T19:18:36.400] sched: Allocate JobId=42880 NodeList=cpu12 #CPUs=48 Partition=cpu-epyc
[2022-06-01T19:22:41.388] _slurm_rpc_submit_batch_job: JobId=42881 InitPrio=31041 usec=448
[2022-06-01T19:22:41.876] sched: Allocate JobId=42881 NodeList=gpu04 #CPUs=4 Partition=gpu-k40c
[2022-06-01T19:22:56.632] _job_complete: JobId=42881 WEXITSTATUS 1
[2022-06-01T19:22:56.633] _job_complete: JobId=42881 done
[2022-06-01T19:32:36.947] _slurm_rpc_submit_batch_job: JobId=42882 InitPrio=31041 usec=479
[2022-06-01T19:32:37.907] sched: Allocate JobId=42882 NodeList=gpu02 #CPUs=4 Partition=gpu-titan
[2022-06-01T19:33:28.528] _job_complete: JobId=42882 WEXITSTATUS 0
[2022-06-01T19:33:28.528] _job_complete: JobId=42882 done
[2022-06-01T19:35:50.396] _slurm_rpc_submit_batch_job: JobId=42883 InitPrio=31041 usec=486
[2022-06-01T19:54:17.872] _job_complete: JobId=42860 WEXITSTATUS 0
[2022-06-01T19:54:17.872] _job_complete: JobId=42860 done
[2022-06-01T20:09:53.546] _slurm_rpc_kill_job: REQUEST_KILL_JOB JobId=42883 uid 548300557
[2022-06-01T20:11:02.043] _slurm_rpc_submit_batch_job: JobId=42884 InitPrio=29936 usec=506
[2022-06-01T20:11:02.073] sched: Allocate JobId=42884 NodeList=gpu01 #CPUs=4 Partition=gpu-k10
[2022-06-01T20:11:08.407] _job_complete: JobId=42884 WEXITSTATUS 1
[2022-06-01T20:11:08.408] _job_complete: JobId=42884 done
[2022-06-01T21:53:32.340] _job_complete: JobId=42880 WEXITSTATUS 2
[2022-06-01T21:53:32.340] _job_complete: JobId=42880 done
[2022-06-01T23:40:53.053] _job_complete: JobId=42851 WEXITSTATUS 0
[2022-06-01T23:40:53.053] _job_complete: JobId=42851 done
[2022-06-02T00:12:05.706] sched: _slurm_rpc_allocate_resources JobId=42885 NodeList=cpu10 usec=12892
[2022-06-02T00:39:32.343] _slurm_rpc_submit_batch_job: JobId=42886 InitPrio=20994 usec=570
[2022-06-02T00:39:32.454] sched: Allocate JobId=42886 NodeList=cpu01 #CPUs=16 Partition=cpu-opteron
[2022-06-02T00:39:44.701] _job_complete: JobId=42886 WEXITSTATUS 1
[2022-06-02T00:39:44.701] _job_complete: JobId=42886 done
[2022-06-02T00:40:36.775] _slurm_rpc_submit_batch_job: JobId=42887 InitPrio=20994 usec=436
[2022-06-02T00:40:37.531] sched: Allocate JobId=42887 NodeList=cpu01 #CPUs=16 Partition=cpu-opteron
[2022-06-02T00:40:49.412] _job_complete: JobId=42887 WEXITSTATUS 1
[2022-06-02T00:40:49.412] _job_complete: JobId=42887 done
[2022-06-02T00:41:51.776] _slurm_rpc_submit_batch_job: JobId=42888 InitPrio=20994 usec=526
[2022-06-02T00:41:52.638] sched: Allocate JobId=42888 NodeList=cpu01 #CPUs=16 Partition=cpu-opteron
[2022-06-02T00:42:55.715] _slurm_rpc_submit_batch_job: JobId=42889 InitPrio=20994 usec=433
[2022-06-02T00:42:55.829] sched: Allocate JobId=42889 NodeList=cpu01 #CPUs=16 Partition=cpu-opteron
[2022-06-02T00:44:53.030] _job_complete: JobId=42885 WEXITSTATUS 0
[2022-06-02T00:44:53.030] _job_complete: JobId=42885 done
[2022-06-02T00:51:16.968] error: This association 191(account='free', user='roland', partition='(null)') does not have access to qos normal
[2022-06-02T00:51:16.968] _slurm_rpc_submit_batch_job: Invalid qos specification
[2022-06-02T00:51:23.152] _slurm_rpc_kill_job: REQUEST_KILL_JOB JobId=42888 uid 548200023
[2022-06-02T00:51:45.479] _slurm_rpc_submit_batch_job: JobId=42890 InitPrio=20994 usec=422
[2022-06-02T00:51:45.687] sched: Allocate JobId=42890 NodeList=cpu10 #CPUs=16 Partition=cpu-opteron
[2022-06-02T00:51:51.115] _job_create: exceeded association/QOS limit for user 548300561: AssocGrpCpuLimit
[2022-06-02T00:51:51.115] _slurm_rpc_submit_batch_job: Job violates accounting/QOS policy (job submit limit, user's size and/or time limits)
[2022-06-02T00:54:05.459] _slurm_rpc_kill_job: REQUEST_KILL_JOB JobId=42889 uid 548200023
[2022-06-02T00:54:13.155] _slurm_rpc_submit_batch_job: JobId=42891 InitPrio=20994 usec=414
[2022-06-02T00:54:14.014] sched: Allocate JobId=42891 NodeList=cpu04 #CPUs=16 Partition=cpu-opteron
[2022-06-02T00:54:27.413] _job_complete: JobId=42891 WEXITSTATUS 1
[2022-06-02T00:54:27.414] _job_complete: JobId=42891 done
[2022-06-02T00:59:22.256] _slurm_rpc_submit_batch_job: JobId=42892 InitPrio=20994 usec=446
[2022-06-02T00:59:22.555] sched: Allocate JobId=42892 NodeList=cpu01 #CPUs=16 Partition=cpu-opteron
[2022-06-02T00:59:38.621] _slurm_rpc_kill_job: REQUEST_KILL_JOB JobId=42890 uid 548200023
[2022-06-02T01:00:23.048] _job_complete: JobId=42869 WEXITSTATUS 0
[2022-06-02T01:00:23.048] _job_complete: JobId=42869 done
[2022-06-02T01:01:10.163] _slurm_rpc_submit_batch_job: JobId=42893 InitPrio=20994 usec=591
[2022-06-02T01:01:10.700] sched: Allocate JobId=42893 NodeList=cpu10 #CPUs=16 Partition=cpu-opteron
[2022-06-02T01:08:49.924] _job_create: exceeded association/QOS limit for user 548300561: AssocGrpCpuLimit
[2022-06-02T01:08:49.924] _slurm_rpc_submit_batch_job: Job violates accounting/QOS policy (job submit limit, user's size and/or time limits)
[2022-06-02T01:09:04.347] _job_create: exceeded association/QOS limit for user 548300561: AssocGrpMemLimit
[2022-06-02T01:09:04.347] _slurm_rpc_submit_batch_job: Job violates accounting/QOS policy (job submit limit, user's size and/or time limits)
[2022-06-02T01:10:31.037] _job_create: exceeded association/QOS limit for user 548300561: AssocGrpMemLimit
[2022-06-02T01:10:31.038] _slurm_rpc_submit_batch_job: Job violates accounting/QOS policy (job submit limit, user's size and/or time limits)
[2022-06-02T01:10:41.718] _job_create: exceeded association/QOS limit for user 548300561: AssocGrpCpuLimit
[2022-06-02T01:10:41.718] _slurm_rpc_submit_batch_job: Job violates accounting/QOS policy (job submit limit, user's size and/or time limits)
[2022-06-02T01:10:54.463] _slurm_rpc_submit_batch_job: JobId=42894 InitPrio=29936 usec=541
[2022-06-02T01:10:55.210] sched: Allocate JobId=42894 NodeList=cpu01 #CPUs=4 Partition=cpu-opteron
[2022-06-02T01:11:00.222] _job_complete: JobId=42894 WEXITSTATUS 1
[2022-06-02T01:11:00.222] _job_complete: JobId=42894 done
[2022-06-02T01:11:24.231] _job_complete: JobId=42879 WEXITSTATUS 1
[2022-06-02T01:11:24.231] _job_complete: JobId=42879 done
[2022-06-02T01:16:01.768] _slurm_rpc_submit_batch_job: JobId=42895 InitPrio=29936 usec=410
[2022-06-02T01:16:02.738] sched: Allocate JobId=42895 NodeList=cpu01 #CPUs=4 Partition=cpu-opteron
[2022-06-02T01:16:05.437] _job_complete: JobId=42895 WEXITSTATUS 1
[2022-06-02T01:16:05.437] _job_complete: JobId=42895 done
[2022-06-02T01:28:08.813] _job_complete: JobId=42844 WEXITSTATUS 0
[2022-06-02T01:28:08.814] _job_complete: JobId=42844 done
[2022-06-02T01:29:24.583] _slurm_rpc_submit_batch_job: JobId=42896 InitPrio=29936 usec=398
[2022-06-02T01:29:25.212] sched: Allocate JobId=42896 NodeList=cpu01 #CPUs=4 Partition=cpu-opteron
[2022-06-02T01:29:27.567] _job_complete: JobId=42896 WEXITSTATUS 1
[2022-06-02T01:29:27.567] _job_complete: JobId=42896 done
[2022-06-02T01:30:11.740] _slurm_rpc_submit_batch_job: JobId=42897 InitPrio=29936 usec=498
[2022-06-02T01:30:12.278] sched: Allocate JobId=42897 NodeList=cpu01 #CPUs=4 Partition=cpu-opteron
[2022-06-02T01:30:14.741] _job_complete: JobId=42897 WEXITSTATUS 1
[2022-06-02T01:30:14.741] _job_complete: JobId=42897 done
[2022-06-02T01:35:35.454] sched: _slurm_rpc_allocate_resources JobId=42898 NodeList=cpu01 usec=1208
[2022-06-02T02:08:33.020] _job_complete: JobId=42898 WEXITSTATUS 0
[2022-06-02T02:08:33.021] _job_complete: JobId=42898 done
[2022-06-02T02:13:33.208] cleanup_completing: JobId=42898 completion process took 300 seconds
[2022-06-02T02:48:07.909] _job_complete: JobId=42837 WEXITSTATUS 0
[2022-06-02T02:48:07.909] _job_complete: JobId=42837 done
[2022-06-02T03:05:48.033] sched: _slurm_rpc_allocate_resources JobId=42899 NodeList=cpu01 usec=12814
[2022-06-02T03:23:41.294] _job_complete: JobId=42899 WEXITSTATUS 130
[2022-06-02T03:23:41.295] _job_complete: JobId=42899 done
[2022-06-02T03:24:21.837] sched: _slurm_rpc_allocate_resources JobId=42900 NodeList=cpu01 usec=4880
[2022-06-02T03:29:46.803] _job_complete: JobId=42900 WEXITSTATUS 0
[2022-06-02T03:29:46.803] _job_complete: JobId=42900 done
[2022-06-02T03:31:40.564] sched: _slurm_rpc_allocate_resources JobId=42901 NodeList=cpu01 usec=1298
[2022-06-02T03:36:59.316] _job_complete: JobId=42893 WEXITSTATUS 0
[2022-06-02T03:36:59.316] _job_complete: JobId=42893 done
[2022-06-02T04:08:50.160] _job_complete: JobId=42892 WEXITSTATUS 0
[2022-06-02T04:08:50.160] _job_complete: JobId=42892 done
[2022-06-02T04:15:50.012] _slurm_rpc_submit_batch_job: JobId=42902 InitPrio=24930 usec=570
[2022-06-02T04:15:50.381] sched: Allocate JobId=42902 NodeList=gpu02 #CPUs=8 Partition=gpu-titan
[2022-06-02T04:31:49.131] Time limit exhausted for JobId=42901
[2022-06-02T04:36:55.817] cleanup_completing: JobId=42901 completion process took 306 seconds
[2022-06-02T04:37:19.771] sched: _slurm_rpc_allocate_resources JobId=42903 NodeList=cpu10 usec=14630
[2022-06-02T04:45:05.120] _job_complete: JobId=42903 WEXITSTATUS 0
[2022-06-02T04:45:05.120] _job_complete: JobId=42903 done
[2022-06-02T04:48:33.193] sched: _slurm_rpc_allocate_resources JobId=42904 NodeList=cpu10 usec=3982
[2022-06-02T04:55:19.033] _job_complete: JobId=42904 WEXITSTATUS 127
[2022-06-02T04:55:19.033] _job_complete: JobId=42904 done
[2022-06-02T08:19:19.637] _job_complete: JobId=42873 WEXITSTATUS 0
[2022-06-02T08:19:19.637] _job_complete: JobId=42873 done
[2022-06-02T08:45:42.694] Requeuing JobId=42829
[2022-06-02T08:46:04.392] Requeuing JobId=42832
[2022-06-02T08:46:05.278] Requeuing JobId=42833
[2022-06-02T08:49:10.653] _job_complete: JobId=42804 WEXITSTATUS 0
[2022-06-02T08:49:10.653] _job_complete: JobId=42804 done
[2022-06-02T09:18:48.884] _slurm_rpc_submit_batch_job: JobId=42905 InitPrio=24377 usec=570
[2022-06-02T09:18:49.558] sched: Allocate JobId=42905 NodeList=gpu02 #CPUs=8 Partition=gpu-titan
[2022-06-02T09:23:39.471] _slurm_rpc_submit_batch_job: JobId=42906 InitPrio=24450 usec=301
[2022-06-02T09:23:40.188] sched: Allocate JobId=42906 NodeList=cpu07 #CPUs=64 Partition=cpu-opteron
[2022-06-02T09:45:07.974] _slurm_rpc_kill_job: REQUEST_KILL_JOB JobId=42906 uid 548300543
[2022-06-02T09:53:04.194] sched: _slurm_rpc_allocate_resources JobId=42907 NodeList=cpu10 usec=25365
[2022-06-02T09:53:04.700] _job_complete: JobId=42907 WEXITSTATUS 127
[2022-06-02T09:53:04.700] _job_complete: JobId=42907 done
[2022-06-02T09:53:06.659] sched: _slurm_rpc_allocate_resources JobId=42908 NodeList=cpu10 usec=1192
[2022-06-02T09:53:51.278] _job_complete: JobId=42908 WEXITSTATUS 0
[2022-06-02T09:53:51.278] _job_complete: JobId=42908 done
[2022-06-02T10:01:32.737] _job_complete: JobId=42902 WEXITSTATUS 0
[2022-06-02T10:01:32.737] _job_complete: JobId=42902 done
[2022-06-02T10:17:26.488] sched: _slurm_rpc_allocate_resources JobId=42909 NodeList=cpu10 usec=70438
[2022-06-02T10:31:59.757] _slurm_rpc_submit_batch_job: JobId=42910 InitPrio=20994 usec=518
[2022-06-02T10:32:00.130] sched: Allocate JobId=42910 NodeList=cpu13 #CPUs=16 Partition=cpu-epyc
[2022-06-02T11:07:44.537] _slurm_rpc_submit_batch_job: JobId=42911 InitPrio=19338 usec=445
[2022-06-02T11:07:45.108] sched: Allocate JobId=42911 NodeList=cpu12 #CPUs=48 Partition=cpu-epyc
[2022-06-02T11:13:00.645] _slurm_rpc_submit_batch_job: JobId=42912 InitPrio=19338 usec=474
[2022-06-02T11:13:00.705] sched: Allocate JobId=42912 NodeList=cpu14 #CPUs=48 Partition=cpu-epyc
[2022-06-02T11:34:04.954] _job_complete: JobId=42910 WEXITSTATUS 0
[2022-06-02T11:34:04.954] _job_complete: JobId=42910 done
[2022-06-02T11:34:38.841] _job_complete: JobId=42726 WEXITSTATUS 0
[2022-06-02T11:34:38.841] _job_complete: JobId=42726 done
[2022-06-02T11:59:09.186] _slurm_rpc_submit_batch_job: JobId=42913 InitPrio=19752 usec=537
[2022-06-02T11:59:09.908] sched: Allocate JobId=42913 NodeList=gpu05 #CPUs=32 Partition=gpu-v100s
[2022-06-02T12:41:06.371] _get_job_parts: invalid partition specified: gpu-k40c,gpu-titam,gpu-v100s
[2022-06-02T12:41:06.371] _slurm_rpc_submit_batch_job: Invalid partition name specified
[2022-06-02T12:45:58.384] error: This association 195(account='free', user='shahreeza', partition='(null)') does not have access to qos normal
[2022-06-02T12:45:58.384] _slurm_rpc_submit_batch_job: Invalid qos specification
[2022-06-02T12:46:36.492] _job_create: exceeded association/QOS limit for user 548300565: AssocGrpCpuLimit
[2022-06-02T12:46:36.492] _slurm_rpc_submit_batch_job: Job violates accounting/QOS policy (job submit limit, user's size and/or time limits)
[2022-06-02T12:46:57.620] error: This association 195(account='free', user='shahreeza', partition='(null)') does not have access to qos long
[2022-06-02T12:46:57.620] _slurm_rpc_submit_batch_job: Invalid qos specification
[2022-06-02T12:53:01.536] _slurm_rpc_submit_batch_job: JobId=42914 InitPrio=27726 usec=564
[2022-06-02T12:53:02.312] sched: Allocate JobId=42914 NodeList=cpu10 #CPUs=4 Partition=cpu-opteron
[2022-06-02T12:54:26.754] error: This association 195(account='free', user='shahreeza', partition='(null)') does not have access to qos long
[2022-06-02T12:54:26.754] _slurm_rpc_submit_batch_job: Invalid qos specification
[2022-06-02T12:57:08.418] error: This association 195(account='free', user='shahreeza', partition='(null)') does not have access to qos normal
[2022-06-02T12:57:08.418] _slurm_rpc_submit_batch_job: Invalid qos specification
[2022-06-02T13:28:58.166] _job_complete: JobId=42909 WEXITSTATUS 0
[2022-06-02T13:28:58.166] _job_complete: JobId=42909 done
[2022-06-02T13:42:38.999] _job_complete: JobId=42854 WEXITSTATUS 1
[2022-06-02T13:42:39.000] _job_complete: JobId=42854 done
[2022-06-02T13:50:53.535] _slurm_rpc_kill_job: REQUEST_KILL_JOB JobId=42914 uid 548300561
[2022-06-02T13:52:14.395] _job_create: exceeded association/QOS limit for user 548300561: AssocGrpCpuLimit
[2022-06-02T13:52:14.395] _slurm_rpc_submit_batch_job: Job violates accounting/QOS policy (job submit limit, user's size and/or time limits)
[2022-06-02T13:52:40.505] _slurm_rpc_submit_batch_job: JobId=42915 InitPrio=27726 usec=549
[2022-06-02T13:52:40.920] sched: Allocate JobId=42915 NodeList=cpu10 #CPUs=4 Partition=cpu-opteron
[2022-06-02T14:21:23.235] _slurm_rpc_submit_batch_job: JobId=42916 InitPrio=23756 usec=473
[2022-06-02T14:21:24.000] sched: Allocate JobId=42916 NodeList=cpu10 #CPUs=16 Partition=cpu-opteron
[2022-06-02T14:25:43.325] _slurm_rpc_submit_batch_job: JobId=42917 InitPrio=20096 usec=363
[2022-06-02T14:25:43.492] sched: Allocate JobId=42917 NodeList=gpu02 #CPUs=24 Partition=gpu-titan
[2022-06-02T14:28:18.407] _slurm_rpc_submit_batch_job: JobId=42918 InitPrio=23619 usec=416
[2022-06-02T14:28:18.836] sched: Allocate JobId=42918 NodeList=cpu13 #CPUs=32 Partition=cpu-epyc
[2022-06-02T14:32:41.513] _job_complete: JobId=42917 WEXITSTATUS 0
[2022-06-02T14:32:41.513] _job_complete: JobId=42917 done
[2022-06-02T14:46:33.238] _slurm_rpc_submit_batch_job: JobId=42919 InitPrio=20994 usec=575
[2022-06-02T14:46:33.846] sched: Allocate JobId=42919 NodeList=cpu14 #CPUs=16 Partition=cpu-epyc
[2022-06-02T14:49:33.657] _slurm_rpc_submit_batch_job: JobId=42920 InitPrio=19754 usec=507
[2022-06-02T14:49:34.247] sched: Allocate JobId=42920 NodeList=cpu07 #CPUs=64 Partition=cpu-opteron
[2022-06-02T14:50:45.718] _job_complete: JobId=42905 WEXITSTATUS 0
[2022-06-02T14:50:45.718] _job_complete: JobId=42905 done
[2022-06-02T14:51:24.354] _job_complete: JobId=42920 WEXITSTATUS 1
[2022-06-02T14:51:24.354] _job_complete: JobId=42920 done
[2022-06-02T14:52:54.837] Time limit exhausted for JobId=42915
[2022-06-02T14:54:32.707] _slurm_rpc_submit_batch_job: JobId=42921 InitPrio=19754 usec=457
[2022-06-02T14:54:32.979] sched: Allocate JobId=42921 NodeList=cpu07 #CPUs=64 Partition=cpu-opteron
[2022-06-02T14:54:45.930] error: This association 191(account='free', user='roland', partition='(null)') does not have access to qos normal
[2022-06-02T14:54:45.930] _slurm_rpc_submit_batch_job: Invalid qos specification
[2022-06-02T14:55:56.416] error: This association 191(account='free', user='roland', partition='(null)') does not have access to qos long
[2022-06-02T14:55:56.416] _slurm_rpc_submit_batch_job: Invalid qos specification
[2022-06-02T14:56:23.231] _job_complete: JobId=42921 WEXITSTATUS 1
[2022-06-02T14:56:23.231] _job_complete: JobId=42921 done
[2022-06-02T15:05:21.038] _slurm_rpc_submit_batch_job: JobId=42922 InitPrio=19754 usec=834
[2022-06-02T15:05:21.205] sched: Allocate JobId=42922 NodeList=cpu07 #CPUs=64 Partition=cpu-opteron
[2022-06-02T15:30:28.224] error: This association 195(account='free', user='shahreeza', partition='(null)') does not have access to qos normal
[2022-06-02T15:30:28.224] _slurm_rpc_submit_batch_job: Invalid qos specification
[2022-06-02T15:31:45.620] _slurm_rpc_submit_batch_job: JobId=42923 InitPrio=24101 usec=578
[2022-06-02T15:31:46.174] sched: Allocate JobId=42923 NodeList=gpu04 #CPUs=8 Partition=gpu-k40c
[2022-06-02T15:33:09.068] _job_complete: JobId=42923 WEXITSTATUS 0
[2022-06-02T15:33:09.069] _job_complete: JobId=42923 done
[2022-06-02T15:38:43.379] _job_complete: JobId=42918 WEXITSTATUS 0
[2022-06-02T15:38:43.379] _job_complete: JobId=42918 done
[2022-06-02T15:48:39.143] _job_complete: JobId=42919 WEXITSTATUS 0
[2022-06-02T15:48:39.144] _job_complete: JobId=42919 done
[2022-06-02T15:50:11.307] _slurm_rpc_submit_batch_job: JobId=42924 InitPrio=20304 usec=518
[2022-06-02T15:50:11.616] sched: Allocate JobId=42924 NodeList=cpu01 #CPUs=32 Partition=cpu-opteron
[2022-06-02T15:51:37.882] _slurm_rpc_kill_job: REQUEST_KILL_JOB JobId=42924 uid 548300516
[2022-06-02T15:53:38.778] _slurm_rpc_submit_batch_job: JobId=42925 InitPrio=20304 usec=367
[2022-06-02T15:53:38.981] sched: Allocate JobId=42925 NodeList=cpu01 #CPUs=32 Partition=cpu-opteron
[2022-06-02T15:56:03.910] _slurm_rpc_submit_batch_job: JobId=42926 InitPrio=20304 usec=508
[2022-06-02T16:44:15.782] _slurm_rpc_submit_batch_job: JobId=42927 InitPrio=19202 usec=585
[2022-06-02T16:44:16.504] sched: Allocate JobId=42927 NodeList=cpu03 #CPUs=64 Partition=cpu-opteron
[2022-06-02T16:45:25.802] _job_complete: JobId=42927 WEXITSTATUS 0
[2022-06-02T16:45:25.803] _job_complete: JobId=42927 done
[2022-06-02T16:58:12.426] _slurm_rpc_submit_batch_job: JobId=42928 InitPrio=19475 usec=493
[2022-06-02T16:58:13.232] sched: Allocate JobId=42928 NodeList=cpu01 #CPUs=32 Partition=cpu-opteron
[2022-06-02T16:59:39.509] _job_complete: JobId=42928 WEXITSTATUS 0
[2022-06-02T16:59:39.509] _job_complete: JobId=42928 done
[2022-06-02T17:02:32.001] _slurm_rpc_submit_batch_job: JobId=42929 InitPrio=19475 usec=393
[2022-06-02T17:02:32.832] sched: Allocate JobId=42929 NodeList=cpu01 #CPUs=32 Partition=cpu-opteron
[2022-06-02T17:03:35.569] _job_complete: JobId=42929 WEXITSTATUS 0
[2022-06-02T17:03:35.569] _job_complete: JobId=42929 done
[2022-06-02T17:07:29.217] _slurm_rpc_submit_batch_job: JobId=42930 InitPrio=19475 usec=417
[2022-06-02T17:07:29.390] sched: Allocate JobId=42930 NodeList=cpu01 #CPUs=32 Partition=cpu-opteron
[2022-06-02T17:08:32.373] _job_complete: JobId=42930 WEXITSTATUS 0
[2022-06-02T17:08:32.373] _job_complete: JobId=42930 done
[2022-06-02T17:10:17.362] _slurm_rpc_submit_batch_job: JobId=42931 InitPrio=19475 usec=750
[2022-06-02T17:10:17.632] sched: Allocate JobId=42931 NodeList=cpu01 #CPUs=32 Partition=cpu-opteron
[2022-06-02T17:10:33.320] _job_complete: JobId=42931 WEXITSTATUS 0
[2022-06-02T17:10:33.321] _job_complete: JobId=42931 done
[2022-06-02T17:12:33.364] _slurm_rpc_submit_batch_job: JobId=42932 InitPrio=19612 usec=357
[2022-06-02T17:12:33.902] sched: Allocate JobId=42932 NodeList=cpu13 #CPUs=16 Partition=cpu-epyc
[2022-06-02T17:13:27.710] _job_complete: JobId=42932 WEXITSTATUS 0
[2022-06-02T17:13:27.710] _job_complete: JobId=42932 done
[2022-06-02T17:23:56.911] _slurm_rpc_submit_batch_job: JobId=42933 InitPrio=19612 usec=377
[2022-06-02T17:23:58.163] sched: Allocate JobId=42933 NodeList=cpu13 #CPUs=16 Partition=cpu-epyc
[2022-06-02T17:24:53.165] _job_complete: JobId=42933 WEXITSTATUS 0
[2022-06-02T17:24:53.166] _job_complete: JobId=42933 done
[2022-06-02T17:48:44.689] _slurm_rpc_submit_batch_job: JobId=42934 InitPrio=19612 usec=503
[2022-06-02T17:48:44.807] sched: Allocate JobId=42934 NodeList=cpu13 #CPUs=16 Partition=cpu-epyc
[2022-06-02T17:50:07.267] _job_complete: JobId=42934 WEXITSTATUS 0
[2022-06-02T17:50:07.267] _job_complete: JobId=42934 done
[2022-06-02T17:51:17.063] _slurm_rpc_submit_batch_job: JobId=42935 InitPrio=19612 usec=412
[2022-06-02T17:51:18.023] sched: Allocate JobId=42935 NodeList=cpu13 #CPUs=16 Partition=cpu-epyc
[2022-06-02T17:53:48.512] _slurm_rpc_submit_batch_job: JobId=42936 InitPrio=19612 usec=415
[2022-06-02T17:53:49.355] sched: Allocate JobId=42936 NodeList=cpu13 #CPUs=16 Partition=cpu-epyc
[2022-06-02T17:54:07.694] _job_complete: JobId=42936 WEXITSTATUS 0
[2022-06-02T17:54:07.695] _job_complete: JobId=42936 done
[2022-06-02T18:51:25.507] Time limit exhausted for JobId=42935
[2022-06-02T19:57:03.011] _slurm_rpc_kill_job: REQUEST_KILL_JOB JobId=42833 uid 548200029
[2022-06-02T19:57:08.768] _slurm_rpc_kill_job: REQUEST_KILL_JOB JobId=42832 uid 548200029
[2022-06-02T19:57:13.588] _slurm_rpc_kill_job: REQUEST_KILL_JOB JobId=42829 uid 548200029
[2022-06-02T20:04:21.114] _job_complete: JobId=42925 WEXITSTATUS 0
[2022-06-02T20:04:21.114] _job_complete: JobId=42925 done
[2022-06-02T20:40:14.345] _slurm_rpc_submit_batch_job: JobId=42937 InitPrio=19612 usec=461
[2022-06-02T20:40:14.451] sched: Allocate JobId=42937 NodeList=cpu13 #CPUs=16 Partition=cpu-epyc
[2022-06-02T20:41:36.461] _job_complete: JobId=42937 WEXITSTATUS 0
[2022-06-02T20:41:36.462] _job_complete: JobId=42937 done
[2022-06-02T20:44:14.078] _slurm_rpc_submit_batch_job: JobId=42938 InitPrio=19475 usec=389
[2022-06-02T20:44:14.909] sched: Allocate JobId=42938 NodeList=cpu13 #CPUs=32 Partition=cpu-epyc
[2022-06-02T20:45:37.382] _slurm_rpc_submit_batch_job: JobId=42939 InitPrio=19612 usec=343
[2022-06-02T20:45:38.033] sched: Allocate JobId=42939 NodeList=cpu14 #CPUs=16 Partition=cpu-epyc
[2022-06-02T20:46:03.713] _job_complete: JobId=42939 WEXITSTATUS 0
[2022-06-02T20:46:03.713] _job_complete: JobId=42939 done
[2022-06-02T22:28:36.287] sched: _slurm_rpc_allocate_resources JobId=42940 NodeList=cpu10 usec=16331
[2022-06-02T22:35:07.983] job_step_signal: JobId=42940 StepId=0 not found
[2022-06-02T22:35:07.985] _job_complete: JobId=42940 WTERMSIG 126
[2022-06-02T22:35:07.985] _job_complete: JobId=42940 cancelled by interactive user
[2022-06-02T22:35:07.985] _job_complete: JobId=42940 done
[2022-06-02T22:47:04.806] _job_complete: JobId=42916 WEXITSTATUS 0
[2022-06-02T22:47:04.807] _job_complete: JobId=42916 done
[2022-06-03T00:01:41.664] _slurm_rpc_submit_batch_job: JobId=42941 InitPrio=25137 usec=447
[2022-06-03T00:01:42.152] sched: Allocate JobId=42941 NodeList=cpu14 #CPUs=16 Partition=cpu-epyc
[2022-06-03T00:02:39.024] _job_complete: JobId=42941 WEXITSTATUS 0
[2022-06-03T00:02:39.024] _job_complete: JobId=42941 done
[2022-06-03T00:05:12.821] _job_complete: JobId=42938 WEXITSTATUS 3
[2022-06-03T00:05:12.821] _job_complete: JobId=42938 done
[2022-06-03T00:24:12.816] _slurm_rpc_submit_batch_job: JobId=42942 InitPrio=25137 usec=598
[2022-06-03T00:24:13.797] sched: Allocate JobId=42942 NodeList=cpu14 #CPUs=16 Partition=cpu-epyc
[2022-06-03T00:25:07.247] _job_complete: JobId=42942 WEXITSTATUS 0
[2022-06-03T00:25:07.247] _job_complete: JobId=42942 done
[2022-06-03T00:37:48.586] _slurm_rpc_submit_batch_job: JobId=42943 InitPrio=23206 usec=457
[2022-06-03T00:37:49.459] sched: Allocate JobId=42943 NodeList=cpu14 #CPUs=48 Partition=cpu-epyc
[2022-06-03T00:39:54.038] _job_complete: JobId=42943 OOM failure
[2022-06-03T00:39:54.038] _job_complete: JobId=42943 done
[2022-06-03T00:47:48.659] _slurm_rpc_submit_batch_job: JobId=42944 InitPrio=20846 usec=394
[2022-06-03T00:47:49.563] sched: Allocate JobId=42944 NodeList=cpu10 #CPUs=1 Partition=cpu-opteron
[2022-06-03T00:47:58.372] _job_complete: JobId=42944 WEXITSTATUS 0
[2022-06-03T00:47:58.373] _job_complete: JobId=42944 done
[2022-06-03T00:49:19.563] _slurm_rpc_submit_batch_job: JobId=42945 InitPrio=20846 usec=573
[2022-06-03T00:49:19.675] sched: Allocate JobId=42945 NodeList=cpu10 #CPUs=1 Partition=cpu-opteron
[2022-06-03T00:49:28.913] _job_complete: JobId=42945 WEXITSTATUS 0
[2022-06-03T00:49:28.913] _job_complete: JobId=42945 done
[2022-06-03T00:51:02.041] _slurm_rpc_submit_batch_job: JobId=42946 InitPrio=20846 usec=351
[2022-06-03T00:51:02.821] sched: Allocate JobId=42946 NodeList=cpu10 #CPUs=1 Partition=cpu-opteron
[2022-06-03T00:51:31.987] _job_complete: JobId=42946 WEXITSTATUS 0
[2022-06-03T00:51:31.987] _job_complete: JobId=42946 done
[2022-06-03T02:31:20.233] _job_complete: JobId=42922 OOM failure
[2022-06-03T02:31:20.233] _job_complete: JobId=42922 done
[2022-06-03T03:39:42.449] _slurm_rpc_submit_batch_job: JobId=42947 InitPrio=21615 usec=480
[2022-06-03T03:39:42.800] sched: Allocate JobId=42947 NodeList=gpu02 #CPUs=8 Partition=gpu-titan
[2022-06-03T03:40:24.334] _job_complete: JobId=42947 WEXITSTATUS 1
[2022-06-03T03:40:24.334] _job_complete: JobId=42947 done
[2022-06-03T03:40:35.799] _slurm_rpc_submit_batch_job: JobId=42948 InitPrio=21615 usec=494
[2022-06-03T03:40:35.859] sched: Allocate JobId=42948 NodeList=gpu02 #CPUs=8 Partition=gpu-titan
[2022-06-03T03:40:59.758] _job_complete: JobId=42948 WEXITSTATUS 1
[2022-06-03T03:40:59.758] _job_complete: JobId=42948 done
[2022-06-03T03:43:09.507] _slurm_rpc_submit_batch_job: JobId=42949 InitPrio=21615 usec=459
[2022-06-03T03:43:10.228] sched: Allocate JobId=42949 NodeList=gpu02 #CPUs=8 Partition=gpu-titan
[2022-06-03T03:43:35.123] _job_complete: JobId=42949 WEXITSTATUS 1
[2022-06-03T03:43:35.123] _job_complete: JobId=42949 done
[2022-06-03T03:44:07.986] _slurm_rpc_submit_batch_job: JobId=42950 InitPrio=21615 usec=392
[2022-06-03T03:44:08.310] sched: Allocate JobId=42950 NodeList=gpu02 #CPUs=8 Partition=gpu-titan
[2022-06-03T03:44:31.901] _job_complete: JobId=42950 WEXITSTATUS 1
[2022-06-03T03:44:31.901] _job_complete: JobId=42950 done
[2022-06-03T03:45:43.842] _slurm_rpc_submit_batch_job: JobId=42951 InitPrio=21615 usec=409
[2022-06-03T03:45:44.446] sched: Allocate JobId=42951 NodeList=gpu02 #CPUs=8 Partition=gpu-titan
[2022-06-03T03:46:33.890] _slurm_rpc_submit_batch_job: JobId=42952 InitPrio=21615 usec=694
[2022-06-03T03:46:34.516] sched: Allocate JobId=42952 NodeList=gpu02 #CPUs=8 Partition=gpu-titan
[2022-06-03T03:50:49.829] _slurm_rpc_submit_batch_job: JobId=42953 InitPrio=21615 usec=423
[2022-06-03T03:50:49.993] sched: Allocate JobId=42953 NodeList=gpu02 #CPUs=8 Partition=gpu-titan
[2022-06-03T03:51:29.754] _slurm_rpc_submit_batch_job: JobId=42954 InitPrio=21615 usec=469
[2022-06-03T03:52:21.078] _slurm_rpc_submit_batch_job: JobId=42955 InitPrio=21615 usec=413
[2022-06-03T03:57:27.101] _slurm_rpc_submit_batch_job: JobId=42956 InitPrio=21615 usec=561
[2022-06-03T04:11:02.277] _slurm_rpc_submit_batch_job: JobId=42957 InitPrio=24377 usec=426
[2022-06-03T05:51:04.902] _job_complete: JobId=42913 WEXITSTATUS 0
[2022-06-03T05:51:04.902] _job_complete: JobId=42913 done
[2022-06-03T05:51:05.266] sched: Allocate JobId=42954 NodeList=gpu05 #CPUs=8 Partition=gpu-v100s
[2022-06-03T05:51:05.267] sched: Allocate JobId=42955 NodeList=gpu05 #CPUs=8 Partition=gpu-v100s
[2022-06-03T07:34:06.101] _slurm_rpc_kill_job: REQUEST_KILL_JOB JobId=42926 uid 548300516
[2022-06-03T08:29:13.775] _slurm_rpc_submit_batch_job: JobId=42958 InitPrio=25137 usec=720
[2022-06-03T08:29:14.026] sched: Allocate JobId=42958 NodeList=cpu14 #CPUs=16 Partition=cpu-epyc
[2022-06-03T08:37:49.251] _job_complete: JobId=42958 WEXITSTATUS 0
[2022-06-03T08:37:49.251] _job_complete: JobId=42958 done
[2022-06-03T12:57:18.760] _job_complete: JobId=42912 WEXITSTATUS 0
[2022-06-03T12:57:18.761] _job_complete: JobId=42912 done
[2022-06-03T13:39:52.322] _slurm_rpc_submit_batch_job: JobId=42959 InitPrio=20028 usec=465
[2022-06-03T13:39:52.615] sched: Allocate JobId=42959 NodeList=gpu03 #CPUs=32 Partition=gpu-k10
[2022-06-03T13:40:25.197] _job_complete: JobId=42959 WEXITSTATUS 1
[2022-06-03T13:40:25.198] _job_complete: JobId=42959 done
[2022-06-03T13:42:36.882] _slurm_rpc_submit_batch_job: JobId=42960 InitPrio=19754 usec=434
[2022-06-03T13:42:36.939] sched: Allocate JobId=42960 NodeList=cpu07 #CPUs=64 Partition=cpu-opteron
[2022-06-03T14:32:40.071] _job_complete: JobId=42810 WEXITSTATUS 1
[2022-06-03T14:32:40.071] _job_complete: JobId=42810 done
[2022-06-03T15:02:22.311] _slurm_rpc_submit_batch_job: JobId=42961 InitPrio=22099 usec=523
[2022-06-03T15:02:22.819] sched: Allocate JobId=42961 NodeList=cpu10 #CPUs=16 Partition=cpu-opteron
[2022-06-03T15:02:41.842] _slurm_rpc_submit_batch_job: JobId=42962 InitPrio=22099 usec=426
[2022-06-03T15:02:41.874] sched: Allocate JobId=42962 NodeList=cpu13 #CPUs=16 Partition=cpu-epyc
[2022-06-03T15:02:54.826] _slurm_rpc_submit_batch_job: JobId=42963 InitPrio=22099 usec=480
[2022-06-03T15:02:54.892] sched: Allocate JobId=42963 NodeList=cpu13 #CPUs=16 Partition=cpu-epyc
[2022-06-03T15:03:06.219] _slurm_rpc_submit_batch_job: JobId=42964 InitPrio=22099 usec=573
[2022-06-03T15:03:06.907] sched: Allocate JobId=42964 NodeList=cpu14 #CPUs=16 Partition=cpu-epyc
[2022-06-03T15:03:18.394] _slurm_rpc_submit_batch_job: JobId=42965 InitPrio=22099 usec=523
[2022-06-03T15:03:18.923] sched: Allocate JobId=42965 NodeList=cpu14 #CPUs=16 Partition=cpu-epyc
[2022-06-03T15:03:24.651] _slurm_rpc_submit_batch_job: JobId=42966 InitPrio=22099 usec=575
[2022-06-03T15:03:24.931] sched: Allocate JobId=42966 NodeList=cpu14 #CPUs=16 Partition=cpu-epyc
[2022-06-03T15:03:31.651] _slurm_rpc_submit_batch_job: JobId=42967 InitPrio=22099 usec=453
[2022-06-03T15:03:31.942] sched: Allocate JobId=42967 NodeList=cpu14 #CPUs=16 Partition=cpu-epyc
[2022-06-03T15:03:39.450] _slurm_rpc_submit_batch_job: JobId=42968 InitPrio=22099 usec=428
[2022-06-03T15:03:39.953] sched: Allocate JobId=42968 NodeList=cpu14 #CPUs=16 Partition=cpu-epyc
[2022-06-03T15:03:45.106] _slurm_rpc_submit_batch_job: JobId=42969 InitPrio=22099 usec=469
[2022-06-03T15:03:45.962] sched: Allocate JobId=42969 NodeList=cpu14 #CPUs=16 Partition=cpu-epyc
[2022-06-03T15:03:54.707] _slurm_rpc_submit_batch_job: JobId=42970 InitPrio=22099 usec=555
[2022-06-03T15:08:44.139] _slurm_rpc_kill_job: REQUEST_KILL_JOB JobId=42961 uid 548200020
[2022-06-03T15:08:57.107] _slurm_rpc_submit_batch_job: JobId=42971 InitPrio=22099 usec=367
[2022-06-03T15:33:32.068] _slurm_rpc_submit_batch_job: JobId=42972 InitPrio=20028 usec=593
[2022-06-03T15:33:32.296] sched: Allocate JobId=42972 NodeList=gpu03 #CPUs=32 Partition=gpu-k10
[2022-06-03T15:42:34.918] _job_complete: JobId=42775 WEXITSTATUS 0
[2022-06-03T15:42:34.918] _job_complete: JobId=42775 done
[2022-06-03T15:42:35.842] sched: Allocate JobId=42970 NodeList=cpu15 #CPUs=16 Partition=cpu-epyc
[2022-06-03T15:42:35.842] sched: Allocate JobId=42971 NodeList=cpu15 #CPUs=16 Partition=cpu-epyc
[2022-06-03T15:43:39.047] _slurm_rpc_submit_batch_job: JobId=42973 InitPrio=20028 usec=606
[2022-06-03T15:43:39.328] sched: Allocate JobId=42973 NodeList=gpu01 #CPUs=32 Partition=gpu-k10
[2022-06-03T15:44:09.606] _job_complete: JobId=42968 WEXITSTATUS 0
[2022-06-03T15:44:09.606] _job_complete: JobId=42968 done
[2022-06-03T15:44:10.107] _job_complete: JobId=42963 WEXITSTATUS 0
[2022-06-03T15:44:10.108] _job_complete: JobId=42963 done
[2022-06-03T15:44:20.419] _job_complete: JobId=42962 WEXITSTATUS 0
[2022-06-03T15:44:20.420] _job_complete: JobId=42962 done
[2022-06-03T15:44:28.550] _job_complete: JobId=42967 WEXITSTATUS 0
[2022-06-03T15:44:28.550] _job_complete: JobId=42967 done
[2022-06-03T15:45:14.984] _job_complete: JobId=42964 WEXITSTATUS 0
[2022-06-03T15:45:14.984] _job_complete: JobId=42964 done
[2022-06-03T15:45:31.884] _job_complete: JobId=42966 WEXITSTATUS 0
[2022-06-03T15:45:31.884] _job_complete: JobId=42966 done
[2022-06-03T15:45:43.687] _job_complete: JobId=42969 WEXITSTATUS 0
[2022-06-03T15:45:43.687] _job_complete: JobId=42969 done
[2022-06-03T15:45:45.073] _job_complete: JobId=42965 WEXITSTATUS 0
[2022-06-03T15:45:45.073] _job_complete: JobId=42965 done
[2022-06-03T15:50:17.480] _slurm_rpc_submit_batch_job: JobId=42974 InitPrio=22099 usec=401
[2022-06-03T15:50:18.012] sched: Allocate JobId=42974 NodeList=cpu10 #CPUs=16 Partition=cpu-opteron
[2022-06-03T16:20:15.801] _job_complete: JobId=42970 WEXITSTATUS 0
[2022-06-03T16:20:15.801] _job_complete: JobId=42970 done
[2022-06-03T16:21:14.921] _job_complete: JobId=42971 WEXITSTATUS 0
[2022-06-03T16:21:14.921] _job_complete: JobId=42971 done
[2022-06-03T17:02:53.696] _slurm_rpc_submit_batch_job: JobId=42975 InitPrio=34598 usec=545
[2022-06-03T17:02:54.075] sched: Allocate JobId=42975 NodeList=cpu10 #CPUs=8 Partition=cpu-opteron
[2022-06-03T17:14:43.021] _job_complete: JobId=42974 WEXITSTATUS 0
[2022-06-03T17:14:43.021] _job_complete: JobId=42974 done
[2022-06-03T17:23:55.338] _job_complete: JobId=42975 WEXITSTATUS 0
[2022-06-03T17:23:55.339] _job_complete: JobId=42975 done
[2022-06-03T17:26:20.096] _slurm_rpc_submit_batch_job: JobId=42976 InitPrio=22238 usec=491
[2022-06-03T17:26:20.570] sched: Allocate JobId=42976 NodeList=cpu10 #CPUs=32 Partition=cpu-opteron
[2022-06-03T17:59:18.940] _job_complete: JobId=42976 WEXITSTATUS 1
[2022-06-03T17:59:18.941] _job_complete: JobId=42976 done
[2022-06-03T18:17:35.670] _job_complete: JobId=42744 WEXITSTATUS 0
[2022-06-03T18:17:35.671] _job_complete: JobId=42744 done
[2022-06-03T18:54:47.585] _job_complete: JobId=42698 WEXITSTATUS 0
[2022-06-03T18:54:47.585] _job_complete: JobId=42698 done
[2022-06-03T20:51:13.514] _slurm_rpc_submit_batch_job: JobId=42977 InitPrio=22238 usec=479
[2022-06-03T20:51:14.038] sched: Allocate JobId=42977 NodeList=cpu10 #CPUs=32 Partition=cpu-opteron
[2022-06-03T21:05:31.833] _slurm_rpc_submit_batch_job: JobId=42978 InitPrio=22238 usec=411
[2022-06-03T21:05:32.585] sched: Allocate JobId=42978 NodeList=cpu11 #CPUs=32 Partition=cpu-opteron
[2022-06-03T21:20:34.088] _job_complete: JobId=42973 WEXITSTATUS 1
[2022-06-03T21:20:34.088] _job_complete: JobId=42973 done
[2022-06-03T21:25:50.878] _job_complete: JobId=42340 WEXITSTATUS 0
[2022-06-03T21:25:50.882] _job_complete: JobId=42340 done
[2022-06-03T23:32:18.701] _job_complete: JobId=42456 WEXITSTATUS 0
[2022-06-03T23:32:18.707] _job_complete: JobId=42456 done
[2022-06-04T00:13:29.544] _job_complete: JobId=42977 WEXITSTATUS 0
[2022-06-04T00:13:29.549] _job_complete: JobId=42977 done
[2022-06-04T02:20:02.167] _job_complete: JobId=42972 WEXITSTATUS 0
[2022-06-04T02:20:02.168] _job_complete: JobId=42972 done
[2022-06-04T02:40:44.834] _slurm_rpc_submit_batch_job: JobId=42979 InitPrio=28848 usec=413
[2022-06-04T02:40:45.094] sched: Allocate JobId=42979 NodeList=cpu01 #CPUs=2 Partition=cpu-opteron
[2022-06-04T02:57:43.753] _job_complete: JobId=42979 WEXITSTATUS 0
[2022-06-04T02:57:43.754] _job_complete: JobId=42979 done
[2022-06-04T02:59:57.063] _job_complete: JobId=42978 WEXITSTATUS 0
[2022-06-04T02:59:57.068] _job_complete: JobId=42978 done
[2022-06-04T04:06:04.226] _job_complete: JobId=42699 WEXITSTATUS 0
[2022-06-04T04:06:04.280] _job_complete: JobId=42699 done
[2022-06-04T05:11:02.415] _job_complete: JobId=42960 WEXITSTATUS 0
[2022-06-04T05:11:02.416] _job_complete: JobId=42960 done
[2022-06-04T05:12:51.301] _slurm_rpc_submit_batch_job: JobId=42980 InitPrio=22238 usec=528
[2022-06-04T05:12:52.031] sched: Allocate JobId=42980 NodeList=cpu10 #CPUs=32 Partition=cpu-opteron
[2022-06-04T05:14:09.799] _slurm_rpc_submit_batch_job: JobId=42981 InitPrio=22238 usec=525
[2022-06-04T05:14:10.127] sched: Allocate JobId=42981 NodeList=cpu11 #CPUs=32 Partition=cpu-opteron
[2022-06-04T05:17:22.660] _slurm_rpc_submit_batch_job: JobId=42982 InitPrio=22238 usec=359
[2022-06-04T05:17:23.505] sched: Allocate JobId=42982 NodeList=cpu11 #CPUs=32 Partition=cpu-opteron
[2022-06-04T05:20:33.171] _slurm_rpc_submit_batch_job: JobId=42983 InitPrio=22238 usec=366
[2022-06-04T05:20:33.781] sched: Allocate JobId=42983 NodeList=cpu01 #CPUs=32 Partition=cpu-opteron
[2022-06-04T05:46:39.488] _job_complete: JobId=42983 WEXITSTATUS 0
[2022-06-04T05:46:39.489] _job_complete: JobId=42983 done
[2022-06-04T05:50:09.670] _job_complete: JobId=42982 WEXITSTATUS 0
[2022-06-04T05:50:09.670] _job_complete: JobId=42982 done
[2022-06-04T08:55:08.562] _job_complete: JobId=42780 WEXITSTATUS 0
[2022-06-04T08:55:08.566] _job_complete: JobId=42780 done
[2022-06-04T11:05:48.955] _pick_best_nodes: JobId=42984 never runnable in partition gpu-k10
[2022-06-04T11:05:48.960] _slurm_rpc_submit_batch_job: Requested node configuration is not available
[2022-06-04T11:06:11.904] _slurm_rpc_submit_batch_job: JobId=42985 InitPrio=16896 usec=438
[2022-06-04T11:06:58.938] _slurm_rpc_kill_job: REQUEST_KILL_JOB JobId=42985 uid 548200029
[2022-06-04T11:07:26.671] _slurm_rpc_submit_batch_job: JobId=42986 InitPrio=19001 usec=404
[2022-06-04T11:07:36.086] _slurm_rpc_kill_job: REQUEST_KILL_JOB JobId=42986 uid 548200029
[2022-06-04T11:07:54.922] _pick_best_nodes: JobId=42987 never runnable in partition gpu-k10
[2022-06-04T11:07:54.922] _slurm_rpc_submit_batch_job: Requested node configuration is not available
[2022-06-04T11:08:27.023] _slurm_rpc_submit_batch_job: JobId=42988 InitPrio=20717 usec=510
[2022-06-04T11:08:27.147] sched: Allocate JobId=42988 NodeList=gpu01 #CPUs=16 Partition=gpu-k10
[2022-06-04T11:12:21.870] _slurm_rpc_submit_batch_job: JobId=42989 InitPrio=20717 usec=965
[2022-06-04T11:12:22.574] sched: Allocate JobId=42989 NodeList=gpu03 #CPUs=16 Partition=gpu-k10
[2022-06-04T11:12:23.206] _job_complete: JobId=42988 WEXITSTATUS 134
[2022-06-04T11:12:23.206] _job_complete: JobId=42988 done
[2022-06-04T11:27:09.684] _slurm_rpc_submit_batch_job: JobId=42990 InitPrio=20717 usec=487
[2022-06-04T11:27:10.165] sched: Allocate JobId=42990 NodeList=gpu01 #CPUs=16 Partition=gpu-k10
[2022-06-04T11:27:35.212] _slurm_rpc_kill_job: REQUEST_KILL_JOB JobId=42989 uid 548200029
[2022-06-04T11:27:49.501] _slurm_rpc_submit_batch_job: JobId=42991 InitPrio=20717 usec=880
[2022-06-04T11:27:50.338] sched: Allocate JobId=42991 NodeList=gpu03 #CPUs=16 Partition=gpu-k10
[2022-06-04T11:36:47.309] sched: _slurm_rpc_allocate_resources JobId=42992 NodeList=cpu11 usec=13199
[2022-06-04T11:39:16.362] _job_complete: JobId=42992 WEXITSTATUS 0
[2022-06-04T11:39:16.362] _job_complete: JobId=42992 done
[2022-06-04T11:49:46.731] sched: _slurm_rpc_allocate_resources JobId=42993 NodeList=cpu11 usec=4135
[2022-06-04T11:50:57.248] _job_complete: JobId=42993 WEXITSTATUS 0
[2022-06-04T11:50:57.248] _job_complete: JobId=42993 done
[2022-06-04T11:53:29.065] sched: _slurm_rpc_allocate_resources JobId=42994 NodeList=cpu11 usec=1102
[2022-06-04T11:53:50.187] _job_complete: JobId=42994 WEXITSTATUS 0
[2022-06-04T11:53:50.187] _job_complete: JobId=42994 done
[2022-06-04T11:54:29.187] sched: _slurm_rpc_allocate_resources JobId=42995 NodeList=cpu11 usec=1369
[2022-06-04T11:55:07.054] _job_complete: JobId=42995 WEXITSTATUS 0
[2022-06-04T11:55:07.054] _job_complete: JobId=42995 done
[2022-06-04T11:55:50.483] sched: _slurm_rpc_allocate_resources JobId=42996 NodeList=cpu11 usec=1196
[2022-06-04T11:56:04.510] _job_complete: JobId=42996 WEXITSTATUS 0
[2022-06-04T11:56:04.510] _job_complete: JobId=42996 done
[2022-06-04T11:56:47.403] sched: _slurm_rpc_allocate_resources JobId=42997 NodeList=cpu11 usec=1105
[2022-06-04T11:57:06.644] _job_complete: JobId=42997 WEXITSTATUS 0
[2022-06-04T11:57:06.644] _job_complete: JobId=42997 done
[2022-06-04T14:33:07.389] error: This association 191(account='free', user='roland', partition='(null)') does not have access to qos normal
[2022-06-04T14:33:07.389] _slurm_rpc_submit_batch_job: Invalid qos specification
[2022-06-04T14:33:39.059] _pick_best_nodes: JobId=42998 never runnable in partition cpu-opteron
[2022-06-04T14:33:39.059] _slurm_rpc_submit_batch_job: Requested node configuration is not available
[2022-06-04T14:35:19.307] _pick_best_nodes: JobId=42999 never runnable in partition cpu-opteron
[2022-06-04T14:35:19.307] _slurm_rpc_submit_batch_job: Requested node configuration is not available
[2022-06-04T14:38:16.697] _pick_best_nodes: JobId=43000 never runnable in partition cpu-opteron
[2022-06-04T14:38:16.697] _slurm_rpc_submit_batch_job: Requested node configuration is not available
[2022-06-04T14:39:26.430] _slurm_rpc_submit_batch_job: JobId=43001 InitPrio=27726 usec=896
[2022-06-04T14:39:26.571] sched: Allocate JobId=43001 NodeList=cpu11 #CPUs=4 Partition=cpu-opteron
[2022-06-04T14:40:05.933] _slurm_rpc_kill_job: REQUEST_KILL_JOB JobId=43001 uid 548300561
[2022-06-04T14:41:36.574] _pick_best_nodes: JobId=43002 never runnable in partition cpu-opteron
[2022-06-04T14:41:36.574] _slurm_rpc_submit_batch_job: Requested node configuration is not available
[2022-06-04T14:41:59.666] _slurm_rpc_submit_batch_job: JobId=43003 InitPrio=27726 usec=414
[2022-06-04T14:41:59.774] sched: Allocate JobId=43003 NodeList=cpu11 #CPUs=4 Partition=cpu-opteron
[2022-06-04T14:42:00.218] _job_complete: JobId=43003 WEXITSTATUS 0
[2022-06-04T14:42:00.218] _job_complete: JobId=43003 done
[2022-06-04T14:45:08.571] _slurm_rpc_submit_batch_job: JobId=43004 InitPrio=27726 usec=398
[2022-06-04T14:45:09.208] sched: Allocate JobId=43004 NodeList=cpu13 #CPUs=4 Partition=cpu-epyc
[2022-06-04T14:45:09.560] _job_complete: JobId=43004 WEXITSTATUS 0
[2022-06-04T14:45:09.560] _job_complete: JobId=43004 done
[2022-06-04T16:15:53.282] _slurm_rpc_submit_batch_job: JobId=43005 InitPrio=28521 usec=568
[2022-06-04T16:15:54.001] sched: Allocate JobId=43005 NodeList=cpu11 #CPUs=8 Partition=cpu-opteron
[2022-06-04T17:18:09.451] _job_complete: JobId=43005 WEXITSTATUS 1
[2022-06-04T17:18:09.452] _job_complete: JobId=43005 done
[2022-06-04T18:09:37.315] _slurm_rpc_kill_job: REQUEST_KILL_JOB JobId=42991 uid 548200029
[2022-06-04T18:10:35.373] _slurm_rpc_submit_batch_job: JobId=43006 InitPrio=20717 usec=920
[2022-06-04T18:10:36.040] sched: Allocate JobId=43006 NodeList=gpu03 #CPUs=16 Partition=gpu-k10
[2022-06-04T19:01:39.359] _slurm_rpc_submit_batch_job: JobId=43007 InitPrio=19615 usec=460
[2022-06-04T19:01:39.970] sched: Allocate JobId=43007 NodeList=cpu12 #CPUs=48 Partition=cpu-epyc
[2022-06-04T19:01:57.786] sched: _slurm_rpc_allocate_resources JobId=43008 NodeList=cpu11 usec=12433
[2022-06-04T19:09:41.270] sched: _slurm_rpc_allocate_resources JobId=43009 NodeList=cpu11 usec=1131
[2022-06-04T19:43:45.813] _job_complete: JobId=43009 WEXITSTATUS 0
[2022-06-04T19:43:45.813] _job_complete: JobId=43009 done
[2022-06-04T19:45:01.157] _slurm_rpc_submit_batch_job: JobId=43010 InitPrio=21062 usec=374
[2022-06-04T19:45:18.877] _slurm_rpc_kill_job: REQUEST_KILL_JOB JobId=42955 uid 548200083
[2022-06-04T19:45:26.984] sched: Allocate JobId=43010 NodeList=gpu05 #CPUs=8 Partition=gpu-v100s
[2022-06-04T19:45:27.261] _job_complete: JobId=43010 WEXITSTATUS 1
[2022-06-04T19:45:27.261] _job_complete: JobId=43010 done
[2022-06-04T19:46:36.957] _slurm_rpc_submit_batch_job: JobId=43011 InitPrio=21062 usec=532
[2022-06-04T19:46:37.816] sched: Allocate JobId=43011 NodeList=gpu05 #CPUs=8 Partition=gpu-v100s
[2022-06-04T19:46:38.027] _job_complete: JobId=43011 WEXITSTATUS 1
[2022-06-04T19:46:38.028] _job_complete: JobId=43011 done
[2022-06-04T19:48:18.754] _slurm_rpc_submit_batch_job: JobId=43012 InitPrio=21062 usec=420
[2022-06-04T19:48:19.071] sched: Allocate JobId=43012 NodeList=gpu05 #CPUs=8 Partition=gpu-v100s
[2022-06-04T19:57:01.933] _slurm_rpc_submit_batch_job: JobId=43013 InitPrio=21062 usec=395
[2022-06-04T19:57:17.283] _slurm_rpc_kill_job: REQUEST_KILL_JOB JobId=42954 uid 548200083
[2022-06-04T19:57:25.192] sched: Allocate JobId=43013 NodeList=gpu05 #CPUs=8 Partition=gpu-v100s
[2022-06-04T19:58:22.582] _job_complete: JobId=43013 WEXITSTATUS 1
[2022-06-04T19:58:22.582] _job_complete: JobId=43013 done
[2022-06-04T20:01:40.674] _slurm_rpc_submit_batch_job: JobId=43014 InitPrio=21062 usec=389
[2022-06-04T20:01:41.460] sched: Allocate JobId=43014 NodeList=gpu05 #CPUs=8 Partition=gpu-v100s
[2022-06-04T20:02:36.917] _job_complete: JobId=43014 WEXITSTATUS 1
[2022-06-04T20:02:36.918] _job_complete: JobId=43014 done
[2022-06-04T20:04:47.672] _slurm_rpc_submit_batch_job: JobId=43015 InitPrio=21062 usec=388
[2022-06-04T20:04:47.858] sched: Allocate JobId=43015 NodeList=gpu05 #CPUs=8 Partition=gpu-v100s
[2022-06-04T20:08:21.623] _job_complete: JobId=43008 WEXITSTATUS 0
[2022-06-04T20:08:21.623] _job_complete: JobId=43008 done
[2022-06-04T20:12:49.757] _slurm_rpc_submit_batch_job: JobId=43016 InitPrio=21062 usec=406
[2022-06-04T20:13:03.125] _slurm_rpc_kill_job: REQUEST_KILL_JOB JobId=43015 uid 548200083
[2022-06-04T20:13:05.050] sched: Allocate JobId=43016 NodeList=gpu05 #CPUs=8 Partition=gpu-v100s
[2022-06-04T20:13:51.393] _slurm_rpc_kill_job: REQUEST_KILL_JOB JobId=42951 uid 548200083
[2022-06-04T20:14:30.966] sched/backfill: _start_job: Started JobId=42956 in gpu-titan on gpu02
[2022-06-05T00:34:42.878] _job_complete: JobId=42990 WEXITSTATUS 0
[2022-06-05T00:34:42.883] _job_complete: JobId=42990 done
[2022-06-05T00:52:49.273] _slurm_rpc_submit_batch_job: JobId=43017 InitPrio=28028 usec=431
[2022-06-05T00:52:49.725] sched: Allocate JobId=43017 NodeList=cpu11 #CPUs=1 Partition=cpu-opteron
[2022-06-05T01:17:44.390] _slurm_rpc_submit_batch_job: JobId=43018 InitPrio=20996 usec=411
[2022-06-05T01:17:45.073] sched: Allocate JobId=43018 NodeList=cpu14 #CPUs=48 Partition=cpu-epyc
[2022-06-05T01:21:30.234] _slurm_rpc_submit_batch_job: JobId=43019 InitPrio=21270 usec=373
[2022-06-05T01:21:30.389] sched: Allocate JobId=43019 NodeList=cpu11 #CPUs=16 Partition=cpu-opteron
[2022-06-05T02:32:35.623] _job_complete: JobId=43018 WEXITSTATUS 0
[2022-06-05T02:32:35.623] _job_complete: JobId=43018 done
[2022-06-05T02:33:35.565] _job_complete: JobId=43017 WEXITSTATUS 0
[2022-06-05T02:33:35.569] _job_complete: JobId=43017 done
[2022-06-05T02:41:20.138] _job_complete: JobId=43019 WEXITSTATUS 0
[2022-06-05T02:41:20.138] _job_complete: JobId=43019 done
[2022-06-05T08:48:42.627] _slurm_rpc_submit_batch_job: JobId=43020 InitPrio=28028 usec=457
[2022-06-05T08:48:42.899] sched: Allocate JobId=43020 NodeList=cpu11 #CPUs=1 Partition=cpu-opteron
[2022-06-05T08:50:33.192] _job_complete: JobId=43020 WEXITSTATUS 0
[2022-06-05T08:50:33.193] _job_complete: JobId=43020 done
[2022-06-05T08:54:05.752] _slurm_rpc_submit_batch_job: JobId=43021 InitPrio=28028 usec=513
[2022-06-05T08:54:06.570] sched: Allocate JobId=43021 NodeList=cpu11 #CPUs=1 Partition=cpu-opteron
[2022-06-05T09:18:28.820] _slurm_rpc_kill_job: REQUEST_KILL_JOB JobId=43021 uid 548300504
[2022-06-05T09:18:49.898] _slurm_rpc_kill_job: REQUEST_KILL_JOB JobId=43012 uid 548300504
[2022-06-05T09:18:49.898] error: Security violation, REQUEST_KILL_JOB RPC for JobId=43012 from uid 548300504
[2022-06-05T09:18:49.898] _slurm_rpc_kill_job: job_str_signal() uid=548300504 JobId=43012 sig=9 returned: Access/permission denied
[2022-06-05T12:53:27.990] _slurm_rpc_submit_batch_job: JobId=43022 InitPrio=27718 usec=447
[2022-06-05T12:53:28.379] sched: Allocate JobId=43022 NodeList=cpu11 #CPUs=5 Partition=cpu-opteron
[2022-06-05T12:54:16.541] _slurm_rpc_kill_job: REQUEST_KILL_JOB JobId=43022 uid 548300561
[2022-06-05T12:58:20.775] _slurm_rpc_submit_batch_job: JobId=43023 InitPrio=27658 usec=446
[2022-06-05T12:58:20.871] sched: Allocate JobId=43023 NodeList=cpu11 #CPUs=12 Partition=cpu-opteron
[2022-06-05T12:58:56.456] _slurm_rpc_kill_job: REQUEST_KILL_JOB JobId=43023 uid 548300561
[2022-06-05T14:21:05.080] _job_complete: JobId=42911 WEXITSTATUS 0
[2022-06-05T14:21:05.128] _job_complete: JobId=42911 done
[2022-06-05T16:29:36.604] sched: _slurm_rpc_allocate_resources JobId=43024 NodeList=cpu11 usec=15589
[2022-06-05T16:31:27.643] _job_complete: JobId=43024 WEXITSTATUS 127
[2022-06-05T16:31:27.644] _job_complete: JobId=43024 done
[2022-06-05T17:36:32.774] _slurm_rpc_submit_batch_job: JobId=43025 InitPrio=20786 usec=569
[2022-06-05T17:39:03.643] _slurm_rpc_submit_batch_job: JobId=43026 InitPrio=20786 usec=491
[2022-06-05T18:04:20.804] _slurm_rpc_submit_batch_job: JobId=43027 InitPrio=20786 usec=574
[2022-06-05T18:11:17.292] _slurm_rpc_kill_job: REQUEST_KILL_JOB JobId=43025 uid 548200083
[2022-06-05T21:35:06.901] Time limit exhausted for JobId=42286
[2022-06-05T23:39:25.418] _job_complete: JobId=42953 WEXITSTATUS 0
[2022-06-05T23:39:25.423] _job_complete: JobId=42953 done
[2022-06-05T23:39:29.368] sched: Allocate JobId=42957 NodeList=gpu02 #CPUs=8 Partition=gpu-titan
[2022-06-06T00:25:20.146] sched: _slurm_rpc_allocate_resources JobId=43028 NodeList=cpu11 usec=17099
[2022-06-06T01:13:51.801] _slurm_rpc_submit_batch_job: JobId=43029 InitPrio=20580 usec=380
[2022-06-06T01:13:52.008] sched: Allocate JobId=43029 NodeList=cpu12 #CPUs=32 Partition=cpu-epyc
[2022-06-06T02:08:56.053] _job_complete: JobId=43016 WEXITSTATUS 0
[2022-06-06T02:08:56.058] _job_complete: JobId=43016 done
[2022-06-06T02:08:56.464] sched: Allocate JobId=43026 NodeList=gpu05 #CPUs=8 Partition=gpu-v100s
[2022-06-06T02:09:16.627] _job_complete: JobId=43026 WEXITSTATUS 1
[2022-06-06T02:09:16.628] _job_complete: JobId=43026 done
[2022-06-06T02:09:17.038] sched: Allocate JobId=43027 NodeList=gpu05 #CPUs=8 Partition=gpu-v100s
[2022-06-06T02:09:33.910] _job_complete: JobId=43027 WEXITSTATUS 1
[2022-06-06T02:09:33.910] _job_complete: JobId=43027 done
[2022-06-06T02:15:53.540] _job_complete: JobId=43012 WEXITSTATUS 0
[2022-06-06T02:15:53.541] _job_complete: JobId=43012 done
[2022-06-06T02:42:34.876] _slurm_rpc_submit_batch_job: JobId=43030 InitPrio=20580 usec=470
[2022-06-06T02:42:35.330] sched: Allocate JobId=43030 NodeList=cpu13 #CPUs=32 Partition=cpu-epyc
[2022-06-06T02:47:18.780] _job_complete: JobId=43030 WEXITSTATUS 0
[2022-06-06T02:47:18.781] _job_complete: JobId=43030 done
[2022-06-06T03:40:24.515] _slurm_rpc_submit_batch_job: JobId=43031 InitPrio=20510 usec=579
[2022-06-06T03:40:24.750] sched: Allocate JobId=43031 NodeList=gpu05 #CPUs=8 Partition=gpu-v100s
[2022-06-06T03:41:28.193] _job_complete: JobId=43031 WEXITSTATUS 1
[2022-06-06T03:41:28.194] _job_complete: JobId=43031 done
[2022-06-06T03:41:36.424] sched: _slurm_rpc_allocate_resources JobId=43032 NodeList=cpu11 usec=1119
[2022-06-06T03:42:24.730] _slurm_rpc_submit_batch_job: JobId=43033 InitPrio=20510 usec=535
[2022-06-06T03:42:25.054] sched: Allocate JobId=43033 NodeList=gpu05 #CPUs=8 Partition=gpu-v100s
[2022-06-06T03:43:24.071] sched: _slurm_rpc_allocate_resources JobId=43034 NodeList=cpu11 usec=1032
[2022-06-06T03:43:28.781] _job_complete: JobId=43033 WEXITSTATUS 1
[2022-06-06T03:43:28.782] _job_complete: JobId=43033 done
[2022-06-06T03:49:08.484] _slurm_rpc_submit_batch_job: JobId=43035 InitPrio=20510 usec=484
[2022-06-06T03:49:08.759] sched: Allocate JobId=43035 NodeList=gpu05 #CPUs=8 Partition=gpu-v100s
[2022-06-06T03:49:27.522] _job_complete: JobId=43034 WEXITSTATUS 130
[2022-06-06T03:49:27.523] _job_complete: JobId=43034 done
[2022-06-06T03:49:36.659] _slurm_rpc_submit_batch_job: JobId=43036 InitPrio=20510 usec=567
[2022-06-06T03:49:36.800] sched: Allocate JobId=43036 NodeList=gpu05 #CPUs=8 Partition=gpu-v100s
[2022-06-06T04:14:56.620] _job_complete: JobId=43032 WEXITSTATUS 0
[2022-06-06T04:14:56.620] _job_complete: JobId=43032 done
[2022-06-06T05:03:37.504] _slurm_rpc_submit_batch_job: JobId=43037 InitPrio=20580 usec=474
[2022-06-06T05:03:38.025] sched: Allocate JobId=43037 NodeList=cpu13 #CPUs=32 Partition=cpu-epyc
[2022-06-06T05:03:49.077] _job_complete: JobId=43037 WEXITSTATUS 0
[2022-06-06T05:03:49.077] _job_complete: JobId=43037 done
[2022-06-06T05:07:18.588] _slurm_rpc_submit_batch_job: JobId=43038 InitPrio=20580 usec=406
[2022-06-06T05:07:19.333] sched: Allocate JobId=43038 NodeList=cpu13 #CPUs=32 Partition=cpu-epyc
[2022-06-06T05:07:28.209] _job_complete: JobId=43038 WEXITSTATUS 1
[2022-06-06T05:07:28.209] _job_complete: JobId=43038 done
[2022-06-06T05:08:48.388] _slurm_rpc_submit_batch_job: JobId=43039 InitPrio=20580 usec=333
[2022-06-06T05:08:48.588] sched: Allocate JobId=43039 NodeList=cpu13 #CPUs=32 Partition=cpu-epyc
[2022-06-06T05:08:57.312] _job_complete: JobId=43039 WEXITSTATUS 1
[2022-06-06T05:08:57.312] _job_complete: JobId=43039 done
[2022-06-06T05:10:43.294] _slurm_rpc_submit_batch_job: JobId=43040 InitPrio=20580 usec=381
[2022-06-06T05:10:43.754] sched: Allocate JobId=43040 NodeList=cpu13 #CPUs=32 Partition=cpu-epyc
[2022-06-06T05:10:52.902] _job_complete: JobId=43040 WEXITSTATUS 1
[2022-06-06T05:10:52.903] _job_complete: JobId=43040 done
[2022-06-06T05:13:15.113] _slurm_rpc_submit_batch_job: JobId=43041 InitPrio=20580 usec=355
[2022-06-06T05:13:15.117] sched: Allocate JobId=43041 NodeList=cpu13 #CPUs=32 Partition=cpu-epyc
[2022-06-06T05:13:24.674] _job_complete: JobId=43041 WEXITSTATUS 0
[2022-06-06T05:13:24.674] _job_complete: JobId=43041 done
[2022-06-06T05:14:56.621] _slurm_rpc_submit_batch_job: JobId=43042 InitPrio=20580 usec=387
[2022-06-06T05:14:57.272] sched: Allocate JobId=43042 NodeList=cpu13 #CPUs=32 Partition=cpu-epyc
[2022-06-06T05:18:01.196] _job_complete: JobId=43042 WEXITSTATUS 0
[2022-06-06T05:18:01.196] _job_complete: JobId=43042 done
[2022-06-06T05:26:21.613] _slurm_rpc_submit_batch_job: JobId=43043 InitPrio=20580 usec=370
[2022-06-06T05:26:22.552] sched: Allocate JobId=43043 NodeList=cpu13 #CPUs=32 Partition=cpu-epyc
[2022-06-06T05:27:11.658] _slurm_rpc_submit_batch_job: JobId=43044 InitPrio=20580 usec=474
[2022-06-06T05:27:12.621] sched: Allocate JobId=43044 NodeList=cpu14 #CPUs=32 Partition=cpu-epyc
[2022-06-06T05:27:24.224] _slurm_rpc_kill_job: REQUEST_KILL_JOB JobId=43044 uid 548300516
[2022-06-06T05:29:25.784] _job_complete: JobId=43043 WEXITSTATUS 0
[2022-06-06T05:29:25.785] _job_complete: JobId=43043 done
[2022-06-06T05:29:34.092] _slurm_rpc_kill_job: REQUEST_KILL_JOB JobId=43029 uid 548300516
[2022-06-06T05:29:55.364] _slurm_rpc_submit_batch_job: JobId=43045 InitPrio=20580 usec=348
[2022-06-06T05:29:55.935] sched: Allocate JobId=43045 NodeList=cpu12 #CPUs=32 Partition=cpu-epyc
[2022-06-06T05:37:44.712] _slurm_rpc_submit_batch_job: JobId=43046 InitPrio=20580 usec=338
[2022-06-06T05:37:44.964] sched: Allocate JobId=43046 NodeList=cpu13 #CPUs=32 Partition=cpu-epyc
[2022-06-06T05:40:03.473] _slurm_rpc_submit_batch_job: JobId=43047 InitPrio=20580 usec=380
[2022-06-06T05:40:06.169] sched: Allocate JobId=43047 NodeList=cpu14 #CPUs=32 Partition=cpu-epyc
[2022-06-06T05:40:47.836] _job_complete: JobId=43046 WEXITSTATUS 0
[2022-06-06T05:40:47.837] _job_complete: JobId=43046 done
[2022-06-06T05:43:22.433] _slurm_rpc_submit_batch_job: JobId=43048 InitPrio=20580 usec=336
[2022-06-06T05:43:22.586] sched: Allocate JobId=43048 NodeList=cpu13 #CPUs=32 Partition=cpu-epyc
[2022-06-06T05:43:30.857] _slurm_rpc_kill_job: REQUEST_KILL_JOB JobId=43047 uid 548300516
[2022-06-06T05:43:42.439] _job_complete: JobId=43048 WEXITSTATUS 1
[2022-06-06T05:43:42.440] _job_complete: JobId=43048 done
[2022-06-06T05:44:28.238] _slurm_rpc_submit_batch_job: JobId=43049 InitPrio=20580 usec=361
[2022-06-06T05:44:28.685] sched: Allocate JobId=43049 NodeList=cpu13 #CPUs=32 Partition=cpu-epyc
[2022-06-06T05:44:46.944] _job_complete: JobId=43049 WEXITSTATUS 1
[2022-06-06T05:44:46.944] _job_complete: JobId=43049 done
[2022-06-06T05:45:20.084] sched: _slurm_rpc_allocate_resources JobId=43050 NodeList=cpu11 usec=14419
[2022-06-06T05:47:40.777] _slurm_rpc_submit_batch_job: JobId=43051 InitPrio=20580 usec=314
[2022-06-06T05:47:41.150] sched: Allocate JobId=43051 NodeList=cpu13 #CPUs=32 Partition=cpu-epyc
[2022-06-06T05:50:08.430] _slurm_rpc_submit_batch_job: JobId=43052 InitPrio=20580 usec=398
[2022-06-06T05:50:09.375] sched: Allocate JobId=43052 NodeList=cpu14 #CPUs=32 Partition=cpu-epyc
[2022-06-06T05:50:44.034] _job_complete: JobId=43051 WEXITSTATUS 0
[2022-06-06T05:50:44.034] _job_complete: JobId=43051 done
[2022-06-06T05:55:25.896] _slurm_rpc_submit_batch_job: JobId=43053 InitPrio=20580 usec=415
[2022-06-06T05:55:25.936] sched: Allocate JobId=43053 NodeList=cpu13 #CPUs=32 Partition=cpu-epyc
[2022-06-06T05:55:26.980] _job_complete: JobId=43053 WEXITSTATUS 2
[2022-06-06T05:55:26.980] _job_complete: JobId=43053 done
[2022-06-06T05:57:17.590] _slurm_rpc_submit_batch_job: JobId=43054 InitPrio=20580 usec=384
[2022-06-06T05:57:18.103] sched: Allocate JobId=43054 NodeList=cpu13 #CPUs=32 Partition=cpu-epyc
[2022-06-06T05:58:11.765] _slurm_rpc_submit_batch_job: JobId=43055 InitPrio=20580 usec=372
[2022-06-06T05:58:12.269] sched: Allocate JobId=43055 NodeList=cpu15 #CPUs=32 Partition=cpu-epyc
[2022-06-06T06:00:21.439] _job_complete: JobId=43054 WEXITSTATUS 0
[2022-06-06T06:00:21.439] _job_complete: JobId=43054 done
[2022-06-06T06:05:44.024] _slurm_rpc_submit_batch_job: JobId=43056 InitPrio=20580 usec=433
[2022-06-06T06:05:44.126] sched: Allocate JobId=43056 NodeList=cpu13 #CPUs=32 Partition=cpu-epyc
[2022-06-06T06:07:07.816] _slurm_rpc_submit_batch_job: JobId=43057 InitPrio=20580 usec=435
[2022-06-06T06:08:47.240] _job_complete: JobId=43056 WEXITSTATUS 0
[2022-06-06T06:08:47.240] _job_complete: JobId=43056 done
[2022-06-06T06:08:47.486] sched: Allocate JobId=43057 NodeList=cpu13 #CPUs=32 Partition=cpu-epyc
[2022-06-06T06:10:54.970] _slurm_rpc_submit_batch_job: JobId=43058 InitPrio=20580 usec=547
[2022-06-06T06:11:09.872] _slurm_rpc_kill_job: REQUEST_KILL_JOB JobId=43057 uid 548300516
[2022-06-06T06:11:14.696] sched: Allocate JobId=43058 NodeList=cpu13 #CPUs=32 Partition=cpu-epyc
[2022-06-06T06:11:26.497] _slurm_rpc_submit_batch_job: JobId=43059 InitPrio=20580 usec=363
[2022-06-06T06:11:53.421] _job_complete: JobId=43028 WEXITSTATUS 0
[2022-06-06T06:11:53.421] _job_complete: JobId=43028 done
[2022-06-06T06:14:17.353] _job_complete: JobId=43058 WEXITSTATUS 0
[2022-06-06T06:14:17.354] _job_complete: JobId=43058 done
[2022-06-06T06:14:17.575] sched: Allocate JobId=43059 NodeList=cpu13 #CPUs=32 Partition=cpu-epyc
[2022-06-06T06:21:42.920] sched: _slurm_rpc_allocate_resources JobId=43060 NodeList=cpu11 usec=4534
[2022-06-06T06:34:13.808] _job_complete: JobId=43050 WEXITSTATUS 0
[2022-06-06T06:34:13.808] _job_complete: JobId=43050 done
[2022-06-06T06:34:16.065] _job_complete: JobId=43060 WEXITSTATUS 0
[2022-06-06T06:34:16.065] _job_complete: JobId=43060 done
[2022-06-06T06:35:40.985] _slurm_rpc_submit_batch_job: JobId=43061 InitPrio=20510 usec=467
[2022-06-06T06:36:05.204] _slurm_rpc_kill_job: REQUEST_KILL_JOB JobId=42952 uid 548200083
[2022-06-06T06:36:11.055] _slurm_rpc_kill_job: REQUEST_KILL_JOB JobId=42952 uid 548200083
[2022-06-06T06:36:16.119] sched: Allocate JobId=43061 NodeList=gpu02 #CPUs=8 Partition=gpu-titan
[2022-06-06T06:39:15.102] _slurm_rpc_submit_batch_job: JobId=43062 InitPrio=20510 usec=503
[2022-06-06T06:39:33.638] _slurm_rpc_kill_job: REQUEST_KILL_JOB JobId=42957 uid 548200083
[2022-06-06T06:39:33.638] error: Security violation, REQUEST_KILL_JOB RPC for JobId=42957 from uid 548200083
[2022-06-06T06:39:33.638] _slurm_rpc_kill_job: job_str_signal() uid=548200083 JobId=42957 sig=9 returned: Access/permission denied
[2022-06-06T06:40:01.450] sched: _slurm_rpc_allocate_resources JobId=43063 NodeList=cpu11 usec=1287
[2022-06-06T08:03:54.597] _job_complete: JobId=42957 WEXITSTATUS 0
[2022-06-06T08:03:54.597] _job_complete: JobId=42957 done
[2022-06-06T08:03:55.034] sched: Allocate JobId=43062 NodeList=gpu02 #CPUs=8 Partition=gpu-titan
[2022-06-06T10:02:02.270] sched: _slurm_rpc_allocate_resources JobId=43064 NodeList=cpu11 usec=16444
[2022-06-06T10:02:53.544] _slurm_rpc_kill_job: REQUEST_KILL_JOB JobId=43064 uid 548200029
[2022-06-06T10:06:44.756] _slurm_rpc_submit_batch_job: JobId=43065 InitPrio=21122 usec=450
[2022-06-06T10:06:44.775] sched: Allocate JobId=43065 NodeList=cpu11 #CPUs=1 Partition=cpu-opteron
[2022-06-06T10:07:53.721] _slurm_rpc_submit_batch_job: JobId=43066 InitPrio=21122 usec=420
[2022-06-06T10:07:54.012] sched: Allocate JobId=43066 NodeList=cpu11 #CPUs=1 Partition=cpu-opteron
[2022-06-06T10:07:54.871] _job_complete: JobId=43066 WEXITSTATUS 1
[2022-06-06T10:07:54.871] _job_complete: JobId=43066 done
[2022-06-06T10:08:49.607] _slurm_rpc_submit_batch_job: JobId=43067 InitPrio=21122 usec=373
[2022-06-06T10:08:50.097] sched: Allocate JobId=43067 NodeList=cpu11 #CPUs=1 Partition=cpu-opteron
[2022-06-06T10:08:50.980] _job_complete: JobId=43067 WEXITSTATUS 1
[2022-06-06T10:08:50.981] _job_complete: JobId=43067 done
[2022-06-06T10:11:57.355] _slurm_rpc_submit_batch_job: JobId=43068 InitPrio=21122 usec=484
[2022-06-06T10:11:57.372] sched: Allocate JobId=43068 NodeList=cpu11 #CPUs=1 Partition=cpu-opteron
[2022-06-06T10:12:03.941] _job_complete: JobId=43065 WEXITSTATUS 0
[2022-06-06T10:12:03.941] _job_complete: JobId=43065 done
[2022-06-06T10:12:30.272] _job_complete: JobId=43068 WEXITSTATUS 0
[2022-06-06T10:12:30.272] _job_complete: JobId=43068 done
[2022-06-06T10:13:36.850] _slurm_rpc_submit_batch_job: JobId=43069 InitPrio=21096 usec=507
[2022-06-06T10:13:37.822] sched: Allocate JobId=43069 NodeList=cpu11 #CPUs=4 Partition=cpu-opteron
[2022-06-06T10:14:35.271] _slurm_rpc_submit_batch_job: JobId=43070 InitPrio=21096 usec=427
[2022-06-06T10:14:35.903] sched: Allocate JobId=43070 NodeList=cpu11 #CPUs=4 Partition=cpu-opteron
[2022-06-06T10:19:08.917] _job_complete: JobId=43069 WEXITSTATUS 0
[2022-06-06T10:19:08.918] _job_complete: JobId=43069 done
[2022-06-06T10:19:52.535] _job_complete: JobId=43070 WEXITSTATUS 0
[2022-06-06T10:19:52.536] _job_complete: JobId=43070 done
[2022-06-06T10:32:19.481] _slurm_rpc_submit_batch_job: JobId=43071 InitPrio=21062 usec=490
[2022-06-06T10:32:20.324] sched: Allocate JobId=43071 NodeList=cpu11 #CPUs=8 Partition=cpu-opteron
[2022-06-06T10:34:02.005] _slurm_rpc_submit_batch_job: JobId=43072 InitPrio=21062 usec=491
[2022-06-06T10:34:02.508] sched: Allocate JobId=43072 NodeList=cpu12 #CPUs=8 Partition=cpu-epyc
[2022-06-06T10:35:31.716] _slurm_rpc_submit_batch_job: JobId=43073 InitPrio=20857 usec=443
[2022-06-06T10:35:32.516] sched/backfill: _start_job: Started JobId=43073 in cpu-opteron on cpu01
[2022-06-06T10:46:45.937] _slurm_rpc_submit_batch_job: JobId=43074 InitPrio=20857 usec=379
[2022-06-06T10:46:46.851] sched: Allocate JobId=43074 NodeList=cpu01 #CPUs=32 Partition=cpu-opteron
[2022-06-06T10:47:10.571] _job_complete: JobId=43074 WEXITSTATUS 0
[2022-06-06T10:47:10.571] _job_complete: JobId=43074 done
[2022-06-06T10:54:44.585] _slurm_rpc_submit_batch_job: JobId=43075 InitPrio=20857 usec=379
[2022-06-06T10:54:44.724] sched: Allocate JobId=43075 NodeList=cpu01 #CPUs=32 Partition=cpu-opteron
[2022-06-06T10:55:14.929] _slurm_rpc_submit_batch_job: JobId=43076 InitPrio=20857 usec=468
[2022-06-06T10:55:15.768] sched: Allocate JobId=43076 NodeList=cpu03 #CPUs=32 Partition=cpu-opteron
[2022-06-06T10:55:23.567] _job_complete: JobId=43075 WEXITSTATUS 0
[2022-06-06T10:55:23.568] _job_complete: JobId=43075 done
[2022-06-06T10:55:24.548] _job_complete: JobId=43076 WEXITSTATUS 0
[2022-06-06T10:55:24.548] _job_complete: JobId=43076 done
[2022-06-06T10:56:53.997] _slurm_rpc_submit_batch_job: JobId=43077 InitPrio=20857 usec=491
[2022-06-06T10:56:54.915] sched: Allocate JobId=43077 NodeList=cpu01 #CPUs=32 Partition=cpu-opteron
[2022-06-06T10:56:56.762] _job_complete: JobId=43077 WEXITSTATUS 1
[2022-06-06T10:56:56.763] _job_complete: JobId=43077 done
[2022-06-06T10:57:47.490] _slurm_rpc_submit_batch_job: JobId=43078 InitPrio=20857 usec=487
[2022-06-06T10:57:48.100] sched: Allocate JobId=43078 NodeList=cpu01 #CPUs=32 Partition=cpu-opteron
[2022-06-06T10:58:03.910] _job_complete: JobId=43078 WEXITSTATUS 0
[2022-06-06T10:58:03.911] _job_complete: JobId=43078 done
[2022-06-06T11:06:02.324] _job_complete: JobId=43072 WEXITSTATUS 0
[2022-06-06T11:06:02.325] _job_complete: JobId=43072 done
[2022-06-06T11:10:20.024] _job_complete: JobId=43073 WEXITSTATUS 0
[2022-06-06T11:10:20.024] _job_complete: JobId=43073 done
[2022-06-06T11:31:58.307] _slurm_rpc_submit_batch_job: JobId=43079 InitPrio=28868 usec=490
[2022-06-06T11:41:44.541] _job_complete: JobId=43061 WEXITSTATUS 1
[2022-06-06T11:41:44.546] _job_complete: JobId=43061 done
[2022-06-06T12:03:10.516] _job_complete: JobId=43071 WEXITSTATUS 0
[2022-06-06T12:03:10.517] _job_complete: JobId=43071 done
[2022-06-06T13:27:49.952] _job_complete: JobId=43062 WEXITSTATUS 1
[2022-06-06T13:27:49.957] _job_complete: JobId=43062 done
[2022-06-06T13:58:53.451] _slurm_rpc_submit_batch_job: JobId=43080 InitPrio=23206 usec=505
[2022-06-06T13:58:54.297] sched: Allocate JobId=43080 NodeList=cpu13 #CPUs=48 Partition=cpu-epyc
[2022-06-06T13:59:34.591] _job_complete: JobId=43080 OOM failure
[2022-06-06T13:59:34.591] _job_complete: JobId=43080 done
[2022-06-06T14:06:26.071] _slurm_rpc_submit_batch_job: JobId=43081 InitPrio=23206 usec=473
[2022-06-06T14:06:27.043] sched: Allocate JobId=43081 NodeList=cpu13 #CPUs=48 Partition=cpu-epyc
[2022-06-06T14:06:53.448] _slurm_rpc_submit_batch_job: JobId=43082 InitPrio=23206 usec=608
[2022-06-06T14:06:54.082] sched: Allocate JobId=43082 NodeList=cpu14 #CPUs=48 Partition=cpu-epyc
[2022-06-06T14:07:11.803] _job_complete: JobId=43081 WEXITSTATUS 2
[2022-06-06T14:07:11.803] _job_complete: JobId=43081 done
[2022-06-06T14:08:15.092] _slurm_rpc_submit_batch_job: JobId=43083 InitPrio=23206 usec=414
[2022-06-06T14:08:15.292] sched: Allocate JobId=43083 NodeList=cpu13 #CPUs=48 Partition=cpu-epyc
[2022-06-06T14:20:01.590] _slurm_rpc_submit_batch_job: JobId=43084 InitPrio=23206 usec=426
[2022-06-06T14:20:01.602] sched: Allocate JobId=43084 NodeList=cpu15 #CPUs=48 Partition=cpu-epyc
[2022-06-06T14:23:37.236] _job_complete: JobId=43083 WEXITSTATUS 0
[2022-06-06T14:23:37.236] _job_complete: JobId=43083 done
[2022-06-06T14:41:55.365] _slurm_rpc_submit_batch_job: JobId=43085 InitPrio=21133 usec=396
[2022-06-06T14:41:56.020] sched: Allocate JobId=43085 NodeList=cpu01 #CPUs=32 Partition=cpu-opteron
[2022-06-06T14:44:05.646] _slurm_rpc_submit_batch_job: JobId=43086 InitPrio=20580 usec=322
[2022-06-06T14:58:14.027] _slurm_rpc_submit_batch_job: JobId=43087 InitPrio=23069 usec=468
[2022-06-06T14:58:14.909] sched: Allocate JobId=43087 NodeList=cpu13 #CPUs=64 Partition=cpu-epyc
[2022-06-06T14:59:32.020] _slurm_rpc_kill_job: REQUEST_KILL_JOB JobId=43084 uid 548200019
[2022-06-06T14:59:56.682] _slurm_rpc_submit_batch_job: JobId=43088 InitPrio=23069 usec=584
[2022-06-06T14:59:57.057] sched: Allocate JobId=43088 NodeList=cpu15 #CPUs=64 Partition=cpu-epyc
[2022-06-06T15:02:39.520] _slurm_rpc_submit_batch_job: JobId=43089 InitPrio=23069 usec=438
[2022-06-06T15:02:40.406] sched: Allocate JobId=43089 NodeList=cpu03 #CPUs=64 Partition=cpu-opteron
[2022-06-06T15:22:40.153] _slurm_rpc_kill_job: REQUEST_KILL_JOB JobId=43086 uid 548300516
[2022-06-06T15:23:09.709] _slurm_rpc_submit_batch_job: JobId=43090 InitPrio=20580 usec=357
[2022-06-06T15:23:09.733] sched: Allocate JobId=43090 NodeList=cpu04 #CPUs=32 Partition=cpu-opteron
[2022-06-06T15:23:27.780] _slurm_rpc_submit_batch_job: JobId=43091 InitPrio=20580 usec=480
[2022-06-06T15:25:14.185] _slurm_rpc_submit_batch_job: JobId=43092 InitPrio=20580 usec=373
[2022-06-06T15:25:14.898] sched: Allocate JobId=43092 NodeList=cpu05 #CPUs=32 Partition=cpu-opteron
[2022-06-06T15:26:08.592] _slurm_rpc_submit_batch_job: JobId=43093 InitPrio=20580 usec=419
[2022-06-06T15:27:32.916] _slurm_rpc_submit_batch_job: JobId=43094 InitPrio=20580 usec=418
[2022-06-06T15:27:33.189] sched: Allocate JobId=43094 NodeList=cpu07 #CPUs=32 Partition=cpu-opteron
[2022-06-06T15:28:26.130] _slurm_rpc_submit_batch_job: JobId=43095 InitPrio=20580 usec=370
[2022-06-06T15:29:40.321] _slurm_rpc_submit_batch_job: JobId=43096 InitPrio=20580 usec=369
[2022-06-06T15:29:40.377] sched: Allocate JobId=43096 NodeList=cpu08 #CPUs=32 Partition=cpu-opteron
[2022-06-06T15:30:39.056] _slurm_rpc_submit_batch_job: JobId=43097 InitPrio=20580 usec=538
[2022-06-06T15:53:58.523] _slurm_rpc_submit_batch_job: JobId=43098 InitPrio=20510 usec=398
[2022-06-06T15:53:59.173] sched: Allocate JobId=43098 NodeList=gpu02 #CPUs=8 Partition=gpu-titan
[2022-06-06T15:54:02.172] _slurm_rpc_submit_batch_job: JobId=43099 InitPrio=20510 usec=429
[2022-06-06T15:54:03.159] sched: Allocate JobId=43099 NodeList=gpu02 #CPUs=8 Partition=gpu-titan
[2022-06-06T16:03:51.239] _slurm_rpc_submit_batch_job: JobId=43100 InitPrio=21373 usec=495
[2022-06-06T16:03:51.332] sched: Allocate JobId=43100 NodeList=cpu11 #CPUs=4 Partition=cpu-opteron
[2022-06-06T16:03:52.625] _job_complete: JobId=43100 WEXITSTATUS 31
[2022-06-06T16:03:52.625] _job_complete: JobId=43100 done
[2022-06-06T16:04:26.522] _slurm_rpc_submit_batch_job: JobId=43101 InitPrio=21373 usec=420
[2022-06-06T16:04:27.381] sched: Allocate JobId=43101 NodeList=cpu11 #CPUs=4 Partition=cpu-opteron
[2022-06-06T16:04:28.508] _job_complete: JobId=43101 WEXITSTATUS 0
[2022-06-06T16:04:28.508] _job_complete: JobId=43101 done
[2022-06-06T16:10:14.142] _slurm_rpc_submit_batch_job: JobId=43102 InitPrio=21270 usec=623
[2022-06-06T16:10:15.024] sched: Allocate JobId=43102 NodeList=cpu11 #CPUs=16 Partition=cpu-opteron
[2022-06-06T16:10:27.893] _job_complete: JobId=43102 WEXITSTATUS 0
[2022-06-06T16:10:27.893] _job_complete: JobId=43102 done
[2022-06-06T16:11:35.035] _slurm_rpc_submit_batch_job: JobId=43103 InitPrio=21398 usec=400
[2022-06-06T16:11:35.143] sched: Allocate JobId=43103 NodeList=gpu04 #CPUs=1 Partition=gpu-k40c
[2022-06-06T16:12:09.059] _job_complete: JobId=43103 WEXITSTATUS 0
[2022-06-06T16:12:09.059] _job_complete: JobId=43103 done
[2022-06-06T16:12:45.027] _slurm_rpc_submit_batch_job: JobId=43104 InitPrio=21373 usec=442
[2022-06-06T16:12:45.392] sched: Allocate JobId=43104 NodeList=cpu11 #CPUs=4 Partition=cpu-opteron
[2022-06-06T16:12:46.901] _job_complete: JobId=43104 WEXITSTATUS 0
[2022-06-06T16:12:46.901] _job_complete: JobId=43104 done
[2022-06-06T16:14:46.251] _slurm_rpc_submit_batch_job: JobId=43105 InitPrio=21373 usec=478
[2022-06-06T16:14:46.567] sched: Allocate JobId=43105 NodeList=cpu11 #CPUs=4 Partition=cpu-opteron
[2022-06-06T16:14:59.987] _job_complete: JobId=43105 WEXITSTATUS 0
[2022-06-06T16:14:59.987] _job_complete: JobId=43105 done
[2022-06-06T16:17:34.991] _slurm_rpc_submit_batch_job: JobId=43106 InitPrio=20510 usec=449
[2022-06-06T16:17:41.204] _slurm_rpc_submit_batch_job: JobId=43107 InitPrio=21133 usec=595
[2022-06-06T16:20:25.203] _slurm_rpc_submit_batch_job: JobId=43108 InitPrio=21321 usec=516
[2022-06-06T16:23:50.011] _slurm_rpc_submit_batch_job: JobId=43109 InitPrio=20510 usec=476
[2022-06-06T16:24:44.401] _slurm_rpc_kill_job: REQUEST_KILL_JOB JobId=53099 uid 548200083
[2022-06-06T16:24:44.401] job_str_signal(3): invalid JobId=53099
[2022-06-06T16:24:44.401] _slurm_rpc_kill_job: job_str_signal() uid=548200083 JobId=53099 sig=9 returned: Invalid job id specified
[2022-06-06T16:24:48.947] _slurm_rpc_kill_job: REQUEST_KILL_JOB JobId=43099 uid 548200083
[2022-06-06T16:24:50.838] sched: Allocate JobId=43108 NodeList=gpu02 #CPUs=10 Partition=gpu-titan
[2022-06-06T16:24:52.052] _slurm_rpc_kill_job: REQUEST_KILL_JOB JobId=43098 uid 548200083
[2022-06-06T16:24:53.916] sched: Allocate JobId=43106 NodeList=gpu02 #CPUs=8 Partition=gpu-titan
[2022-06-06T16:27:19.236] _slurm_rpc_kill_job: REQUEST_KILL_JOB JobId=42956 uid 548200083
[2022-06-06T16:27:30.173] sched: Allocate JobId=43109 NodeList=gpu02 #CPUs=8 Partition=gpu-titan
[2022-06-06T17:16:37.994] _job_complete: JobId=43063 WEXITSTATUS 0
[2022-06-06T17:16:37.994] _job_complete: JobId=43063 done
[2022-06-06T17:41:25.756] _slurm_rpc_submit_batch_job: JobId=43110 InitPrio=21373 usec=446
[2022-06-06T17:41:26.617] sched: Allocate JobId=43110 NodeList=cpu01 #CPUs=4 Partition=cpu-opteron
[2022-06-06T17:41:27.821] _job_complete: JobId=43110 WEXITSTATUS 0
[2022-06-06T17:41:27.821] _job_complete: JobId=43110 done
[2022-06-06T17:42:17.371] _slurm_rpc_submit_batch_job: JobId=43111 InitPrio=21270 usec=506
[2022-06-06T17:42:17.669] sched: Allocate JobId=43111 NodeList=cpu01 #CPUs=16 Partition=cpu-opteron
[2022-06-06T17:42:33.224] _job_complete: JobId=43111 WEXITSTATUS 0
[2022-06-06T17:42:33.224] _job_complete: JobId=43111 done
[2022-06-06T17:43:51.720] _slurm_rpc_submit_batch_job: JobId=43112 InitPrio=21398 usec=463
[2022-06-06T17:43:51.896] sched: Allocate JobId=43112 NodeList=gpu04 #CPUs=1 Partition=gpu-k40c
[2022-06-06T17:44:22.956] _job_complete: JobId=43112 WEXITSTATUS 0
[2022-06-06T17:44:22.956] _job_complete: JobId=43112 done
[2022-06-06T17:44:41.366] _slurm_rpc_submit_batch_job: JobId=43113 InitPrio=21373 usec=387
[2022-06-06T17:44:41.971] sched: Allocate JobId=43113 NodeList=cpu01 #CPUs=4 Partition=cpu-opteron
[2022-06-06T17:44:43.998] _job_complete: JobId=43113 WEXITSTATUS 0
[2022-06-06T17:44:43.998] _job_complete: JobId=43113 done
[2022-06-06T17:45:47.075] _slurm_rpc_submit_batch_job: JobId=43114 InitPrio=21270 usec=407
[2022-06-06T17:45:48.067] sched: Allocate JobId=43114 NodeList=cpu01 #CPUs=16 Partition=cpu-opteron
[2022-06-06T17:46:03.803] _job_complete: JobId=43114 WEXITSTATUS 0
[2022-06-06T17:46:03.803] _job_complete: JobId=43114 done
[2022-06-06T17:47:05.991] _slurm_rpc_submit_batch_job: JobId=43115 InitPrio=21321 usec=525
[2022-06-06T18:48:24.848] _job_complete: JobId=43090 WEXITSTATUS 0
[2022-06-06T18:48:24.854] _job_complete: JobId=43090 done
[2022-06-06T18:48:54.903] _job_complete: JobId=43092 WEXITSTATUS 0
[2022-06-06T18:48:54.904] _job_complete: JobId=43092 done
[2022-06-06T18:52:57.629] _job_complete: JobId=43094 WEXITSTATUS 0
[2022-06-06T18:52:57.630] _job_complete: JobId=43094 done
[2022-06-06T18:54:48.556] _job_complete: JobId=43096 WEXITSTATUS 0
[2022-06-06T18:54:48.557] _job_complete: JobId=43096 done
[2022-06-06T19:00:39.087] _slurm_rpc_submit_batch_job: JobId=43116 InitPrio=20857 usec=394
[2022-06-06T19:00:39.392] sched: Allocate JobId=43116 NodeList=cpu01 #CPUs=32 Partition=cpu-opteron
[2022-06-06T19:01:51.928] _slurm_rpc_submit_batch_job: JobId=43117 InitPrio=20857 usec=387
[2022-06-06T19:01:52.477] sched: Allocate JobId=43117 NodeList=cpu11 #CPUs=32 Partition=cpu-opteron
[2022-06-06T19:02:56.153] _slurm_rpc_submit_batch_job: JobId=43118 InitPrio=20857 usec=419
[2022-06-06T19:02:56.693] sched: Allocate JobId=43118 NodeList=cpu04 #CPUs=32 Partition=cpu-opteron
[2022-06-06T19:09:50.835] _slurm_rpc_submit_batch_job: JobId=43119 InitPrio=20857 usec=382
[2022-06-06T19:09:51.391] sched: Allocate JobId=43119 NodeList=cpu04 #CPUs=32 Partition=cpu-opteron
[2022-06-06T19:09:56.553] _job_complete: JobId=43119 WEXITSTATUS 1
[2022-06-06T19:09:56.553] _job_complete: JobId=43119 done
[2022-06-06T19:11:07.474] _slurm_rpc_submit_batch_job: JobId=43120 InitPrio=20857 usec=391
[2022-06-06T19:11:09.504] sched: Allocate JobId=43120 NodeList=cpu04 #CPUs=32 Partition=cpu-opteron
[2022-06-06T19:11:14.411] _job_complete: JobId=43120 WEXITSTATUS 1
[2022-06-06T19:11:14.411] _job_complete: JobId=43120 done
[2022-06-06T19:11:33.830] _slurm_rpc_submit_batch_job: JobId=43121 InitPrio=20857 usec=467
[2022-06-06T19:11:34.538] sched: Allocate JobId=43121 NodeList=cpu04 #CPUs=32 Partition=cpu-opteron
[2022-06-06T19:11:41.211] _job_complete: JobId=43121 WEXITSTATUS 0
[2022-06-06T19:11:41.212] _job_complete: JobId=43121 done
[2022-06-06T19:12:10.631] _slurm_rpc_submit_batch_job: JobId=43122 InitPrio=20857 usec=407
[2022-06-06T19:12:11.591] sched: Allocate JobId=43122 NodeList=cpu04 #CPUs=32 Partition=cpu-opteron
[2022-06-06T19:12:28.949] _job_complete: JobId=43122 WEXITSTATUS 0
[2022-06-06T19:12:28.949] _job_complete: JobId=43122 done
[2022-06-06T19:14:14.561] _slurm_rpc_submit_batch_job: JobId=43123 InitPrio=20857 usec=363
[2022-06-06T19:14:14.867] sched: Allocate JobId=43123 NodeList=cpu04 #CPUs=32 Partition=cpu-opteron
[2022-06-06T19:18:12.151] _job_complete: JobId=43123 WEXITSTATUS 1
[2022-06-06T19:18:12.152] _job_complete: JobId=43123 done
[2022-06-06T19:23:00.035] _slurm_rpc_submit_batch_job: JobId=43124 InitPrio=20857 usec=443
[2022-06-06T19:23:00.837] sched: Allocate JobId=43124 NodeList=cpu04 #CPUs=32 Partition=cpu-opteron
[2022-06-06T19:26:39.273] _job_complete: JobId=43124 WEXITSTATUS 1
[2022-06-06T19:26:39.274] _job_complete: JobId=43124 done
[2022-06-06T21:53:21.838] _job_complete: JobId=43082 WEXITSTATUS 0
[2022-06-06T21:53:21.838] _job_complete: JobId=43082 done
[2022-06-06T21:59:56.028] _job_complete: JobId=43109 WEXITSTATUS 1
[2022-06-06T21:59:56.033] _job_complete: JobId=43109 done
[2022-06-06T21:59:56.475] sched: Allocate JobId=43115 NodeList=gpu02 #CPUs=10 Partition=gpu-titan
[2022-06-06T22:36:18.518] _job_complete: JobId=43118 WEXITSTATUS 0
[2022-06-06T22:36:18.523] _job_complete: JobId=43118 done
[2022-06-06T22:36:52.023] _job_complete: JobId=43116 WEXITSTATUS 0
[2022-06-06T22:36:52.023] _job_complete: JobId=43116 done
[2022-06-06T22:44:06.144] _job_complete: JobId=43117 WEXITSTATUS 0
[2022-06-06T22:44:06.144] _job_complete: JobId=43117 done
[2022-06-06T22:46:16.197] _slurm_rpc_submit_batch_job: JobId=43125 InitPrio=21964 usec=513
[2022-06-06T22:46:16.289] sched: Allocate JobId=43125 NodeList=cpu14 #CPUs=64 Partition=cpu-epyc
[2022-06-06T23:03:36.539] _job_complete: JobId=43106 WEXITSTATUS 0
[2022-06-06T23:03:36.540] _job_complete: JobId=43106 done
[2022-06-07T01:19:09.973] _slurm_rpc_submit_batch_job: JobId=43126 InitPrio=20510 usec=445
[2022-06-07T01:19:10.136] sched: Allocate JobId=43126 NodeList=gpu02 #CPUs=8 Partition=gpu-titan
[2022-06-07T01:19:15.920] _slurm_rpc_submit_batch_job: JobId=43127 InitPrio=20510 usec=439
[2022-06-07T01:21:32.533] _slurm_rpc_submit_batch_job: JobId=43128 InitPrio=21373 usec=452
[2022-06-07T01:21:32.810] sched/backfill: _start_job: Started JobId=43128 in cpu-opteron on cpu01
[2022-06-07T01:21:33.990] _job_complete: JobId=43128 WEXITSTATUS 0
[2022-06-07T01:21:33.990] _job_complete: JobId=43128 done
[2022-06-07T01:27:13.857] _slurm_rpc_submit_batch_job: JobId=43129 InitPrio=21270 usec=412
[2022-06-07T01:27:13.939] sched: Allocate JobId=43129 NodeList=cpu01 #CPUs=16 Partition=cpu-opteron
[2022-06-07T01:27:28.237] _job_complete: JobId=43129 WEXITSTATUS 0
[2022-06-07T01:27:28.237] _job_complete: JobId=43129 done
[2022-06-07T01:28:43.002] _slurm_rpc_submit_batch_job: JobId=43130 InitPrio=21398 usec=527
[2022-06-07T01:28:43.143] sched: Allocate JobId=43130 NodeList=gpu04 #CPUs=1 Partition=gpu-k40c
[2022-06-07T01:29:10.934] _job_complete: JobId=43130 WEXITSTATUS 0
[2022-06-07T01:29:10.935] _job_complete: JobId=43130 done
[2022-06-07T01:29:17.535] _slurm_rpc_submit_batch_job: JobId=43131 InitPrio=21373 usec=480
[2022-06-07T01:29:18.193] sched: Allocate JobId=43131 NodeList=cpu01 #CPUs=4 Partition=cpu-opteron
[2022-06-07T01:29:19.743] _job_complete: JobId=43131 WEXITSTATUS 0
[2022-06-07T01:29:19.743] _job_complete: JobId=43131 done
[2022-06-07T01:31:11.972] _slurm_rpc_submit_batch_job: JobId=43132 InitPrio=21373 usec=393
[2022-06-07T01:31:12.359] sched: Allocate JobId=43132 NodeList=cpu01 #CPUs=4 Partition=cpu-opteron
[2022-06-07T01:31:26.484] _job_complete: JobId=43132 WEXITSTATUS 0
[2022-06-07T01:31:26.484] _job_complete: JobId=43132 done
[2022-06-07T01:32:13.171] _slurm_rpc_submit_batch_job: JobId=43133 InitPrio=21321 usec=498
[2022-06-07T01:32:47.645] _slurm_rpc_kill_job: REQUEST_KILL_JOB JobId=43006 uid 548200029
[2022-06-07T01:35:43.215] _slurm_rpc_submit_batch_job: JobId=43134 InitPrio=20994 usec=509
[2022-06-07T01:35:43.887] sched: Allocate JobId=43134 NodeList=gpu03 #CPUs=16 Partition=gpu-k10
[2022-06-07T01:37:19.510] _slurm_rpc_submit_batch_job: JobId=43135 InitPrio=20857 usec=460
[2022-06-07T01:37:20.101] sched: Allocate JobId=43135 NodeList=cpu01 #CPUs=32 Partition=cpu-opteron
[2022-06-07T01:38:51.113] _slurm_rpc_submit_batch_job: JobId=43136 InitPrio=20857 usec=364
[2022-06-07T01:38:51.277] sched: Allocate JobId=43136 NodeList=cpu11 #CPUs=32 Partition=cpu-opteron
[2022-06-07T01:40:08.023] _slurm_rpc_submit_batch_job: JobId=43137 InitPrio=20857 usec=421
[2022-06-07T01:40:09.390] sched: Allocate JobId=43137 NodeList=cpu04 #CPUs=32 Partition=cpu-opteron
[2022-06-07T05:30:07.222] Time limit exhausted for JobId=43045
[2022-06-07T05:50:37.511] Time limit exhausted for JobId=43052
[2022-06-07T05:58:37.575] Time limit exhausted for JobId=43055
[2022-06-07T06:14:37.464] Time limit exhausted for JobId=43059
[2022-06-07T06:20:44.377] _job_complete: JobId=43137 WEXITSTATUS 0
[2022-06-07T06:20:44.382] _job_complete: JobId=43137 done
[2022-06-07T06:23:02.219] _job_complete: JobId=43135 WEXITSTATUS 0
[2022-06-07T06:23:02.220] _job_complete: JobId=43135 done
[2022-06-07T06:29:39.025] _job_complete: JobId=43136 WEXITSTATUS 0
[2022-06-07T06:29:39.025] _job_complete: JobId=43136 done
[2022-06-07T07:58:47.959] _job_complete: JobId=43126 WEXITSTATUS 0
[2022-06-07T07:58:47.964] _job_complete: JobId=43126 done
[2022-06-07T07:58:48.392] sched: Allocate JobId=43133 NodeList=gpu02 #CPUs=10 Partition=gpu-titan
[2022-06-07T09:38:31.958] _slurm_rpc_submit_batch_job: JobId=43138 InitPrio=23480 usec=356
[2022-06-07T09:38:32.215] sched: Allocate JobId=43138 NodeList=cpu13 #CPUs=16 Partition=cpu-epyc
[2022-06-07T09:39:03.188] _job_complete: JobId=43138 WEXITSTATUS 1
[2022-06-07T09:39:03.188] _job_complete: JobId=43138 done
[2022-06-07T09:39:12.995] _slurm_rpc_submit_batch_job: JobId=43139 InitPrio=23480 usec=349
[2022-06-07T09:39:13.251] sched: Allocate JobId=43139 NodeList=cpu13 #CPUs=16 Partition=cpu-epyc
[2022-06-07T09:39:42.372] _slurm_rpc_submit_batch_job: JobId=43140 InitPrio=24450 usec=297
[2022-06-07T09:39:43.314] sched: Allocate JobId=43140 NodeList=cpu04 #CPUs=64 Partition=cpu-opteron
[2022-06-07T09:40:08.878] _job_complete: JobId=43036 WEXITSTATUS 0
[2022-06-07T09:40:08.882] _job_complete: JobId=43036 done
[2022-06-07T09:40:09.285] sched: Allocate JobId=43079 NodeList=gpu05 #CPUs=32 Partition=gpu-v100s
[2022-06-07T09:40:30.644] _slurm_rpc_kill_job: REQUEST_KILL_JOB JobId=43140 uid 548300543
[2022-06-07T09:40:53.681] _slurm_rpc_submit_batch_job: JobId=43141 InitPrio=24587 usec=264
[2022-06-07T09:41:07.854] _slurm_rpc_kill_job: REQUEST_KILL_JOB JobId=43141 uid 548300543
[2022-06-07T09:41:15.911] _slurm_rpc_submit_batch_job: JobId=43142 InitPrio=24793 usec=302
[2022-06-07T09:41:31.348] _slurm_rpc_kill_job: REQUEST_KILL_JOB JobId=43142 uid 548300543
[2022-06-07T09:41:35.990] _job_complete: JobId=43139 WEXITSTATUS 1
[2022-06-07T09:41:35.990] _job_complete: JobId=43139 done
[2022-06-07T09:41:37.108] _slurm_rpc_submit_batch_job: JobId=43143 InitPrio=24793 usec=306
[2022-06-07T09:41:37.458] sched: Allocate JobId=43143 NodeList=cpu12 #CPUs=24 Partition=cpu-epyc
[2022-06-07T09:42:02.662] _slurm_rpc_kill_job: REQUEST_KILL_JOB JobId=43143 uid 548300543
[2022-06-07T09:42:16.061] _slurm_rpc_submit_batch_job: JobId=43144 InitPrio=23480 usec=327
[2022-06-07T09:42:16.514] sched: Allocate JobId=43144 NodeList=cpu13 #CPUs=16 Partition=cpu-epyc
[2022-06-07T09:42:41.032] _job_complete: JobId=43144 WEXITSTATUS 1
[2022-06-07T09:42:41.032] _job_complete: JobId=43144 done
[2022-06-07T09:42:48.224] _slurm_rpc_submit_batch_job: JobId=43145 InitPrio=23480 usec=333
[2022-06-07T09:42:48.700] sched: Allocate JobId=43145 NodeList=cpu01 #CPUs=16 Partition=cpu-opteron
[2022-06-07T09:43:18.551] _job_complete: JobId=43145 WEXITSTATUS 1
[2022-06-07T09:43:18.551] _job_complete: JobId=43145 done
[2022-06-07T09:44:27.780] _slurm_rpc_submit_batch_job: JobId=43146 InitPrio=23480 usec=343
[2022-06-07T09:44:27.842] sched: Allocate JobId=43146 NodeList=cpu13 #CPUs=16 Partition=cpu-epyc
[2022-06-07T09:47:54.300] _slurm_rpc_kill_job: REQUEST_KILL_JOB JobId=43146 uid 548200003
[2022-06-07T09:48:27.874] _slurm_rpc_submit_batch_job: JobId=43147 InitPrio=23480 usec=395
[2022-06-07T09:48:28.286] sched: Allocate JobId=43147 NodeList=cpu13 #CPUs=16 Partition=cpu-epyc
[2022-06-07T09:48:41.457] _slurm_rpc_kill_job: REQUEST_KILL_JOB JobId=43147 uid 548200003
[2022-06-07T09:49:05.163] _slurm_rpc_submit_batch_job: JobId=43148 InitPrio=68507 usec=49200
[2022-06-07T09:49:05.390] sched: Allocate JobId=43148 NodeList=cpu13 #CPUs=16 Partition=cpu-epyc
[2022-06-07T09:49:52.860] _slurm_rpc_kill_job: REQUEST_KILL_JOB JobId=43148 uid 548200005
[2022-06-07T09:50:25.641] _slurm_rpc_submit_batch_job: JobId=43149 InitPrio=23480 usec=317
[2022-06-07T09:50:26.458] sched: Allocate JobId=43149 NodeList=cpu13 #CPUs=16 Partition=cpu-epyc
[2022-06-07T09:50:46.893] _job_complete: JobId=43149 WEXITSTATUS 1
[2022-06-07T09:50:46.893] _job_complete: JobId=43149 done
[2022-06-07T09:52:50.837] _slurm_rpc_submit_batch_job: JobId=43150 InitPrio=23608 usec=388
[2022-06-07T09:52:51.742] sched: Allocate JobId=43150 NodeList=cpu01 #CPUs=1 Partition=cpu-opteron
[2022-06-07T09:53:14.968] _job_complete: JobId=43150 WEXITSTATUS 0
[2022-06-07T09:53:14.968] _job_complete: JobId=43150 done
[2022-06-07T09:53:23.556] _slurm_rpc_submit_batch_job: JobId=43151 InitPrio=23480 usec=317
[2022-06-07T09:53:23.788] sched: Allocate JobId=43151 NodeList=cpu13 #CPUs=16 Partition=cpu-epyc
[2022-06-07T09:57:30.327] _slurm_rpc_kill_job: REQUEST_KILL_JOB JobId=43151 uid 548200003
[2022-06-07T10:05:52.301] _slurm_rpc_submit_batch_job: JobId=43152 InitPrio=23480 usec=310
[2022-06-07T10:05:53.229] sched: Allocate JobId=43152 NodeList=cpu13 #CPUs=16 Partition=cpu-epyc
[2022-06-07T10:05:59.112] _slurm_rpc_kill_job: REQUEST_KILL_JOB JobId=43079 uid 548300558
[2022-06-07T10:06:08.072] sched: Allocate JobId=43107 NodeList=gpu05 #CPUs=32 Partition=gpu-v100s
[2022-06-07T10:06:08.893] _job_complete: JobId=43152 WEXITSTATUS 1
[2022-06-07T10:06:08.893] _job_complete: JobId=43152 done
[2022-06-07T10:08:31.844] _slurm_rpc_submit_batch_job: JobId=43153 InitPrio=23480 usec=343
[2022-06-07T10:08:32.615] sched: Allocate JobId=43153 NodeList=cpu13 #CPUs=16 Partition=cpu-epyc
[2022-06-07T10:19:18.654] _slurm_rpc_submit_batch_job: JobId=43154 InitPrio=22099 usec=447
[2022-06-07T10:19:18.823] sched: Allocate JobId=43154 NodeList=gpu04 #CPUs=16 Partition=gpu-k40c
[2022-06-07T10:22:04.003] _slurm_rpc_kill_job: REQUEST_KILL_JOB JobId=43153 uid 548200003
[2022-06-07T10:26:35.028] error: _find_node_record: lookup failure for node "gpu08"
[2022-06-07T10:26:35.028] error: node_name2bitmap: invalid node specified: "gpu08"
[2022-06-07T10:26:35.028] _slurm_rpc_submit_batch_job: Invalid node name specified
[2022-06-07T10:27:04.481] _slurm_rpc_submit_batch_job: JobId=43155 InitPrio=20028 usec=413
[2022-06-07T10:27:04.620] sched: Allocate JobId=43155 NodeList=gpu01 #CPUs=32 Partition=gpu-k10
[2022-06-07T10:27:28.206] _slurm_rpc_submit_batch_job: JobId=43156 InitPrio=20028 usec=399
[2022-06-07T10:27:56.369] _slurm_rpc_submit_batch_job: JobId=43157 InitPrio=20028 usec=418
[2022-06-07T10:28:00.801] _slurm_rpc_submit_batch_job: JobId=43158 InitPrio=26658 usec=400
[2022-06-07T10:33:18.029] _job_complete: JobId=43155 WEXITSTATUS 1
[2022-06-07T10:33:18.029] _job_complete: JobId=43155 done
[2022-06-07T10:33:18.467] sched: Allocate JobId=43156 NodeList=gpu01 #CPUs=32 Partition=gpu-k10
[2022-06-07T10:38:59.241] _job_complete: JobId=43156 WEXITSTATUS 1
[2022-06-07T10:38:59.241] _job_complete: JobId=43156 done
[2022-06-07T10:38:59.550] sched: Allocate JobId=43157 NodeList=gpu01 #CPUs=32 Partition=gpu-k10
[2022-06-07T10:46:25.846] _job_complete: JobId=43157 WEXITSTATUS 1
[2022-06-07T10:46:25.846] _job_complete: JobId=43157 done
[2022-06-07T11:20:29.207] _slurm_rpc_submit_batch_job: JobId=43159 InitPrio=20028 usec=420
[2022-06-07T11:20:29.791] sched: Allocate JobId=43159 NodeList=gpu01 #CPUs=32 Partition=gpu-k10
[2022-06-07T11:20:35.111] _slurm_rpc_submit_batch_job: JobId=43160 InitPrio=20028 usec=436
[2022-06-07T11:20:38.090] _slurm_rpc_submit_batch_job: JobId=43161 InitPrio=20028 usec=524
[2022-06-07T11:29:39.838] _job_complete: JobId=43159 WEXITSTATUS 0
[2022-06-07T11:29:39.838] _job_complete: JobId=43159 done
[2022-06-07T11:29:40.146] sched: Allocate JobId=43160 NodeList=gpu01 #CPUs=32 Partition=gpu-k10
[2022-06-07T11:36:32.322] _job_complete: JobId=43160 WEXITSTATUS 0
[2022-06-07T11:36:32.323] _job_complete: JobId=43160 done
[2022-06-07T11:36:32.617] sched: Allocate JobId=43161 NodeList=gpu01 #CPUs=32 Partition=gpu-k10
[2022-06-07T11:43:37.039] _job_complete: JobId=43161 WEXITSTATUS 0
[2022-06-07T11:43:37.039] _job_complete: JobId=43161 done
[2022-06-07T11:52:39.757] _slurm_rpc_kill_job: REQUEST_KILL_JOB JobId=43158 uid 548300558
[2022-06-07T11:55:07.612] _slurm_rpc_submit_batch_job: JobId=43162 InitPrio=26658 usec=511
[2022-06-07T12:07:01.497] _slurm_rpc_submit_batch_job: JobId=43163 InitPrio=20028 usec=433
[2022-06-07T12:07:59.600] _slurm_rpc_submit_batch_job: JobId=43164 InitPrio=20028 usec=389
[2022-06-07T12:08:00.187] sched: Allocate JobId=43164 NodeList=gpu01 #CPUs=32 Partition=gpu-k10
[2022-06-07T12:08:04.908] _job_complete: JobId=43164 WEXITSTATUS 1
[2022-06-07T12:08:04.908] _job_complete: JobId=43164 done
[2022-06-07T12:08:28.123] _slurm_rpc_kill_job: REQUEST_KILL_JOB JobId=43163 uid 548200021
[2022-06-07T12:08:54.761] _slurm_rpc_submit_batch_job: JobId=43165 InitPrio=20028 usec=559
[2022-06-07T12:08:55.266] sched: Allocate JobId=43165 NodeList=gpu01 #CPUs=32 Partition=gpu-k10
[2022-06-07T12:08:57.708] _job_complete: JobId=43165 WEXITSTATUS 1
[2022-06-07T12:08:57.708] _job_complete: JobId=43165 done
[2022-06-07T12:09:52.340] _slurm_rpc_submit_batch_job: JobId=43166 InitPrio=20028 usec=380
[2022-06-07T12:09:52.348] sched: Allocate JobId=43166 NodeList=gpu01 #CPUs=32 Partition=gpu-k10
[2022-06-07T12:09:53.544] _job_complete: JobId=43166 WEXITSTATUS 1
[2022-06-07T12:09:53.544] _job_complete: JobId=43166 done
[2022-06-07T12:10:58.276] _slurm_rpc_submit_batch_job: JobId=43167 InitPrio=20028 usec=398
[2022-06-07T12:10:58.448] sched: Allocate JobId=43167 NodeList=gpu01 #CPUs=32 Partition=gpu-k10
[2022-06-07T12:10:59.872] _job_complete: JobId=43167 WEXITSTATUS 1
[2022-06-07T12:10:59.872] _job_complete: JobId=43167 done
[2022-06-07T12:14:25.839] _slurm_rpc_submit_batch_job: JobId=43168 InitPrio=20028 usec=465
[2022-06-07T12:14:26.839] sched: Allocate JobId=43168 NodeList=gpu01 #CPUs=32 Partition=gpu-k10
[2022-06-07T12:14:28.258] _job_complete: JobId=43168 WEXITSTATUS 1
[2022-06-07T12:14:28.259] _job_complete: JobId=43168 done
[2022-06-07T12:15:47.115] _slurm_rpc_submit_batch_job: JobId=43169 InitPrio=24793 usec=309
[2022-06-07T12:15:47.975] sched: Allocate JobId=43169 NodeList=cpu12 #CPUs=24 Partition=cpu-epyc
[2022-06-07T12:22:59.717] _slurm_rpc_submit_batch_job: JobId=43170 InitPrio=20028 usec=440
[2022-06-07T12:22:59.823] sched: Allocate JobId=43170 NodeList=gpu01 #CPUs=32 Partition=gpu-k10
[2022-06-07T12:23:23.521] _job_complete: JobId=43170 WEXITSTATUS 1
[2022-06-07T12:23:23.521] _job_complete: JobId=43170 done
[2022-06-07T12:28:26.338] _slurm_rpc_kill_job: REQUEST_KILL_JOB JobId=43169 uid 548300543
[2022-06-07T12:28:31.440] _slurm_rpc_submit_batch_job: JobId=43171 InitPrio=24793 usec=496
[2022-06-07T12:28:31.450] sched: Allocate JobId=43171 NodeList=cpu12 #CPUs=24 Partition=cpu-epyc
[2022-06-07T12:30:01.071] _slurm_rpc_submit_batch_job: JobId=43172 InitPrio=20028 usec=461
[2022-06-07T12:30:01.575] sched: Allocate JobId=43172 NodeList=gpu01 #CPUs=32 Partition=gpu-k10
[2022-06-07T12:30:51.188] _job_complete: JobId=43171 WEXITSTATUS 0
[2022-06-07T12:30:51.188] _job_complete: JobId=43171 done
[2022-06-07T12:37:33.057] _slurm_rpc_submit_batch_job: JobId=43173 InitPrio=24793 usec=309
[2022-06-07T12:37:33.472] sched: Allocate JobId=43173 NodeList=cpu12 #CPUs=24 Partition=cpu-epyc
[2022-06-07T12:45:33.702] _slurm_rpc_submit_batch_job: JobId=43174 InitPrio=25758 usec=606
[2022-06-07T12:45:34.061] sched/backfill: _start_job: Started JobId=43174 in cpu-opteron on cpu01
[2022-06-07T12:45:50.513] _job_complete: JobId=43174 WEXITSTATUS 0
[2022-06-07T12:45:50.513] _job_complete: JobId=43174 done
[2022-06-07T12:49:03.487] _slurm_rpc_submit_batch_job: JobId=43175 InitPrio=25758 usec=459
[2022-06-07T12:49:03.539] sched: Allocate JobId=43175 NodeList=cpu01 #CPUs=8 Partition=cpu-opteron
[2022-06-07T12:49:11.104] _job_complete: JobId=43175 WEXITSTATUS 0
[2022-06-07T12:49:11.104] _job_complete: JobId=43175 done
[2022-06-07T12:50:36.169] _slurm_rpc_submit_batch_job: JobId=43176 InitPrio=25758 usec=618
[2022-06-07T12:50:36.677] sched: Allocate JobId=43176 NodeList=cpu01 #CPUs=8 Partition=cpu-opteron
[2022-06-07T12:50:44.001] _job_complete: JobId=43176 WEXITSTATUS 0
[2022-06-07T12:50:44.001] _job_complete: JobId=43176 done
[2022-06-07T12:51:59.994] _slurm_rpc_submit_batch_job: JobId=43177 InitPrio=25758 usec=576
[2022-06-07T12:52:00.798] sched: Allocate JobId=43177 NodeList=cpu01 #CPUs=8 Partition=cpu-opteron
[2022-06-07T12:52:01.081] _job_complete: JobId=43177 WEXITSTATUS 1
[2022-06-07T12:52:01.081] _job_complete: JobId=43177 done
[2022-06-07T12:53:55.311] _slurm_rpc_submit_batch_job: JobId=43178 InitPrio=25758 usec=389
[2022-06-07T12:53:56.082] sched: Allocate JobId=43178 NodeList=cpu01 #CPUs=8 Partition=cpu-opteron
[2022-06-07T12:54:03.713] _job_complete: JobId=43178 WEXITSTATUS 0
[2022-06-07T12:54:03.713] _job_complete: JobId=43178 done
[2022-06-07T12:57:25.233] _slurm_rpc_submit_batch_job: JobId=43179 InitPrio=25758 usec=425
[2022-06-07T12:57:25.431] sched: Allocate JobId=43179 NodeList=cpu01 #CPUs=8 Partition=cpu-opteron
[2022-06-07T12:57:33.116] _job_complete: JobId=43179 WEXITSTATUS 0
[2022-06-07T12:57:33.116] _job_complete: JobId=43179 done
[2022-06-07T13:00:08.050] _slurm_rpc_submit_batch_job: JobId=43180 InitPrio=25758 usec=583
[2022-06-07T13:00:08.705] sched: Allocate JobId=43180 NodeList=cpu01 #CPUs=8 Partition=cpu-opteron
[2022-06-07T13:00:16.320] _job_complete: JobId=43180 WEXITSTATUS 0
[2022-06-07T13:00:16.320] _job_complete: JobId=43180 done
[2022-06-07T13:00:46.231] _slurm_rpc_submit_batch_job: JobId=43181 InitPrio=20028 usec=432
[2022-06-07T13:00:46.766] sched: Allocate JobId=43181 NodeList=cpu13 #CPUs=32 Partition=cpu-epyc
[2022-06-07T13:01:13.847] _slurm_rpc_submit_batch_job: JobId=43182 InitPrio=20028 usec=479
[2022-06-07T13:01:14.803] sched: Allocate JobId=43182 NodeList=cpu14 #CPUs=32 Partition=cpu-epyc
[2022-06-07T13:01:33.822] _slurm_rpc_submit_batch_job: JobId=43183 InitPrio=20028 usec=543
[2022-06-07T13:01:33.830] sched: Allocate JobId=43183 NodeList=cpu15 #CPUs=32 Partition=cpu-epyc
[2022-06-07T13:02:02.790] _slurm_rpc_submit_batch_job: JobId=43184 InitPrio=20028 usec=416
[2022-06-07T13:02:36.188] _slurm_rpc_submit_batch_job: JobId=43185 InitPrio=25758 usec=400
[2022-06-07T13:02:37.028] sched: Allocate JobId=43185 NodeList=cpu01 #CPUs=8 Partition=cpu-opteron
[2022-06-07T13:02:44.720] _job_complete: JobId=43185 WEXITSTATUS 0
[2022-06-07T13:02:44.720] _job_complete: JobId=43185 done
[2022-06-07T13:27:57.086] _job_complete: JobId=43182 WEXITSTATUS 0
[2022-06-07T13:27:57.086] _job_complete: JobId=43182 done
[2022-06-07T13:27:57.404] sched: Allocate JobId=43184 NodeList=cpu14 #CPUs=32 Partition=cpu-epyc
[2022-06-07T13:31:06.189] _job_complete: JobId=43183 WEXITSTATUS 0
[2022-06-07T13:31:06.190] _job_complete: JobId=43183 done
[2022-06-07T13:36:30.691] _job_complete: JobId=43181 WEXITSTATUS 0
[2022-06-07T13:36:30.691] _job_complete: JobId=43181 done
[2022-06-07T13:57:47.267] _job_complete: JobId=43184 WEXITSTATUS 0
[2022-06-07T13:57:47.267] _job_complete: JobId=43184 done
[2022-06-07T13:58:21.703] sched: _slurm_rpc_allocate_resources JobId=43186 NodeList=cpu13 usec=4682
[2022-06-07T13:58:24.716] _job_complete: JobId=43186 WEXITSTATUS 1
[2022-06-07T13:58:24.716] _job_complete: JobId=43186 done
[2022-06-07T13:58:32.030] sched: _slurm_rpc_allocate_resources JobId=43187 NodeList=cpu13 usec=980
[2022-06-07T14:02:20.689] _slurm_rpc_kill_job: REQUEST_KILL_JOB JobId=43173 uid 548300543
[2022-06-07T14:02:47.632] _slurm_rpc_submit_batch_job: JobId=43188 InitPrio=25758 usec=494
[2022-06-07T14:02:47.803] sched: Allocate JobId=43188 NodeList=cpu01 #CPUs=8 Partition=cpu-opteron
[2022-06-07T14:07:12.393] _job_complete: JobId=43188 WEXITSTATUS 0
[2022-06-07T14:07:12.393] _job_complete: JobId=43188 done
[2022-06-07T14:20:27.032] _slurm_rpc_submit_batch_job: JobId=43189 InitPrio=20994 usec=927
[2022-06-07T14:21:03.758] _slurm_rpc_kill_job: REQUEST_KILL_JOB JobId=43189 uid 548200029
[2022-06-07T14:21:25.175] _slurm_rpc_submit_batch_job: JobId=43190 InitPrio=20994 usec=912
[2022-06-07T14:21:31.558] _slurm_rpc_kill_job: REQUEST_KILL_JOB JobId=43190 uid 548200029
[2022-06-07T14:22:35.136] _slurm_rpc_submit_batch_job: JobId=43191 InitPrio=20994 usec=903
[2022-06-07T14:24:28.075] _slurm_rpc_submit_batch_job: JobId=43192 InitPrio=20857 usec=401
[2022-06-07T14:24:28.206] sched: Allocate JobId=43192 NodeList=cpu01 #CPUs=32 Partition=cpu-opteron
[2022-06-07T14:24:33.929] _job_complete: JobId=43192 WEXITSTATUS 1
[2022-06-07T14:24:33.930] _job_complete: JobId=43192 done
[2022-06-07T14:24:57.732] _slurm_rpc_submit_batch_job: JobId=43193 InitPrio=20857 usec=414
[2022-06-07T14:24:58.236] sched: Allocate JobId=43193 NodeList=cpu01 #CPUs=32 Partition=cpu-opteron
[2022-06-07T14:25:03.781] _job_complete: JobId=43193 WEXITSTATUS 1
[2022-06-07T14:25:03.781] _job_complete: JobId=43193 done
[2022-06-07T14:25:21.291] _slurm_rpc_submit_batch_job: JobId=43194 InitPrio=20857 usec=436
[2022-06-07T14:25:22.272] sched: Allocate JobId=43194 NodeList=cpu01 #CPUs=32 Partition=cpu-opteron
[2022-06-07T14:25:29.690] _job_complete: JobId=43194 WEXITSTATUS 0
[2022-06-07T14:25:29.690] _job_complete: JobId=43194 done
[2022-06-07T14:25:58.492] _slurm_rpc_submit_batch_job: JobId=43195 InitPrio=20857 usec=392
[2022-06-07T14:25:59.325] sched: Allocate JobId=43195 NodeList=cpu01 #CPUs=32 Partition=cpu-opteron
[2022-06-07T14:26:25.231] _job_complete: JobId=43195 WEXITSTATUS 0
[2022-06-07T14:26:25.231] _job_complete: JobId=43195 done
[2022-06-07T14:26:50.621] _job_complete: JobId=43172 WEXITSTATUS 1
[2022-06-07T14:26:50.621] _job_complete: JobId=43172 done
[2022-06-07T14:26:50.907] sched: Allocate JobId=43191 NodeList=gpu01 #CPUs=16 Partition=gpu-k10
[2022-06-07T14:27:24.895] _slurm_rpc_submit_batch_job: JobId=43196 InitPrio=20857 usec=363
[2022-06-07T14:27:25.570] sched: Allocate JobId=43196 NodeList=cpu01 #CPUs=32 Partition=cpu-opteron
[2022-06-07T14:27:31.089] _job_complete: JobId=43196 WEXITSTATUS 1
[2022-06-07T14:27:31.089] _job_complete: JobId=43196 done
[2022-06-07T14:27:39.483] _slurm_rpc_submit_batch_job: JobId=43197 InitPrio=20857 usec=367
[2022-06-07T14:27:39.630] sched: Allocate JobId=43197 NodeList=cpu01 #CPUs=32 Partition=cpu-opteron
[2022-06-07T14:27:44.811] _job_complete: JobId=43197 WEXITSTATUS 1
[2022-06-07T14:27:44.811] _job_complete: JobId=43197 done
[2022-06-07T14:30:24.935] _slurm_rpc_submit_batch_job: JobId=43198 InitPrio=20857 usec=389
[2022-06-07T14:30:25.876] sched: Allocate JobId=43198 NodeList=cpu01 #CPUs=32 Partition=cpu-opteron
[2022-06-07T14:30:43.531] _job_complete: JobId=43198 WEXITSTATUS 0
[2022-06-07T14:30:43.532] _job_complete: JobId=43198 done
[2022-06-07T14:34:37.958] _job_complete: JobId=43088 WEXITSTATUS 0
[2022-06-07T14:34:37.958] _job_complete: JobId=43088 done
[2022-06-07T14:35:29.307] _slurm_rpc_submit_batch_job: JobId=43199 InitPrio=20857 usec=443
[2022-06-07T14:35:29.443] sched: Allocate JobId=43199 NodeList=cpu01 #CPUs=32 Partition=cpu-opteron
[2022-06-07T14:35:56.737] _slurm_rpc_submit_batch_job: JobId=43200 InitPrio=20857 usec=412
[2022-06-07T14:35:57.481] sched: Allocate JobId=43200 NodeList=cpu11 #CPUs=32 Partition=cpu-opteron
[2022-06-07T14:36:00.156] _job_complete: JobId=43199 WEXITSTATUS 0
[2022-06-07T14:36:00.156] _job_complete: JobId=43199 done
[2022-06-07T14:36:04.320] _job_complete: JobId=43200 WEXITSTATUS 0
[2022-06-07T14:36:04.320] _job_complete: JobId=43200 done
[2022-06-07T14:38:05.149] _slurm_rpc_submit_batch_job: JobId=43201 InitPrio=20857 usec=372
[2022-06-07T14:38:05.772] sched: Allocate JobId=43201 NodeList=cpu01 #CPUs=32 Partition=cpu-opteron
[2022-06-07T14:38:25.703] _job_complete: JobId=43201 WEXITSTATUS 0
[2022-06-07T14:38:25.703] _job_complete: JobId=43201 done
[2022-06-07T14:51:36.216] _job_complete: JobId=43191 WEXITSTATUS 134
[2022-06-07T14:51:36.217] _job_complete: JobId=43191 done
[2022-06-07T14:58:39.105] Time limit exhausted for JobId=43087
[2022-06-07T15:02:18.278] _slurm_rpc_submit_batch_job: JobId=43202 InitPrio=21411 usec=445
[2022-06-07T15:02:18.431] sched: Allocate JobId=43202 NodeList=cpu13 #CPUs=64 Partition=cpu-epyc
[2022-06-07T15:03:09.577] Time limit exhausted for JobId=43089
[2022-06-07T15:53:22.756] _slurm_rpc_submit_batch_job: JobId=43203 InitPrio=21411 usec=520
[2022-06-07T15:53:23.190] sched: Allocate JobId=43203 NodeList=cpu15 #CPUs=64 Partition=cpu-epyc
[2022-06-07T16:01:53.146] _slurm_rpc_submit_batch_job: JobId=43204 InitPrio=20580 usec=389
[2022-06-07T16:01:54.044] sched: Allocate JobId=43204 NodeList=cpu12 #CPUs=32 Partition=cpu-epyc
[2022-06-07T16:03:04.431] _slurm_rpc_submit_batch_job: JobId=43205 InitPrio=20580 usec=349
[2022-06-07T16:03:05.262] sched: Allocate JobId=43205 NodeList=cpu11 #CPUs=32 Partition=cpu-opteron
[2022-06-07T16:04:02.575] _slurm_rpc_submit_batch_job: JobId=43206 InitPrio=20580 usec=340
[2022-06-07T16:04:03.349] sched: Allocate JobId=43206 NodeList=cpu14 #CPUs=32 Partition=cpu-epyc
[2022-06-07T16:04:53.669] _slurm_rpc_submit_batch_job: JobId=43207 InitPrio=20580 usec=421
[2022-06-07T16:04:54.424] sched: Allocate JobId=43207 NodeList=cpu15 #CPUs=32 Partition=cpu-epyc
[2022-06-07T16:18:20.916] _slurm_rpc_submit_batch_job: JobId=43208 InitPrio=23480 usec=351
[2022-06-07T16:18:28.338] _slurm_rpc_kill_job: REQUEST_KILL_JOB JobId=43208 uid 548200003
[2022-06-07T16:50:16.561] _slurm_rpc_submit_batch_job: JobId=43209 InitPrio=21411 usec=551
[2022-06-07T16:50:17.470] sched: Allocate JobId=43209 NodeList=cpu03 #CPUs=64 Partition=cpu-opteron
[2022-06-07T18:21:32.378] sched: _slurm_rpc_allocate_resources JobId=43210 NodeList=cpu01 usec=15013
[2022-06-07T18:21:35.390] _job_complete: JobId=43210 WEXITSTATUS 1
[2022-06-07T18:21:35.391] _job_complete: JobId=43210 done
[2022-06-07T18:22:05.074] sched: _slurm_rpc_allocate_resources JobId=43211 NodeList=cpu01 usec=1336
[2022-06-07T18:26:49.875] _job_complete: JobId=43211 WEXITSTATUS 0
[2022-06-07T18:26:49.875] _job_complete: JobId=43211 done
[2022-06-07T19:28:19.262] _job_complete: JobId=43187 WEXITSTATUS 0
[2022-06-07T19:28:19.263] _job_complete: JobId=43187 done
[2022-06-07T19:33:19.799] cleanup_completing: JobId=43187 completion process took 300 seconds
[2022-06-07T20:57:25.153] _slurm_rpc_submit_batch_job: JobId=43212 InitPrio=25206 usec=522
[2022-06-07T20:57:25.510] sched: Allocate JobId=43212 NodeList=cpu01 #CPUs=8 Partition=cpu-opteron
[2022-06-07T20:57:30.202] _job_complete: JobId=43212 WEXITSTATUS 1
[2022-06-07T20:57:30.202] _job_complete: JobId=43212 done
[2022-06-07T21:08:21.756] _slurm_rpc_submit_batch_job: JobId=43213 InitPrio=25206 usec=568
[2022-06-07T21:08:22.762] sched: Allocate JobId=43213 NodeList=cpu01 #CPUs=8 Partition=cpu-opteron
[2022-06-07T21:08:26.864] _job_complete: JobId=43213 WEXITSTATUS 1
[2022-06-07T21:08:26.864] _job_complete: JobId=43213 done
[2022-06-07T21:36:41.813] _slurm_rpc_submit_batch_job: JobId=43214 InitPrio=25206 usec=453
[2022-06-07T21:36:41.893] sched: Allocate JobId=43214 NodeList=cpu01 #CPUs=8 Partition=cpu-opteron
[2022-06-07T21:36:46.090] _job_complete: JobId=43214 WEXITSTATUS 0
[2022-06-07T21:36:46.090] _job_complete: JobId=43214 done
[2022-06-07T21:39:15.334] _job_complete: JobId=43134 WEXITSTATUS 0
[2022-06-07T21:39:15.339] _job_complete: JobId=43134 done
[2022-06-07T21:56:21.007] _slurm_rpc_submit_batch_job: JobId=43215 InitPrio=21522 usec=447
[2022-06-07T21:56:33.449] _slurm_rpc_kill_job: REQUEST_KILL_JOB JobId=43215 uid 548200084
[2022-06-07T21:57:43.293] _slurm_rpc_submit_batch_job: JobId=43216 InitPrio=25137 usec=539
[2022-06-07T21:57:43.395] sched: Allocate JobId=43216 NodeList=cpu13 #CPUs=16 Partition=cpu-epyc
[2022-06-07T21:57:49.212] _job_complete: JobId=43216 WEXITSTATUS 1
[2022-06-07T21:57:49.212] _job_complete: JobId=43216 done
[2022-06-07T22:46:39.798] Time limit exhausted for JobId=43125
[2022-06-07T23:30:51.588] _slurm_rpc_submit_batch_job: JobId=43217 InitPrio=25000 usec=516
[2022-06-07T23:30:51.807] sched: Allocate JobId=43217 NodeList=cpu01 #CPUs=32 Partition=cpu-opteron
[2022-06-07T23:31:14.775] _job_complete: JobId=43217 WEXITSTATUS 0
[2022-06-07T23:31:14.775] _job_complete: JobId=43217 done
[2022-06-07T23:41:30.611] _slurm_rpc_submit_batch_job: JobId=43218 InitPrio=25000 usec=487
[2022-06-07T23:41:31.000] sched: Allocate JobId=43218 NodeList=cpu13 #CPUs=32 Partition=cpu-epyc
[2022-06-07T23:43:18.819] _job_complete: JobId=43218 WEXITSTATUS 0
[2022-06-07T23:43:18.819] _job_complete: JobId=43218 done
[2022-06-08T00:04:13.225] _slurm_rpc_submit_batch_job: JobId=43219 InitPrio=27934 usec=380
[2022-06-08T00:04:14.097] sched: Allocate JobId=43219 NodeList=cpu01 #CPUs=12 Partition=cpu-opteron
[2022-06-08T00:11:22.020] _slurm_rpc_kill_job: REQUEST_KILL_JOB JobId=43219 uid 548300561
[2022-06-08T00:11:35.349] _slurm_rpc_submit_batch_job: JobId=43220 InitPrio=27934 usec=437
[2022-06-08T00:11:35.824] sched: Allocate JobId=43220 NodeList=cpu01 #CPUs=12 Partition=cpu-opteron
[2022-06-08T00:30:27.561] _slurm_rpc_submit_batch_job: JobId=43221 InitPrio=21135 usec=529
[2022-06-08T00:30:27.933] sched: Allocate JobId=43221 NodeList=cpu04 #CPUs=64 Partition=cpu-opteron
[2022-06-08T00:49:49.746] _slurm_rpc_kill_job: REQUEST_KILL_JOB JobId=43220 uid 548300561
[2022-06-08T00:52:24.189] sched: _slurm_rpc_allocate_resources JobId=43222 NodeList=cpu01 usec=4719
[2022-06-08T01:39:51.824] _slurm_rpc_submit_batch_job: JobId=43223 InitPrio=27658 usec=682
[2022-06-08T01:39:52.365] sched: Allocate JobId=43223 NodeList=cpu01 #CPUs=12 Partition=cpu-opteron
[2022-06-08T01:50:59.075] _slurm_rpc_kill_job: REQUEST_KILL_JOB JobId=43223 uid 548300561
[2022-06-08T01:51:07.725] _job_complete: JobId=43222 WEXITSTATUS 0
[2022-06-08T01:51:07.725] _job_complete: JobId=43222 done
[2022-06-08T01:55:27.472] _slurm_rpc_submit_batch_job: JobId=43224 InitPrio=27692 usec=447
[2022-06-08T01:55:28.042] sched: Allocate JobId=43224 NodeList=gpu04 #CPUs=8 Partition=gpu-k40c
[2022-06-08T01:55:35.018] _job_complete: JobId=43224 WEXITSTATUS 1
[2022-06-08T01:55:35.018] _job_complete: JobId=43224 done
[2022-06-08T01:59:39.504] _slurm_rpc_submit_batch_job: JobId=43225 InitPrio=27658 usec=510
[2022-06-08T01:59:40.465] sched: Allocate JobId=43225 NodeList=cpu01 #CPUs=12 Partition=cpu-opteron
[2022-06-08T03:00:09.438] Time limit exhausted for JobId=43225
[2022-06-08T03:13:10.196] _job_complete: JobId=43205 WEXITSTATUS 0
[2022-06-08T03:13:10.201] _job_complete: JobId=43205 done
[2022-06-08T06:37:51.753] _job_complete: JobId=43203 WEXITSTATUS 0
[2022-06-08T06:37:51.753] _job_complete: JobId=43203 done
[2022-06-08T09:23:24.627] _slurm_rpc_submit_batch_job: JobId=43226 InitPrio=24937 usec=424
[2022-06-08T09:23:25.405] sched: Allocate JobId=43226 NodeList=cpu13 #CPUs=32 Partition=cpu-epyc
[2022-06-08T09:25:17.189] _slurm_rpc_submit_batch_job: JobId=43227 InitPrio=21112 usec=458
[2022-06-08T10:07:30.015] _slurm_rpc_submit_batch_job: JobId=43228 InitPrio=24929 usec=347
[2022-06-08T10:09:41.210] _slurm_rpc_submit_batch_job: JobId=43229 InitPrio=24929 usec=355
[2022-06-08T10:10:47.616] _slurm_rpc_submit_batch_job: JobId=43230 InitPrio=19198 usec=344
[2022-06-08T10:10:47.735] sched: Allocate JobId=43230 NodeList=cpu14 #CPUs=64 Partition=cpu-epyc
[2022-06-08T10:22:53.886] _slurm_rpc_submit_batch_job: JobId=43231 InitPrio=19198 usec=438
[2022-06-08T10:22:54.297] sched: Allocate JobId=43231 NodeList=cpu05 #CPUs=64 Partition=cpu-opteron
[2022-06-08T10:29:05.379] _slurm_rpc_submit_batch_job: JobId=43232 InitPrio=19198 usec=403
[2022-06-08T10:29:05.921] sched: Allocate JobId=43232 NodeList=cpu07 #CPUs=64 Partition=cpu-opteron
[2022-06-08T10:31:51.914] _slurm_rpc_submit_batch_job: JobId=43233 InitPrio=19472 usec=395
[2022-06-08T10:31:52.165] sched: Allocate JobId=43233 NodeList=cpu15 #CPUs=32 Partition=cpu-epyc
[2022-06-08T10:37:58.863] _job_complete: JobId=43226 WEXITSTATUS 0
[2022-06-08T10:37:58.864] _job_complete: JobId=43226 done
[2022-06-08T10:39:00.550] _slurm_rpc_submit_batch_job: JobId=43234 InitPrio=19472 usec=696
[2022-06-08T10:39:00.995] sched: Allocate JobId=43234 NodeList=cpu13 #CPUs=32 Partition=cpu-epyc
[2022-06-08T10:41:02.130] _slurm_rpc_submit_batch_job: JobId=43235 InitPrio=19198 usec=368
[2022-06-08T10:41:02.166] sched: Allocate JobId=43235 NodeList=cpu08 #CPUs=64 Partition=cpu-opteron
[2022-06-08T10:46:13.178] _slurm_rpc_submit_batch_job: JobId=43236 InitPrio=19198 usec=356
[2022-06-08T10:46:13.767] sched: Allocate JobId=43236 NodeList=cpu09 #CPUs=64 Partition=cpu-opteron
[2022-06-08T10:52:48.806] _slurm_rpc_submit_batch_job: JobId=43237 InitPrio=19472 usec=450
[2022-06-08T10:52:49.603] sched: Allocate JobId=43237 NodeList=cpu15 #CPUs=32 Partition=cpu-epyc
[2022-06-08T12:00:17.811] _slurm_rpc_submit_batch_job: JobId=43238 InitPrio=24499 usec=400
[2022-06-08T12:00:18.312] sched: Allocate JobId=43238 NodeList=gpu01 #CPUs=16 Partition=gpu-k10
[2022-06-08T12:03:25.154] _slurm_rpc_kill_job: REQUEST_KILL_JOB JobId=43238 uid 548300543
[2022-06-08T12:28:16.896] Processing Reconfiguration Request
[2022-06-08T12:28:16.903] restoring original state of nodes
[2022-06-08T12:28:16.903] select/cons_tres: part_data_create_array: select/cons_tres: preparing for 6 partitions
[2022-06-08T12:28:16.904] read_slurm_conf: backup_controller not specified
[2022-06-08T12:28:16.904] select/cons_tres: select_p_reconfigure: select/cons_tres: reconfigure
[2022-06-08T12:28:16.904] select/cons_tres: part_data_create_array: select/cons_tres: preparing for 6 partitions
[2022-06-08T12:28:16.904] No parameter for mcs plugin, default values set
[2022-06-08T12:28:16.904] mcs: MCSParameters = (null). ondemand set.
[2022-06-08T12:28:16.905] _slurm_rpc_reconfigure_controller: completed usec=8989
[2022-06-08T12:28:17.356] SchedulerParameters=default_queue_depth=100,max_rpc_cnt=0,max_sched_time=2,partition_job_depth=0,sched_max_job_start=0,sched_min_interval=2
[2022-06-08T12:49:31.189] _slurm_rpc_submit_batch_job: JobId=43239 InitPrio=27557 usec=465
[2022-06-08T12:50:07.276] _slurm_rpc_kill_job: REQUEST_KILL_JOB JobId=43239 uid 548300561
[2022-06-08T13:02:06.115] _slurm_rpc_submit_batch_job: JobId=43240 InitPrio=23541 usec=388
[2022-06-08T13:02:06.991] sched: Allocate JobId=43240 NodeList=cpu01 #CPUs=1 Partition=cpu-opteron
[2022-06-08T13:02:07.567] _job_complete: JobId=43240 WEXITSTATUS 0
[2022-06-08T13:02:07.567] _job_complete: JobId=43240 done
[2022-06-08T13:03:43.496] _slurm_rpc_submit_batch_job: JobId=43241 InitPrio=24499 usec=411
[2022-06-08T13:03:44.231] sched: Allocate JobId=43241 NodeList=gpu01 #CPUs=16 Partition=gpu-k10
[2022-06-08T13:03:49.925] _slurm_rpc_kill_job: REQUEST_KILL_JOB JobId=43241 uid 548300543
[2022-06-08T13:05:47.639] _slurm_rpc_submit_batch_job: JobId=43242 InitPrio=24499 usec=356
[2022-06-08T13:05:48.409] sched: Allocate JobId=43242 NodeList=gpu01 #CPUs=16 Partition=gpu-k10
[2022-06-08T13:07:53.729] _slurm_rpc_kill_job: REQUEST_KILL_JOB JobId=43242 uid 548300543
[2022-06-08T13:11:13.860] _pick_best_nodes: JobId=43243 never runnable in partition cpu-opteron
[2022-06-08T13:11:13.860] _slurm_rpc_submit_batch_job: Requested node configuration is not available
[2022-06-08T13:12:08.232] _slurm_rpc_submit_batch_job: JobId=43244 InitPrio=24499 usec=346
[2022-06-08T13:12:09.159] sched: Allocate JobId=43244 NodeList=cpu01 #CPUs=16 Partition=cpu-opteron
[2022-06-08T13:12:53.780] _slurm_rpc_kill_job: REQUEST_KILL_JOB JobId=43244 uid 548300543
[2022-06-08T13:59:50.626] _slurm_rpc_submit_batch_job: JobId=43245 InitPrio=23684 usec=448
[2022-06-08T13:59:51.652] sched: Allocate JobId=43245 NodeList=cpu01 #CPUs=16 Partition=cpu-opteron
[2022-06-08T14:02:00.901] _slurm_rpc_submit_batch_job: JobId=43246 InitPrio=23684 usec=437
[2022-06-08T14:02:01.807] sched: Allocate JobId=43246 NodeList=cpu01 #CPUs=16 Partition=cpu-opteron
[2022-06-08T14:53:38.736] sched: _slurm_rpc_allocate_resources JobId=43247 NodeList=cpu11 usec=14732
[2022-06-08T15:00:47.217] _job_complete: JobId=43247 WEXITSTATUS 0
[2022-06-08T15:00:47.218] _job_complete: JobId=43247 done
[2022-06-08T15:02:40.075] Time limit exhausted for JobId=43202
[2022-06-08T15:05:48.946] cleanup_completing: JobId=43247 completion process took 301 seconds
[2022-06-08T15:29:18.690] _slurm_rpc_submit_batch_job: JobId=43248 InitPrio=21099 usec=706
[2022-06-08T15:29:19.332] sched: Allocate JobId=43248 NodeList=cpu13 #CPUs=64 Partition=cpu-epyc
[2022-06-08T15:39:55.457] _job_complete: JobId=43245 WEXITSTATUS 1
[2022-06-08T15:39:55.457] _job_complete: JobId=43245 done
[2022-06-08T16:07:38.448] _job_complete: JobId=43035 WEXITSTATUS 0
[2022-06-08T16:07:38.454] _job_complete: JobId=43035 done
[2022-06-08T16:07:38.854] sched: Allocate JobId=43162 NodeList=gpu05 #CPUs=32 Partition=gpu-v100s
[2022-06-08T16:48:38.549] _job_complete: JobId=43246 WEXITSTATUS 1
[2022-06-08T16:48:38.549] _job_complete: JobId=43246 done
[2022-06-08T16:50:40.352] Time limit exhausted for JobId=43209
[2022-06-08T16:59:25.234] _slurm_rpc_submit_batch_job: JobId=43249 InitPrio=21099 usec=415
[2022-06-08T16:59:47.959] _slurm_rpc_kill_job: REQUEST_KILL_JOB JobId=43249 uid 548200019
[2022-06-08T17:00:13.540] _slurm_rpc_submit_batch_job: JobId=43250 InitPrio=21099 usec=472
[2022-06-08T17:00:14.487] sched: Allocate JobId=43250 NodeList=cpu03 #CPUs=64 Partition=cpu-opteron
[2022-06-08T17:27:44.423] _slurm_rpc_submit_batch_job: JobId=43251 InitPrio=23684 usec=449
[2022-06-08T17:27:44.571] sched: Allocate JobId=43251 NodeList=cpu01 #CPUs=16 Partition=cpu-opteron
[2022-06-08T17:28:00.146] _slurm_rpc_submit_batch_job: JobId=43252 InitPrio=23684 usec=749
[2022-06-08T17:28:00.581] sched: Allocate JobId=43252 NodeList=cpu11 #CPUs=16 Partition=cpu-opteron
[2022-06-08T18:30:00.263] _job_complete: JobId=43162 WEXITSTATUS 0
[2022-06-08T18:30:00.263] _job_complete: JobId=43162 done
[2022-06-08T18:30:10.196] sched: Allocate JobId=43229 NodeList=gpu05 #CPUs=1 Partition=gpu-v100s
[2022-06-08T19:45:06.660] _slurm_rpc_submit_batch_job: JobId=43253 InitPrio=29765 usec=452
[2022-06-08T19:45:06.986] sched: Allocate JobId=43253 NodeList=cpu01 #CPUs=4 Partition=cpu-opteron
[2022-06-08T19:48:07.570] _job_complete: JobId=43253 WEXITSTATUS 0
[2022-06-08T19:48:07.570] _job_complete: JobId=43253 done
[2022-06-08T20:03:01.786] _job_complete: JobId=43252 WEXITSTATUS 0
[2022-06-08T20:03:01.787] _job_complete: JobId=43252 done
[2022-06-08T20:07:11.880] error: This association 195(account='free', user='shahreeza', partition='(null)') does not have access to qos normal
[2022-06-08T20:07:11.880] _slurm_rpc_submit_batch_job: Invalid qos specification
[2022-06-08T20:25:04.749] _job_complete: JobId=43206 WEXITSTATUS 0
[2022-06-08T20:25:04.755] _job_complete: JobId=43206 done
[2022-06-08T20:31:11.603] _job_complete: JobId=43204 WEXITSTATUS 1
[2022-06-08T20:31:11.604] _job_complete: JobId=43204 done
[2022-06-08T20:36:56.133] _job_complete: JobId=43251 WEXITSTATUS 0
[2022-06-08T20:36:56.133] _job_complete: JobId=43251 done
[2022-06-08T20:43:59.736] _job_complete: JobId=43207 WEXITSTATUS 0
[2022-06-08T20:43:59.737] _job_complete: JobId=43207 done
[2022-06-08T22:41:19.586] _slurm_rpc_submit_batch_job: JobId=43254 InitPrio=20014 usec=507
[2022-06-08T22:41:20.502] sched: Allocate JobId=43254 NodeList=gpu01 #CPUs=32 Partition=gpu-k10
[2022-06-08T22:44:40.502] No nodes satisfy requirements for JobId=43255 in partition gpu-k10
[2022-06-08T22:44:40.502] _slurm_rpc_submit_batch_job: Requested node configuration is not available
[2022-06-08T22:45:00.356] _slurm_rpc_submit_batch_job: JobId=43256 InitPrio=20014 usec=380
[2022-06-08T22:45:00.931] sched: Allocate JobId=43256 NodeList=gpu03 #CPUs=32 Partition=gpu-k10
[2022-06-08T23:31:47.951] _job_complete: JobId=43256 WEXITSTATUS 0
[2022-06-08T23:31:47.951] _job_complete: JobId=43256 done
[2022-06-09T00:30:40.852] Time limit exhausted for JobId=43221
[2022-06-09T00:33:19.955] _slurm_rpc_submit_batch_job: JobId=43257 InitPrio=21307 usec=521
[2022-06-09T00:33:20.246] sched: Allocate JobId=43257 NodeList=cpu01 #CPUs=8 Partition=cpu-opteron
[2022-06-09T00:34:01.179] _job_complete: JobId=43257 WEXITSTATUS 0
[2022-06-09T00:34:01.179] _job_complete: JobId=43257 done
[2022-06-09T00:35:20.865] _slurm_rpc_submit_batch_job: JobId=43258 InitPrio=21373 usec=441
[2022-06-09T00:35:21.418] sched: Allocate JobId=43258 NodeList=cpu12 #CPUs=32 Partition=cpu-epyc
[2022-06-09T00:51:21.245] _job_complete: JobId=43107 WEXITSTATUS 0
[2022-06-09T00:51:21.245] _job_complete: JobId=43107 done
[2022-06-09T00:51:22.141] sched: Allocate JobId=43091 NodeList=gpu05 #CPUs=32 Partition=gpu-v100s
[2022-06-09T00:52:54.685] _slurm_rpc_submit_batch_job: JobId=43259 InitPrio=21238 usec=383
[2022-06-09T00:52:55.394] sched: Allocate JobId=43259 NodeList=cpu01 #CPUs=16 Partition=cpu-opteron
[2022-06-09T00:53:11.006] _slurm_rpc_submit_batch_job: JobId=43260 InitPrio=21238 usec=562
[2022-06-09T00:53:13.421] sched: Allocate JobId=43260 NodeList=cpu01 #CPUs=16 Partition=cpu-opteron
[2022-06-09T00:55:46.276] _job_complete: JobId=43259 WEXITSTATUS 0
[2022-06-09T00:55:46.276] _job_complete: JobId=43259 done
[2022-06-09T00:59:50.686] _slurm_rpc_submit_batch_job: JobId=43261 InitPrio=21101 usec=489
[2022-06-09T00:59:51.126] sched: Allocate JobId=43261 NodeList=cpu14 #CPUs=32 Partition=cpu-epyc
[2022-06-09T01:24:12.857] _job_complete: JobId=43261 WEXITSTATUS 0
[2022-06-09T01:24:12.858] _job_complete: JobId=43261 done
[2022-06-09T01:26:22.616] _job_complete: JobId=43237 WEXITSTATUS 0
[2022-06-09T01:26:22.622] _job_complete: JobId=43237 done
[2022-06-09T01:48:30.857] _job_complete: JobId=43260 WEXITSTATUS 0
[2022-06-09T01:48:30.858] _job_complete: JobId=43260 done
[2022-06-09T02:53:59.739] _job_complete: JobId=43234 WEXITSTATUS 0
[2022-06-09T02:53:59.740] _job_complete: JobId=43234 done
[2022-06-09T03:02:43.764] _job_complete: JobId=43233 WEXITSTATUS 0
[2022-06-09T03:02:43.764] _job_complete: JobId=43233 done
[2022-06-09T06:41:01.319] _job_complete: JobId=43154 WEXITSTATUS 1
[2022-06-09T06:41:01.325] _job_complete: JobId=43154 done
[2022-06-09T08:59:27.533] _slurm_rpc_submit_batch_job: JobId=43262 InitPrio=22054 usec=431
[2022-06-09T08:59:28.435] sched: Allocate JobId=43262 NodeList=gpu04 #CPUs=16 Partition=gpu-k40c
[2022-06-09T09:39:30.301] _job_complete: JobId=43254 WEXITSTATUS 0
[2022-06-09T09:39:30.301] _job_complete: JobId=43254 done
[2022-06-09T10:13:22.148] _job_complete: JobId=43232 WEXITSTATUS 0
[2022-06-09T10:13:22.153] _job_complete: JobId=43232 done
[2022-06-09T10:26:21.948] _slurm_rpc_submit_batch_job: JobId=43263 InitPrio=21069 usec=422
[2022-06-09T10:26:22.434] sched: Allocate JobId=43263 NodeList=cpu01 #CPUs=4 Partition=cpu-opteron
[2022-06-09T10:27:16.231] _job_complete: JobId=43263 WEXITSTATUS 0
[2022-06-09T10:27:16.231] _job_complete: JobId=43263 done
[2022-06-09T11:09:01.287] _slurm_rpc_submit_batch_job: JobId=43264 InitPrio=19197 usec=382
[2022-06-09T11:09:01.336] sched: Allocate JobId=43264 NodeList=cpu04 #CPUs=64 Partition=cpu-opteron
[2022-06-09T11:32:07.640] _slurm_rpc_submit_batch_job: JobId=43265 InitPrio=19471 usec=429
[2022-06-09T11:32:07.892] sched: Allocate JobId=43265 NodeList=cpu13 #CPUs=32 Partition=cpu-epyc
[2022-06-09T11:36:16.097] _slurm_rpc_submit_batch_job: JobId=43266 InitPrio=19334 usec=368
[2022-06-09T11:36:16.407] sched: Allocate JobId=43266 NodeList=cpu15 #CPUs=48 Partition=cpu-epyc
[2022-06-09T11:42:21.185] _slurm_rpc_submit_batch_job: JobId=43267 InitPrio=31019 usec=496
[2022-06-09T11:48:32.219] _slurm_rpc_submit_batch_job: JobId=43268 InitPrio=31224 usec=483
[2022-06-09T11:48:32.975] sched: Allocate JobId=43268 NodeList=cpu15 #CPUs=24 Partition=cpu-epyc
[2022-06-09T11:49:18.570] _slurm_rpc_kill_job: REQUEST_KILL_JOB JobId=43267 uid 548300570
[2022-06-09T11:57:06.665] _slurm_rpc_submit_batch_job: JobId=43269 InitPrio=21238 usec=947
[2022-06-09T11:57:06.799] sched: Allocate JobId=43269 NodeList=gpu01 #CPUs=16 Partition=gpu-k10
[2022-06-09T11:58:46.523] _slurm_rpc_submit_batch_job: JobId=43270 InitPrio=21238 usec=934
[2022-06-09T11:58:47.057] sched: Allocate JobId=43270 NodeList=gpu03 #CPUs=16 Partition=gpu-k10
[2022-06-09T12:05:59.795] _slurm_rpc_submit_batch_job: JobId=43271 InitPrio=19471 usec=396
[2022-06-09T12:05:59.820] sched: Allocate JobId=43271 NodeList=cpu14 #CPUs=32 Partition=cpu-epyc
[2022-06-09T12:07:59.781] _slurm_rpc_submit_batch_job: JobId=43272 InitPrio=21101 usec=375
[2022-06-09T12:08:00.086] sched: Allocate JobId=43272 NodeList=cpu01 #CPUs=32 Partition=cpu-opteron
[2022-06-09T12:09:45.575] _slurm_rpc_submit_batch_job: JobId=43273 InitPrio=19197 usec=518
[2022-06-09T12:09:46.234] sched: Allocate JobId=43273 NodeList=cpu07 #CPUs=64 Partition=cpu-opteron
[2022-06-09T12:13:01.579] _job_complete: JobId=43007 WEXITSTATUS 0
[2022-06-09T12:13:01.579] _job_complete: JobId=43007 done
[2022-06-09T12:13:01.747] _job_complete: JobId=43272 WEXITSTATUS 1
[2022-06-09T12:13:01.748] _job_complete: JobId=43272 done
[2022-06-09T12:13:03.716] _slurm_rpc_submit_batch_job: JobId=43274 InitPrio=27895 usec=554
[2022-06-09T12:54:59.688] _slurm_rpc_submit_batch_job: JobId=43275 InitPrio=24771 usec=457
[2022-06-09T12:55:03.083] _slurm_rpc_kill_job: REQUEST_KILL_JOB JobId=43275 uid 548300543
[2022-06-09T12:57:25.462] _slurm_rpc_submit_batch_job: JobId=43276 InitPrio=24771 usec=427
[2022-06-09T12:57:25.611] sched: Allocate JobId=43276 NodeList=cpu01 #CPUs=16 Partition=cpu-opteron
[2022-06-09T12:57:27.966] _slurm_rpc_kill_job: REQUEST_KILL_JOB JobId=43276 uid 548300543
[2022-06-09T12:57:35.494] Processing Reconfiguration Request
[2022-06-09T12:57:35.502] restoring original state of nodes
[2022-06-09T12:57:35.502] select/cons_tres: part_data_create_array: select/cons_tres: preparing for 6 partitions
[2022-06-09T12:57:35.503] read_slurm_conf: backup_controller not specified
[2022-06-09T12:57:35.503] select/cons_tres: select_p_reconfigure: select/cons_tres: reconfigure
[2022-06-09T12:57:35.503] select/cons_tres: part_data_create_array: select/cons_tres: preparing for 6 partitions
[2022-06-09T12:57:35.503] No parameter for mcs plugin, default values set
[2022-06-09T12:57:35.503] mcs: MCSParameters = (null). ondemand set.
[2022-06-09T12:57:35.504] _slurm_rpc_reconfigure_controller: completed usec=10238
[2022-06-09T12:57:35.652] SchedulerParameters=default_queue_depth=100,max_rpc_cnt=0,max_sched_time=2,partition_job_depth=0,sched_max_job_start=0,sched_min_interval=2
[2022-06-09T13:25:52.488] _slurm_rpc_submit_batch_job: JobId=43277 InitPrio=20014 usec=410
[2022-06-09T13:28:48.305] _slurm_rpc_submit_batch_job: JobId=43278 InitPrio=21101 usec=396
[2022-06-09T13:28:48.831] sched: Allocate JobId=43278 NodeList=cpu01 #CPUs=32 Partition=cpu-opteron
[2022-06-09T13:29:14.805] _job_complete: JobId=43278 WEXITSTATUS 0
[2022-06-09T13:29:14.806] _job_complete: JobId=43278 done
[2022-06-09T13:30:01.268] _slurm_rpc_submit_batch_job: JobId=43279 InitPrio=24771 usec=351
[2022-06-09T13:30:05.537] _slurm_rpc_kill_job: REQUEST_KILL_JOB JobId=43279 uid 548300543
[2022-06-09T13:32:34.554] _slurm_rpc_submit_batch_job: JobId=43280 InitPrio=24771 usec=402
[2022-06-09T13:32:34.983] sched/backfill: _start_job: Started JobId=43280 in cpu-opteron on cpu01
[2022-06-09T13:32:38.106] _slurm_rpc_kill_job: REQUEST_KILL_JOB JobId=43280 uid 548300543
[2022-06-09T13:32:57.923] _slurm_rpc_submit_batch_job: JobId=43281 InitPrio=21101 usec=375
[2022-06-09T13:32:58.366] sched: Allocate JobId=43281 NodeList=cpu01 #CPUs=32 Partition=cpu-opteron
[2022-06-09T13:32:59.161] _job_complete: JobId=43281 WEXITSTATUS 127
[2022-06-09T13:32:59.162] _job_complete: JobId=43281 done
[2022-06-09T13:33:15.428] _slurm_rpc_submit_batch_job: JobId=43282 InitPrio=21101 usec=433
[2022-06-09T13:33:16.393] sched: Allocate JobId=43282 NodeList=cpu01 #CPUs=32 Partition=cpu-opteron
[2022-06-09T13:33:22.909] _job_complete: JobId=43282 WEXITSTATUS 0
[2022-06-09T13:33:22.910] _job_complete: JobId=43282 done
[2022-06-09T13:35:21.081] _slurm_rpc_submit_batch_job: JobId=43283 InitPrio=21101 usec=393
[2022-06-09T13:35:21.573] sched: Allocate JobId=43283 NodeList=cpu01 #CPUs=32 Partition=cpu-opteron
[2022-06-09T13:35:22.343] _job_complete: JobId=43283 WEXITSTATUS 127
[2022-06-09T13:35:22.344] _job_complete: JobId=43283 done
[2022-06-09T13:39:31.131] _slurm_rpc_submit_batch_job: JobId=43284 InitPrio=24771 usec=423
[2022-06-09T13:39:32.038] sched: Allocate JobId=43284 NodeList=cpu01 #CPUs=16 Partition=cpu-opteron
[2022-06-09T13:39:35.490] _slurm_rpc_kill_job: REQUEST_KILL_JOB JobId=43284 uid 548300543
[2022-06-09T13:41:14.029] _pick_best_nodes: JobId=43285 never runnable in partition cpu-opteron
[2022-06-09T13:41:14.029] _slurm_rpc_submit_batch_job: Requested node configuration is not available
[2022-06-09T13:41:42.968] _slurm_rpc_submit_batch_job: JobId=43286 InitPrio=24771 usec=394
[2022-06-09T13:41:48.512] _slurm_rpc_kill_job: REQUEST_KILL_JOB JobId=43286 uid 548300543
[2022-06-09T13:41:57.827] _slurm_rpc_submit_batch_job: JobId=43287 InitPrio=24771 usec=366
[2022-06-09T13:42:01.307] _slurm_rpc_kill_job: REQUEST_KILL_JOB JobId=43287 uid 548300543
[2022-06-09T13:47:55.848] _slurm_rpc_submit_batch_job: JobId=43288 InitPrio=21091 usec=444
[2022-06-09T13:47:56.047] sched: Allocate JobId=43288 NodeList=cpu01 #CPUs=32 Partition=cpu-opteron
[2022-06-09T13:48:25.904] _slurm_rpc_submit_batch_job: JobId=43289 InitPrio=21091 usec=344
[2022-06-09T13:48:26.090] sched: Allocate JobId=43289 NodeList=cpu11 #CPUs=32 Partition=cpu-opteron
[2022-06-09T13:48:29.169] _job_complete: JobId=43288 WEXITSTATUS 0
[2022-06-09T13:48:29.170] _job_complete: JobId=43288 done
[2022-06-09T13:48:51.622] _job_complete: JobId=43289 WEXITSTATUS 0
[2022-06-09T13:48:51.623] _job_complete: JobId=43289 done
[2022-06-09T13:50:07.498] _slurm_rpc_submit_batch_job: JobId=43290 InitPrio=21091 usec=529
[2022-06-09T13:50:08.239] sched: Allocate JobId=43290 NodeList=cpu01 #CPUs=32 Partition=cpu-opteron
[2022-06-09T13:50:53.241] _job_complete: JobId=43290 WEXITSTATUS 0
[2022-06-09T13:50:53.242] _job_complete: JobId=43290 done
[2022-06-09T14:20:19.177] sched: _slurm_rpc_allocate_resources JobId=43291 NodeList=cpu12 usec=19391
[2022-06-09T14:29:41.133] _job_complete: JobId=43231 WEXITSTATUS 0
[2022-06-09T14:29:41.138] _job_complete: JobId=43231 done
[2022-06-09T14:29:43.150] sched: Allocate JobId=43274 NodeList=cpu05 #CPUs=32 Partition=cpu-opteron
[2022-06-09T15:23:27.378] _pick_best_nodes: JobId=43292 never runnable in partition cpu-opteron
[2022-06-09T15:23:27.379] _slurm_rpc_submit_batch_job: Requested node configuration is not available
[2022-06-09T15:24:25.764] _slurm_rpc_submit_batch_job: JobId=43293 InitPrio=24742 usec=401
[2022-06-09T15:24:29.817] _slurm_rpc_kill_job: REQUEST_KILL_JOB JobId=43293 uid 548300543
[2022-06-09T15:24:41.990] _slurm_rpc_submit_batch_job: JobId=43294 InitPrio=24742 usec=356
[2022-06-09T15:24:45.834] _slurm_rpc_kill_job: REQUEST_KILL_JOB JobId=43294 uid 548300543
[2022-06-09T15:29:44.640] Time limit exhausted for JobId=43248
[2022-06-09T15:33:29.105] _job_complete: JobId=43271 WEXITSTATUS 2
[2022-06-09T15:33:29.106] _job_complete: JobId=43271 done
[2022-06-09T15:40:15.253] _slurm_rpc_submit_batch_job: JobId=43295 InitPrio=24742 usec=382
[2022-06-09T15:40:17.861] sched: Allocate JobId=43295 NodeList=cpu01 #CPUs=16 Partition=cpu-opteron
[2022-06-09T15:40:19.011] _slurm_rpc_kill_job: REQUEST_KILL_JOB JobId=43295 uid 548300543
[2022-06-09T15:41:49.862] _slurm_rpc_submit_batch_job: JobId=43296 InitPrio=21061 usec=535
[2022-06-09T15:41:49.992] sched: Allocate JobId=43296 NodeList=cpu01 #CPUs=4 Partition=cpu-opteron
[2022-06-09T15:42:42.298] _job_complete: JobId=43296 WEXITSTATUS 0
[2022-06-09T15:42:42.298] _job_complete: JobId=43296 done
[2022-06-09T15:48:08.769] _slurm_rpc_submit_batch_job: JobId=43297 InitPrio=20821 usec=518
[2022-06-09T15:48:08.800] sched: Allocate JobId=43297 NodeList=cpu14 #CPUs=32 Partition=cpu-epyc
[2022-06-09T15:48:20.826] _job_complete: JobId=43297 WEXITSTATUS 1
[2022-06-09T15:48:20.826] _job_complete: JobId=43297 done
[2022-06-09T15:49:08.103] _slurm_rpc_submit_batch_job: JobId=43298 InitPrio=24742 usec=336
[2022-06-09T15:49:11.640] _slurm_rpc_kill_job: REQUEST_KILL_JOB JobId=43298 uid 548300543
[2022-06-09T15:49:36.637] _slurm_rpc_submit_batch_job: JobId=43299 InitPrio=20821 usec=468
[2022-06-09T15:49:36.928] sched: Allocate JobId=43299 NodeList=cpu14 #CPUs=32 Partition=cpu-epyc
[2022-06-09T15:49:45.585] _job_complete: JobId=43299 WEXITSTATUS 1
[2022-06-09T15:49:45.585] _job_complete: JobId=43299 done
[2022-06-09T15:51:50.233] _slurm_rpc_submit_batch_job: JobId=43300 InitPrio=20821 usec=451
[2022-06-09T15:51:51.129] sched: Allocate JobId=43300 NodeList=cpu14 #CPUs=32 Partition=cpu-epyc
[2022-06-09T15:54:17.660] _slurm_rpc_submit_batch_job: JobId=43301 InitPrio=19196 usec=352
[2022-06-09T15:54:18.511] sched: Allocate JobId=43301 NodeList=cpu13 #CPUs=64 Partition=cpu-epyc
[2022-06-09T15:55:37.988] _slurm_rpc_submit_batch_job: JobId=43302 InitPrio=24742 usec=413
[2022-06-09T15:55:42.168] _slurm_rpc_kill_job: REQUEST_KILL_JOB JobId=43302 uid 548300543
[2022-06-09T16:00:07.545] _slurm_rpc_submit_batch_job: JobId=43303 InitPrio=19264 usec=382
[2022-06-09T16:00:08.103] sched: Allocate JobId=43303 NodeList=cpu12 #CPUs=56 Partition=cpu-epyc
[2022-06-09T16:01:40.601] _slurm_rpc_submit_batch_job: JobId=43304 InitPrio=24742 usec=344
[2022-06-09T16:01:46.613] _slurm_rpc_kill_job: REQUEST_KILL_JOB JobId=43304 uid 548300543
[2022-06-09T16:13:13.126] _job_complete: JobId=43300 WEXITSTATUS 0
[2022-06-09T16:13:13.126] _job_complete: JobId=43300 done
[2022-06-09T16:43:41.871] _job_complete: JobId=43301 WEXITSTATUS 1
[2022-06-09T16:43:41.872] _job_complete: JobId=43301 done
[2022-06-09T17:00:15.811] Time limit exhausted for JobId=43250
[2022-06-09T17:06:19.755] _slurm_rpc_submit_batch_job: JobId=43305 InitPrio=19196 usec=437
[2022-06-09T17:06:20.441] sched: Allocate JobId=43305 NodeList=cpu13 #CPUs=64 Partition=cpu-epyc
[2022-06-09T17:10:50.632] _slurm_rpc_submit_batch_job: JobId=43306 InitPrio=25956 usec=449
[2022-06-09T17:21:35.308] _slurm_rpc_submit_batch_job: JobId=43307 InitPrio=25956 usec=502
[2022-06-09T17:21:35.394] sched: Allocate JobId=43307 NodeList=cpu03 #CPUs=32 Partition=cpu-opteron
[2022-06-09T17:57:15.380] _job_complete: JobId=43273 WEXITSTATUS 2
[2022-06-09T17:57:15.381] _job_complete: JobId=43273 done
[2022-06-09T18:02:13.601] _job_complete: JobId=43235 WEXITSTATUS 0
[2022-06-09T18:02:13.601] _job_complete: JobId=43235 done
[2022-06-09T18:11:25.177] _slurm_rpc_submit_batch_job: JobId=43308 InitPrio=19196 usec=497
[2022-06-09T18:11:25.977] sched: Allocate JobId=43308 NodeList=cpu07 #CPUs=64 Partition=cpu-opteron
[2022-06-09T18:19:12.380] _job_complete: JobId=43305 OOM failure
[2022-06-09T18:19:12.381] _job_complete: JobId=43305 done
[2022-06-09T18:19:12.625] sched: Allocate JobId=43306 NodeList=cpu13 #CPUs=32 Partition=cpu-epyc
[2022-06-09T18:23:19.572] _slurm_rpc_kill_job: REQUEST_KILL_JOB JobId=43228 uid 548300540
[2022-06-09T18:23:24.728] _slurm_rpc_kill_job: REQUEST_KILL_JOB JobId=43229 uid 548300540
[2022-06-09T18:24:49.261] _slurm_rpc_submit_batch_job: JobId=43309 InitPrio=19196 usec=738
[2022-06-09T18:24:49.500] sched: Allocate JobId=43309 NodeList=cpu08 #CPUs=64 Partition=cpu-opteron
[2022-06-09T18:27:57.958] _slurm_rpc_submit_batch_job: JobId=43310 InitPrio=19469 usec=369
[2022-06-09T18:27:58.919] sched: Allocate JobId=43310 NodeList=cpu14 #CPUs=32 Partition=cpu-epyc
[2022-06-09T18:31:05.843] _job_complete: JobId=43291 WEXITSTATUS 0
[2022-06-09T18:31:05.844] _job_complete: JobId=43291 done
[2022-06-09T18:36:06.395] cleanup_completing: JobId=43291 completion process took 301 seconds
[2022-06-09T19:07:17.722] _slurm_rpc_submit_batch_job: JobId=43311 InitPrio=25415 usec=429
[2022-06-09T19:07:18.507] sched: Allocate JobId=43311 NodeList=gpu05 #CPUs=32 Partition=gpu-v100s
[2022-06-09T19:07:22.574] _job_complete: JobId=43311 WEXITSTATUS 1
[2022-06-09T19:07:22.574] _job_complete: JobId=43311 done
[2022-06-09T19:12:48.328] _slurm_rpc_submit_batch_job: JobId=43312 InitPrio=25415 usec=475
[2022-06-09T19:12:49.188] sched: Allocate JobId=43312 NodeList=gpu05 #CPUs=32 Partition=gpu-v100s
[2022-06-09T19:12:50.938] _job_complete: JobId=43312 WEXITSTATUS 1
[2022-06-09T19:12:50.938] _job_complete: JobId=43312 done
[2022-06-09T19:15:36.608] _slurm_rpc_submit_batch_job: JobId=43313 InitPrio=25415 usec=470
[2022-06-09T19:15:37.431] sched: Allocate JobId=43313 NodeList=gpu05 #CPUs=32 Partition=gpu-v100s
[2022-06-09T19:15:38.908] _job_complete: JobId=43313 WEXITSTATUS 1
[2022-06-09T19:15:38.908] _job_complete: JobId=43313 done
[2022-06-09T19:17:56.658] _slurm_rpc_submit_batch_job: JobId=43314 InitPrio=25415 usec=633
[2022-06-09T19:17:56.781] sched: Allocate JobId=43314 NodeList=gpu05 #CPUs=32 Partition=gpu-v100s
[2022-06-09T19:18:07.500] _job_complete: JobId=43314 WEXITSTATUS 1
[2022-06-09T19:18:07.501] _job_complete: JobId=43314 done
[2022-06-09T20:13:05.776] _job_complete: JobId=43108 WEXITSTATUS 0
[2022-06-09T20:13:05.776] _job_complete: JobId=43108 done
[2022-06-09T20:13:06.724] sched: Allocate JobId=43127 NodeList=gpu02 #CPUs=8 Partition=gpu-titan
[2022-06-09T20:21:29.165] _job_complete: JobId=43265 WEXITSTATUS 2
[2022-06-09T20:21:29.170] _job_complete: JobId=43265 done
[2022-06-09T21:05:41.494] _slurm_rpc_submit_batch_job: JobId=43315 InitPrio=25415 usec=445
[2022-06-09T21:05:42.303] sched: Allocate JobId=43315 NodeList=gpu05 #CPUs=32 Partition=gpu-v100s
[2022-06-09T21:05:43.835] _job_complete: JobId=43315 WEXITSTATUS 1
[2022-06-09T21:05:43.835] _job_complete: JobId=43315 done
[2022-06-09T21:07:30.755] _slurm_rpc_submit_batch_job: JobId=43316 InitPrio=25415 usec=440
[2022-06-09T21:07:31.526] sched: Allocate JobId=43316 NodeList=gpu05 #CPUs=32 Partition=gpu-v100s
[2022-06-09T21:26:25.266] _job_complete: JobId=43266 WEXITSTATUS 0
[2022-06-09T21:26:25.267] _job_complete: JobId=43266 done
[2022-06-09T21:42:47.317] _slurm_rpc_submit_batch_job: JobId=43317 InitPrio=30280 usec=445
[2022-06-09T21:50:19.193] _slurm_rpc_kill_job: REQUEST_KILL_JOB JobId=43317 uid 548300557
[2022-06-09T21:53:00.362] _slurm_rpc_submit_batch_job: JobId=43318 InitPrio=30280 usec=442
[2022-06-09T21:53:00.577] sched: Allocate JobId=43318 NodeList=cpu05 #CPUs=32 Partition=cpu-opteron
[2022-06-09T21:53:30.472] _job_complete: JobId=43318 WEXITSTATUS 1
[2022-06-09T21:53:30.473] _job_complete: JobId=43318 done
[2022-06-09T21:55:31.096] _job_complete: JobId=43309 OOM failure
[2022-06-09T21:55:31.097] _job_complete: JobId=43309 done
[2022-06-09T21:57:46.865] _slurm_rpc_submit_batch_job: JobId=43319 InitPrio=30280 usec=375
[2022-06-09T21:57:47.083] sched: Allocate JobId=43319 NodeList=cpu05 #CPUs=32 Partition=cpu-opteron
[2022-06-09T21:58:14.145] _job_complete: JobId=43319 WEXITSTATUS 1
[2022-06-09T21:58:14.145] _job_complete: JobId=43319 done
[2022-06-09T22:02:29.153] _slurm_rpc_submit_batch_job: JobId=43320 InitPrio=29199 usec=394
[2022-06-09T22:03:02.370] _job_complete: JobId=43133 WEXITSTATUS 0
[2022-06-09T22:03:02.370] _job_complete: JobId=43133 done
[2022-06-09T22:04:31.494] _slurm_rpc_submit_batch_job: JobId=43321 InitPrio=19469 usec=445
[2022-06-09T22:04:31.827] sched: Allocate JobId=43321 NodeList=cpu13 #CPUs=32 Partition=cpu-epyc
[2022-06-09T22:05:15.227] _slurm_rpc_kill_job: REQUEST_KILL_JOB JobId=43310 uid 548200017
[2022-06-09T22:05:15.227] _slurm_rpc_kill_job: REQUEST_KILL_JOB JobId=43321 uid 548200017
[2022-06-09T22:05:33.227] _slurm_rpc_submit_batch_job: JobId=43322 InitPrio=19469 usec=347
[2022-06-09T22:05:33.905] sched: Allocate JobId=43322 NodeList=cpu13 #CPUs=32 Partition=cpu-epyc
[2022-06-09T22:07:20.199] _slurm_rpc_submit_batch_job: JobId=43323 InitPrio=19196 usec=365
[2022-06-09T22:07:21.184] sched: Allocate JobId=43323 NodeList=cpu08 #CPUs=64 Partition=cpu-opteron
[2022-06-09T22:58:51.734] _slurm_rpc_submit_batch_job: JobId=43324 InitPrio=20958 usec=473
[2022-06-09T22:58:51.894] sched: Allocate JobId=43324 NodeList=cpu05 #CPUs=16 Partition=cpu-opteron
[2022-06-09T23:00:36.050] _slurm_rpc_submit_batch_job: JobId=43325 InitPrio=20958 usec=603
[2022-06-09T23:00:37.028] sched: Allocate JobId=43325 NodeList=cpu05 #CPUs=16 Partition=cpu-opteron
[2022-06-09T23:01:36.262] _job_complete: JobId=43324 WEXITSTATUS 0
[2022-06-09T23:01:36.262] _job_complete: JobId=43324 done
[2022-06-09T23:02:03.499] _slurm_rpc_submit_batch_job: JobId=43326 InitPrio=20821 usec=405
[2022-06-09T23:02:04.157] sched: Allocate JobId=43326 NodeList=cpu14 #CPUs=32 Partition=cpu-epyc
[2022-06-09T23:02:11.205] _job_complete: JobId=43326 WEXITSTATUS 1
[2022-06-09T23:02:11.206] _job_complete: JobId=43326 done
[2022-06-09T23:02:26.057] _job_complete: JobId=43127 WEXITSTATUS 1
[2022-06-09T23:02:26.062] _job_complete: JobId=43127 done
[2022-06-09T23:02:37.553] _slurm_rpc_submit_batch_job: JobId=43327 InitPrio=21026 usec=604
[2022-06-09T23:02:38.295] sched: Allocate JobId=43327 NodeList=cpu05 #CPUs=8 Partition=cpu-opteron
[2022-06-09T23:03:12.887] _job_complete: JobId=43327 WEXITSTATUS 0
[2022-06-09T23:03:12.887] _job_complete: JobId=43327 done
[2022-06-09T23:03:28.022] _slurm_rpc_submit_batch_job: JobId=43328 InitPrio=20821 usec=481
[2022-06-09T23:03:28.364] sched: Allocate JobId=43328 NodeList=cpu14 #CPUs=32 Partition=cpu-epyc
[2022-06-09T23:04:12.391] _slurm_rpc_submit_batch_job: JobId=43329 InitPrio=20958 usec=499
[2022-06-09T23:04:12.432] sched: Allocate JobId=43329 NodeList=cpu05 #CPUs=16 Partition=cpu-opteron
[2022-06-09T23:04:48.655] _slurm_rpc_submit_batch_job: JobId=43330 InitPrio=20958 usec=372
[2022-06-09T23:04:49.484] sched: Allocate JobId=43330 NodeList=cpu11 #CPUs=16 Partition=cpu-opteron
[2022-06-09T23:06:41.179] _job_complete: JobId=43329 WEXITSTATUS 0
[2022-06-09T23:06:41.179] _job_complete: JobId=43329 done
[2022-06-09T23:13:48.196] _job_complete: JobId=43262 WEXITSTATUS 0
[2022-06-09T23:13:48.202] _job_complete: JobId=43262 done
[2022-06-09T23:23:07.233] _job_complete: JobId=43328 WEXITSTATUS 0
[2022-06-09T23:23:07.233] _job_complete: JobId=43328 done
[2022-06-09T23:35:13.363] _slurm_rpc_submit_batch_job: JobId=43331 InitPrio=22039 usec=384
[2022-06-09T23:35:14.153] sched: Allocate JobId=43331 NodeList=gpu04 #CPUs=16 Partition=gpu-k40c
[2022-06-09T23:45:43.236] _job_complete: JobId=43330 WEXITSTATUS 0
[2022-06-09T23:45:43.236] _job_complete: JobId=43330 done
[2022-06-09T23:46:01.508] _job_complete: JobId=43325 WEXITSTATUS 0
[2022-06-09T23:46:01.508] _job_complete: JobId=43325 done
[2022-06-09T23:46:08.467] _job_complete: JobId=43316 WEXITSTATUS 0
[2022-06-09T23:46:08.467] _job_complete: JobId=43316 done
[2022-06-10T00:35:49.802] Time limit exhausted for JobId=43258
[2022-06-10T00:39:22.087] _job_complete: JobId=43269 WEXITSTATUS 1
[2022-06-10T00:39:22.092] _job_complete: JobId=43269 done
[2022-06-10T00:39:22.526] sched: Allocate JobId=43277 NodeList=gpu01 #CPUs=32 Partition=gpu-k10
[2022-06-10T00:39:25.482] _job_complete: JobId=43277 WEXITSTATUS 1
[2022-06-10T00:39:25.483] _job_complete: JobId=43277 done
[2022-06-10T01:06:40.354] _slurm_rpc_submit_batch_job: JobId=43332 InitPrio=24875 usec=534
[2022-06-10T01:06:40.488] sched: Allocate JobId=43332 NodeList=gpu05 #CPUs=32 Partition=gpu-v100s
[2022-06-10T01:07:48.658] _slurm_rpc_submit_batch_job: JobId=43333 InitPrio=21061 usec=579
[2022-06-10T01:07:48.746] sched: Allocate JobId=43333 NodeList=cpu05 #CPUs=4 Partition=cpu-opteron
[2022-06-10T01:07:50.146] _job_complete: JobId=43333 WEXITSTATUS 0
[2022-06-10T01:07:50.147] _job_complete: JobId=43333 done
[2022-06-10T01:08:27.773] _slurm_rpc_submit_batch_job: JobId=43334 InitPrio=20958 usec=494
[2022-06-10T01:08:27.779] sched: Allocate JobId=43334 NodeList=cpu05 #CPUs=16 Partition=cpu-opteron
[2022-06-10T01:08:41.406] _job_complete: JobId=43334 WEXITSTATUS 0
[2022-06-10T01:08:41.406] _job_complete: JobId=43334 done
[2022-06-10T01:10:54.379] _slurm_rpc_submit_batch_job: JobId=43335 InitPrio=21086 usec=469
[2022-06-10T01:10:54.982] sched: Allocate JobId=43335 NodeList=gpu04 #CPUs=1 Partition=gpu-k40c
[2022-06-10T01:11:26.372] _job_complete: JobId=43335 WEXITSTATUS 0
[2022-06-10T01:11:26.372] _job_complete: JobId=43335 done
[2022-06-10T01:12:55.128] _slurm_rpc_submit_batch_job: JobId=43336 InitPrio=21061 usec=415
[2022-06-10T01:12:55.257] sched: Allocate JobId=43336 NodeList=cpu05 #CPUs=4 Partition=cpu-opteron
[2022-06-10T01:12:56.689] _job_complete: JobId=43336 WEXITSTATUS 0
[2022-06-10T01:12:56.689] _job_complete: JobId=43336 done
[2022-06-10T01:14:35.223] _slurm_rpc_submit_batch_job: JobId=43337 InitPrio=21061 usec=387
[2022-06-10T01:14:35.403] sched: Allocate JobId=43337 NodeList=cpu05 #CPUs=4 Partition=cpu-opteron
[2022-06-10T01:14:49.043] _job_complete: JobId=43337 WEXITSTATUS 0
[2022-06-10T01:14:49.043] _job_complete: JobId=43337 done
[2022-06-10T01:15:04.344] _slurm_rpc_submit_batch_job: JobId=43338 InitPrio=21009 usec=543
[2022-06-10T01:15:04.445] sched: Allocate JobId=43338 NodeList=gpu02 #CPUs=10 Partition=gpu-titan
[2022-06-10T01:16:42.815] _slurm_rpc_submit_batch_job: JobId=43339 InitPrio=21061 usec=469
[2022-06-10T01:16:43.585] sched: Allocate JobId=43339 NodeList=cpu05 #CPUs=4 Partition=cpu-opteron
[2022-06-10T01:16:44.655] _job_complete: JobId=43339 WEXITSTATUS 0
[2022-06-10T01:16:44.655] _job_complete: JobId=43339 done
[2022-06-10T01:17:04.329] _slurm_rpc_submit_batch_job: JobId=43340 InitPrio=20958 usec=472
[2022-06-10T01:17:04.609] sched: Allocate JobId=43340 NodeList=cpu05 #CPUs=16 Partition=cpu-opteron
[2022-06-10T01:17:17.680] _job_complete: JobId=43340 WEXITSTATUS 0
[2022-06-10T01:17:17.680] _job_complete: JobId=43340 done
[2022-06-10T01:17:38.216] _slurm_rpc_submit_batch_job: JobId=43341 InitPrio=21086 usec=364
[2022-06-10T01:17:38.749] sched: Allocate JobId=43341 NodeList=gpu04 #CPUs=1 Partition=gpu-k40c
[2022-06-10T01:18:09.708] _job_complete: JobId=43341 WEXITSTATUS 0
[2022-06-10T01:18:09.709] _job_complete: JobId=43341 done
[2022-06-10T01:18:13.108] _slurm_rpc_submit_batch_job: JobId=43342 InitPrio=21061 usec=496
[2022-06-10T01:18:13.799] sched: Allocate JobId=43342 NodeList=cpu05 #CPUs=4 Partition=cpu-opteron
[2022-06-10T01:18:15.402] _job_complete: JobId=43342 WEXITSTATUS 0
[2022-06-10T01:18:15.402] _job_complete: JobId=43342 done
[2022-06-10T01:18:49.813] _slurm_rpc_submit_batch_job: JobId=43343 InitPrio=21061 usec=421
[2022-06-10T01:18:49.851] sched: Allocate JobId=43343 NodeList=cpu05 #CPUs=4 Partition=cpu-opteron
[2022-06-10T01:18:51.036] _job_complete: JobId=43343 WEXITSTATUS 0
[2022-06-10T01:18:51.036] _job_complete: JobId=43343 done
[2022-06-10T01:20:12.161] _slurm_rpc_submit_batch_job: JobId=43344 InitPrio=21061 usec=362
[2022-06-10T01:20:12.971] sched: Allocate JobId=43344 NodeList=cpu05 #CPUs=4 Partition=cpu-opteron
[2022-06-10T01:20:26.297] _job_complete: JobId=43344 WEXITSTATUS 0
[2022-06-10T01:20:26.297] _job_complete: JobId=43344 done
[2022-06-10T01:20:38.837] _slurm_rpc_submit_batch_job: JobId=43345 InitPrio=21009 usec=471
[2022-06-10T01:20:39.007] sched: Allocate JobId=43345 NodeList=gpu02 #CPUs=10 Partition=gpu-titan
[2022-06-10T01:22:16.475] _slurm_rpc_submit_batch_job: JobId=43346 InitPrio=20821 usec=476
[2022-06-10T01:22:17.148] sched: Allocate JobId=43346 NodeList=cpu12 #CPUs=32 Partition=cpu-epyc
[2022-06-10T01:22:31.774] _job_complete: JobId=43346 WEXITSTATUS 1
[2022-06-10T01:22:31.775] _job_complete: JobId=43346 done
[2022-06-10T01:23:23.197] _slurm_rpc_submit_batch_job: JobId=43347 InitPrio=21026 usec=461
[2022-06-10T01:23:23.319] sched: Allocate JobId=43347 NodeList=cpu05 #CPUs=8 Partition=cpu-opteron
[2022-06-10T01:23:50.148] _job_complete: JobId=43347 WEXITSTATUS 0
[2022-06-10T01:23:50.148] _job_complete: JobId=43347 done
[2022-06-10T01:25:01.848] _slurm_rpc_submit_batch_job: JobId=43348 InitPrio=20821 usec=422
[2022-06-10T01:25:02.462] sched: Allocate JobId=43348 NodeList=cpu12 #CPUs=32 Partition=cpu-epyc
[2022-06-10T01:25:11.792] _job_complete: JobId=43348 WEXITSTATUS 1
[2022-06-10T01:25:11.793] _job_complete: JobId=43348 done
[2022-06-10T01:26:07.391] _slurm_rpc_submit_batch_job: JobId=43349 InitPrio=20821 usec=464
[2022-06-10T01:26:07.556] sched: Allocate JobId=43349 NodeList=cpu12 #CPUs=32 Partition=cpu-epyc
[2022-06-10T01:37:37.086] _slurm_rpc_submit_batch_job: JobId=43350 InitPrio=20684 usec=538
[2022-06-10T01:38:41.062] _slurm_rpc_kill_job: REQUEST_KILL_JOB JobId=43350 uid 548200023
[2022-06-10T01:38:58.701] _slurm_rpc_submit_batch_job: JobId=43351 InitPrio=20821 usec=406
[2022-06-10T01:39:43.889] _slurm_rpc_kill_job: REQUEST_KILL_JOB JobId=43351 uid 548200023
[2022-06-10T01:40:26.036] _slurm_rpc_submit_batch_job: JobId=43352 InitPrio=20821 usec=408
[2022-06-10T01:41:18.068] _slurm_rpc_kill_job: REQUEST_KILL_JOB JobId=43352 uid 548200023
[2022-06-10T01:41:20.689] _slurm_rpc_submit_batch_job: JobId=43353 InitPrio=20821 usec=565
[2022-06-10T01:41:21.229] sched: Allocate JobId=43353 NodeList=cpu01 #CPUs=32 Partition=cpu-opteron
[2022-06-10T01:41:43.106] _job_complete: JobId=43353 WEXITSTATUS 1
[2022-06-10T01:41:43.107] _job_complete: JobId=43353 done
[2022-06-10T01:42:31.259] _slurm_rpc_submit_batch_job: JobId=43354 InitPrio=20821 usec=472
[2022-06-10T01:42:31.500] sched: Allocate JobId=43354 NodeList=cpu01 #CPUs=32 Partition=cpu-opteron
[2022-06-10T01:44:27.520] _job_complete: JobId=43349 WEXITSTATUS 0
[2022-06-10T01:44:27.520] _job_complete: JobId=43349 done
[2022-06-10T02:03:49.883] _job_complete: JobId=43236 WEXITSTATUS 0
[2022-06-10T02:03:49.888] _job_complete: JobId=43236 done
[2022-06-10T02:44:07.449] _job_complete: JobId=43332 WEXITSTATUS 0
[2022-06-10T02:44:07.449] _job_complete: JobId=43332 done
[2022-06-10T02:57:50.939] _job_complete: JobId=43354 WEXITSTATUS 0
[2022-06-10T02:57:50.939] _job_complete: JobId=43354 done
[2022-06-10T03:52:17.838] _job_complete: JobId=43268 WEXITSTATUS 0
[2022-06-10T03:52:17.838] _job_complete: JobId=43268 done
[2022-06-10T04:34:25.001] _job_complete: JobId=43306 WEXITSTATUS 1
[2022-06-10T04:34:25.001] _job_complete: JobId=43306 done
[2022-06-10T08:01:20.869] _job_complete: JobId=43264 WEXITSTATUS 0
[2022-06-10T08:01:20.874] _job_complete: JobId=43264 done
[2022-06-10T08:52:01.331] _job_complete: JobId=43115 WEXITSTATUS 0
[2022-06-10T08:52:01.331] _job_complete: JobId=43115 done
[2022-06-10T09:29:21.069] _slurm_rpc_submit_batch_job: JobId=43355 InitPrio=29199 usec=424
[2022-06-10T09:31:12.935] _slurm_rpc_submit_batch_job: JobId=43356 InitPrio=29336 usec=488
[2022-06-10T09:31:13.637] sched: Allocate JobId=43356 NodeList=gpu05 #CPUs=16 Partition=gpu-v100s
[2022-06-10T09:34:38.045] _slurm_rpc_kill_job: REQUEST_KILL_JOB JobId=43355 uid 548300557
[2022-06-10T09:35:05.977] _slurm_rpc_kill_job: REQUEST_KILL_JOB JobId=43320 uid 548300557
[2022-06-10T09:36:21.187] _slurm_rpc_submit_batch_job: JobId=43357 InitPrio=28796 usec=504
[2022-06-10T09:36:49.926] _slurm_rpc_kill_job: REQUEST_KILL_JOB JobId=43356 uid 548300557
[2022-06-10T09:36:52.770] sched: Allocate JobId=43357 NodeList=gpu05 #CPUs=16 Partition=gpu-v100s
[2022-06-10T09:52:24.614] _job_complete: JobId=43091 WEXITSTATUS 1
[2022-06-10T09:52:24.619] _job_complete: JobId=43091 done
[2022-06-10T09:52:25.556] sched: Allocate JobId=43093 NodeList=gpu05 #CPUs=32 Partition=gpu-v100s
[2022-06-10T10:15:02.759] _slurm_rpc_submit_batch_job: JobId=43358 InitPrio=19196 usec=436
[2022-06-10T10:15:03.466] sched: Allocate JobId=43358 NodeList=cpu15 #CPUs=64 Partition=cpu-epyc
[2022-06-10T10:19:26.958] _slurm_rpc_submit_batch_job: JobId=43359 InitPrio=28654 usec=407
[2022-06-10T10:19:27.928] sched: Allocate JobId=43359 NodeList=cpu11 #CPUs=1 Partition=cpu-opteron
[2022-06-10T10:20:03.543] _slurm_rpc_kill_job: REQUEST_KILL_JOB JobId=43359 uid 548300504
[2022-06-10T10:33:12.929] _slurm_rpc_submit_batch_job: JobId=43360 InitPrio=20958 usec=532
[2022-06-10T10:33:13.466] sched: Allocate JobId=43360 NodeList=cpu11 #CPUs=16 Partition=cpu-opteron
[2022-06-10T10:33:14.595] _job_complete: JobId=43360 WEXITSTATUS 1
[2022-06-10T10:33:14.595] _job_complete: JobId=43360 done
[2022-06-10T10:34:40.250] _job_complete: JobId=43357 WEXITSTATUS 0
[2022-06-10T10:34:40.251] _job_complete: JobId=43357 done
[2022-06-10T10:37:04.014] _slurm_rpc_submit_batch_job: JobId=43361 InitPrio=20838 usec=586
[2022-06-10T10:37:04.790] sched: Allocate JobId=43361 NodeList=gpu05 #CPUs=30 Partition=gpu-v100s
[2022-06-10T10:37:24.175] _slurm_rpc_kill_job: REQUEST_KILL_JOB JobId=43227 uid 548200023
[2022-06-10T10:55:52.954] _slurm_rpc_submit_batch_job: JobId=43362 InitPrio=25282 usec=347
[2022-06-10T10:55:53.888] sched: Allocate JobId=43362 NodeList=gpu01 #CPUs=16 Partition=gpu-k10
[2022-06-10T10:55:56.147] _slurm_rpc_kill_job: REQUEST_KILL_JOB JobId=43362 uid 548300543
[2022-06-10T10:58:30.801] _slurm_rpc_submit_batch_job: JobId=43363 InitPrio=25282 usec=339
[2022-06-10T10:58:31.181] sched: Allocate JobId=43363 NodeList=gpu01 #CPUs=16 Partition=gpu-k10
[2022-06-10T10:58:33.595] _slurm_rpc_kill_job: REQUEST_KILL_JOB JobId=43363 uid 548300543
[2022-06-10T10:58:47.003] _slurm_rpc_submit_batch_job: JobId=43364 InitPrio=25282 usec=344
[2022-06-10T10:58:47.202] sched: Allocate JobId=43364 NodeList=gpu01 #CPUs=16 Partition=gpu-k10
[2022-06-10T10:58:49.622] _slurm_rpc_kill_job: REQUEST_KILL_JOB JobId=43364 uid 548300543
[2022-06-10T10:59:11.471] _slurm_rpc_submit_batch_job: JobId=43365 InitPrio=25282 usec=453
[2022-06-10T10:59:12.241] sched: Allocate JobId=43365 NodeList=cpu01 #CPUs=16 Partition=cpu-opteron
[2022-06-10T10:59:14.458] _slurm_rpc_kill_job: REQUEST_KILL_JOB JobId=43365 uid 548300543
[2022-06-10T11:17:32.132] _slurm_rpc_submit_batch_job: JobId=43366 InitPrio=25282 usec=299
[2022-06-10T11:17:32.344] sched: Allocate JobId=43366 NodeList=gpu01 #CPUs=16 Partition=gpu-k10
[2022-06-10T11:17:35.224] _slurm_rpc_kill_job: REQUEST_KILL_JOB JobId=43366 uid 548300543
[2022-06-10T11:47:53.554] _slurm_rpc_submit_batch_job: JobId=43367 InitPrio=23493 usec=360
[2022-06-10T11:47:53.695] sched: Allocate JobId=43367 NodeList=gpu01 #CPUs=4 Partition=gpu-k10
[2022-06-10T11:48:03.283] _slurm_rpc_kill_job: REQUEST_KILL_JOB JobId=43367 uid 548200003
[2022-06-10T12:14:22.165] _slurm_rpc_submit_batch_job: JobId=43368 InitPrio=26767 usec=386
[2022-06-10T12:50:09.798] _slurm_rpc_submit_batch_job: JobId=43369 InitPrio=21361 usec=518
[2022-06-10T12:50:10.700] sched: Allocate JobId=43369 NodeList=cpu14 #CPUs=32 Partition=cpu-epyc
[2022-06-10T12:51:06.045] _slurm_rpc_submit_batch_job: JobId=43370 InitPrio=21087 usec=478
[2022-06-10T12:51:06.768] sched: Allocate JobId=43370 NodeList=cpu13 #CPUs=64 Partition=cpu-epyc
[2022-06-10T12:52:25.662] _slurm_rpc_submit_batch_job: JobId=43371 InitPrio=21361 usec=423
[2022-06-10T12:52:25.983] sched: Allocate JobId=43371 NodeList=cpu15 #CPUs=32 Partition=cpu-epyc
[2022-06-10T13:00:22.517] _slurm_rpc_submit_batch_job: JobId=43372 InitPrio=25282 usec=390
[2022-06-10T13:00:22.835] sched: Allocate JobId=43372 NodeList=cpu01 #CPUs=16 Partition=cpu-opteron
[2022-06-10T13:01:03.484] _slurm_rpc_kill_job: REQUEST_KILL_JOB JobId=43372 uid 548300543
[2022-06-10T13:15:11.562] _slurm_rpc_submit_batch_job: JobId=43373 InitPrio=21087 usec=680
[2022-06-10T13:15:12.474] sched: Allocate JobId=43373 NodeList=cpu04 #CPUs=64 Partition=cpu-opteron
[2022-06-10T13:19:11.520] _slurm_rpc_submit_batch_job: JobId=43374 InitPrio=21293 usec=500
[2022-06-10T13:19:11.952] sched: Allocate JobId=43374 NodeList=cpu12 #CPUs=40 Partition=cpu-epyc
[2022-06-10T13:33:50.890] _job_complete: JobId=43270 WEXITSTATUS 1
[2022-06-10T13:33:50.895] _job_complete: JobId=43270 done
[2022-06-10T14:27:04.257] _slurm_rpc_submit_batch_job: JobId=43375 InitPrio=25282 usec=358
[2022-06-10T14:27:05.174] sched: Allocate JobId=43375 NodeList=cpu01 #CPUs=16 Partition=cpu-opteron
[2022-06-10T14:27:36.445] _slurm_rpc_kill_job: REQUEST_KILL_JOB JobId=43375 uid 548300543
[2022-06-10T14:29:39.326] _slurm_rpc_submit_batch_job: JobId=43376 InitPrio=25282 usec=406
[2022-06-10T14:29:39.551] sched: Allocate JobId=43376 NodeList=gpu01 #CPUs=16 Partition=gpu-k10
[2022-06-10T14:30:08.379] _slurm_rpc_submit_batch_job: JobId=43377 InitPrio=22579 usec=549
[2022-06-10T14:30:08.604] sched: Allocate JobId=43377 NodeList=cpu05 #CPUs=16 Partition=cpu-opteron
[2022-06-10T14:30:13.331] _slurm_rpc_submit_batch_job: JobId=43378 InitPrio=22579 usec=385
[2022-06-10T14:30:13.599] sched: Allocate JobId=43378 NodeList=cpu11 #CPUs=16 Partition=cpu-opteron
[2022-06-10T14:30:17.659] _slurm_rpc_submit_batch_job: JobId=43379 InitPrio=22579 usec=406
[2022-06-10T14:30:18.606] sched: Allocate JobId=43379 NodeList=cpu11 #CPUs=16 Partition=cpu-opteron
[2022-06-10T14:30:21.707] _slurm_rpc_submit_batch_job: JobId=43380 InitPrio=22579 usec=559
[2022-06-10T14:30:22.612] sched: Allocate JobId=43380 NodeList=cpu01 #CPUs=16 Partition=cpu-opteron
[2022-06-10T14:30:28.723] _slurm_rpc_submit_batch_job: JobId=43381 InitPrio=22579 usec=616
[2022-06-10T14:30:29.622] sched: Allocate JobId=43381 NodeList=cpu01 #CPUs=16 Partition=cpu-opteron
[2022-06-10T14:30:33.518] _slurm_rpc_submit_batch_job: JobId=43382 InitPrio=22579 usec=371
[2022-06-10T14:30:33.628] sched: Allocate JobId=43382 NodeList=cpu03 #CPUs=16 Partition=cpu-opteron
[2022-06-10T14:30:37.741] _slurm_rpc_submit_batch_job: JobId=43383 InitPrio=22579 usec=413
[2022-06-10T14:30:38.635] sched: Allocate JobId=43383 NodeList=cpu09 #CPUs=16 Partition=cpu-opteron
[2022-06-10T14:30:42.260] _slurm_rpc_submit_batch_job: JobId=43384 InitPrio=22579 usec=412
[2022-06-10T14:30:42.641] sched: Allocate JobId=43384 NodeList=cpu09 #CPUs=16 Partition=cpu-opteron
[2022-06-10T14:30:48.243] _slurm_rpc_submit_batch_job: JobId=43385 InitPrio=22579 usec=381
[2022-06-10T14:30:48.650] sched: Allocate JobId=43385 NodeList=cpu09 #CPUs=16 Partition=cpu-opteron
[2022-06-10T14:30:52.827] _slurm_rpc_submit_batch_job: JobId=43386 InitPrio=22579 usec=420
[2022-06-10T14:30:53.657] sched: Allocate JobId=43386 NodeList=cpu09 #CPUs=16 Partition=cpu-opteron
[2022-06-10T14:30:56.996] _slurm_rpc_submit_batch_job: JobId=43387 InitPrio=22579 usec=608
[2022-06-10T14:31:01.251] _slurm_rpc_submit_batch_job: JobId=43388 InitPrio=22579 usec=500
[2022-06-10T14:31:05.355] _slurm_rpc_submit_batch_job: JobId=43389 InitPrio=22579 usec=444
[2022-06-10T14:31:10.019] _slurm_rpc_submit_batch_job: JobId=43390 InitPrio=22579 usec=403
[2022-06-10T14:31:14.595] _slurm_rpc_submit_batch_job: JobId=43391 InitPrio=22579 usec=447
[2022-06-10T14:31:53.635] _slurm_rpc_kill_job: REQUEST_KILL_JOB JobId=43376 uid 548300543
[2022-06-10T15:21:09.807] _slurm_rpc_submit_batch_job: JobId=43392 InitPrio=25282 usec=370
[2022-06-10T15:21:15.589] _slurm_rpc_kill_job: REQUEST_KILL_JOB JobId=43392 uid 548300543
[2022-06-10T15:21:39.075] _slurm_rpc_submit_batch_job: JobId=43393 InitPrio=25282 usec=448
[2022-06-10T15:21:43.491] _slurm_rpc_kill_job: REQUEST_KILL_JOB JobId=43393 uid 548300543
[2022-06-10T15:28:57.182] _slurm_rpc_submit_batch_job: JobId=43394 InitPrio=23657 usec=499
[2022-06-10T16:19:28.054] _slurm_rpc_submit_batch_job: JobId=43395 InitPrio=21228 usec=884
[2022-06-10T16:19:28.489] sched: Allocate JobId=43395 NodeList=gpu01 #CPUs=16 Partition=gpu-k10
[2022-06-10T16:20:30.518] _slurm_rpc_submit_batch_job: JobId=43396 InitPrio=21228 usec=809
[2022-06-10T16:20:30.562] sched: Allocate JobId=43396 NodeList=gpu03 #CPUs=16 Partition=gpu-k10
[2022-06-10T16:28:33.466] _slurm_rpc_submit_batch_job: JobId=43397 InitPrio=25351 usec=396
[2022-06-10T16:28:34.324] sched: Allocate JobId=43397 NodeList=gpu04 #CPUs=8 Partition=gpu-k40c
[2022-06-10T16:55:08.255] _slurm_rpc_submit_batch_job: JobId=43398 InitPrio=23657 usec=440
[2022-06-10T17:10:33.466] error: This association 205(account='free', user='janvik', partition='(null)') does not have access to qos normal
[2022-06-10T17:10:33.466] _slurm_rpc_submit_batch_job: Invalid qos specification
[2022-06-10T17:11:37.090] error: This association 205(account='free', user='janvik', partition='(null)') does not have access to qos normal
[2022-06-10T17:11:37.090] _slurm_rpc_submit_batch_job: Invalid qos specification
[2022-06-10T17:18:28.366] _slurm_rpc_kill_job: REQUEST_KILL_JOB JobId=43397 uid 548300543
[2022-06-10T17:19:34.455] error: This association 205(account='free', user='janvik', partition='(null)') does not have access to qos normal
[2022-06-10T17:19:34.455] _slurm_rpc_submit_batch_job: Invalid qos specification
[2022-06-10T17:40:40.444] _slurm_rpc_submit_batch_job: JobId=43399 InitPrio=20684 usec=595
[2022-06-10T19:08:30.272] error: This association 205(account='free', user='janvik', partition='(null)') does not have access to qos normal
[2022-06-10T19:08:30.272] _slurm_rpc_submit_batch_job: Invalid qos specification
[2022-06-10T19:20:50.911] _slurm_rpc_submit_batch_job: JobId=43400 InitPrio=24776 usec=514
[2022-06-10T19:20:51.628] sched: Allocate JobId=43400 NodeList=gpu02 #CPUs=12 Partition=gpu-titan
[2022-06-10T19:21:00.620] _job_complete: JobId=43400 WEXITSTATUS 2
[2022-06-10T19:21:00.621] _job_complete: JobId=43400 done
[2022-06-10T19:21:32.833] error: Invalid qos (normal*)
[2022-06-10T19:21:32.833] _slurm_rpc_submit_batch_job: Invalid qos specification
[2022-06-10T19:22:16.795] _job_create: exceeded association/QOS limit for user 548300579: AssocGrpCpuLimit
[2022-06-10T19:22:16.795] _slurm_rpc_submit_batch_job: Job violates accounting/QOS policy (job submit limit, user's size and/or time limits)
[2022-06-10T19:23:22.883] _job_create: exceeded association/QOS limit for user 548300579: AssocGrpCpuLimit
[2022-06-10T19:23:22.883] _slurm_rpc_submit_batch_job: Job violates accounting/QOS policy (job submit limit, user's size and/or time limits)
[2022-06-10T19:23:38.036] _slurm_rpc_submit_batch_job: JobId=43401 InitPrio=24776 usec=569
[2022-06-10T19:23:38.993] sched: Allocate JobId=43401 NodeList=gpu02 #CPUs=12 Partition=gpu-titan
[2022-06-10T19:23:45.899] _job_complete: JobId=43401 WEXITSTATUS 1
[2022-06-10T19:23:45.899] _job_complete: JobId=43401 done
[2022-06-10T19:48:37.224] _slurm_rpc_submit_batch_job: JobId=43402 InitPrio=24776 usec=408
[2022-06-10T19:48:37.809] sched: Allocate JobId=43402 NodeList=gpu02 #CPUs=12 Partition=gpu-titan
[2022-06-10T19:48:38.550] _job_complete: JobId=43402 WEXITSTATUS 1
[2022-06-10T19:48:38.550] _job_complete: JobId=43402 done
[2022-06-10T19:51:12.968] _slurm_rpc_submit_batch_job: JobId=43403 InitPrio=24776 usec=599
[2022-06-10T19:51:13.029] sched: Allocate JobId=43403 NodeList=gpu02 #CPUs=12 Partition=gpu-titan
[2022-06-10T19:52:21.725] _job_complete: JobId=43403 WEXITSTATUS 1
[2022-06-10T19:52:21.725] _job_complete: JobId=43403 done
[2022-06-10T20:09:57.674] _slurm_rpc_submit_batch_job: JobId=43404 InitPrio=24776 usec=427
[2022-06-10T20:09:58.244] sched: Allocate JobId=43404 NodeList=gpu02 #CPUs=12 Partition=gpu-titan
[2022-06-10T20:10:02.321] _slurm_rpc_submit_batch_job: JobId=43405 InitPrio=24776 usec=478
[2022-06-10T20:10:27.915] _job_complete: JobId=43404 WEXITSTATUS 1
[2022-06-10T20:10:27.915] _job_complete: JobId=43404 done
[2022-06-10T20:10:28.806] sched: Allocate JobId=43405 NodeList=gpu02 #CPUs=12 Partition=gpu-titan
[2022-06-10T20:15:38.149] _slurm_rpc_kill_job: REQUEST_KILL_JOB JobId=43405 uid 548300558
[2022-06-10T20:47:22.532] _slurm_rpc_submit_batch_job: JobId=43406 InitPrio=24776 usec=448
[2022-06-10T20:47:23.419] sched: Allocate JobId=43406 NodeList=gpu02 #CPUs=12 Partition=gpu-titan
[2022-06-10T20:47:26.954] _slurm_rpc_submit_batch_job: JobId=43407 InitPrio=24776 usec=497
[2022-06-10T20:55:50.584] _job_complete: JobId=43303 WEXITSTATUS 2
[2022-06-10T20:55:50.588] _job_complete: JobId=43303 done
[2022-06-10T21:11:48.626] _slurm_rpc_submit_batch_job: JobId=43408 InitPrio=19264 usec=390
[2022-06-10T21:11:49.047] sched: Allocate JobId=43408 NodeList=cpu12 #CPUs=56 Partition=cpu-epyc
[2022-06-10T21:12:18.627] _job_complete: JobId=43408 WEXITSTATUS 2
[2022-06-10T21:12:18.627] _job_complete: JobId=43408 done
[2022-06-10T21:14:53.247] _slurm_rpc_submit_batch_job: JobId=43409 InitPrio=19264 usec=382
[2022-06-10T21:14:53.387] sched: Allocate JobId=43409 NodeList=cpu12 #CPUs=56 Partition=cpu-epyc
[2022-06-10T21:24:41.014] _job_complete: JobId=43409 WEXITSTATUS 2
[2022-06-10T21:24:41.015] _job_complete: JobId=43409 done
[2022-06-10T21:29:59.073] _slurm_rpc_submit_batch_job: JobId=43410 InitPrio=19603 usec=369
[2022-06-10T21:29:59.208] sched: Allocate JobId=43410 NodeList=cpu12 #CPUs=48 Partition=cpu-epyc
[2022-06-10T22:58:57.562] _job_complete: JobId=43385 WEXITSTATUS 0
[2022-06-10T22:58:57.562] _job_complete: JobId=43385 done
[2022-06-10T22:58:57.971] sched: Allocate JobId=43387 NodeList=cpu09 #CPUs=16 Partition=cpu-opteron
[2022-06-10T23:01:24.776] _job_complete: JobId=43386 WEXITSTATUS 0
[2022-06-10T23:01:24.776] _job_complete: JobId=43386 done
[2022-06-10T23:01:25.294] sched: Allocate JobId=43388 NodeList=cpu09 #CPUs=16 Partition=cpu-opteron
[2022-06-10T23:07:20.591] _job_complete: JobId=43379 WEXITSTATUS 0
[2022-06-10T23:07:20.591] _job_complete: JobId=43379 done
[2022-06-10T23:07:21.159] sched: Allocate JobId=43389 NodeList=cpu11 #CPUs=16 Partition=cpu-opteron
[2022-06-10T23:12:19.241] _job_complete: JobId=43383 WEXITSTATUS 0
[2022-06-10T23:12:19.241] _job_complete: JobId=43383 done
[2022-06-10T23:12:19.744] sched: Allocate JobId=43390 NodeList=cpu09 #CPUs=16 Partition=cpu-opteron
[2022-06-10T23:18:42.493] _job_complete: JobId=43381 WEXITSTATUS 0
[2022-06-10T23:18:42.493] _job_complete: JobId=43381 done
[2022-06-10T23:18:42.970] sched: Allocate JobId=43391 NodeList=cpu01 #CPUs=16 Partition=cpu-opteron
[2022-06-10T23:19:31.147] _job_complete: JobId=43380 WEXITSTATUS 0
[2022-06-10T23:19:31.147] _job_complete: JobId=43380 done
[2022-06-10T23:23:42.062] _job_complete: JobId=43382 WEXITSTATUS 0
[2022-06-10T23:23:42.062] _job_complete: JobId=43382 done
[2022-06-10T23:26:44.517] _job_complete: JobId=43378 WEXITSTATUS 0
[2022-06-10T23:26:44.518] _job_complete: JobId=43378 done
[2022-06-10T23:30:00.683] _slurm_rpc_kill_job: REQUEST_KILL_JOB JobId=43322 uid 548200017
[2022-06-10T23:30:00.684] _slurm_rpc_kill_job: REQUEST_KILL_JOB JobId=43358 uid 548200017
[2022-06-10T23:30:00.684] _slurm_rpc_kill_job: REQUEST_KILL_JOB JobId=43323 uid 548200017
[2022-06-10T23:30:49.145] _slurm_rpc_submit_batch_job: JobId=43411 InitPrio=19196 usec=385
[2022-06-10T23:30:49.688] sched: Allocate JobId=43411 NodeList=cpu15 #CPUs=64 Partition=cpu-epyc
[2022-06-10T23:40:55.250] _job_complete: JobId=43411 WEXITSTATUS 2
[2022-06-10T23:40:55.250] _job_complete: JobId=43411 done
[2022-06-10T23:56:59.325] _job_complete: JobId=43377 WEXITSTATUS 0
[2022-06-10T23:56:59.325] _job_complete: JobId=43377 done
[2022-06-11T00:43:00.185] _slurm_rpc_submit_batch_job: JobId=43412 InitPrio=20280 usec=361
[2022-06-11T00:43:00.710] sched: Allocate JobId=43412 NodeList=cpu13 #CPUs=32 Partition=cpu-epyc
[2022-06-11T00:46:10.805] _slurm_rpc_kill_job: REQUEST_KILL_JOB JobId=43412 uid 548300516
[2022-06-11T00:46:21.493] _slurm_rpc_submit_batch_job: JobId=43413 InitPrio=20280 usec=400
[2022-06-11T00:46:21.986] sched: Allocate JobId=43413 NodeList=cpu13 #CPUs=32 Partition=cpu-epyc
[2022-06-11T00:48:09.322] _slurm_rpc_submit_batch_job: JobId=43414 InitPrio=20280 usec=390
[2022-06-11T00:48:10.251] sched: Allocate JobId=43414 NodeList=cpu15 #CPUs=32 Partition=cpu-epyc
[2022-06-11T00:49:36.040] _job_complete: JobId=43414 WEXITSTATUS 0
[2022-06-11T00:49:36.041] _job_complete: JobId=43414 done
[2022-06-11T00:53:04.899] _job_complete: JobId=43413 WEXITSTATUS 0
[2022-06-11T00:53:04.899] _job_complete: JobId=43413 done
[2022-06-11T00:57:25.179] _slurm_rpc_submit_batch_job: JobId=43415 InitPrio=20280 usec=357
[2022-06-11T00:57:25.282] sched: Allocate JobId=43415 NodeList=cpu13 #CPUs=32 Partition=cpu-epyc
[2022-06-11T00:58:33.556] _job_complete: JobId=43415 WEXITSTATUS 1
[2022-06-11T00:58:33.556] _job_complete: JobId=43415 done
[2022-06-11T00:59:06.343] _job_complete: JobId=43406 WEXITSTATUS 0
[2022-06-11T00:59:06.344] _job_complete: JobId=43406 done
[2022-06-11T00:59:07.232] sched: Allocate JobId=43407 NodeList=gpu02 #CPUs=12 Partition=gpu-titan
[2022-06-11T01:01:11.796] _slurm_rpc_submit_batch_job: JobId=43416 InitPrio=20280 usec=372
[2022-06-11T01:01:12.637] sched: Allocate JobId=43416 NodeList=cpu13 #CPUs=32 Partition=cpu-epyc
[2022-06-11T01:02:19.239] _job_complete: JobId=43416 WEXITSTATUS 1
[2022-06-11T01:02:19.239] _job_complete: JobId=43416 done
[2022-06-11T01:02:43.576] _slurm_rpc_submit_batch_job: JobId=43417 InitPrio=20280 usec=433
[2022-06-11T01:02:44.146] sched: Allocate JobId=43417 NodeList=cpu13 #CPUs=32 Partition=cpu-epyc
[2022-06-11T01:03:51.751] _job_complete: JobId=43417 WEXITSTATUS 1
[2022-06-11T01:03:51.751] _job_complete: JobId=43417 done
[2022-06-11T01:04:54.960] _slurm_rpc_submit_batch_job: JobId=43418 InitPrio=20280 usec=386
[2022-06-11T01:04:55.315] sched: Allocate JobId=43418 NodeList=cpu13 #CPUs=32 Partition=cpu-epyc
[2022-06-11T01:06:14.189] _job_complete: JobId=43418 WEXITSTATUS 0
[2022-06-11T01:06:14.189] _job_complete: JobId=43418 done
[2022-06-11T01:09:33.797] _slurm_rpc_submit_batch_job: JobId=43419 InitPrio=20280 usec=317
[2022-06-11T01:09:34.174] sched: Allocate JobId=43419 NodeList=cpu13 #CPUs=32 Partition=cpu-epyc
[2022-06-11T01:11:19.777] _slurm_rpc_submit_batch_job: JobId=43420 InitPrio=20280 usec=475
[2022-06-11T01:11:20.319] sched: Allocate JobId=43420 NodeList=cpu15 #CPUs=32 Partition=cpu-epyc
[2022-06-11T01:13:48.236] _slurm_rpc_kill_job: REQUEST_KILL_JOB JobId=43407 uid 548300558
[2022-06-11T01:14:26.209] _slurm_rpc_submit_batch_job: JobId=43421 InitPrio=20280 usec=444
[2022-06-11T01:16:13.926] _job_complete: JobId=43419 WEXITSTATUS 0
[2022-06-11T01:16:13.927] _job_complete: JobId=43419 done
[2022-06-11T01:16:14.275] sched: Allocate JobId=43421 NodeList=cpu13 #CPUs=32 Partition=cpu-epyc
[2022-06-11T01:17:17.933] _slurm_rpc_submit_batch_job: JobId=43422 InitPrio=20280 usec=348
[2022-06-11T01:17:37.557] _job_complete: JobId=43420 WEXITSTATUS 0
[2022-06-11T01:17:37.558] _job_complete: JobId=43420 done
[2022-06-11T01:18:03.599] _slurm_rpc_kill_job: REQUEST_KILL_JOB JobId=43093 uid 548300516
[2022-06-11T01:18:11.483] sched: Allocate JobId=43095 NodeList=gpu05 #CPUs=32 Partition=gpu-v100s
[2022-06-11T01:18:31.399] _slurm_rpc_submit_batch_job: JobId=43423 InitPrio=20280 usec=417
[2022-06-11T01:19:24.387] _slurm_rpc_submit_batch_job: JobId=43424 InitPrio=20280 usec=385
[2022-06-11T01:19:56.578] _slurm_rpc_kill_job: REQUEST_KILL_JOB JobId=43095 uid 548300516
[2022-06-11T01:20:00.478] sched: Allocate JobId=43097 NodeList=gpu05 #CPUs=32 Partition=gpu-v100s
[2022-06-11T01:20:29.144] _slurm_rpc_kill_job: REQUEST_KILL_JOB JobId=43097 uid 548300516
[2022-06-11T01:20:31.012] sched: Allocate JobId=43422 NodeList=gpu05 #CPUs=32 Partition=gpu-v100s
[2022-06-11T01:21:59.505] _slurm_rpc_submit_batch_job: JobId=43425 InitPrio=20280 usec=473
[2022-06-11T01:22:56.661] _job_complete: JobId=43421 WEXITSTATUS 0
[2022-06-11T01:22:56.662] _job_complete: JobId=43421 done
[2022-06-11T01:25:40.770] _slurm_rpc_submit_batch_job: JobId=43426 InitPrio=20280 usec=416
[2022-06-11T01:25:40.845] sched: Allocate JobId=43426 NodeList=cpu13 #CPUs=32 Partition=cpu-epyc
[2022-06-11T01:32:18.931] _job_complete: JobId=43426 WEXITSTATUS 0
[2022-06-11T01:32:18.931] _job_complete: JobId=43426 done
[2022-06-11T01:32:39.640] _slurm_rpc_submit_batch_job: JobId=43427 InitPrio=26989 usec=457
[2022-06-11T01:32:39.727] sched: Allocate JobId=43427 NodeList=gpu02 #CPUs=6 Partition=gpu-titan
[2022-06-11T01:41:21.774] _slurm_rpc_kill_job: REQUEST_KILL_JOB JobId=43368 uid 548300557
[2022-06-11T01:42:43.122] _slurm_rpc_submit_batch_job: JobId=43428 InitPrio=26904 usec=451
[2022-06-11T03:33:28.816] _job_complete: JobId=43427 WEXITSTATUS 0
[2022-06-11T03:33:28.820] _job_complete: JobId=43427 done
[2022-06-11T07:07:05.121] _job_complete: JobId=43389 WEXITSTATUS 0
[2022-06-11T07:07:05.122] _job_complete: JobId=43389 done
[2022-06-11T07:26:29.300] _job_complete: JobId=43388 WEXITSTATUS 0
[2022-06-11T07:26:29.300] _job_complete: JobId=43388 done
[2022-06-11T07:32:44.106] _job_complete: JobId=43390 WEXITSTATUS 0
[2022-06-11T07:32:44.107] _job_complete: JobId=43390 done
[2022-06-11T09:28:12.232] _job_complete: JobId=43384 WEXITSTATUS 0
[2022-06-11T09:28:12.232] _job_complete: JobId=43384 done
[2022-06-11T10:08:10.309] _slurm_rpc_submit_batch_job: JobId=43429 InitPrio=24776 usec=471
[2022-06-11T10:08:11.269] sched: Allocate JobId=43429 NodeList=gpu02 #CPUs=12 Partition=gpu-titan
[2022-06-11T10:48:51.958] _slurm_rpc_submit_batch_job: JobId=43430 InitPrio=26363 usec=405
[2022-06-11T11:09:17.264] _slurm_rpc_submit_batch_job: JobId=43431 InitPrio=19469 usec=439
[2022-06-11T11:09:19.984] sched: Allocate JobId=43431 NodeList=cpu13 #CPUs=32 Partition=cpu-epyc
[2022-06-11T11:09:26.117] _slurm_rpc_submit_batch_job: JobId=43432 InitPrio=19469 usec=487
[2022-06-11T11:09:26.972] sched: Allocate JobId=43432 NodeList=cpu15 #CPUs=32 Partition=cpu-epyc
[2022-06-11T11:09:35.007] _slurm_rpc_submit_batch_job: JobId=43433 InitPrio=19469 usec=492
[2022-06-11T11:09:35.985] sched: Allocate JobId=43433 NodeList=cpu15 #CPUs=32 Partition=cpu-epyc
[2022-06-11T11:09:43.270] _slurm_rpc_submit_batch_job: JobId=43434 InitPrio=19332 usec=387
[2022-06-11T11:09:43.997] sched: Allocate JobId=43434 NodeList=cpu09 #CPUs=48 Partition=cpu-opteron
[2022-06-11T11:09:51.639] _slurm_rpc_submit_batch_job: JobId=43435 InitPrio=19196 usec=514
[2022-06-11T11:09:52.009] sched: Allocate JobId=43435 NodeList=cpu08 #CPUs=64 Partition=cpu-opteron
[2022-06-11T11:26:15.496] _slurm_rpc_submit_batch_job: JobId=43436 InitPrio=19469 usec=505
[2022-06-11T11:26:15.759] sched: Allocate JobId=43436 NodeList=cpu11 #CPUs=32 Partition=cpu-opteron
[2022-06-11T11:26:27.140] _slurm_rpc_submit_batch_job: JobId=43437 InitPrio=19469 usec=466
[2022-06-11T12:14:40.818] _slurm_rpc_submit_batch_job: JobId=43438 InitPrio=25080 usec=459
[2022-06-11T12:16:59.450] _slurm_rpc_submit_batch_job: JobId=43439 InitPrio=25080 usec=437
[2022-06-11T12:44:32.275] _job_complete: JobId=43371 WEXITSTATUS 0
[2022-06-11T12:44:32.275] _job_complete: JobId=43371 done
[2022-06-11T12:50:31.030] Time limit exhausted for JobId=43369
[2022-06-11T12:51:31.117] Time limit exhausted for JobId=43370
[2022-06-11T13:15:31.726] Time limit exhausted for JobId=43373
[2022-06-11T13:15:33.765] sched: Allocate JobId=43437 NodeList=cpu04 #CPUs=32 Partition=cpu-opteron
[2022-06-11T13:19:31.152] Time limit exhausted for JobId=43374
[2022-06-11T13:38:00.921] _slurm_rpc_submit_batch_job: JobId=43440 InitPrio=19469 usec=403
[2022-06-11T13:38:01.187] sched: Allocate JobId=43440 NodeList=cpu14 #CPUs=32 Partition=cpu-epyc
[2022-06-11T13:40:29.315] _slurm_rpc_kill_job: REQUEST_KILL_JOB JobId=43431 uid 548200017
[2022-06-11T13:40:31.165] sched: Allocate JobId=43394 NodeList=cpu13 #CPUs=48 Partition=cpu-epyc
[2022-06-11T13:41:28.584] _slurm_rpc_kill_job: REQUEST_KILL_JOB JobId=43432 uid 548200017
[2022-06-11T13:42:52.872] _slurm_rpc_submit_batch_job: JobId=43441 InitPrio=19469 usec=368
[2022-06-11T13:42:53.725] sched: Allocate JobId=43441 NodeList=cpu12 #CPUs=32 Partition=cpu-epyc
[2022-06-11T13:43:26.683] _slurm_rpc_kill_job: REQUEST_KILL_JOB JobId=43433 uid 548200017
[2022-06-11T13:43:28.535] sched: Allocate JobId=43398 NodeList=cpu15 #CPUs=48 Partition=cpu-epyc
[2022-06-11T13:44:10.893] _slurm_rpc_submit_batch_job: JobId=43442 InitPrio=19469 usec=354
[2022-06-11T13:44:44.664] _slurm_rpc_kill_job: REQUEST_KILL_JOB JobId=43434 uid 548200017
[2022-06-11T13:45:47.807] _slurm_rpc_submit_batch_job: JobId=43443 InitPrio=20954 usec=522
[2022-06-11T13:45:47.996] sched: Allocate JobId=43443 NodeList=cpu09 #CPUs=48 Partition=cpu-opteron
[2022-06-11T13:45:51.994] _slurm_rpc_submit_batch_job: JobId=43444 InitPrio=19332 usec=435
[2022-06-11T13:46:46.886] _slurm_rpc_kill_job: REQUEST_KILL_JOB JobId=43435 uid 548200017
[2022-06-11T13:46:48.923] sched: Allocate JobId=43444 NodeList=cpu08 #CPUs=48 Partition=cpu-opteron
[2022-06-11T13:47:00.741] _slurm_rpc_submit_batch_job: JobId=43445 InitPrio=21091 usec=514
[2022-06-11T13:47:01.088] sched: Allocate JobId=43445 NodeList=cpu03 #CPUs=32 Partition=cpu-opteron
[2022-06-11T13:47:30.208] _slurm_rpc_submit_batch_job: JobId=43446 InitPrio=19196 usec=411
[2022-06-11T13:47:56.243] _slurm_rpc_kill_job: REQUEST_KILL_JOB JobId=43442 uid 548200017
[2022-06-11T13:48:24.571] _slurm_rpc_submit_batch_job: JobId=43447 InitPrio=21091 usec=521
[2022-06-11T13:48:25.302] sched: Allocate JobId=43447 NodeList=cpu04 #CPUs=32 Partition=cpu-opteron
[2022-06-11T13:48:36.205] _slurm_rpc_submit_batch_job: JobId=43448 InitPrio=19606 usec=388
[2022-06-11T13:48:36.321] sched: Allocate JobId=43448 NodeList=cpu12 #CPUs=16 Partition=cpu-epyc
[2022-06-11T13:49:38.057] _slurm_rpc_kill_job: REQUEST_KILL_JOB JobId=43436 uid 548200017
[2022-06-11T13:50:20.878] _slurm_rpc_submit_batch_job: JobId=43449 InitPrio=19469 usec=498
[2022-06-11T13:50:21.470] sched: Allocate JobId=43449 NodeList=cpu11 #CPUs=32 Partition=cpu-opteron
[2022-06-11T13:51:06.069] _slurm_rpc_submit_batch_job: JobId=43450 InitPrio=21091 usec=452
[2022-06-11T13:51:06.533] sched: Allocate JobId=43450 NodeList=cpu05 #CPUs=32 Partition=cpu-opteron
[2022-06-11T13:51:07.494] _slurm_rpc_kill_job: REQUEST_KILL_JOB JobId=43437 uid 548200017
[2022-06-11T13:51:58.968] _slurm_rpc_submit_batch_job: JobId=43451 InitPrio=19469 usec=541
[2022-06-11T13:51:59.610] sched: Allocate JobId=43451 NodeList=cpu04 #CPUs=32 Partition=cpu-opteron
[2022-06-11T13:53:35.502] _slurm_rpc_submit_batch_job: JobId=43452 InitPrio=21091 usec=448
[2022-06-11T13:54:03.580] _slurm_rpc_kill_job: REQUEST_KILL_JOB JobId=43452 uid 548200019
[2022-06-11T13:54:38.400] _slurm_rpc_submit_batch_job: JobId=43453 InitPrio=21091 usec=462
[2022-06-11T13:55:22.644] _slurm_rpc_kill_job: REQUEST_KILL_JOB JobId=43450 uid 548200019
[2022-06-11T13:55:23.711] sched: Allocate JobId=43453 NodeList=cpu05 #CPUs=32 Partition=cpu-opteron
[2022-06-11T13:55:59.722] _slurm_rpc_submit_batch_job: JobId=43454 InitPrio=19196 usec=360
[2022-06-11T13:56:15.361] _slurm_rpc_submit_batch_job: JobId=43455 InitPrio=21228 usec=517
[2022-06-11T13:56:16.080] sched: Allocate JobId=43455 NodeList=cpu01 #CPUs=16 Partition=cpu-opteron
[2022-06-11T14:02:18.804] _slurm_rpc_submit_batch_job: JobId=43456 InitPrio=22576 usec=444
[2022-06-11T14:03:27.425] _slurm_rpc_submit_batch_job: JobId=43457 InitPrio=19606 usec=426
[2022-06-11T14:03:27.881] sched: Allocate JobId=43457 NodeList=cpu08 #CPUs=16 Partition=cpu-opteron
[2022-06-11T14:05:10.210] _slurm_rpc_submit_batch_job: JobId=43458 InitPrio=22713 usec=525
[2022-06-11T14:06:23.279] _job_complete: JobId=43457 WEXITSTATUS 0
[2022-06-11T14:06:23.280] _job_complete: JobId=43457 done
[2022-06-11T14:09:17.249] _slurm_rpc_submit_batch_job: JobId=43459 InitPrio=21228 usec=467
[2022-06-11T14:09:19.726] sched: Allocate JobId=43459 NodeList=cpu08 #CPUs=16 Partition=cpu-opteron
[2022-06-11T14:12:49.719] _slurm_rpc_submit_batch_job: JobId=43460 InitPrio=19606 usec=543
[2022-06-11T14:14:02.574] _slurm_rpc_kill_job: REQUEST_KILL_JOB JobId=43460 uid 548200017
[2022-06-11T14:26:12.786] _job_complete: JobId=43429 WEXITSTATUS 0
[2022-06-11T14:26:12.786] _job_complete: JobId=43429 done
[2022-06-11T14:26:36.389] sched/backfill: _start_job: Started JobId=43439 in gpu-titan on gpu02
[2022-06-11T14:36:09.310] _job_complete: JobId=43387 WEXITSTATUS 0
[2022-06-11T14:36:09.310] _job_complete: JobId=43387 done
[2022-06-11T14:46:48.018] _get_job_parts: invalid partition specified: cpu-epcy
[2022-06-11T14:46:48.018] _slurm_rpc_submit_batch_job: Invalid partition name specified
[2022-06-11T14:47:16.365] _slurm_rpc_kill_job: REQUEST_KILL_JOB JobId=43446 uid 548200017
[2022-06-11T14:47:16.576] _slurm_rpc_submit_batch_job: JobId=43461 InitPrio=22576 usec=485
[2022-06-11T15:11:11.625] _slurm_rpc_submit_batch_job: JobId=43462 InitPrio=21228 usec=512
[2022-06-11T15:11:11.636] sched: Allocate JobId=43462 NodeList=cpu09 #CPUs=16 Partition=cpu-opteron
[2022-06-11T16:35:27.869] _job_complete: JobId=43394 WEXITSTATUS 1
[2022-06-11T16:35:27.869] _job_complete: JobId=43394 done
[2022-06-11T16:35:28.201] sched: Allocate JobId=43456 NodeList=cpu13 #CPUs=48 Partition=cpu-epyc
[2022-06-11T17:48:53.031] _job_complete: JobId=43391 WEXITSTATUS 0
[2022-06-11T17:48:53.032] _job_complete: JobId=43391 done
[2022-06-11T18:25:07.994] _slurm_rpc_submit_batch_job: JobId=43463 InitPrio=24471 usec=563
[2022-06-11T18:25:08.190] sched: Allocate JobId=43463 NodeList=gpu04 #CPUs=16 Partition=gpu-k40c
[2022-06-11T18:25:56.592] _job_complete: JobId=43463 WEXITSTATUS 1
[2022-06-11T18:25:56.592] _job_complete: JobId=43463 done
[2022-06-11T18:28:34.675] _slurm_rpc_submit_batch_job: JobId=43464 InitPrio=24471 usec=409
[2022-06-11T18:28:35.591] sched: Allocate JobId=43464 NodeList=gpu04 #CPUs=16 Partition=gpu-k40c
[2022-06-11T18:29:03.910] _job_complete: JobId=43464 WEXITSTATUS 1
[2022-06-11T18:29:03.910] _job_complete: JobId=43464 done
[2022-06-11T19:31:34.557] _slurm_rpc_submit_batch_job: JobId=43465 InitPrio=24334 usec=458
[2022-06-11T19:31:38.247] _slurm_rpc_submit_batch_job: JobId=43466 InitPrio=24334 usec=331
[2022-06-11T19:39:51.309] _slurm_rpc_kill_job: REQUEST_KILL_JOB JobId=43466 uid 548300558
[2022-06-11T19:39:56.589] _slurm_rpc_kill_job: REQUEST_KILL_JOB JobId=43465 uid 548300558
[2022-06-11T19:40:07.544] _slurm_rpc_submit_batch_job: JobId=43467 InitPrio=24506 usec=450
[2022-06-11T19:40:12.161] _slurm_rpc_submit_batch_job: JobId=43468 InitPrio=24506 usec=361
[2022-06-11T20:09:52.004] _job_complete: JobId=43447 WEXITSTATUS 0
[2022-06-11T20:09:52.005] _job_complete: JobId=43447 done
[2022-06-11T20:48:32.395] _slurm_rpc_submit_batch_job: JobId=43469 InitPrio=24334 usec=559
[2022-06-11T20:48:33.332] sched: Allocate JobId=43469 NodeList=cpu04 #CPUs=32 Partition=cpu-opteron
[2022-06-11T20:48:36.456] _slurm_rpc_submit_batch_job: JobId=43470 InitPrio=24334 usec=393
[2022-06-11T20:48:48.690] _job_complete: JobId=43469 WEXITSTATUS 1
[2022-06-11T20:48:48.690] _job_complete: JobId=43469 done
[2022-06-11T20:48:49.665] sched: Allocate JobId=43470 NodeList=cpu04 #CPUs=32 Partition=cpu-opteron
[2022-06-11T20:49:01.061] _job_complete: JobId=43470 WEXITSTATUS 1
[2022-06-11T20:49:01.061] _job_complete: JobId=43470 done
[2022-06-11T21:12:30.256] _slurm_rpc_submit_batch_job: JobId=43471 InitPrio=24334 usec=415
[2022-06-11T21:12:31.032] sched: Allocate JobId=43471 NodeList=cpu04 #CPUs=32 Partition=cpu-opteron
[2022-06-11T21:12:34.060] _slurm_rpc_submit_batch_job: JobId=43472 InitPrio=24334 usec=381
[2022-06-11T21:15:11.478] _slurm_rpc_kill_job: REQUEST_KILL_JOB JobId=43471 uid 548300558
[2022-06-11T21:15:13.489] sched: Allocate JobId=43472 NodeList=cpu04 #CPUs=32 Partition=cpu-opteron
[2022-06-11T21:15:15.859] _slurm_rpc_kill_job: REQUEST_KILL_JOB JobId=43472 uid 548300558
[2022-06-11T21:15:43.044] _slurm_rpc_submit_batch_job: JobId=43473 InitPrio=24334 usec=417
[2022-06-11T21:15:43.308] sched: Allocate JobId=43473 NodeList=cpu04 #CPUs=32 Partition=cpu-opteron
[2022-06-11T21:15:46.168] _slurm_rpc_submit_batch_job: JobId=43474 InitPrio=24334 usec=385
[2022-06-11T21:18:57.817] _job_complete: JobId=43473 WEXITSTATUS 1
[2022-06-11T21:18:57.818] _job_complete: JobId=43473 done
[2022-06-11T21:18:58.315] sched: Allocate JobId=43474 NodeList=cpu04 #CPUs=32 Partition=cpu-opteron
[2022-06-11T21:22:46.363] _job_complete: JobId=43474 WEXITSTATUS 1
[2022-06-11T21:22:46.363] _job_complete: JobId=43474 done
[2022-06-11T21:35:19.364] _job_complete: JobId=43307 WEXITSTATUS 0
[2022-06-11T21:35:19.364] _job_complete: JobId=43307 done
[2022-06-11T21:35:19.872] sched: Allocate JobId=43458 NodeList=cpu03 #CPUs=32 Partition=cpu-opteron
[2022-06-11T22:10:00.783] _slurm_rpc_submit_batch_job: JobId=43475 InitPrio=24334 usec=513
[2022-06-11T22:10:01.483] sched: Allocate JobId=43475 NodeList=cpu04 #CPUs=32 Partition=cpu-opteron
[2022-06-11T22:10:05.049] _slurm_rpc_submit_batch_job: JobId=43476 InitPrio=24334 usec=351
[2022-06-11T22:11:26.168] _slurm_rpc_kill_job: REQUEST_KILL_JOB JobId=43468 uid 548300558
[2022-06-11T22:11:29.844] _slurm_rpc_kill_job: REQUEST_KILL_JOB JobId=43467 uid 548300558
[2022-06-11T22:13:17.671] _job_complete: JobId=43475 WEXITSTATUS 1
[2022-06-11T22:13:17.672] _job_complete: JobId=43475 done
[2022-06-11T22:13:18.160] sched: Allocate JobId=43476 NodeList=cpu04 #CPUs=32 Partition=cpu-opteron
[2022-06-11T22:16:50.900] _job_complete: JobId=43476 WEXITSTATUS 1
[2022-06-11T22:16:50.901] _job_complete: JobId=43476 done
[2022-06-11T22:34:19.597] _slurm_rpc_submit_batch_job: JobId=43477 InitPrio=21091 usec=554
[2022-06-11T22:34:20.171] sched: Allocate JobId=43477 NodeList=cpu04 #CPUs=32 Partition=cpu-opteron
[2022-06-11T22:46:15.118] sched: _slurm_rpc_allocate_resources JobId=43478 NodeList=gpu04 usec=16293
[2022-06-11T22:46:28.875] _slurm_rpc_submit_batch_job: JobId=43479 InitPrio=24471 usec=384
[2022-06-11T22:46:29.471] sched: Allocate JobId=43479 NodeList=cpu01 #CPUs=16 Partition=cpu-opteron
[2022-06-11T22:46:31.887] _slurm_rpc_submit_batch_job: JobId=43480 InitPrio=24471 usec=473
[2022-06-11T22:49:40.493] _job_complete: JobId=43478 WEXITSTATUS 0
[2022-06-11T22:49:40.493] _job_complete: JobId=43478 done
[2022-06-11T22:51:50.930] _job_complete: JobId=43479 WEXITSTATUS 0
[2022-06-11T22:51:50.931] _job_complete: JobId=43479 done
[2022-06-11T22:51:52.908] sched: Allocate JobId=43480 NodeList=cpu01 #CPUs=16 Partition=cpu-opteron
[2022-06-11T22:57:43.948] _job_complete: JobId=43480 WEXITSTATUS 0
[2022-06-11T22:57:43.949] _job_complete: JobId=43480 done
[2022-06-12T00:14:07.028] _job_complete: JobId=43308 WEXITSTATUS 2
[2022-06-12T00:14:07.033] _job_complete: JobId=43308 done
[2022-06-12T00:49:39.240] _job_complete: JobId=43439 WEXITSTATUS 0
[2022-06-12T00:49:39.241] _job_complete: JobId=43439 done
[2022-06-12T01:37:49.879] _job_complete: JobId=43361 WEXITSTATUS 0
[2022-06-12T01:37:49.879] _job_complete: JobId=43361 done
[2022-06-12T01:37:51.795] sched: Allocate JobId=43428 NodeList=gpu05 #CPUs=16 Partition=gpu-v100s
[2022-06-12T01:38:36.540] _job_complete: JobId=43428 WEXITSTATUS 1
[2022-06-12T01:38:36.540] _job_complete: JobId=43428 done
[2022-06-12T01:38:37.427] sched: Allocate JobId=43430 NodeList=gpu05 #CPUs=16 Partition=gpu-v100s
[2022-06-12T01:38:59.715] _job_complete: JobId=43430 WEXITSTATUS 1
[2022-06-12T01:38:59.715] _job_complete: JobId=43430 done
[2022-06-12T04:30:19.571] _slurm_rpc_kill_job: REQUEST_KILL_JOB JobId=43438 uid 548200110
[2022-06-12T04:31:02.250] _slurm_rpc_submit_batch_job: JobId=43481 InitPrio=25080 usec=532
[2022-06-12T04:31:03.131] sched: Allocate JobId=43481 NodeList=gpu02 #CPUs=8 Partition=gpu-titan
[2022-06-12T04:31:39.699] _job_complete: JobId=43481 OOM failure
[2022-06-12T04:31:39.700] _job_complete: JobId=43481 done
[2022-06-12T04:32:52.888] _slurm_rpc_submit_batch_job: JobId=43482 InitPrio=21078 usec=445
[2022-06-12T04:32:53.410] sched: Allocate JobId=43482 NodeList=gpu02 #CPUs=2 Partition=gpu-titan
[2022-06-12T04:32:56.959] _job_complete: JobId=43482 WEXITSTATUS 0
[2022-06-12T04:32:56.960] _job_complete: JobId=43482 done
[2022-06-12T04:53:43.791] _job_complete: JobId=43456 WEXITSTATUS 0
[2022-06-12T04:53:43.791] _job_complete: JobId=43456 done
[2022-06-12T04:53:44.121] sched: Allocate JobId=43461 NodeList=cpu13 #CPUs=48 Partition=cpu-epyc
[2022-06-12T07:11:59.717] _slurm_rpc_submit_batch_job: JobId=43483 InitPrio=26363 usec=603
[2022-06-12T07:12:00.047] sched: Allocate JobId=43483 NodeList=gpu05 #CPUs=16 Partition=gpu-v100s
[2022-06-12T07:14:32.170] _slurm_rpc_kill_job: REQUEST_KILL_JOB JobId=43483 uid 548300557
[2022-06-12T07:14:48.360] _slurm_rpc_submit_batch_job: JobId=43484 InitPrio=26363 usec=416
[2022-06-12T07:14:49.347] sched: Allocate JobId=43484 NodeList=gpu05 #CPUs=16 Partition=gpu-v100s
[2022-06-12T07:33:11.406] _slurm_rpc_submit_batch_job: JobId=43485 InitPrio=26363 usec=379
[2022-06-12T08:14:05.803] _job_complete: JobId=43484 WEXITSTATUS 0
[2022-06-12T08:14:05.804] _job_complete: JobId=43484 done
[2022-06-12T08:14:06.173] sched: Allocate JobId=43485 NodeList=gpu05 #CPUs=16 Partition=gpu-v100s
[2022-06-12T08:30:37.886] _slurm_rpc_submit_batch_job: JobId=43486 InitPrio=25823 usec=485
[2022-06-12T08:32:53.627] _slurm_rpc_submit_batch_job: JobId=43487 InitPrio=25823 usec=360
[2022-06-12T08:58:18.848] Requeuing JobId=43422
[2022-06-12T08:58:18.864] sched: Allocate JobId=43486 NodeList=gpu05 #CPUs=16 Partition=gpu-v100s
[2022-06-12T09:18:22.865] _job_complete: JobId=43485 WEXITSTATUS 0
[2022-06-12T09:18:22.866] _job_complete: JobId=43485 done
[2022-06-12T09:18:23.165] sched: Allocate JobId=43487 NodeList=gpu05 #CPUs=16 Partition=gpu-v100s
[2022-06-12T09:30:15.563] _slurm_rpc_kill_job: REQUEST_KILL_JOB JobId=43486 uid 548300557
[2022-06-12T09:30:17.390] sched: Allocate JobId=43423 NodeList=gpu05 #CPUs=32 Partition=gpu-v100s
[2022-06-12T09:31:26.199] _slurm_rpc_submit_batch_job: JobId=43488 InitPrio=25823 usec=382
[2022-06-12T09:56:46.267] _slurm_rpc_submit_batch_job: JobId=43489 InitPrio=25552 usec=500
[2022-06-12T10:14:10.405] _slurm_rpc_submit_batch_job: JobId=43490 InitPrio=21498 usec=910
[2022-06-12T10:14:24.570] _slurm_rpc_kill_job: REQUEST_KILL_JOB JobId=43490 uid 548200029
[2022-06-12T10:15:05.451] _slurm_rpc_submit_batch_job: JobId=43491 InitPrio=21498 usec=912
[2022-06-12T10:28:02.925] _job_complete: JobId=43487 WEXITSTATUS 0
[2022-06-12T10:28:02.926] _job_complete: JobId=43487 done
[2022-06-12T10:28:03.791] sched: Allocate JobId=43488 NodeList=gpu05 #CPUs=16 Partition=gpu-v100s
[2022-06-12T10:58:42.920] _slurm_rpc_submit_batch_job: JobId=43492 InitPrio=24471 usec=397
[2022-06-12T11:00:51.785] _slurm_rpc_submit_batch_job: JobId=43493 InitPrio=24471 usec=462
[2022-06-12T11:06:21.545] _slurm_rpc_submit_batch_job: JobId=43494 InitPrio=25282 usec=443
[2022-06-12T11:31:03.707] _job_complete: JobId=43488 WEXITSTATUS 0
[2022-06-12T11:31:03.708] _job_complete: JobId=43488 done
[2022-06-12T11:31:04.573] sched: Allocate JobId=43489 NodeList=gpu05 #CPUs=16 Partition=gpu-v100s
[2022-06-12T11:53:42.756] _slurm_rpc_kill_job: REQUEST_KILL_JOB JobId=43494 uid 548300557
[2022-06-12T11:56:05.442] _slurm_rpc_submit_batch_job: JobId=43495 InitPrio=25282 usec=398
[2022-06-12T12:03:04.229] _slurm_rpc_kill_job: REQUEST_KILL_JOB JobId=43495 uid 548300557
[2022-06-12T12:05:06.535] _slurm_rpc_submit_batch_job: JobId=43496 InitPrio=25368 usec=394
[2022-06-12T12:05:07.002] sched: Allocate JobId=43496 NodeList=gpu02 #CPUs=6 Partition=gpu-titan
[2022-06-12T12:05:32.910] _job_complete: JobId=43496 WEXITSTATUS 1
[2022-06-12T12:05:32.911] _job_complete: JobId=43496 done
[2022-06-12T12:07:47.790] _slurm_rpc_submit_batch_job: JobId=43497 InitPrio=25368 usec=357
[2022-06-12T12:07:48.369] sched: Allocate JobId=43497 NodeList=gpu02 #CPUs=6 Partition=gpu-titan
[2022-06-12T12:36:14.893] _job_complete: JobId=43489 WEXITSTATUS 0
[2022-06-12T12:36:14.894] _job_complete: JobId=43489 done
[2022-06-12T12:36:15.754] sched: Allocate JobId=43492 NodeList=gpu05 #CPUs=16 Partition=gpu-v100s
[2022-06-12T13:06:30.371] _job_complete: JobId=43492 WEXITSTATUS 255
[2022-06-12T13:06:30.372] _job_complete: JobId=43492 done
[2022-06-12T13:06:33.270] sched: Allocate JobId=43493 NodeList=gpu05 #CPUs=16 Partition=gpu-v100s
[2022-06-12T13:06:33.482] _job_complete: JobId=43493 WEXITSTATUS 1
[2022-06-12T13:06:33.483] _job_complete: JobId=43493 done
[2022-06-12T13:46:06.584] Time limit exhausted for JobId=43443
[2022-06-12T13:47:06.667] Time limit exhausted for JobId=43445
[2022-06-12T13:52:52.430] _job_complete: JobId=43461 WEXITSTATUS 0
[2022-06-12T13:52:52.430] _job_complete: JobId=43461 done
[2022-06-12T13:52:52.760] sched: Allocate JobId=43399 NodeList=cpu13 #CPUs=48 Partition=cpu-epyc
[2022-06-12T13:55:36.663] Time limit exhausted for JobId=43453
[2022-06-12T13:56:36.752] Time limit exhausted for JobId=43455
[2022-06-12T13:59:48.606] _slurm_rpc_submit_batch_job: JobId=43498 InitPrio=29675 usec=518
[2022-06-12T13:59:49.186] sched: Allocate JobId=43498 NodeList=gpu04 #CPUs=8 Partition=gpu-k40c
[2022-06-12T14:01:01.672] _job_complete: JobId=43498 WEXITSTATUS 0
[2022-06-12T14:01:01.672] _job_complete: JobId=43498 done
[2022-06-12T14:04:56.916] _slurm_rpc_submit_batch_job: JobId=43499 InitPrio=29675 usec=392
[2022-06-12T14:04:57.700] sched: Allocate JobId=43499 NodeList=gpu04 #CPUs=8 Partition=gpu-k40c
[2022-06-12T14:05:01.881] _job_complete: JobId=43499 WEXITSTATUS 0
[2022-06-12T14:05:01.881] _job_complete: JobId=43499 done
[2022-06-12T14:05:51.817] _slurm_rpc_submit_batch_job: JobId=43500 InitPrio=25282 usec=379
[2022-06-12T14:05:52.795] sched: Allocate JobId=43500 NodeList=gpu05 #CPUs=16 Partition=gpu-v100s
[2022-06-12T14:09:36.203] Time limit exhausted for JobId=43459
[2022-06-12T14:21:09.590] _slurm_rpc_submit_batch_job: JobId=43501 InitPrio=24471 usec=497
[2022-06-12T14:21:12.402] _slurm_rpc_submit_batch_job: JobId=43502 InitPrio=24471 usec=419
[2022-06-12T14:27:00.856] _slurm_rpc_submit_batch_job: JobId=43503 InitPrio=24471 usec=488
[2022-06-12T14:36:54.258] _slurm_rpc_kill_job: REQUEST_KILL_JOB JobId=43503 uid 548300558
[2022-06-12T14:37:08.089] _slurm_rpc_submit_batch_job: JobId=43504 InitPrio=24471 usec=391
[2022-06-12T14:44:09.076] _slurm_rpc_submit_batch_job: JobId=43505 InitPrio=68324 usec=57265
[2022-06-12T14:44:09.154] sched: Allocate JobId=43505 NodeList=gpu04 #CPUs=8 Partition=gpu-k40c
[2022-06-12T14:44:09.429] _job_complete: JobId=43505 WEXITSTATUS 2
[2022-06-12T14:44:09.430] _job_complete: JobId=43505 done
[2022-06-12T14:46:09.246] _slurm_rpc_submit_batch_job: JobId=43506 InitPrio=68324 usec=512
[2022-06-12T14:46:09.263] sched: Allocate JobId=43506 NodeList=gpu04 #CPUs=8 Partition=gpu-k40c
[2022-06-12T14:46:11.215] _job_complete: JobId=43506 WEXITSTATUS 1
[2022-06-12T14:46:11.216] _job_complete: JobId=43506 done
[2022-06-12T14:48:06.586] _job_complete: JobId=43497 WEXITSTATUS 0
[2022-06-12T14:48:06.588] _job_complete: JobId=43497 done
[2022-06-12T14:48:22.837] _slurm_rpc_submit_batch_job: JobId=43507 InitPrio=34270 usec=563
[2022-06-12T14:48:23.578] sched: Allocate JobId=43507 NodeList=gpu04 #CPUs=8 Partition=gpu-k40c
[2022-06-12T14:48:25.035] _job_complete: JobId=43507 WEXITSTATUS 1
[2022-06-12T14:48:25.035] _job_complete: JobId=43507 done
[2022-06-12T14:50:42.154] _slurm_rpc_submit_batch_job: JobId=43508 InitPrio=34270 usec=548
[2022-06-12T14:50:42.780] sched: Allocate JobId=43508 NodeList=gpu04 #CPUs=8 Partition=gpu-k40c
[2022-06-12T14:50:44.187] _job_complete: JobId=43508 WEXITSTATUS 1
[2022-06-12T14:50:44.188] _job_complete: JobId=43508 done
[2022-06-12T14:54:56.042] _slurm_rpc_submit_batch_job: JobId=43509 InitPrio=33729 usec=591
[2022-06-12T14:54:56.253] sched: Allocate JobId=43509 NodeList=gpu04 #CPUs=8 Partition=gpu-k40c
[2022-06-12T14:54:57.819] _job_complete: JobId=43509 WEXITSTATUS 2
[2022-06-12T14:54:57.819] _job_complete: JobId=43509 done
[2022-06-12T14:56:25.260] _slurm_rpc_submit_batch_job: JobId=43510 InitPrio=33729 usec=632
[2022-06-12T14:56:25.380] sched: Allocate JobId=43510 NodeList=gpu04 #CPUs=8 Partition=gpu-k40c
[2022-06-12T14:56:26.960] _job_complete: JobId=43510 WEXITSTATUS 1
[2022-06-12T14:56:26.961] _job_complete: JobId=43510 done
[2022-06-12T15:03:32.717] _slurm_rpc_submit_batch_job: JobId=43511 InitPrio=33459 usec=560
[2022-06-12T15:03:33.223] sched: Allocate JobId=43511 NodeList=gpu04 #CPUs=8 Partition=gpu-k40c
[2022-06-12T15:03:46.161] _job_complete: JobId=43511 WEXITSTATUS 139
[2022-06-12T15:03:46.162] _job_complete: JobId=43511 done
[2022-06-12T15:05:06.832] _slurm_rpc_submit_batch_job: JobId=43512 InitPrio=33459 usec=589
[2022-06-12T15:05:07.364] sched: Allocate JobId=43512 NodeList=gpu04 #CPUs=8 Partition=gpu-k40c
[2022-06-12T15:05:18.092] _job_complete: JobId=43512 WEXITSTATUS 139
[2022-06-12T15:05:18.092] _job_complete: JobId=43512 done
[2022-06-12T15:09:05.859] _job_complete: JobId=43500 WEXITSTATUS 0
[2022-06-12T15:09:05.860] _job_complete: JobId=43500 done
[2022-06-12T15:09:06.246] sched: Allocate JobId=43501 NodeList=gpu05 #CPUs=16 Partition=gpu-v100s
[2022-06-12T15:09:42.502] _slurm_rpc_submit_batch_job: JobId=43513 InitPrio=31567 usec=554
[2022-06-12T15:09:42.861] sched: Allocate JobId=43513 NodeList=gpu04 #CPUs=8 Partition=gpu-k40c
[2022-06-12T15:09:54.390] _job_complete: JobId=43513 WEXITSTATUS 139
[2022-06-12T15:09:54.390] _job_complete: JobId=43513 done
[2022-06-12T15:11:16.064] _slurm_rpc_submit_batch_job: JobId=43514 InitPrio=31567 usec=541
[2022-06-12T15:11:16.997] sched: Allocate JobId=43514 NodeList=gpu04 #CPUs=8 Partition=gpu-k40c
[2022-06-12T15:11:28.082] _job_complete: JobId=43514 WEXITSTATUS 139
[2022-06-12T15:11:28.083] _job_complete: JobId=43514 done
[2022-06-12T15:11:36.024] Time limit exhausted for JobId=43462
[2022-06-12T15:27:20.864] _slurm_rpc_submit_batch_job: JobId=43515 InitPrio=30756 usec=43473
[2022-06-12T15:27:21.873] sched: Allocate JobId=43515 NodeList=gpu04 #CPUs=8 Partition=gpu-k40c
[2022-06-12T15:27:34.441] _job_complete: JobId=43515 WEXITSTATUS 139
[2022-06-12T15:27:34.441] _job_complete: JobId=43515 done
[2022-06-12T15:43:07.111] _slurm_rpc_submit_batch_job: JobId=43516 InitPrio=30756 usec=517
[2022-06-12T15:43:07.972] sched: Allocate JobId=43516 NodeList=gpu04 #CPUs=8 Partition=gpu-k40c
[2022-06-12T15:43:16.516] _job_complete: JobId=43516 WEXITSTATUS 1
[2022-06-12T15:43:16.517] _job_complete: JobId=43516 done
[2022-06-12T15:44:16.495] _slurm_rpc_submit_batch_job: JobId=43517 InitPrio=30756 usec=611
[2022-06-12T15:44:17.068] sched: Allocate JobId=43517 NodeList=gpu04 #CPUs=8 Partition=gpu-k40c
[2022-06-12T15:44:22.861] _job_complete: JobId=43517 WEXITSTATUS 1
[2022-06-12T15:44:22.861] _job_complete: JobId=43517 done
[2022-06-12T15:46:52.103] _slurm_rpc_submit_batch_job: JobId=43518 InitPrio=20817 usec=484
[2022-06-12T15:46:52.312] sched: Allocate JobId=43518 NodeList=cpu07 #CPUs=64 Partition=cpu-opteron
[2022-06-12T15:47:44.421] _pick_best_nodes: JobId=43519 never runnable in partition gpu-k40c
[2022-06-12T15:47:44.421] _pick_best_nodes: JobId=43519 never runnable in partition gpu-titan
[2022-06-12T15:47:44.421] _pick_best_nodes: JobId=43519 never runnable in partition gpu-v100s
[2022-06-12T15:47:44.421] _slurm_rpc_submit_batch_job: Requested node configuration is not available
[2022-06-12T15:48:10.257] _pick_best_nodes: JobId=43520 never runnable in partition gpu-k40c
[2022-06-12T15:48:10.257] _pick_best_nodes: JobId=43520 never runnable in partition gpu-titan
[2022-06-12T15:48:10.257] _pick_best_nodes: JobId=43520 never runnable in partition gpu-v100s
[2022-06-12T15:48:10.258] _slurm_rpc_submit_batch_job: Requested node configuration is not available
[2022-06-12T15:48:34.882] _slurm_rpc_submit_batch_job: JobId=43521 InitPrio=21091 usec=509
[2022-06-12T15:48:35.660] sched: Allocate JobId=43521 NodeList=cpu05 #CPUs=32 Partition=cpu-opteron
[2022-06-12T15:48:49.659] _slurm_rpc_submit_batch_job: JobId=43522 InitPrio=30486 usec=537
[2022-06-12T15:48:49.681] sched: Allocate JobId=43522 NodeList=gpu04 #CPUs=8 Partition=gpu-k40c
[2022-06-12T15:49:09.718] _job_complete: JobId=43522 WEXITSTATUS 1
[2022-06-12T15:49:09.719] _job_complete: JobId=43522 done
[2022-06-12T15:50:16.030] _slurm_rpc_submit_batch_job: JobId=43523 InitPrio=20817 usec=498
[2022-06-12T15:50:16.806] sched: Allocate JobId=43523 NodeList=cpu09 #CPUs=64 Partition=cpu-opteron
[2022-06-12T15:51:20.955] _slurm_rpc_submit_batch_job: JobId=43524 InitPrio=21091 usec=548
[2022-06-12T15:51:21.899] sched: Allocate JobId=43524 NodeList=cpu01 #CPUs=32 Partition=cpu-opteron
[2022-06-12T15:52:22.062] _get_job_parts: invalid partition specified: gpu-k40c,gpu-titanx
[2022-06-12T15:52:22.062] _slurm_rpc_submit_batch_job: Invalid partition name specified
[2022-06-12T15:52:37.641] _pick_best_nodes: JobId=43525 never runnable in partition gpu-k40c
[2022-06-12T15:52:37.641] _pick_best_nodes: JobId=43525 never runnable in partition gpu-titan
[2022-06-12T15:52:37.641] _slurm_rpc_submit_batch_job: Requested node configuration is not available
[2022-06-12T15:53:15.899] _get_job_parts: invalid partition specified: gpu-k40c,gpu-titan:titanx
[2022-06-12T15:53:15.899] _slurm_rpc_submit_batch_job: Invalid partition name specified
[2022-06-12T15:54:27.464] _pick_best_nodes: JobId=43526 never runnable in partition gpu-k40c
[2022-06-12T15:54:27.464] _pick_best_nodes: JobId=43526 never runnable in partition gpu-titan
[2022-06-12T15:54:27.465] _slurm_rpc_submit_batch_job: Requested node configuration is not available
[2022-06-12T15:54:30.206] _job_complete: JobId=43440 WEXITSTATUS 0
[2022-06-12T15:54:30.211] _job_complete: JobId=43440 done
[2022-06-12T15:54:56.538] _pick_best_nodes: JobId=43527 never runnable in partition gpu-k40c
[2022-06-12T15:54:56.538] _pick_best_nodes: JobId=43527 never runnable in partition gpu-titan
[2022-06-12T15:54:56.538] _slurm_rpc_submit_batch_job: Requested node configuration is not available
[2022-06-12T15:55:17.262] _pick_best_nodes: JobId=43528 never runnable in partition gpu-k40c
[2022-06-12T15:55:17.262] _pick_best_nodes: JobId=43528 never runnable in partition gpu-titan
[2022-06-12T15:55:17.262] _slurm_rpc_submit_batch_job: Requested node configuration is not available
[2022-06-12T15:56:45.629] _slurm_rpc_submit_batch_job: JobId=43529 InitPrio=29945 usec=535
[2022-06-12T15:57:15.882] _slurm_rpc_submit_batch_job: JobId=43530 InitPrio=29945 usec=464
[2022-06-12T15:58:27.270] _slurm_rpc_submit_batch_job: JobId=43531 InitPrio=29979 usec=494
[2022-06-12T15:58:28.061] sched: Allocate JobId=43531 NodeList=gpu04 #CPUs=4 Partition=gpu-k40c
[2022-06-12T15:58:41.823] _job_complete: JobId=43531 WEXITSTATUS 1
[2022-06-12T15:58:41.824] _job_complete: JobId=43531 done
[2022-06-12T15:59:33.116] _slurm_rpc_submit_batch_job: JobId=43532 InitPrio=29911 usec=541
[2022-06-12T15:59:33.152] sched: Allocate JobId=43532 NodeList=gpu04 #CPUs=12 Partition=gpu-k40c
[2022-06-12T15:59:47.503] _job_complete: JobId=43532 WEXITSTATUS 1
[2022-06-12T15:59:47.504] _job_complete: JobId=43532 done
[2022-06-12T16:00:47.020] _slurm_rpc_submit_batch_job: JobId=43533 InitPrio=29911 usec=453
[2022-06-12T16:00:47.258] sched: Allocate JobId=43533 NodeList=gpu04 #CPUs=12 Partition=gpu-k40c
[2022-06-12T16:01:00.827] _job_complete: JobId=43533 WEXITSTATUS 1
[2022-06-12T16:01:00.827] _job_complete: JobId=43533 done
[2022-06-12T16:07:02.901] _slurm_rpc_submit_batch_job: JobId=43534 InitPrio=25282 usec=510
[2022-06-12T16:18:28.948] _slurm_rpc_submit_batch_job: JobId=43535 InitPrio=19469 usec=369
[2022-06-12T16:18:29.382] sched: Allocate JobId=43535 NodeList=cpu14 #CPUs=32 Partition=cpu-epyc
[2022-06-12T16:40:27.875] _slurm_rpc_submit_batch_job: JobId=43536 InitPrio=29911 usec=502
[2022-06-12T16:40:28.848] sched: Allocate JobId=43536 NodeList=gpu04 #CPUs=12 Partition=gpu-k40c
[2022-06-12T16:40:45.780] _job_complete: JobId=43536 WEXITSTATUS 139
[2022-06-12T16:40:45.781] _job_complete: JobId=43536 done
[2022-06-12T16:41:32.709] _slurm_rpc_submit_batch_job: JobId=43537 InitPrio=29911 usec=476
[2022-06-12T16:41:32.937] sched: Allocate JobId=43537 NodeList=gpu04 #CPUs=12 Partition=gpu-k40c
[2022-06-12T16:41:45.677] _job_complete: JobId=43537 WEXITSTATUS 1
[2022-06-12T16:41:45.677] _job_complete: JobId=43537 done
[2022-06-12T16:41:48.632] _job_complete: JobId=43399 WEXITSTATUS 0
[2022-06-12T16:41:48.632] _job_complete: JobId=43399 done
[2022-06-12T16:41:48.858] sched: Allocate JobId=43454 NodeList=cpu13 #CPUs=64 Partition=cpu-epyc
[2022-06-12T17:17:59.147] _slurm_rpc_submit_batch_job: JobId=43538 InitPrio=25368 usec=488
[2022-06-12T17:17:59.197] sched: Allocate JobId=43538 NodeList=gpu02 #CPUs=6 Partition=gpu-titan
[2022-06-12T17:18:21.629] _job_complete: JobId=43538 WEXITSTATUS 1
[2022-06-12T17:18:21.630] _job_complete: JobId=43538 done
[2022-06-12T17:21:24.814] _slurm_rpc_submit_batch_job: JobId=43539 InitPrio=25368 usec=394
[2022-06-12T17:21:25.480] sched: Allocate JobId=43539 NodeList=gpu02 #CPUs=6 Partition=gpu-titan
[2022-06-12T17:26:26.527] _slurm_rpc_kill_job: REQUEST_KILL_JOB JobId=43539 uid 548300557
[2022-06-12T17:26:36.406] _slurm_rpc_submit_batch_job: JobId=43540 InitPrio=25368 usec=410
[2022-06-12T17:26:37.035] sched: Allocate JobId=43540 NodeList=gpu02 #CPUs=6 Partition=gpu-titan
[2022-06-12T17:33:00.345] _slurm_rpc_kill_job: REQUEST_KILL_JOB JobId=43540 uid 548300557
[2022-06-12T17:33:05.080] _slurm_rpc_submit_batch_job: JobId=43541 InitPrio=25368 usec=380
[2022-06-12T17:33:05.843] sched: Allocate JobId=43541 NodeList=gpu02 #CPUs=6 Partition=gpu-titan
[2022-06-12T17:37:06.238] _slurm_rpc_kill_job: REQUEST_KILL_JOB JobId=43541 uid 548300557
[2022-06-12T17:37:16.403] _slurm_rpc_submit_batch_job: JobId=43542 InitPrio=25368 usec=448
[2022-06-12T17:37:17.205] sched: Allocate JobId=43542 NodeList=gpu02 #CPUs=6 Partition=gpu-titan
[2022-06-12T17:37:58.532] _slurm_rpc_submit_batch_job: JobId=43543 InitPrio=29641 usec=466
[2022-06-12T17:37:59.390] sched: Allocate JobId=43543 NodeList=gpu04 #CPUs=12 Partition=gpu-k40c
[2022-06-12T17:38:12.331] _job_complete: JobId=43543 WEXITSTATUS 1
[2022-06-12T17:38:12.332] _job_complete: JobId=43543 done
[2022-06-12T17:41:10.691] _slurm_rpc_kill_job: REQUEST_KILL_JOB JobId=43542 uid 548300557
[2022-06-12T17:41:26.328] _slurm_rpc_submit_batch_job: JobId=43544 InitPrio=25368 usec=389
[2022-06-12T17:41:26.679] sched: Allocate JobId=43544 NodeList=gpu02 #CPUs=6 Partition=gpu-titan
[2022-06-12T17:43:57.374] sched: _slurm_rpc_allocate_resources JobId=43545 NodeList=cpu13 usec=16772
[2022-06-12T17:46:27.187] _job_complete: JobId=43545 WEXITSTATUS 0
[2022-06-12T17:46:27.188] _job_complete: JobId=43545 done
[2022-06-12T17:57:41.591] _slurm_rpc_submit_batch_job: JobId=43546 InitPrio=29370 usec=467
[2022-06-12T17:57:41.618] sched: Allocate JobId=43546 NodeList=gpu04 #CPUs=12 Partition=gpu-k40c
[2022-06-12T17:57:54.599] _job_complete: JobId=43546 WEXITSTATUS 1
[2022-06-12T17:57:54.599] _job_complete: JobId=43546 done
[2022-06-12T18:01:58.490] _slurm_rpc_submit_batch_job: JobId=43547 InitPrio=29370 usec=613
[2022-06-12T18:01:58.996] sched: Allocate JobId=43547 NodeList=gpu04 #CPUs=12 Partition=gpu-k40c
[2022-06-12T18:02:12.950] _job_complete: JobId=43547 WEXITSTATUS 1
[2022-06-12T18:02:12.951] _job_complete: JobId=43547 done
[2022-06-12T18:02:44.084] _job_complete: JobId=43501 WEXITSTATUS 0
[2022-06-12T18:02:44.089] _job_complete: JobId=43501 done
[2022-06-12T18:02:47.012] sched: Allocate JobId=43534 NodeList=gpu05 #CPUs=16 Partition=gpu-v100s
[2022-06-12T18:03:25.138] _slurm_rpc_submit_batch_job: JobId=43548 InitPrio=29370 usec=576
[2022-06-12T18:03:25.216] sched: Allocate JobId=43548 NodeList=gpu04 #CPUs=12 Partition=gpu-k40c
[2022-06-12T18:03:37.958] _job_complete: JobId=43548 WEXITSTATUS 1
[2022-06-12T18:03:37.959] _job_complete: JobId=43548 done
[2022-06-12T18:05:31.775] _slurm_rpc_submit_batch_job: JobId=43549 InitPrio=29370 usec=622
[2022-06-12T18:05:32.397] sched: Allocate JobId=43549 NodeList=gpu04 #CPUs=12 Partition=gpu-k40c
[2022-06-12T18:05:46.637] _job_complete: JobId=43549 WEXITSTATUS 1
[2022-06-12T18:05:46.637] _job_complete: JobId=43549 done
[2022-06-12T20:37:38.686] _slurm_rpc_kill_job: REQUEST_KILL_JOB JobId=43544 uid 548300557
[2022-06-12T20:39:49.206] _job_complete: JobId=43534 WEXITSTATUS 0
[2022-06-12T20:39:49.206] _job_complete: JobId=43534 done
[2022-06-12T20:39:50.088] sched: Allocate JobId=43502 NodeList=gpu05 #CPUs=16 Partition=gpu-v100s
[2022-06-12T20:45:26.446] _slurm_rpc_submit_batch_job: JobId=43550 InitPrio=24742 usec=454
[2022-06-12T22:34:36.320] Time limit exhausted for JobId=43477
[2022-06-12T22:56:28.476] _slurm_rpc_submit_batch_job: JobId=43551 InitPrio=19469 usec=432
[2022-06-12T22:56:28.737] sched: Allocate JobId=43551 NodeList=cpu13 #CPUs=32 Partition=cpu-epyc
[2022-06-12T23:06:34.025] _job_complete: JobId=43338 WEXITSTATUS 0
[2022-06-12T23:06:34.025] _job_complete: JobId=43338 done
[2022-06-12T23:12:24.004] _job_complete: JobId=43502 WEXITSTATUS 0
[2022-06-12T23:12:24.009] _job_complete: JobId=43502 done
[2022-06-12T23:12:26.937] sched: Allocate JobId=43550 NodeList=gpu05 #CPUs=16 Partition=gpu-v100s
[2022-06-12T23:23:08.625] _slurm_rpc_submit_batch_job: JobId=43552 InitPrio=29100 usec=452
[2022-06-12T23:23:08.788] sched: Allocate JobId=43552 NodeList=gpu02 #CPUs=12 Partition=gpu-titan
[2022-06-12T23:23:27.664] _job_complete: JobId=43552 WEXITSTATUS 139
[2022-06-12T23:23:27.664] _job_complete: JobId=43552 done
[2022-06-12T23:24:58.172] _slurm_rpc_submit_batch_job: JobId=43553 InitPrio=29100 usec=492
[2022-06-12T23:24:58.929] sched: Allocate JobId=43553 NodeList=gpu02 #CPUs=12 Partition=gpu-titan
[2022-06-12T23:25:08.814] _job_complete: JobId=43553 WEXITSTATUS 139
[2022-06-12T23:25:08.814] _job_complete: JobId=43553 done
[2022-06-12T23:28:09.646] _slurm_rpc_submit_batch_job: JobId=43554 InitPrio=29100 usec=472
[2022-06-12T23:28:10.290] sched: Allocate JobId=43554 NodeList=gpu02 #CPUs=12 Partition=gpu-titan
[2022-06-12T23:28:20.144] _job_complete: JobId=43554 WEXITSTATUS 139
[2022-06-12T23:28:20.144] _job_complete: JobId=43554 done
[2022-06-12T23:35:17.915] _slurm_rpc_submit_batch_job: JobId=43555 InitPrio=24827 usec=496
[2022-06-12T23:35:18.035] sched: Allocate JobId=43555 NodeList=gpu02 #CPUs=6 Partition=gpu-titan
[2022-06-12T23:35:40.037] _job_complete: JobId=43555 WEXITSTATUS 1
[2022-06-12T23:35:40.037] _job_complete: JobId=43555 done
[2022-06-12T23:37:02.120] _slurm_rpc_submit_batch_job: JobId=43556 InitPrio=24827 usec=356
[2022-06-12T23:37:02.183] sched: Allocate JobId=43556 NodeList=gpu02 #CPUs=6 Partition=gpu-titan
[2022-06-12T23:49:47.938] _slurm_rpc_submit_batch_job: JobId=43557 InitPrio=24742 usec=443
[2022-06-12T23:50:34.077] _slurm_rpc_kill_job: REQUEST_KILL_JOB JobId=43550 uid 548300557
[2022-06-12T23:50:35.931] sched: Allocate JobId=43557 NodeList=gpu05 #CPUs=16 Partition=gpu-v100s
[2022-06-12T23:54:43.647] _slurm_rpc_submit_batch_job: JobId=43558 InitPrio=24742 usec=350
[2022-06-12T23:55:05.651] _slurm_rpc_kill_job: REQUEST_KILL_JOB JobId=43557 uid 548300557
[2022-06-12T23:55:07.628] sched: Allocate JobId=43558 NodeList=gpu05 #CPUs=16 Partition=gpu-v100s
[2022-06-13T01:22:54.399] _job_complete: JobId=43398 WEXITSTATUS 1
[2022-06-13T01:22:54.399] _job_complete: JobId=43398 done
[2022-06-13T01:54:26.013] _job_complete: JobId=43396 WEXITSTATUS 0
[2022-06-13T01:54:26.018] _job_complete: JobId=43396 done
[2022-06-13T01:54:27.944] sched: Allocate JobId=43491 NodeList=gpu03 #CPUs=16 Partition=gpu-k10
[2022-06-13T02:07:59.448] _job_complete: JobId=43558 WEXITSTATUS 0
[2022-06-13T02:07:59.453] _job_complete: JobId=43558 done
[2022-06-13T02:08:00.344] sched: Allocate JobId=43504 NodeList=gpu05 #CPUs=16 Partition=gpu-v100s
[2022-06-13T03:52:21.298] _job_complete: JobId=43504 WEXITSTATUS 0
[2022-06-13T03:52:21.304] _job_complete: JobId=43504 done
[2022-06-13T04:27:45.154] _job_complete: JobId=43491 WEXITSTATUS 1
[2022-06-13T04:27:45.160] _job_complete: JobId=43491 done
[2022-06-13T04:32:23.942] _job_complete: JobId=43345 WEXITSTATUS 0
[2022-06-13T04:32:23.942] _job_complete: JobId=43345 done
[2022-06-13T04:45:50.482] _job_complete: JobId=43556 WEXITSTATUS 0
[2022-06-13T04:45:50.487] _job_complete: JobId=43556 done
[2022-06-13T07:31:56.858] _job_complete: JobId=43444 WEXITSTATUS 0
[2022-06-13T07:31:56.864] _job_complete: JobId=43444 done
[2022-06-13T08:28:06.233] _slurm_rpc_submit_batch_job: JobId=43559 InitPrio=19332 usec=429
[2022-06-13T08:28:06.835] sched: Allocate JobId=43559 NodeList=cpu15 #CPUs=48 Partition=cpu-epyc
[2022-06-13T08:58:33.890] _slurm_rpc_submit_batch_job: JobId=43560 InitPrio=23592 usec=370
[2022-06-13T08:58:34.319] sched: Allocate JobId=43560 NodeList=cpu15 #CPUs=24 Partition=cpu-epyc
[2022-06-13T09:15:09.659] _slurm_rpc_submit_batch_job: JobId=43561 InitPrio=24471 usec=380
[2022-06-13T09:15:10.247] sched: Allocate JobId=43561 NodeList=gpu05 #CPUs=16 Partition=gpu-v100s
[2022-06-13T09:17:54.484] _slurm_rpc_submit_batch_job: JobId=43562 InitPrio=24471 usec=355
[2022-06-13T09:18:08.890] _slurm_rpc_kill_job: REQUEST_KILL_JOB JobId=43561 uid 548300557
[2022-06-13T09:18:10.758] sched: Allocate JobId=43562 NodeList=gpu05 #CPUs=16 Partition=gpu-v100s
[2022-06-13T09:19:21.882] _slurm_rpc_submit_batch_job: JobId=43563 InitPrio=68388 usec=486
[2022-06-13T09:19:22.756] sched: Allocate JobId=43563 NodeList=cpu04 #CPUs=32 Partition=cpu-opteron
[2022-06-13T09:23:25.001] _slurm_rpc_kill_job: REQUEST_KILL_JOB JobId=43563 uid 548200005
[2022-06-13T09:23:56.050] _slurm_rpc_kill_job: REQUEST_KILL_JOB JobId=43560 uid 548200003
[2022-06-13T09:38:13.489] _slurm_rpc_submit_batch_job: JobId=43564 InitPrio=25351 usec=513
[2022-06-13T09:38:13.795] sched: Allocate JobId=43564 NodeList=gpu02 #CPUs=8 Partition=gpu-titan
[2022-06-13T09:45:24.925] _slurm_rpc_submit_batch_job: JobId=43565 InitPrio=20688 usec=447
[2022-06-13T09:45:25.512] sched: Allocate JobId=43565 NodeList=cpu03 #CPUs=16 Partition=cpu-opteron
[2022-06-13T09:45:55.055] _slurm_rpc_submit_batch_job: JobId=43566 InitPrio=20756 usec=474
[2022-06-13T09:45:55.539] sched: Allocate JobId=43566 NodeList=cpu03 #CPUs=8 Partition=cpu-opteron
[2022-06-13T09:46:31.374] _job_complete: JobId=43566 WEXITSTATUS 0
[2022-06-13T09:46:31.374] _job_complete: JobId=43566 done
[2022-06-13T09:47:31.251] _slurm_rpc_submit_batch_job: JobId=43567 InitPrio=20688 usec=512
[2022-06-13T09:47:31.832] sched: Allocate JobId=43567 NodeList=cpu03 #CPUs=16 Partition=cpu-opteron
[2022-06-13T09:48:36.290] _job_complete: JobId=43565 WEXITSTATUS 0
[2022-06-13T09:48:36.290] _job_complete: JobId=43565 done
[2022-06-13T09:53:08.728] _slurm_rpc_submit_batch_job: JobId=43568 InitPrio=20414 usec=386
[2022-06-13T09:53:09.434] sched: Allocate JobId=43568 NodeList=cpu15 #CPUs=48 Partition=cpu-epyc
[2022-06-13T09:53:31.679] _job_complete: JobId=43568 WEXITSTATUS 1
[2022-06-13T09:53:31.679] _job_complete: JobId=43568 done
[2022-06-13T09:54:20.224] _slurm_rpc_submit_batch_job: JobId=43569 InitPrio=20414 usec=474
[2022-06-13T09:54:22.545] sched: Allocate JobId=43569 NodeList=cpu15 #CPUs=48 Partition=cpu-epyc
[2022-06-13T09:55:34.100] _slurm_rpc_submit_batch_job: JobId=43570 InitPrio=20688 usec=444
[2022-06-13T09:55:34.654] sched: Allocate JobId=43570 NodeList=cpu03 #CPUs=16 Partition=cpu-opteron
[2022-06-13T09:56:32.681] _slurm_rpc_submit_batch_job: JobId=43571 InitPrio=20688 usec=553
[2022-06-13T09:56:32.739] sched: Allocate JobId=43571 NodeList=cpu04 #CPUs=16 Partition=cpu-opteron
[2022-06-13T09:57:15.898] _slurm_rpc_submit_batch_job: JobId=43572 InitPrio=20756 usec=398
[2022-06-13T09:57:16.803] sched: Allocate JobId=43572 NodeList=cpu04 #CPUs=8 Partition=cpu-opteron
[2022-06-13T09:57:43.504] _job_complete: JobId=43572 WEXITSTATUS 0
[2022-06-13T09:57:43.504] _job_complete: JobId=43572 done
[2022-06-13T09:58:56.912] _job_complete: JobId=43570 WEXITSTATUS 0
[2022-06-13T09:58:56.912] _job_complete: JobId=43570 done
[2022-06-13T09:59:26.684] _job_complete: JobId=43571 WEXITSTATUS 0
[2022-06-13T09:59:26.684] _job_complete: JobId=43571 done
[2022-06-13T10:04:44.870] _slurm_rpc_submit_batch_job: JobId=43573 InitPrio=20688 usec=431
[2022-06-13T10:04:45.860] sched: Allocate JobId=43573 NodeList=cpu03 #CPUs=16 Partition=cpu-opteron
[2022-06-13T10:05:12.172] _slurm_rpc_submit_batch_job: JobId=43574 InitPrio=20414 usec=422
[2022-06-13T10:09:46.118] _job_complete: JobId=43569 WEXITSTATUS 0
[2022-06-13T10:09:46.118] _job_complete: JobId=43569 done
[2022-06-13T10:09:46.987] sched: Allocate JobId=43574 NodeList=cpu15 #CPUs=48 Partition=cpu-epyc
[2022-06-13T10:21:51.496] _slurm_rpc_submit_batch_job: JobId=43575 InitPrio=20688 usec=478
[2022-06-13T10:21:51.818] sched: Allocate JobId=43575 NodeList=cpu04 #CPUs=16 Partition=cpu-opteron
[2022-06-13T10:22:17.892] _slurm_rpc_submit_batch_job: JobId=43576 InitPrio=20756 usec=456
[2022-06-13T10:22:18.854] sched: Allocate JobId=43576 NodeList=cpu04 #CPUs=8 Partition=cpu-opteron
[2022-06-13T10:22:44.407] _job_complete: JobId=43576 WEXITSTATUS 0
[2022-06-13T10:22:44.407] _job_complete: JobId=43576 done
[2022-06-13T10:23:24.630] _slurm_rpc_submit_batch_job: JobId=43577 InitPrio=20414 usec=390
[2022-06-13T10:32:56.989] _job_complete: JobId=43574 WEXITSTATUS 0
[2022-06-13T10:32:56.989] _job_complete: JobId=43574 done
[2022-06-13T10:32:57.872] sched: Allocate JobId=43577 NodeList=cpu15 #CPUs=48 Partition=cpu-epyc
[2022-06-13T10:33:13.345] _job_complete: JobId=43577 WEXITSTATUS 1
[2022-06-13T10:33:13.345] _job_complete: JobId=43577 done
[2022-06-13T10:34:51.600] _slurm_rpc_submit_batch_job: JobId=43578 InitPrio=29100 usec=585
[2022-06-13T10:34:52.266] sched: Allocate JobId=43578 NodeList=gpu04 #CPUs=12 Partition=gpu-k40c
[2022-06-13T10:35:13.307] _job_complete: JobId=43578 WEXITSTATUS 139
[2022-06-13T10:35:13.308] _job_complete: JobId=43578 done
[2022-06-13T10:43:15.757] _job_complete: JobId=43567 WEXITSTATUS 0
[2022-06-13T10:43:15.757] _job_complete: JobId=43567 done
[2022-06-13T10:51:19.610] _slurm_rpc_submit_batch_job: JobId=43579 InitPrio=29100 usec=648
[2022-06-13T10:51:22.039] sched: Allocate JobId=43579 NodeList=gpu04 #CPUs=12 Partition=gpu-k40c
[2022-06-13T10:51:33.833] _job_complete: JobId=43579 WEXITSTATUS 1
[2022-06-13T10:51:33.834] _job_complete: JobId=43579 done
[2022-06-13T10:51:56.407] _slurm_rpc_submit_batch_job: JobId=43580 InitPrio=29100 usec=524
[2022-06-13T10:51:57.086] sched: Allocate JobId=43580 NodeList=gpu04 #CPUs=12 Partition=gpu-k40c
[2022-06-13T10:52:01.063] _job_complete: JobId=43580 WEXITSTATUS 1
[2022-06-13T10:52:01.064] _job_complete: JobId=43580 done
[2022-06-13T10:53:13.625] _slurm_rpc_submit_batch_job: JobId=43581 InitPrio=29100 usec=610
[2022-06-13T10:53:14.323] sched: Allocate JobId=43581 NodeList=gpu03 #CPUs=12 Partition=gpu-k10
[2022-06-13T10:53:28.022] _job_complete: JobId=43581 WEXITSTATUS 1
[2022-06-13T10:53:28.023] _job_complete: JobId=43581 done
[2022-06-13T10:54:50.865] _slurm_rpc_submit_batch_job: JobId=43582 InitPrio=29100 usec=489
[2022-06-13T10:55:48.417] _slurm_rpc_submit_batch_job: JobId=43583 InitPrio=29100 usec=447
[2022-06-13T10:59:44.137] _job_complete: JobId=43573 WEXITSTATUS 0
[2022-06-13T10:59:44.137] _job_complete: JobId=43573 done
[2022-06-13T11:09:20.640] _job_complete: JobId=43575 WEXITSTATUS 0
[2022-06-13T11:09:20.640] _job_complete: JobId=43575 done
[2022-06-13T11:36:13.014] _slurm_rpc_submit_batch_job: JobId=43584 InitPrio=25681 usec=438
[2022-06-13T11:36:13.961] sched: Allocate JobId=43584 NodeList=cpu03 #CPUs=1 Partition=cpu-opteron
[2022-06-13T11:36:20.792] _job_complete: JobId=43584 WEXITSTATUS 1
[2022-06-13T11:36:20.792] _job_complete: JobId=43584 done
[2022-06-13T11:46:21.165] _slurm_rpc_submit_batch_job: JobId=43587 InitPrio=22241 usec=466
[2022-06-13T11:46:22.049] sched: Allocate JobId=43587 NodeList=cpu15 #CPUs=24 Partition=cpu-epyc
[2022-06-13T11:48:28.893] _slurm_rpc_submit_batch_job: JobId=43588 InitPrio=22172 usec=470
[2022-06-13T11:48:29.350] sched: Allocate JobId=43588 NodeList=cpu08 #CPUs=32 Partition=cpu-opteron
[2022-06-13T11:49:31.916] _slurm_rpc_kill_job: REQUEST_KILL_JOB JobId=43588 uid 548300570
[2022-06-13T11:50:39.818] _slurm_rpc_submit_batch_job: JobId=43589 InitPrio=22172 usec=679
[2022-06-13T11:50:40.534] sched: Allocate JobId=43589 NodeList=cpu04 #CPUs=32 Partition=cpu-opteron
[2022-06-13T11:52:55.331] _slurm_rpc_submit_batch_job: JobId=43590 InitPrio=22172 usec=405
[2022-06-13T11:52:55.860] sched: Allocate JobId=43590 NodeList=cpu08 #CPUs=32 Partition=cpu-opteron
[2022-06-13T11:59:10.717] _slurm_rpc_submit_batch_job: JobId=43591 InitPrio=22035 usec=409
[2022-06-13T12:03:04.383] _slurm_rpc_submit_batch_job: JobId=43592 InitPrio=22241 usec=436
[2022-06-13T12:07:07.832] _slurm_rpc_submit_batch_job: JobId=43593 InitPrio=24201 usec=376
[2022-06-13T12:36:18.851] _job_complete: JobId=43562 WEXITSTATUS 0
[2022-06-13T12:36:18.856] _job_complete: JobId=43562 done
[2022-06-13T12:36:19.743] sched: Allocate JobId=43593 NodeList=gpu05 #CPUs=16 Partition=gpu-v100s
[2022-06-13T12:54:21.816] _slurm_rpc_submit_batch_job: JobId=43594 InitPrio=25621 usec=352
[2022-06-13T12:54:22.030] sched: Allocate JobId=43594 NodeList=cpu08 #CPUs=8 Partition=cpu-opteron
[2022-06-13T12:55:02.431] _slurm_rpc_submit_batch_job: JobId=43595 InitPrio=25621 usec=359
[2022-06-13T12:55:03.081] sched: Allocate JobId=43595 NodeList=cpu08 #CPUs=8 Partition=cpu-opteron
[2022-06-13T12:56:46.095] _slurm_rpc_submit_batch_job: JobId=43596 InitPrio=25621 usec=354
[2022-06-13T12:56:46.225] sched: Allocate JobId=43596 NodeList=cpu08 #CPUs=8 Partition=cpu-opteron
[2022-06-13T12:57:26.073] _slurm_rpc_submit_batch_job: JobId=43597 InitPrio=20551 usec=489
[2022-06-13T12:57:26.342] sched: Allocate JobId=43597 NodeList=cpu03 #CPUs=32 Partition=cpu-opteron
[2022-06-13T13:01:28.116] _slurm_rpc_submit_batch_job: JobId=43598 InitPrio=21498 usec=880
[2022-06-13T13:01:28.718] sched: Allocate JobId=43598 NodeList=gpu03 #CPUs=16 Partition=gpu-k10
[2022-06-13T13:05:26.422] _slurm_rpc_submit_batch_job: JobId=43599 InitPrio=25621 usec=364
[2022-06-13T13:09:15.294] _slurm_rpc_submit_batch_job: JobId=43600 InitPrio=25621 usec=577
[2022-06-13T13:10:37.972] _slurm_rpc_submit_batch_job: JobId=43601 InitPrio=25621 usec=423
[2022-06-13T13:11:29.609] _slurm_rpc_kill_job: REQUEST_KILL_JOB JobId=43599 uid 548300543
[2022-06-13T13:11:37.067] _slurm_rpc_kill_job: REQUEST_KILL_JOB JobId=43601 uid 548300543
[2022-06-13T13:11:39.650] _slurm_rpc_kill_job: REQUEST_KILL_JOB JobId=43600 uid 548300543
[2022-06-13T13:11:44.617] _slurm_rpc_kill_job: REQUEST_KILL_JOB JobId=43596 uid 548300543
[2022-06-13T13:11:50.714] _slurm_rpc_kill_job: REQUEST_KILL_JOB JobId=43595 uid 548300543
[2022-06-13T13:11:52.890] _slurm_rpc_kill_job: REQUEST_KILL_JOB JobId=43594 uid 548300543
[2022-06-13T13:15:52.701] _job_complete: JobId=43597 OOM failure
[2022-06-13T13:15:52.702] _job_complete: JobId=43597 done
[2022-06-13T13:25:05.322] _slurm_rpc_submit_batch_job: JobId=43602 InitPrio=25621 usec=326
[2022-06-13T13:25:05.338] sched: Allocate JobId=43602 NodeList=cpu08 #CPUs=8 Partition=cpu-opteron
[2022-06-13T13:29:32.243] _slurm_rpc_kill_job: REQUEST_KILL_JOB JobId=43602 uid 548300543
[2022-06-13T13:29:50.603] _slurm_rpc_submit_batch_job: JobId=43603 InitPrio=25621 usec=357
[2022-06-13T13:29:50.887] sched: Allocate JobId=43603 NodeList=cpu08 #CPUs=8 Partition=cpu-opteron
[2022-06-13T13:30:05.749] _slurm_rpc_kill_job: REQUEST_KILL_JOB JobId=43603 uid 548300543
[2022-06-13T13:31:15.013] _slurm_rpc_submit_batch_job: JobId=43604 InitPrio=25621 usec=364
[2022-06-13T13:31:16.001] sched: Allocate JobId=43604 NodeList=cpu08 #CPUs=8 Partition=cpu-opteron
[2022-06-13T13:31:36.381] _slurm_rpc_kill_job: REQUEST_KILL_JOB JobId=43604 uid 548300543
[2022-06-13T13:59:58.083] _slurm_rpc_submit_batch_job: JobId=43605 InitPrio=25621 usec=421
[2022-06-13T13:59:58.257] sched: Allocate JobId=43605 NodeList=cpu08 #CPUs=8 Partition=cpu-opteron
[2022-06-13T14:00:39.748] _slurm_rpc_kill_job: REQUEST_KILL_JOB JobId=43605 uid 548300543
[2022-06-13T14:01:35.017] _slurm_rpc_submit_batch_job: JobId=43606 InitPrio=25621 usec=345
[2022-06-13T14:01:35.387] sched: Allocate JobId=43606 NodeList=cpu08 #CPUs=8 Partition=cpu-opteron
[2022-06-13T14:01:44.669] _slurm_rpc_kill_job: REQUEST_KILL_JOB JobId=43606 uid 548300543
[2022-06-13T14:01:49.650] _slurm_rpc_submit_batch_job: JobId=43607 InitPrio=25621 usec=346
[2022-06-13T14:02:06.405] _slurm_rpc_kill_job: REQUEST_KILL_JOB JobId=43607 uid 548300543
[2022-06-13T14:02:36.811] _slurm_rpc_submit_batch_job: JobId=43608 InitPrio=25621 usec=341
[2022-06-13T14:02:37.548] sched/backfill: _start_job: Started JobId=43608 in gpu-titan on gpu02
[2022-06-13T14:02:45.020] _job_complete: JobId=43608 WEXITSTATUS 1
[2022-06-13T14:02:45.020] _job_complete: JobId=43608 done
[2022-06-13T14:05:18.427] _slurm_rpc_submit_batch_job: JobId=43609 InitPrio=24471 usec=370
[2022-06-13T14:05:19.021] sched: Allocate JobId=43609 NodeList=cpu03 #CPUs=16 Partition=cpu-opteron
[2022-06-13T14:05:22.023] _slurm_rpc_submit_batch_job: JobId=43610 InitPrio=24471 usec=396
[2022-06-13T14:05:23.007] sched: Allocate JobId=43610 NodeList=cpu03 #CPUs=16 Partition=cpu-opteron
[2022-06-13T14:05:24.685] _slurm_rpc_submit_batch_job: JobId=43611 InitPrio=24471 usec=389
[2022-06-13T14:05:26.011] sched: Allocate JobId=43611 NodeList=cpu08 #CPUs=16 Partition=cpu-opteron
[2022-06-13T14:05:27.319] _slurm_rpc_submit_batch_job: JobId=43612 InitPrio=24471 usec=411
[2022-06-13T14:05:29.015] sched: Allocate JobId=43612 NodeList=cpu08 #CPUs=16 Partition=cpu-opteron
[2022-06-13T14:07:24.494] _job_complete: JobId=43612 WEXITSTATUS 0
[2022-06-13T14:07:24.495] _job_complete: JobId=43612 done
[2022-06-13T14:07:28.712] _job_complete: JobId=43609 WEXITSTATUS 0
[2022-06-13T14:07:28.713] _job_complete: JobId=43609 done
[2022-06-13T14:08:19.521] _job_complete: JobId=43610 WEXITSTATUS 0
[2022-06-13T14:08:19.522] _job_complete: JobId=43610 done
[2022-06-13T14:08:26.920] _job_complete: JobId=43611 WEXITSTATUS 0
[2022-06-13T14:08:26.920] _job_complete: JobId=43611 done
[2022-06-13T14:10:01.217] _job_complete: JobId=43441 WEXITSTATUS 0
[2022-06-13T14:10:01.222] _job_complete: JobId=43441 done
[2022-06-13T14:20:01.773] _slurm_rpc_submit_batch_job: JobId=43613 InitPrio=25621 usec=453
[2022-06-13T14:20:02.575] sched: Allocate JobId=43613 NodeList=cpu08 #CPUs=8 Partition=cpu-opteron
[2022-06-13T14:20:18.097] _slurm_rpc_kill_job: REQUEST_KILL_JOB JobId=43613 uid 548300543
[2022-06-13T14:21:09.652] _slurm_rpc_submit_batch_job: JobId=43614 InitPrio=25621 usec=357
[2022-06-13T14:21:09.665] sched: Allocate JobId=43614 NodeList=cpu08 #CPUs=8 Partition=cpu-opteron
[2022-06-13T14:21:37.066] _slurm_rpc_kill_job: REQUEST_KILL_JOB JobId=43614 uid 548300543
[2022-06-13T14:23:38.441] _slurm_rpc_submit_batch_job: JobId=43615 InitPrio=25621 usec=326
[2022-06-13T14:23:38.982] sched: Allocate JobId=43615 NodeList=cpu08 #CPUs=8 Partition=cpu-opteron
[2022-06-13T14:27:10.704] _slurm_rpc_submit_batch_job: JobId=43616 InitPrio=25621 usec=295
[2022-06-13T14:27:11.284] sched: Allocate JobId=43616 NodeList=cpu08 #CPUs=8 Partition=cpu-opteron
[2022-06-13T14:27:28.600] _slurm_rpc_kill_job: REQUEST_KILL_JOB JobId=43616 uid 548300543
[2022-06-13T14:27:31.056] _slurm_rpc_kill_job: REQUEST_KILL_JOB JobId=43615 uid 548300543
[2022-06-13T14:33:57.001] _slurm_rpc_submit_batch_job: JobId=43617 InitPrio=20551 usec=482
[2022-06-13T14:33:57.045] sched: Allocate JobId=43617 NodeList=cpu12 #CPUs=32 Partition=cpu-epyc
[2022-06-13T14:34:07.015] _slurm_rpc_submit_batch_job: JobId=43618 InitPrio=21361 usec=334
[2022-06-13T14:34:07.060] sched: Allocate JobId=43618 NodeList=cpu03 #CPUs=32 Partition=cpu-opteron
[2022-06-13T14:34:29.632] _job_complete: JobId=43618 WEXITSTATUS 0
[2022-06-13T14:34:29.632] _job_complete: JobId=43618 done
[2022-06-13T14:34:43.898] _slurm_rpc_submit_batch_job: JobId=43619 InitPrio=21361 usec=448
[2022-06-13T14:34:44.092] sched: Allocate JobId=43619 NodeList=cpu03 #CPUs=32 Partition=cpu-opteron
[2022-06-13T14:35:20.873] _job_complete: JobId=43619 WEXITSTATUS 0
[2022-06-13T14:35:20.873] _job_complete: JobId=43619 done
[2022-06-13T14:37:27.604] _slurm_rpc_submit_batch_job: JobId=43620 InitPrio=21361 usec=387
[2022-06-13T14:37:28.443] sched: Allocate JobId=43620 NodeList=cpu03 #CPUs=32 Partition=cpu-opteron
[2022-06-13T14:37:54.098] _job_complete: JobId=43620 WEXITSTATUS 0
[2022-06-13T14:37:54.099] _job_complete: JobId=43620 done
[2022-06-13T14:39:15.765] _slurm_rpc_submit_batch_job: JobId=43621 InitPrio=25621 usec=350
[2022-06-13T14:39:16.598] sched: Allocate JobId=43621 NodeList=cpu08 #CPUs=8 Partition=cpu-opteron
[2022-06-13T14:39:53.460] _slurm_rpc_kill_job: REQUEST_KILL_JOB JobId=43621 uid 548300543
[2022-06-13T14:40:17.234] _slurm_rpc_submit_batch_job: JobId=43622 InitPrio=25621 usec=296
[2022-06-13T14:40:17.676] sched: Allocate JobId=43622 NodeList=cpu08 #CPUs=8 Partition=cpu-opteron
[2022-06-13T14:40:33.052] _slurm_rpc_kill_job: REQUEST_KILL_JOB JobId=43622 uid 548300543
[2022-06-13T14:42:26.236] _slurm_rpc_submit_batch_job: JobId=43623 InitPrio=25621 usec=362
[2022-06-13T14:42:43.847] _slurm_rpc_kill_job: REQUEST_KILL_JOB JobId=43623 uid 548300543
[2022-06-13T14:46:15.432] _slurm_rpc_submit_batch_job: JobId=43624 InitPrio=20551 usec=419
[2022-06-13T14:46:16.261] sched: Allocate JobId=43624 NodeList=cpu08 #CPUs=32 Partition=cpu-opteron
[2022-06-13T14:57:44.129] _slurm_rpc_submit_batch_job: JobId=43625 InitPrio=25621 usec=460
[2022-06-13T14:58:37.782] _slurm_rpc_kill_job: REQUEST_KILL_JOB JobId=43625 uid 548300543
[2022-06-13T14:58:52.165] _slurm_rpc_submit_batch_job: JobId=43626 InitPrio=25484 usec=277
[2022-06-13T14:59:23.229] _slurm_rpc_submit_batch_job: JobId=43627 InitPrio=68654 usec=332
[2022-06-13T14:59:26.327] _slurm_rpc_kill_job: REQUEST_KILL_JOB JobId=43627 uid 548200005
[2022-06-13T14:59:35.262] _slurm_rpc_submit_batch_job: JobId=43628 InitPrio=25484 usec=298
[2022-06-13T14:59:49.832] _slurm_rpc_kill_job: REQUEST_KILL_JOB JobId=43626 uid 548300543
[2022-06-13T14:59:52.160] _slurm_rpc_kill_job: REQUEST_KILL_JOB JobId=43628 uid 548300543
[2022-06-13T15:00:39.758] _slurm_rpc_submit_batch_job: JobId=43629 InitPrio=25484 usec=341
[2022-06-13T15:04:08.231] _slurm_rpc_submit_batch_job: JobId=43630 InitPrio=25681 usec=283
[2022-06-13T15:04:09.185] sched: Allocate JobId=43630 NodeList=cpu03 #CPUs=1 Partition=cpu-opteron
[2022-06-13T15:04:18.476] _slurm_rpc_kill_job: REQUEST_KILL_JOB JobId=43630 uid 548300543
[2022-06-13T15:04:43.805] _slurm_rpc_kill_job: REQUEST_KILL_JOB JobId=43629 uid 548300543
[2022-06-13T15:05:27.563] _slurm_rpc_submit_batch_job: JobId=43631 InitPrio=24471 usec=452
[2022-06-13T15:05:30.809] _slurm_rpc_submit_batch_job: JobId=43632 InitPrio=24471 usec=375
[2022-06-13T15:05:33.889] _slurm_rpc_submit_batch_job: JobId=43633 InitPrio=24471 usec=370
[2022-06-13T15:05:36.946] _slurm_rpc_submit_batch_job: JobId=43634 InitPrio=24471 usec=328
[2022-06-13T15:11:42.312] _slurm_rpc_submit_batch_job: JobId=43635 InitPrio=20079 usec=428
[2022-06-13T15:11:42.927] sched: Allocate JobId=43635 NodeList=gpu02 #CPUs=24 Partition=gpu-titan
[2022-06-13T15:12:33.673] _slurm_rpc_submit_batch_job: JobId=43636 InitPrio=25681 usec=323
[2022-06-13T15:12:36.350] _slurm_rpc_kill_job: REQUEST_KILL_JOB JobId=43636 uid 548300543
[2022-06-13T15:13:04.436] _job_complete: JobId=43635 WEXITSTATUS 0
[2022-06-13T15:13:04.436] _job_complete: JobId=43635 done
[2022-06-13T15:18:50.064] _slurm_rpc_submit_batch_job: JobId=43637 InitPrio=23661 usec=508
[2022-06-13T15:20:20.842] _job_complete: JobId=43395 WEXITSTATUS 0
[2022-06-13T15:20:20.843] _job_complete: JobId=43395 done
[2022-06-13T15:26:08.276] _slurm_rpc_submit_batch_job: JobId=43638 InitPrio=25681 usec=369
[2022-06-13T15:26:08.477] sched: Allocate JobId=43638 NodeList=gpu01 #CPUs=1 Partition=gpu-k10
[2022-06-13T15:26:17.489] _slurm_rpc_kill_job: REQUEST_KILL_JOB JobId=43638 uid 548300543
[2022-06-13T15:31:58.115] _slurm_rpc_submit_batch_job: JobId=43639 InitPrio=20079 usec=430
[2022-06-13T15:31:59.087] sched: Allocate JobId=43639 NodeList=gpu02 #CPUs=24 Partition=gpu-titan
[2022-06-13T15:32:03.382] _job_complete: JobId=43639 WEXITSTATUS 1
[2022-06-13T15:32:03.382] _job_complete: JobId=43639 done
[2022-06-13T15:34:29.660] _slurm_rpc_submit_batch_job: JobId=43640 InitPrio=20079 usec=448
[2022-06-13T15:34:30.390] sched: Allocate JobId=43640 NodeList=gpu02 #CPUs=24 Partition=gpu-titan
[2022-06-13T15:34:31.440] _job_complete: JobId=43640 WEXITSTATUS 1
[2022-06-13T15:34:31.440] _job_complete: JobId=43640 done
[2022-06-13T15:35:29.365] _slurm_rpc_submit_batch_job: JobId=43641 InitPrio=20079 usec=484
[2022-06-13T15:35:29.472] sched: Allocate JobId=43641 NodeList=gpu02 #CPUs=24 Partition=gpu-titan
[2022-06-13T15:35:30.167] _job_complete: JobId=43641 WEXITSTATUS 1
[2022-06-13T15:35:30.167] _job_complete: JobId=43641 done
[2022-06-13T15:36:23.419] _slurm_rpc_submit_batch_job: JobId=43642 InitPrio=20079 usec=423
[2022-06-13T15:36:23.543] sched: Allocate JobId=43642 NodeList=gpu02 #CPUs=24 Partition=gpu-titan
[2022-06-13T15:39:49.095] _slurm_rpc_submit_batch_job: JobId=43643 InitPrio=25681 usec=360
[2022-06-13T15:39:49.955] sched: Allocate JobId=43643 NodeList=gpu01 #CPUs=1 Partition=gpu-k10
[2022-06-13T15:41:59.456] _job_complete: JobId=43643 OOM failure
[2022-06-13T15:41:59.456] _job_complete: JobId=43643 done
[2022-06-13T15:42:04.616] _slurm_rpc_kill_job: REQUEST_KILL_JOB JobId=43643 uid 548300543
[2022-06-13T15:42:34.625] _slurm_rpc_submit_batch_job: JobId=43644 InitPrio=25552 usec=372
[2022-06-13T15:42:35.297] sched: Allocate JobId=43644 NodeList=gpu01 #CPUs=16 Partition=gpu-k10
[2022-06-13T15:45:43.525] _slurm_rpc_kill_job: REQUEST_KILL_JOB JobId=43644 uid 548300543
[2022-06-13T15:45:56.956] _slurm_rpc_submit_batch_job: JobId=43645 InitPrio=25552 usec=430
[2022-06-13T15:46:11.364] _slurm_rpc_kill_job: REQUEST_KILL_JOB JobId=43645 uid 548300543
[2022-06-13T15:46:15.864] _slurm_rpc_submit_batch_job: JobId=43646 InitPrio=25552 usec=319
[2022-06-13T15:46:16.602] sched: Allocate JobId=43646 NodeList=cpu03 #CPUs=16 Partition=cpu-opteron
[2022-06-13T15:46:52.668] _slurm_rpc_kill_job: REQUEST_KILL_JOB JobId=43646 uid 548300543
[2022-06-13T15:47:06.164] _slurm_rpc_submit_batch_job: JobId=43647 InitPrio=25552 usec=390
[2022-06-13T15:47:06.671] sched: Allocate JobId=43647 NodeList=gpu01 #CPUs=16 Partition=gpu-k10
[2022-06-13T15:47:09.674] Time limit exhausted for JobId=43518
[2022-06-13T15:47:35.131] _slurm_rpc_kill_job: REQUEST_KILL_JOB JobId=43647 uid 548300543
[2022-06-13T15:48:39.887] Time limit exhausted for JobId=43521
[2022-06-13T15:50:39.052] Time limit exhausted for JobId=43523
[2022-06-13T15:51:05.901] _slurm_rpc_submit_batch_job: JobId=43648 InitPrio=25552 usec=348
[2022-06-13T15:51:06.094] sched: Allocate JobId=43648 NodeList=gpu01 #CPUs=16 Partition=gpu-k10
[2022-06-13T15:51:38.984] _slurm_rpc_kill_job: REQUEST_KILL_JOB JobId=43648 uid 548300543
[2022-06-13T15:51:39.135] Time limit exhausted for JobId=43524
[2022-06-13T15:52:44.946] _slurm_rpc_submit_batch_job: JobId=43649 InitPrio=25681 usec=505
[2022-06-13T15:52:45.323] sched: Allocate JobId=43649 NodeList=cpu01 #CPUs=1 Partition=cpu-opteron
[2022-06-13T15:53:23.125] _slurm_rpc_kill_job: REQUEST_KILL_JOB JobId=43649 uid 548300543
[2022-06-13T15:53:39.708] _pick_best_nodes: JobId=43650 never runnable in partition cpu-opteron
[2022-06-13T15:53:39.708] _slurm_rpc_submit_batch_job: Requested node configuration is not available
[2022-06-13T15:54:18.305] _slurm_rpc_submit_batch_job: JobId=43651 InitPrio=25681 usec=388
[2022-06-13T15:54:18.450] sched: Allocate JobId=43651 NodeList=cpu01 #CPUs=1 Partition=cpu-opteron
[2022-06-13T15:54:39.817] _slurm_rpc_kill_job: REQUEST_KILL_JOB JobId=43651 uid 548300543
[2022-06-13T15:55:16.699] _job_complete: JobId=43593 WEXITSTATUS 0
[2022-06-13T15:55:16.704] _job_complete: JobId=43593 done
[2022-06-13T15:55:17.569] sched: Allocate JobId=43631 NodeList=gpu05 #CPUs=16 Partition=gpu-v100s
[2022-06-13T15:56:46.482] _slurm_rpc_submit_batch_job: JobId=43652 InitPrio=25681 usec=447
[2022-06-13T15:56:46.652] sched: Allocate JobId=43652 NodeList=cpu01 #CPUs=1 Partition=cpu-opteron
[2022-06-13T15:57:02.749] _slurm_rpc_submit_batch_job: JobId=43653 InitPrio=29100 usec=622
[2022-06-13T15:57:04.716] _slurm_rpc_kill_job: REQUEST_KILL_JOB JobId=43652 uid 548300543
[2022-06-13T16:21:15.618] _job_complete: JobId=43617 WEXITSTATUS 0
[2022-06-13T16:21:15.618] _job_complete: JobId=43617 done
[2022-06-13T16:22:42.799] _pick_best_nodes: JobId=43654 never runnable in partition gpu-k10
[2022-06-13T16:22:42.799] _slurm_rpc_submit_batch_job: Requested node configuration is not available
[2022-06-13T16:23:18.870] _slurm_rpc_submit_batch_job: JobId=43655 InitPrio=25686 usec=430
[2022-06-13T16:23:19.472] sched: Allocate JobId=43655 NodeList=cpu01 #CPUs=32 Partition=cpu-opteron
[2022-06-13T16:23:44.443] _job_complete: JobId=43655 WEXITSTATUS 0
[2022-06-13T16:23:44.443] _job_complete: JobId=43655 done
[2022-06-13T17:02:43.220] _slurm_rpc_submit_batch_job: JobId=43656 InitPrio=19469 usec=404
[2022-06-13T17:02:43.850] sched: Allocate JobId=43656 NodeList=cpu12 #CPUs=32 Partition=cpu-epyc
[2022-06-13T17:02:53.304] _slurm_rpc_submit_batch_job: JobId=43657 InitPrio=19196 usec=418
[2022-06-13T17:02:53.845] sched: Allocate JobId=43657 NodeList=cpu07 #CPUs=64 Partition=cpu-opteron
[2022-06-13T17:05:50.979] _job_complete: JobId=43587 WEXITSTATUS 1
[2022-06-13T17:05:50.980] _job_complete: JobId=43587 done
[2022-06-13T17:05:51.402] sched: Allocate JobId=43592 NodeList=cpu15 #CPUs=24 Partition=cpu-epyc
[2022-06-13T17:20:08.854] _slurm_rpc_submit_batch_job: JobId=43658 InitPrio=25686 usec=520
[2022-06-13T17:20:09.649] sched: Allocate JobId=43658 NodeList=cpu05 #CPUs=32 Partition=cpu-opteron
[2022-06-13T17:20:35.933] _job_complete: JobId=43658 WEXITSTATUS 0
[2022-06-13T17:20:35.933] _job_complete: JobId=43658 done
[2022-06-13T17:29:09.154] _slurm_rpc_submit_batch_job: JobId=43659 InitPrio=20821 usec=389
[2022-06-13T17:29:09.568] sched: Allocate JobId=43659 NodeList=cpu05 #CPUs=32 Partition=cpu-opteron
[2022-06-13T17:31:34.800] _slurm_rpc_submit_batch_job: JobId=43660 InitPrio=20821 usec=418
[2022-06-13T17:31:35.756] sched: Allocate JobId=43660 NodeList=cpu01 #CPUs=32 Partition=cpu-opteron
[2022-06-13T17:32:30.492] _slurm_rpc_submit_batch_job: JobId=43661 InitPrio=20821 usec=465
[2022-06-13T17:32:30.955] sched: Allocate JobId=43661 NodeList=cpu03 #CPUs=32 Partition=cpu-opteron
[2022-06-13T17:34:44.212] _slurm_rpc_submit_batch_job: JobId=43662 InitPrio=20821 usec=435
[2022-06-13T17:34:45.143] sched: Allocate JobId=43662 NodeList=cpu09 #CPUs=32 Partition=cpu-opteron
[2022-06-13T17:36:24.837] _slurm_rpc_submit_batch_job: JobId=43663 InitPrio=20821 usec=386
[2022-06-13T17:36:25.280] sched: Allocate JobId=43663 NodeList=cpu09 #CPUs=32 Partition=cpu-opteron
[2022-06-13T17:37:23.433] _slurm_rpc_submit_batch_job: JobId=43664 InitPrio=20551 usec=389
[2022-06-13T17:39:52.576] _slurm_rpc_submit_batch_job: JobId=43665 InitPrio=20414 usec=410
[2022-06-13T17:40:53.845] _slurm_rpc_submit_batch_job: JobId=43666 InitPrio=20414 usec=388
[2022-06-13T17:41:10.894] _slurm_rpc_submit_batch_job: JobId=43667 InitPrio=25686 usec=448
[2022-06-13T17:43:33.100] _job_complete: JobId=43564 WEXITSTATUS 0
[2022-06-13T17:43:33.100] _job_complete: JobId=43564 done
[2022-06-13T18:22:47.077] _job_complete: JobId=43631 WEXITSTATUS 0
[2022-06-13T18:22:47.082] _job_complete: JobId=43631 done
[2022-06-13T18:22:49.997] sched: Allocate JobId=43632 NodeList=gpu05 #CPUs=16 Partition=gpu-v100s
[2022-06-13T18:35:09.385] _job_complete: JobId=43423 WEXITSTATUS 0
[2022-06-13T18:35:09.390] _job_complete: JobId=43423 done
[2022-06-13T18:35:09.804] sched: Allocate JobId=43633 NodeList=gpu05 #CPUs=16 Partition=gpu-v100s
[2022-06-13T18:40:18.302] _slurm_rpc_submit_batch_job: JobId=43668 InitPrio=21357 usec=449
[2022-06-13T18:50:02.645] _slurm_rpc_kill_job: REQUEST_KILL_JOB JobId=43668 uid 548200083
[2022-06-13T19:31:43.978] _job_complete: JobId=43633 WEXITSTATUS 255
[2022-06-13T19:31:43.979] _job_complete: JobId=43633 done
[2022-06-13T19:31:45.901] sched: Allocate JobId=43634 NodeList=gpu05 #CPUs=16 Partition=gpu-v100s
[2022-06-13T19:31:46.146] _job_complete: JobId=43634 WEXITSTATUS 1
[2022-06-13T19:31:46.146] _job_complete: JobId=43634 done
[2022-06-13T19:31:46.468] sched: Allocate JobId=43637 NodeList=gpu05 #CPUs=16 Partition=gpu-v100s
[2022-06-13T19:32:36.010] _job_complete: JobId=43458 WEXITSTATUS 1
[2022-06-13T19:32:36.011] _job_complete: JobId=43458 done
[2022-06-13T19:32:37.999] sched: Allocate JobId=43667 NodeList=cpu03 #CPUs=32 Partition=cpu-opteron
[2022-06-13T19:32:40.541] _job_complete: JobId=43667 WEXITSTATUS 1
[2022-06-13T19:32:40.541] _job_complete: JobId=43667 done
[2022-06-13T19:32:40.922] sched: Allocate JobId=43664 NodeList=cpu03 #CPUs=32 Partition=cpu-opteron
[2022-06-13T19:32:54.365] _job_complete: JobId=43664 WEXITSTATUS 1
[2022-06-13T19:32:54.365] _job_complete: JobId=43664 done
[2022-06-13T19:33:40.119] _job_complete: JobId=43624 WEXITSTATUS 0
[2022-06-13T19:33:40.119] _job_complete: JobId=43624 done
[2022-06-13T19:33:48.406] _job_complete: JobId=43559 WEXITSTATUS 0
[2022-06-13T19:33:48.411] _job_complete: JobId=43559 done
[2022-06-13T19:33:50.263] sched: Allocate JobId=43665 NodeList=cpu15 #CPUs=48 Partition=cpu-epyc
[2022-06-13T19:53:36.442] _slurm_rpc_submit_batch_job: JobId=43669 InitPrio=20010 usec=525
[2022-06-13T19:53:36.494] sched: Allocate JobId=43669 NodeList=gpu01 #CPUs=32 Partition=gpu-k10
[2022-06-13T20:06:43.435] _job_complete: JobId=43642 WEXITSTATUS 0
[2022-06-13T20:06:43.435] _job_complete: JobId=43642 done
[2022-06-13T20:15:22.406] _slurm_rpc_kill_job: REQUEST_KILL_JOB JobId=43632 uid 548300558
[2022-06-13T20:15:28.313] sched: Allocate JobId=43424 NodeList=gpu05 #CPUs=32 Partition=gpu-v100s
[2022-06-13T20:17:59.371] _slurm_rpc_submit_batch_job: JobId=43670 InitPrio=23390 usec=399
[2022-06-13T20:18:02.315] _slurm_rpc_submit_batch_job: JobId=43671 InitPrio=23390 usec=407
[2022-06-13T20:18:05.034] _slurm_rpc_submit_batch_job: JobId=43672 InitPrio=23390 usec=342
[2022-06-13T20:18:35.688] _slurm_rpc_submit_batch_job: JobId=43673 InitPrio=29100 usec=490
[2022-06-13T20:18:36.365] sched: Allocate JobId=43673 NodeList=gpu02 #CPUs=12 Partition=gpu-titan
[2022-06-13T20:20:28.117] _slurm_rpc_kill_job: REQUEST_KILL_JOB JobId=43670 uid 548300558
[2022-06-13T20:20:30.081] _slurm_rpc_kill_job: REQUEST_KILL_JOB JobId=43671 uid 548300558
[2022-06-13T20:20:31.853] _slurm_rpc_kill_job: REQUEST_KILL_JOB JobId=43672 uid 548300558
[2022-06-13T20:20:40.035] _slurm_rpc_submit_batch_job: JobId=43674 InitPrio=23390 usec=403
[2022-06-13T20:20:43.468] _slurm_rpc_submit_batch_job: JobId=43675 InitPrio=23390 usec=362
[2022-06-13T20:20:46.032] _slurm_rpc_submit_batch_job: JobId=43676 InitPrio=23390 usec=395
[2022-06-13T20:27:06.149] _slurm_rpc_kill_job: REQUEST_KILL_JOB JobId=43673 uid 548300547
[2022-06-13T20:29:00.660] _slurm_rpc_submit_batch_job: JobId=43677 InitPrio=28525 usec=448
[2022-06-13T20:29:01.508] sched: Allocate JobId=43677 NodeList=gpu02 #CPUs=16 Partition=gpu-titan
[2022-06-13T20:36:54.793] _slurm_rpc_kill_job: REQUEST_KILL_JOB JobId=43582 uid 548300547
[2022-06-13T20:36:54.793] _slurm_rpc_kill_job: REQUEST_KILL_JOB JobId=43653 uid 548300547
[2022-06-13T20:36:54.793] _slurm_rpc_kill_job: REQUEST_KILL_JOB JobId=43583 uid 548300547
[2022-06-13T20:39:01.695] _job_complete: JobId=43669 WEXITSTATUS 0
[2022-06-13T20:39:01.695] _job_complete: JobId=43669 done
[2022-06-13T20:40:16.522] _slurm_rpc_submit_batch_job: JobId=43678 InitPrio=28255 usec=396
[2022-06-13T20:46:07.119] _job_complete: JobId=43665 WEXITSTATUS 0
[2022-06-13T20:46:07.119] _job_complete: JobId=43665 done
[2022-06-13T20:46:07.457] sched: Allocate JobId=43666 NodeList=cpu15 #CPUs=48 Partition=cpu-epyc
[2022-06-13T20:56:36.682] _slurm_rpc_submit_batch_job: JobId=43679 InitPrio=21297 usec=586
[2022-06-13T20:56:37.551] sched: Allocate JobId=43679 NodeList=gpu01 #CPUs=8 Partition=gpu-k10
[2022-06-13T20:56:37.787] _job_complete: JobId=43679 WEXITSTATUS 1
[2022-06-13T20:56:37.787] _job_complete: JobId=43679 done
[2022-06-13T20:57:29.532] _slurm_rpc_submit_batch_job: JobId=43680 InitPrio=21297 usec=420
[2022-06-13T20:57:29.686] sched: Allocate JobId=43680 NodeList=gpu01 #CPUs=8 Partition=gpu-k10
[2022-06-13T20:57:29.950] _job_complete: JobId=43680 WEXITSTATUS 1
[2022-06-13T20:57:29.950] _job_complete: JobId=43680 done
[2022-06-13T20:59:18.499] _slurm_rpc_submit_batch_job: JobId=43681 InitPrio=19469 usec=495
[2022-06-13T20:59:18.857] sched: Allocate JobId=43681 NodeList=cpu03 #CPUs=32 Partition=cpu-opteron
[2022-06-13T21:08:35.817] _job_complete: JobId=43598 WEXITSTATUS 1
[2022-06-13T21:08:35.822] _job_complete: JobId=43598 done
[2022-06-13T21:24:40.512] _job_complete: JobId=43274 WEXITSTATUS 0
[2022-06-13T21:24:40.512] _job_complete: JobId=43274 done
[2022-06-13T21:26:32.915] _slurm_rpc_submit_batch_job: JobId=43682 InitPrio=23120 usec=434
[2022-06-13T21:51:00.073] sched: _slurm_rpc_allocate_resources JobId=43683 NodeList=cpu05 usec=4476
[2022-06-13T21:53:48.718] _job_complete: JobId=43683 WEXITSTATUS 130
[2022-06-13T21:53:48.719] _job_complete: JobId=43683 done
[2022-06-13T21:57:32.418] _job_complete: JobId=43666 WEXITSTATUS 0
[2022-06-13T21:57:32.418] _job_complete: JobId=43666 done
[2022-06-13T23:09:08.123] _job_complete: JobId=43637 WEXITSTATUS 0
[2022-06-13T23:09:08.129] _job_complete: JobId=43637 done
[2022-06-13T23:09:09.004] sched: Allocate JobId=43674 NodeList=gpu05 #CPUs=16 Partition=gpu-v100s
[2022-06-14T00:06:32.535] _slurm_rpc_submit_batch_job: JobId=43684 InitPrio=20414 usec=453
[2022-06-14T00:06:50.152] _slurm_rpc_kill_job: REQUEST_KILL_JOB JobId=43684 uid 548200023
[2022-06-14T00:07:05.727] _slurm_rpc_submit_batch_job: JobId=43685 InitPrio=20414 usec=573
[2022-06-14T00:07:06.318] sched: Allocate JobId=43685 NodeList=cpu15 #CPUs=48 Partition=cpu-epyc
[2022-06-14T00:12:52.737] _slurm_rpc_submit_batch_job: JobId=43686 InitPrio=20551 usec=539
[2022-06-14T00:12:53.012] sched: Allocate JobId=43686 NodeList=cpu05 #CPUs=32 Partition=cpu-opteron
[2022-06-14T00:13:06.883] _job_complete: JobId=43686 WEXITSTATUS 1
[2022-06-14T00:13:06.883] _job_complete: JobId=43686 done
[2022-06-14T00:13:42.317] _slurm_rpc_submit_batch_job: JobId=43687 InitPrio=20551 usec=396
[2022-06-14T00:13:43.085] sched: Allocate JobId=43687 NodeList=cpu05 #CPUs=32 Partition=cpu-opteron
[2022-06-14T00:16:45.441] _slurm_rpc_submit_batch_job: JobId=43688 InitPrio=20551 usec=572
[2022-06-14T00:16:46.352] sched: Allocate JobId=43688 NodeList=cpu08 #CPUs=32 Partition=cpu-opteron
[2022-06-14T00:18:45.730] _slurm_rpc_submit_batch_job: JobId=43689 InitPrio=20790 usec=399
[2022-06-14T00:19:11.495] _slurm_rpc_kill_job: REQUEST_KILL_JOB JobId=43689 uid 548200023
[2022-06-14T00:19:19.009] _slurm_rpc_submit_batch_job: JobId=43690 InitPrio=20816 usec=433
[2022-06-14T00:24:26.919] _slurm_rpc_submit_batch_job: JobId=43691 InitPrio=20739 usec=490
[2022-06-14T00:24:51.297] _slurm_rpc_kill_job: REQUEST_KILL_JOB JobId=43691 uid 548200023
[2022-06-14T00:25:19.690] _slurm_rpc_submit_batch_job: JobId=43692 InitPrio=20756 usec=427
[2022-06-14T00:25:22.295] sched: Allocate JobId=43692 NodeList=gpu01 #CPUs=8 Partition=gpu-k10
[2022-06-14T00:25:24.733] _job_complete: JobId=43692 WEXITSTATUS 1
[2022-06-14T00:25:24.733] _job_complete: JobId=43692 done
[2022-06-14T00:26:04.765] _slurm_rpc_submit_batch_job: JobId=43693 InitPrio=20790 usec=424
[2022-06-14T00:27:11.838] _slurm_rpc_submit_batch_job: JobId=43694 InitPrio=20756 usec=436
[2022-06-14T00:27:12.452] sched: Allocate JobId=43694 NodeList=gpu01 #CPUs=8 Partition=gpu-k10
[2022-06-14T00:27:40.452] _job_complete: JobId=43448 WEXITSTATUS 0
[2022-06-14T00:27:40.457] _job_complete: JobId=43448 done
[2022-06-14T00:27:44.342] _job_complete: JobId=43694 WEXITSTATUS 0
[2022-06-14T00:27:44.343] _job_complete: JobId=43694 done
[2022-06-14T00:28:39.455] _slurm_rpc_submit_batch_job: JobId=43695 InitPrio=20756 usec=556
[2022-06-14T00:28:39.685] sched: Allocate JobId=43695 NodeList=gpu01 #CPUs=8 Partition=gpu-k10
[2022-06-14T00:29:09.864] _job_complete: JobId=43695 WEXITSTATUS 0
[2022-06-14T00:29:09.864] _job_complete: JobId=43695 done
[2022-06-14T00:29:17.768] _slurm_rpc_submit_batch_job: JobId=43696 InitPrio=20756 usec=411
[2022-06-14T00:29:18.738] sched: Allocate JobId=43696 NodeList=gpu01 #CPUs=8 Partition=gpu-k10
[2022-06-14T00:29:51.618] _job_complete: JobId=43696 WEXITSTATUS 0
[2022-06-14T00:29:51.618] _job_complete: JobId=43696 done
[2022-06-14T00:31:32.153] _slurm_rpc_submit_batch_job: JobId=43697 InitPrio=20688 usec=411
[2022-06-14T00:31:32.932] sched: Allocate JobId=43697 NodeList=gpu01 #CPUs=16 Partition=gpu-k10
[2022-06-14T00:32:02.271] _job_complete: JobId=43697 WEXITSTATUS 0
[2022-06-14T00:32:02.272] _job_complete: JobId=43697 done
[2022-06-14T00:35:25.075] _slurm_rpc_submit_batch_job: JobId=43698 InitPrio=20414 usec=420
[2022-06-14T00:38:00.564] _slurm_rpc_submit_batch_job: JobId=43699 InitPrio=20756 usec=440
[2022-06-14T00:38:00.809] sched: Allocate JobId=43699 NodeList=gpu01 #CPUs=8 Partition=gpu-k10
[2022-06-14T00:38:30.553] _job_complete: JobId=43699 WEXITSTATUS 0
[2022-06-14T00:38:30.553] _job_complete: JobId=43699 done
[2022-06-14T00:41:30.409] _slurm_rpc_submit_batch_job: JobId=43700 InitPrio=20414 usec=441
[2022-06-14T00:42:45.402] _slurm_rpc_submit_batch_job: JobId=43701 InitPrio=20756 usec=712
[2022-06-14T00:42:46.366] sched: Allocate JobId=43701 NodeList=gpu01 #CPUs=8 Partition=gpu-k10
[2022-06-14T00:43:17.348] _job_complete: JobId=43701 WEXITSTATUS 0
[2022-06-14T00:43:17.348] _job_complete: JobId=43701 done
[2022-06-14T00:43:27.090] _slurm_rpc_submit_batch_job: JobId=43702 InitPrio=23493 usec=397
[2022-06-14T00:43:27.436] sched: Allocate JobId=43702 NodeList=cpu12 #CPUs=4 Partition=cpu-epyc
[2022-06-14T00:45:18.151] _slurm_rpc_kill_job: REQUEST_KILL_JOB JobId=43702 uid 548300558
[2022-06-14T00:47:06.125] _slurm_rpc_submit_batch_job: JobId=43703 InitPrio=20756 usec=430
[2022-06-14T00:47:06.742] sched: Allocate JobId=43703 NodeList=gpu01 #CPUs=8 Partition=gpu-k10
[2022-06-14T00:47:33.841] _job_complete: JobId=43703 WEXITSTATUS 0
[2022-06-14T00:47:33.842] _job_complete: JobId=43703 done
[2022-06-14T00:50:22.830] _slurm_rpc_submit_batch_job: JobId=43704 InitPrio=20414 usec=516
[2022-06-14T00:50:53.133] _slurm_rpc_kill_job: REQUEST_KILL_JOB JobId=43688 uid 548200023
[2022-06-14T00:50:55.177] _slurm_rpc_kill_job: REQUEST_KILL_JOB JobId=43687 uid 548200023
[2022-06-14T00:50:56.228] sched: Allocate JobId=43690 NodeList=cpu08 #CPUs=1 Partition=cpu-opteron
[2022-06-14T00:50:56.228] sched: Allocate JobId=43693 NodeList=cpu08 #CPUs=4 Partition=cpu-opteron
[2022-06-14T00:51:38.202] _job_complete: JobId=43690 WEXITSTATUS 0
[2022-06-14T00:51:38.202] _job_complete: JobId=43690 done
[2022-06-14T00:51:41.684] _job_complete: JobId=43693 WEXITSTATUS 0
[2022-06-14T00:51:41.684] _job_complete: JobId=43693 done
[2022-06-14T00:53:44.888] _slurm_rpc_submit_batch_job: JobId=43705 InitPrio=21357 usec=485
[2022-06-14T00:53:45.541] sched: Allocate JobId=43705 NodeList=cpu05 #CPUs=1 Partition=cpu-opteron
[2022-06-14T00:56:11.045] _job_complete: JobId=43705 WEXITSTATUS 1
[2022-06-14T00:56:11.045] _job_complete: JobId=43705 done
[2022-06-14T01:03:41.921] _slurm_rpc_submit_batch_job: JobId=43706 InitPrio=21357 usec=485
[2022-06-14T01:03:42.503] sched: Allocate JobId=43706 NodeList=cpu05 #CPUs=1 Partition=cpu-opteron
[2022-06-14T01:04:56.361] _slurm_rpc_kill_job: REQUEST_KILL_JOB JobId=43706 uid 548200083
[2022-06-14T01:05:22.310] _slurm_rpc_submit_batch_job: JobId=43707 InitPrio=21331 usec=469
[2022-06-14T01:05:22.642] sched: Allocate JobId=43707 NodeList=cpu12 #CPUs=4 Partition=cpu-epyc
[2022-06-14T01:05:29.061] _job_complete: JobId=43707 WEXITSTATUS 1
[2022-06-14T01:05:29.066] _job_complete: JobId=43707 done
[2022-06-14T01:10:07.317] _slurm_rpc_kill_job: REQUEST_KILL_JOB JobId=43675 uid 548300558
[2022-06-14T01:10:14.228] _slurm_rpc_kill_job: REQUEST_KILL_JOB JobId=43676 uid 548300558
[2022-06-14T01:11:13.147] _slurm_rpc_submit_batch_job: JobId=43708 InitPrio=21331 usec=444
[2022-06-14T01:11:13.622] sched: Allocate JobId=43708 NodeList=cpu12 #CPUs=4 Partition=cpu-epyc
[2022-06-14T01:12:23.970] _slurm_rpc_submit_batch_job: JobId=43709 InitPrio=23390 usec=342
[2022-06-14T01:12:27.224] _slurm_rpc_submit_batch_job: JobId=43710 InitPrio=23390 usec=361
[2022-06-14T01:12:30.407] _slurm_rpc_submit_batch_job: JobId=43711 InitPrio=23390 usec=324
[2022-06-14T01:12:58.645] _slurm_rpc_kill_job: REQUEST_KILL_JOB JobId=43674 uid 548300558
[2022-06-14T01:13:04.555] sched: Allocate JobId=43709 NodeList=gpu05 #CPUs=16 Partition=gpu-v100s
[2022-06-14T01:15:06.362] _job_complete: JobId=43685 WEXITSTATUS 0
[2022-06-14T01:15:06.362] _job_complete: JobId=43685 done
[2022-06-14T01:15:06.702] sched: Allocate JobId=43698 NodeList=cpu15 #CPUs=48 Partition=cpu-epyc
[2022-06-14T01:20:21.721] _job_complete: JobId=43592 WEXITSTATUS 1
[2022-06-14T01:20:21.721] _job_complete: JobId=43592 done
[2022-06-14T01:20:22.126] sched: Allocate JobId=43700 NodeList=cpu15 #CPUs=48 Partition=cpu-epyc
[2022-06-14T01:25:08.543] _job_complete: JobId=43708 WEXITSTATUS 0
[2022-06-14T01:25:08.543] _job_complete: JobId=43708 done
[2022-06-14T01:49:30.145] _slurm_rpc_submit_batch_job: JobId=43712 InitPrio=21331 usec=514
[2022-06-14T01:49:30.915] sched: Allocate JobId=43712 NodeList=cpu12 #CPUs=4 Partition=cpu-epyc
[2022-06-14T02:02:52.769] _job_complete: JobId=43712 WEXITSTATUS 0
[2022-06-14T02:02:52.769] _job_complete: JobId=43712 done
[2022-06-14T02:24:58.841] _job_complete: JobId=43709 WEXITSTATUS 0
[2022-06-14T02:24:58.843] _job_complete: JobId=43709 done
[2022-06-14T02:24:59.724] sched: Allocate JobId=43710 NodeList=gpu05 #CPUs=16 Partition=gpu-v100s
[2022-06-14T02:25:04.177] _job_complete: JobId=43663 WEXITSTATUS 0
[2022-06-14T02:25:04.177] _job_complete: JobId=43663 done
[2022-06-14T03:00:10.711] _slurm_rpc_submit_batch_job: JobId=43713 InitPrio=21331 usec=417
[2022-06-14T03:00:10.736] _slurm_rpc_submit_batch_job: JobId=43714 InitPrio=21331 usec=396
[2022-06-14T03:00:10.749] _slurm_rpc_submit_batch_job: JobId=43715 InitPrio=21331 usec=276
[2022-06-14T03:00:10.925] sched: Allocate JobId=43713 NodeList=cpu12 #CPUs=4 Partition=cpu-epyc
[2022-06-14T03:00:10.925] sched: Allocate JobId=43714 NodeList=cpu12 #CPUs=4 Partition=cpu-epyc
[2022-06-14T03:00:10.926] sched: Allocate JobId=43715 NodeList=cpu12 #CPUs=4 Partition=cpu-epyc
[2022-06-14T03:02:18.364] _job_complete: JobId=43714 WEXITSTATUS 0
[2022-06-14T03:02:18.364] _job_complete: JobId=43714 done
[2022-06-14T03:03:23.067] _job_complete: JobId=43713 WEXITSTATUS 0
[2022-06-14T03:03:23.067] _job_complete: JobId=43713 done
[2022-06-14T03:03:45.179] _job_complete: JobId=43715 WEXITSTATUS 0
[2022-06-14T03:03:45.179] _job_complete: JobId=43715 done
[2022-06-14T03:36:11.446] _job_complete: JobId=43710 WEXITSTATUS 0
[2022-06-14T03:36:11.447] _job_complete: JobId=43710 done
[2022-06-14T03:36:12.468] sched: Allocate JobId=43682 NodeList=gpu05 #CPUs=16 Partition=gpu-v100s
[2022-06-14T03:47:31.382] _job_complete: JobId=43449 WEXITSTATUS 0
[2022-06-14T03:47:31.387] _job_complete: JobId=43449 done
[2022-06-14T05:23:50.905] _job_complete: JobId=43535 WEXITSTATUS 0
[2022-06-14T05:23:50.911] _job_complete: JobId=43535 done
[2022-06-14T05:32:51.674] _job_complete: JobId=43331 WEXITSTATUS 0
[2022-06-14T05:32:51.679] _job_complete: JobId=43331 done
[2022-06-14T05:32:55.591] sched: Allocate JobId=43529 NodeList=gpu04 #CPUs=8 Partition=gpu-k40c
[2022-06-14T05:33:12.898] _job_complete: JobId=43529 WEXITSTATUS 1
[2022-06-14T05:33:12.898] _job_complete: JobId=43529 done
[2022-06-14T05:33:13.791] sched: Allocate JobId=43530 NodeList=gpu04 #CPUs=8 Partition=gpu-k40c
[2022-06-14T05:33:30.216] _job_complete: JobId=43530 WEXITSTATUS 1
[2022-06-14T05:33:30.217] _job_complete: JobId=43530 done
[2022-06-14T06:58:03.738] _job_complete: JobId=43682 WEXITSTATUS 0
[2022-06-14T06:58:03.744] _job_complete: JobId=43682 done
[2022-06-14T06:58:04.620] sched: Allocate JobId=43711 NodeList=gpu05 #CPUs=16 Partition=gpu-v100s
[2022-06-14T07:21:45.457] _slurm_rpc_submit_batch_job: JobId=43716 InitPrio=23120 usec=434
[2022-06-14T07:54:09.031] _job_complete: JobId=43551 WEXITSTATUS 0
[2022-06-14T07:54:09.036] _job_complete: JobId=43551 done
[2022-06-14T08:08:23.604] _job_complete: JobId=43711 WEXITSTATUS 0
[2022-06-14T08:08:23.605] _job_complete: JobId=43711 done
[2022-06-14T08:08:24.516] sched: Allocate JobId=43716 NodeList=gpu05 #CPUs=16 Partition=gpu-v100s
[2022-06-14T08:27:33.204] _slurm_rpc_kill_job: REQUEST_KILL_JOB JobId=43659 uid 548200019
[2022-06-14T08:28:28.822] _slurm_rpc_submit_batch_job: JobId=43717 InitPrio=20821 usec=496
[2022-06-14T08:28:29.452] sched: Allocate JobId=43717 NodeList=cpu13 #CPUs=32 Partition=cpu-epyc
[2022-06-14T08:29:07.022] _slurm_rpc_kill_job: REQUEST_KILL_JOB JobId=43660 uid 548200019
[2022-06-14T08:29:40.073] _slurm_rpc_submit_batch_job: JobId=43718 InitPrio=20821 usec=449
[2022-06-14T08:29:40.539] sched: Allocate JobId=43718 NodeList=cpu14 #CPUs=32 Partition=cpu-epyc
[2022-06-14T08:30:00.921] _slurm_rpc_kill_job: REQUEST_KILL_JOB JobId=43662 uid 548200019
[2022-06-14T08:31:00.446] _slurm_rpc_submit_batch_job: JobId=43719 InitPrio=20547 usec=434
[2022-06-14T08:31:00.655] sched: Allocate JobId=43719 NodeList=cpu05 #CPUs=64 Partition=cpu-opteron
[2022-06-14T08:32:10.878] _slurm_rpc_submit_batch_job: JobId=43720 InitPrio=20821 usec=435
[2022-06-14T08:32:11.756] sched: Allocate JobId=43720 NodeList=cpu01 #CPUs=32 Partition=cpu-opteron
[2022-06-14T08:33:31.308] _slurm_rpc_submit_batch_job: JobId=43721 InitPrio=20821 usec=459
[2022-06-14T08:33:32.047] sched: Allocate JobId=43721 NodeList=cpu11 #CPUs=32 Partition=cpu-opteron
[2022-06-14T08:34:32.529] _slurm_rpc_submit_batch_job: JobId=43722 InitPrio=20547 usec=476
[2022-06-14T08:34:33.135] sched: Allocate JobId=43722 NodeList=cpu09 #CPUs=64 Partition=cpu-opteron
[2022-06-14T08:41:21.757] _slurm_rpc_submit_batch_job: JobId=43723 InitPrio=20821 usec=436
[2022-06-14T08:41:23.917] sched: Allocate JobId=43723 NodeList=cpu08 #CPUs=32 Partition=cpu-opteron
[2022-06-14T08:46:26.772] _slurm_rpc_submit_batch_job: JobId=43724 InitPrio=19196 usec=381
[2022-06-14T08:48:17.467] _slurm_rpc_submit_batch_job: JobId=43725 InitPrio=25951 usec=377
[2022-06-14T08:50:18.032] _slurm_rpc_kill_job: REQUEST_KILL_JOB JobId=43725 uid 548300543
[2022-06-14T08:50:22.450] _slurm_rpc_submit_batch_job: JobId=43726 InitPrio=25951 usec=442
[2022-06-14T08:50:38.367] _slurm_rpc_kill_job: REQUEST_KILL_JOB JobId=43726 uid 548300543
[2022-06-14T08:50:42.523] _slurm_rpc_submit_batch_job: JobId=43727 InitPrio=25951 usec=364
[2022-06-14T08:50:43.101] sched: Allocate JobId=43727 NodeList=cpu12 #CPUs=1 Partition=cpu-epyc
[2022-06-14T08:51:18.931] _slurm_rpc_kill_job: REQUEST_KILL_JOB JobId=43727 uid 548300543
[2022-06-14T08:51:59.762] _slurm_rpc_submit_batch_job: JobId=43728 InitPrio=25823 usec=360
[2022-06-14T08:52:00.190] sched: Allocate JobId=43728 NodeList=gpu01 #CPUs=16 Partition=gpu-k10
[2022-06-14T08:53:21.784] _slurm_rpc_kill_job: REQUEST_KILL_JOB JobId=43728 uid 548300543
[2022-06-14T08:54:23.973] _pick_best_nodes: JobId=43729 never runnable in partition cpu-epyc
[2022-06-14T08:54:23.973] _slurm_rpc_submit_batch_job: Requested node configuration is not available
[2022-06-14T08:54:42.802] _slurm_rpc_submit_batch_job: JobId=43730 InitPrio=25891 usec=467
[2022-06-14T08:54:43.574] sched: Allocate JobId=43730 NodeList=cpu12 #CPUs=8 Partition=cpu-epyc
[2022-06-14T08:55:22.076] _slurm_rpc_kill_job: REQUEST_KILL_JOB JobId=43730 uid 548300543
[2022-06-14T09:07:26.060] _slurm_rpc_submit_batch_job: JobId=43731 InitPrio=21498 usec=982
[2022-06-14T09:07:27.042] sched: Allocate JobId=43731 NodeList=gpu01 #CPUs=16 Partition=gpu-k10
[2022-06-14T09:10:48.277] _slurm_rpc_kill_job: REQUEST_KILL_JOB JobId=43724 uid 548200017
[2022-06-14T09:11:04.108] _slurm_rpc_submit_batch_job: JobId=43732 InitPrio=19196 usec=456
[2022-06-14T09:41:10.215] _slurm_rpc_submit_batch_job: JobId=43733 InitPrio=25891 usec=369
[2022-06-14T09:41:10.979] sched: Allocate JobId=43733 NodeList=cpu12 #CPUs=8 Partition=cpu-epyc
[2022-06-14T09:41:23.538] _slurm_rpc_kill_job: REQUEST_KILL_JOB JobId=43733 uid 548300543
[2022-06-14T09:57:06.519] _get_job_parts: invalid partition specified: 
[2022-06-14T09:57:06.519] _slurm_rpc_submit_batch_job: Invalid partition name specified
[2022-06-14T09:58:13.749] _slurm_rpc_submit_batch_job: JobId=43734 InitPrio=21361 usec=546
[2022-06-14T09:58:15.255] _get_job_parts: invalid partition specified: 
[2022-06-14T09:58:15.255] _slurm_rpc_submit_batch_job: Invalid partition name specified
[2022-06-14T09:59:07.477] _get_job_parts: invalid partition specified: 
[2022-06-14T09:59:07.477] _slurm_rpc_submit_batch_job: Invalid partition name specified
[2022-06-14T10:00:20.678] _get_job_parts: invalid partition specified: 
[2022-06-14T10:00:20.678] _slurm_rpc_submit_batch_job: Invalid partition name specified
[2022-06-14T10:02:17.981] _slurm_rpc_submit_batch_job: JobId=43735 InitPrio=25951 usec=335
[2022-06-14T10:02:18.648] sched: Allocate JobId=43735 NodeList=cpu12 #CPUs=1 Partition=cpu-epyc
[2022-06-14T10:02:20.909] _slurm_rpc_kill_job: REQUEST_KILL_JOB JobId=43735 uid 548300543
[2022-06-14T10:03:43.104] _slurm_rpc_submit_batch_job: JobId=43736 InitPrio=21361 usec=459
[2022-06-14T10:04:02.808] _slurm_rpc_submit_batch_job: JobId=43737 InitPrio=25951 usec=330
[2022-06-14T10:04:02.888] sched: Allocate JobId=43737 NodeList=cpu12 #CPUs=1 Partition=cpu-epyc
[2022-06-14T10:05:18.215] _slurm_rpc_kill_job: REQUEST_KILL_JOB JobId=43737 uid 548300543
[2022-06-14T10:05:29.926] _slurm_rpc_submit_batch_job: JobId=43738 InitPrio=25951 usec=396
[2022-06-14T10:05:30.013] sched: Allocate JobId=43738 NodeList=cpu12 #CPUs=1 Partition=cpu-epyc
[2022-06-14T10:05:57.524] _slurm_rpc_kill_job: REQUEST_KILL_JOB JobId=43738 uid 548300543
[2022-06-14T10:06:01.985] _slurm_rpc_submit_batch_job: JobId=43739 InitPrio=22039 usec=476
[2022-06-14T10:06:02.122] sched: Allocate JobId=43739 NodeList=gpu04 #CPUs=16 Partition=gpu-k40c
[2022-06-14T10:06:02.332] _slurm_rpc_submit_batch_job: JobId=43740 InitPrio=25951 usec=414
[2022-06-14T10:06:05.064] sched: Allocate JobId=43740 NodeList=cpu12 #CPUs=1 Partition=cpu-epyc
[2022-06-14T10:06:26.052] _slurm_rpc_kill_job: REQUEST_KILL_JOB JobId=43740 uid 548300543
[2022-06-14T10:08:07.402] _slurm_rpc_submit_batch_job: JobId=43741 InitPrio=25951 usec=406
[2022-06-14T10:08:08.391] sched: Allocate JobId=43741 NodeList=cpu12 #CPUs=1 Partition=cpu-epyc
[2022-06-14T10:08:26.121] _slurm_rpc_kill_job: REQUEST_KILL_JOB JobId=43741 uid 548300543
[2022-06-14T10:08:31.676] _slurm_rpc_submit_batch_job: JobId=43742 InitPrio=25951 usec=423
[2022-06-14T10:08:32.427] sched: Allocate JobId=43742 NodeList=cpu12 #CPUs=1 Partition=cpu-epyc
[2022-06-14T10:08:55.618] _slurm_rpc_kill_job: REQUEST_KILL_JOB JobId=43742 uid 548300543
[2022-06-14T10:19:48.265] _job_complete: JobId=43720 WEXITSTATUS 1
[2022-06-14T10:19:48.265] _job_complete: JobId=43720 done
[2022-06-14T10:19:48.735] sched: Allocate JobId=43734 NodeList=cpu01 #CPUs=32 Partition=cpu-opteron
[2022-06-14T10:20:24.975] _slurm_rpc_submit_batch_job: JobId=43743 InitPrio=25951 usec=357
[2022-06-14T10:20:25.736] sched: Allocate JobId=43743 NodeList=cpu12 #CPUs=1 Partition=cpu-epyc
[2022-06-14T10:20:30.245] _job_complete: JobId=43734 WEXITSTATUS 0
[2022-06-14T10:20:30.245] _job_complete: JobId=43734 done
[2022-06-14T10:20:32.215] sched: Allocate JobId=43736 NodeList=cpu01 #CPUs=32 Partition=cpu-opteron
[2022-06-14T10:20:45.225] _job_complete: JobId=43736 WEXITSTATUS 0
[2022-06-14T10:20:45.225] _job_complete: JobId=43736 done
[2022-06-14T10:20:46.042] _slurm_rpc_kill_job: REQUEST_KILL_JOB JobId=43743 uid 548300543
[2022-06-14T10:21:28.148] _slurm_rpc_submit_batch_job: JobId=43744 InitPrio=25951 usec=368
[2022-06-14T10:21:28.823] sched: Allocate JobId=43744 NodeList=cpu12 #CPUs=1 Partition=cpu-epyc
[2022-06-14T10:21:55.984] _slurm_rpc_kill_job: REQUEST_KILL_JOB JobId=43744 uid 548300543
[2022-06-14T10:24:11.569] _slurm_rpc_submit_batch_job: JobId=43745 InitPrio=23120 usec=378
[2022-06-14T10:47:14.921] _slurm_rpc_submit_batch_job: JobId=43746 InitPrio=25951 usec=399
[2022-06-14T10:47:15.587] sched: Allocate JobId=43746 NodeList=cpu12 #CPUs=1 Partition=cpu-epyc
[2022-06-14T10:47:17.141] _slurm_rpc_kill_job: REQUEST_KILL_JOB JobId=43746 uid 548300543
[2022-06-14T11:36:49.534] _slurm_rpc_submit_batch_job: JobId=43747 InitPrio=21361 usec=412
[2022-06-14T11:36:50.501] sched: Allocate JobId=43747 NodeList=cpu01 #CPUs=32 Partition=cpu-opteron
[2022-06-14T11:36:55.143] _job_complete: JobId=43747 WEXITSTATUS 0
[2022-06-14T11:36:55.143] _job_complete: JobId=43747 done
[2022-06-14T11:53:36.900] _job_complete: JobId=43716 WEXITSTATUS 0
[2022-06-14T11:53:36.906] _job_complete: JobId=43716 done
[2022-06-14T11:53:37.804] sched: Allocate JobId=43745 NodeList=gpu05 #CPUs=16 Partition=gpu-v100s
[2022-06-14T12:04:11.042] Requeuing JobId=43424
[2022-06-14T12:04:11.061] sched: Allocate JobId=43425 NodeList=gpu05 #CPUs=32 Partition=gpu-v100s
[2022-06-14T12:04:39.309] Requeuing JobId=43425
[2022-06-14T12:07:04.668] _slurm_rpc_submit_batch_job: JobId=43748 InitPrio=21361 usec=470
[2022-06-14T12:07:04.699] sched: Allocate JobId=43748 NodeList=cpu01 #CPUs=32 Partition=cpu-opteron
[2022-06-14T12:07:09.408] _job_complete: JobId=43748 WEXITSTATUS 0
[2022-06-14T12:07:09.408] _job_complete: JobId=43748 done
[2022-06-14T12:28:14.024] _slurm_rpc_submit_batch_job: JobId=43749 InitPrio=22850 usec=453
[2022-06-14T12:28:14.153] sched: Allocate JobId=43749 NodeList=gpu05 #CPUs=16 Partition=gpu-v100s
[2022-06-14T12:34:52.613] _slurm_rpc_submit_batch_job: JobId=43750 InitPrio=20280 usec=432
[2022-06-14T12:34:52.845] sched: Allocate JobId=43750 NodeList=gpu03 #CPUs=32 Partition=gpu-k10
[2022-06-14T12:35:13.449] _job_complete: JobId=43750 WEXITSTATUS 1
[2022-06-14T12:35:13.449] _job_complete: JobId=43750 done
[2022-06-14T12:35:34.756] _slurm_rpc_submit_batch_job: JobId=43751 InitPrio=20280 usec=379
[2022-06-14T12:35:34.889] sched: Allocate JobId=43751 NodeList=gpu03 #CPUs=32 Partition=gpu-k10
[2022-06-14T12:43:17.023] _pick_best_nodes: JobId=43752 never runnable in partition gpu-k10
[2022-06-14T12:43:17.023] _slurm_rpc_submit_batch_job: Requested node configuration is not available
[2022-06-14T12:43:59.799] _slurm_rpc_submit_batch_job: JobId=43753 InitPrio=20280 usec=446
[2022-06-14T12:50:49.107] _slurm_rpc_submit_batch_job: JobId=43754 InitPrio=20551 usec=524
[2022-06-14T12:51:27.204] _slurm_rpc_kill_job: REQUEST_KILL_JOB JobId=43704 uid 548200023
[2022-06-14T12:51:29.798] _slurm_rpc_submit_batch_job: JobId=43755 InitPrio=20551 usec=401
[2022-06-14T12:51:30.583] sched: Allocate JobId=43755 NodeList=cpu01 #CPUs=32 Partition=cpu-opteron
[2022-06-14T13:18:33.634] _slurm_rpc_submit_batch_job: JobId=43756 InitPrio=20280 usec=779
[2022-06-14T13:25:23.268] _slurm_rpc_submit_batch_job: JobId=43757 InitPrio=24329 usec=329
[2022-06-14T13:25:23.397] sched: Allocate JobId=43757 NodeList=cpu12 #CPUs=1 Partition=cpu-epyc
[2022-06-14T13:26:11.021] _job_complete: JobId=43757 WEXITSTATUS 1
[2022-06-14T13:26:11.021] _job_complete: JobId=43757 done
[2022-06-14T13:39:25.371] _job_complete: JobId=43755 WEXITSTATUS 0
[2022-06-14T13:39:25.371] _job_complete: JobId=43755 done
[2022-06-14T13:41:57.988] _job_complete: JobId=43749 WEXITSTATUS 0
[2022-06-14T13:41:57.993] _job_complete: JobId=43749 done
[2022-06-14T14:22:03.847] _slurm_rpc_submit_batch_job: JobId=43758 InitPrio=20821 usec=456
[2022-06-14T14:22:04.515] sched: Allocate JobId=43758 NodeList=cpu01 #CPUs=32 Partition=cpu-opteron
[2022-06-14T14:23:36.588] _slurm_rpc_submit_batch_job: JobId=43759 InitPrio=20821 usec=436
[2022-06-14T14:25:17.550] _slurm_rpc_submit_batch_job: JobId=43760 InitPrio=20821 usec=444
[2022-06-14T14:26:35.375] _slurm_rpc_submit_batch_job: JobId=43761 InitPrio=20821 usec=460
[2022-06-14T14:27:01.754] _slurm_rpc_kill_job: REQUEST_KILL_JOB JobId=43761 uid 548200023
[2022-06-14T14:27:25.570] _slurm_rpc_submit_batch_job: JobId=43762 InitPrio=20958 usec=552
[2022-06-14T14:27:26.265] sched: Allocate JobId=43762 NodeList=cpu12 #CPUs=16 Partition=cpu-epyc
[2022-06-14T14:34:16.448] _job_complete: JobId=43751 WEXITSTATUS 0
[2022-06-14T14:34:16.448] _job_complete: JobId=43751 done
[2022-06-14T14:34:58.407] _slurm_rpc_submit_batch_job: JobId=43763 InitPrio=25022 usec=371
[2022-06-14T14:36:56.287] _slurm_rpc_kill_job: REQUEST_KILL_JOB JobId=43763 uid 548300543
[2022-06-14T14:40:29.424] sched: _slurm_rpc_allocate_resources JobId=43764 NodeList=(null) usec=1002
[2022-06-14T14:40:48.782] _slurm_rpc_submit_batch_job: JobId=43765 InitPrio=24321 usec=377
[2022-06-14T14:40:49.077] sched: Allocate JobId=43765 NodeList=gpu04 #CPUs=2 Partition=gpu-k40c
[2022-06-14T14:41:09.353] _slurm_rpc_kill_job: REQUEST_KILL_JOB JobId=43765 uid 548200003
[2022-06-14T14:42:39.686] _job_complete: JobId=43764 WTERMSIG 126
[2022-06-14T14:42:39.686] _job_complete: JobId=43764 cancelled by interactive user
[2022-06-14T14:42:39.686] _job_complete: JobId=43764 done
[2022-06-14T14:48:33.963] _slurm_rpc_submit_batch_job: JobId=43766 InitPrio=25823 usec=345
[2022-06-14T14:48:34.033] sched: Allocate JobId=43766 NodeList=gpu03 #CPUs=16 Partition=gpu-k10
[2022-06-14T14:49:08.014] _slurm_rpc_kill_job: REQUEST_KILL_JOB JobId=43766 uid 548300543
[2022-06-14T14:53:01.003] _slurm_rpc_submit_batch_job: JobId=43767 InitPrio=24085 usec=419
[2022-06-14T14:53:36.055] _slurm_rpc_kill_job: REQUEST_KILL_JOB JobId=43767 uid 548300543
[2022-06-14T14:58:18.120] _job_complete: JobId=43745 WEXITSTATUS 0
[2022-06-14T14:58:18.121] _job_complete: JobId=43745 done
[2022-06-14T14:58:18.971] sched: Allocate JobId=43678 NodeList=gpu05 #CPUs=16 Partition=gpu-v100s
[2022-06-14T15:07:27.387] _job_complete: JobId=43762 WEXITSTATUS 0
[2022-06-14T15:07:27.387] _job_complete: JobId=43762 done
[2022-06-14T15:11:36.498] _job_complete: JobId=43451 WEXITSTATUS 0
[2022-06-14T15:11:36.503] _job_complete: JobId=43451 done
[2022-06-14T15:11:41.495] sched: Allocate JobId=43759 NodeList=cpu04 #CPUs=32 Partition=cpu-opteron
[2022-06-14T15:17:49.884] _job_complete: JobId=43758 WEXITSTATUS 0
[2022-06-14T15:17:49.884] _job_complete: JobId=43758 done
[2022-06-14T15:17:50.854] sched: Allocate JobId=43760 NodeList=cpu01 #CPUs=32 Partition=cpu-opteron
[2022-06-14T15:33:41.870] Requeuing JobId=43677
[2022-06-14T15:34:52.164] _slurm_rpc_submit_batch_job: JobId=43768 InitPrio=20280 usec=454
[2022-06-14T15:34:53.152] sched: Allocate JobId=43768 NodeList=gpu03 #CPUs=32 Partition=gpu-k10
[2022-06-14T15:36:26.385] _job_complete: JobId=43768 WEXITSTATUS 0
[2022-06-14T15:36:26.385] _job_complete: JobId=43768 done
[2022-06-14T15:36:39.927] _slurm_rpc_kill_job: REQUEST_KILL_JOB JobId=43753 uid 548200021
[2022-06-14T15:36:45.869] _slurm_rpc_kill_job: REQUEST_KILL_JOB JobId=43756 uid 548200021
[2022-06-14T15:37:14.502] _slurm_rpc_submit_batch_job: JobId=43769 InitPrio=20280 usec=427
[2022-06-14T15:37:15.338] sched: Allocate JobId=43769 NodeList=gpu03 #CPUs=32 Partition=gpu-k10
[2022-06-14T15:37:32.598] _slurm_rpc_submit_batch_job: JobId=43770 InitPrio=20280 usec=376
[2022-06-14T15:37:34.996] _job_complete: JobId=43769 WEXITSTATUS 1
[2022-06-14T15:37:34.997] _job_complete: JobId=43769 done
[2022-06-14T15:37:35.349] sched: Allocate JobId=43770 NodeList=gpu03 #CPUs=32 Partition=gpu-k10
[2022-06-14T15:37:44.512] _slurm_rpc_submit_batch_job: JobId=43771 InitPrio=19606 usec=367
[2022-06-14T15:37:44.580] sched: Allocate JobId=43771 NodeList=cpu12 #CPUs=16 Partition=cpu-epyc
[2022-06-14T15:38:43.245] _slurm_rpc_kill_job: REQUEST_KILL_JOB JobId=43454 uid 548200017
[2022-06-14T15:38:53.111] sched: Allocate JobId=43754 NodeList=cpu13 #CPUs=32 Partition=cpu-epyc
[2022-06-14T15:39:39.133] _slurm_rpc_submit_batch_job: JobId=43772 InitPrio=19196 usec=391
[2022-06-14T15:39:52.109] _slurm_rpc_kill_job: REQUEST_KILL_JOB JobId=43732 uid 548200017
[2022-06-14T15:40:44.552] _slurm_rpc_submit_batch_job: JobId=43773 InitPrio=19469 usec=403
[2022-06-14T15:40:44.827] sched: Allocate JobId=43773 NodeList=cpu13 #CPUs=32 Partition=cpu-epyc
[2022-06-14T15:40:56.393] _slurm_rpc_kill_job: REQUEST_KILL_JOB JobId=43772 uid 548200017
[2022-06-14T15:42:35.456] _slurm_rpc_submit_batch_job: JobId=43774 InitPrio=21769 usec=819
[2022-06-14T15:42:36.249] sched: Allocate JobId=43774 NodeList=gpu02 #CPUs=16 Partition=gpu-titan
[2022-06-14T15:42:38.348] _job_complete: JobId=43774 WEXITSTATUS 127
[2022-06-14T15:42:38.349] _job_complete: JobId=43774 done
[2022-06-14T15:42:53.705] _slurm_rpc_kill_job: REQUEST_KILL_JOB JobId=43774 uid 548200029
[2022-06-14T15:44:08.544] _slurm_rpc_submit_batch_job: JobId=43775 InitPrio=21837 usec=841
[2022-06-14T15:44:09.365] sched: Allocate JobId=43775 NodeList=gpu04 #CPUs=8 Partition=gpu-k40c
[2022-06-14T15:44:11.500] _job_complete: JobId=43775 WEXITSTATUS 127
[2022-06-14T15:44:11.501] _job_complete: JobId=43775 done
[2022-06-14T15:44:25.767] _slurm_rpc_kill_job: REQUEST_KILL_JOB JobId=43775 uid 548200029
[2022-06-14T15:44:40.046] _slurm_rpc_submit_batch_job: JobId=43776 InitPrio=21769 usec=853
[2022-06-14T15:44:40.410] sched: Allocate JobId=43776 NodeList=gpu04 #CPUs=16 Partition=gpu-k40c
[2022-06-14T15:44:42.332] _job_complete: JobId=43776 WEXITSTATUS 127
[2022-06-14T15:44:42.333] _job_complete: JobId=43776 done
[2022-06-14T15:52:12.045] _slurm_rpc_submit_batch_job: JobId=43777 InitPrio=21769 usec=837
[2022-06-14T15:52:12.310] sched: Allocate JobId=43777 NodeList=gpu04 #CPUs=16 Partition=gpu-k40c
[2022-06-14T15:58:52.478] _job_complete: JobId=43754 WEXITSTATUS 0
[2022-06-14T15:58:52.478] _job_complete: JobId=43754 done
[2022-06-14T16:06:27.833] _job_complete: JobId=43759 WEXITSTATUS 0
[2022-06-14T16:06:27.833] _job_complete: JobId=43759 done
[2022-06-14T16:10:19.420] No nodes satisfy requirements for JobId=43778 in partition gpu-k10
[2022-06-14T16:10:19.420] _slurm_rpc_submit_batch_job: Requested node configuration is not available
[2022-06-14T16:10:37.658] _slurm_rpc_submit_batch_job: JobId=43779 InitPrio=20280 usec=558
[2022-06-14T16:10:38.246] sched/backfill: _start_job: Started JobId=43779 in gpu-titan on gpu02
[2022-06-14T16:12:27.241] _job_complete: JobId=43760 WEXITSTATUS 0
[2022-06-14T16:12:27.241] _job_complete: JobId=43760 done
[2022-06-14T16:13:07.687] _slurm_rpc_submit_batch_job: JobId=43780 InitPrio=20280 usec=548
[2022-06-14T16:18:13.447] Time limit exhausted for JobId=42798
[2022-06-14T17:04:59.592] _slurm_rpc_submit_batch_job: JobId=43781 InitPrio=19469 usec=550
[2022-06-14T17:04:59.831] sched: Allocate JobId=43781 NodeList=cpu13 #CPUs=32 Partition=cpu-epyc
[2022-06-14T17:06:44.869] _slurm_rpc_submit_batch_job: JobId=43782 InitPrio=19469 usec=381
[2022-06-14T17:06:44.971] sched: Allocate JobId=43782 NodeList=cpu01 #CPUs=32 Partition=cpu-opteron
[2022-06-14T17:32:43.908] Time limit exhausted for JobId=43661
[2022-06-14T17:33:45.425] _job_complete: JobId=43770 WEXITSTATUS 0
[2022-06-14T17:33:45.425] _job_complete: JobId=43770 done
[2022-06-14T19:09:33.497] _job_complete: JobId=43590 WEXITSTATUS 1
[2022-06-14T19:09:33.497] _job_complete: JobId=43590 done
[2022-06-14T19:28:18.049] _job_complete: JobId=43410 WEXITSTATUS 0
[2022-06-14T19:28:18.049] _job_complete: JobId=43410 done
[2022-06-14T19:39:17.317] _slurm_rpc_submit_batch_job: JobId=43783 InitPrio=19332 usec=479
[2022-06-14T19:39:17.823] sched: Allocate JobId=43783 NodeList=cpu12 #CPUs=48 Partition=cpu-epyc
[2022-06-14T20:35:26.649] _slurm_rpc_submit_batch_job: JobId=43784 InitPrio=20551 usec=474
[2022-06-14T20:35:26.955] sched: Allocate JobId=43784 NodeList=cpu08 #CPUs=32 Partition=cpu-opteron
[2022-06-14T20:39:01.528] _slurm_rpc_kill_job: REQUEST_KILL_JOB JobId=43717 uid 548200019
[2022-06-14T20:39:24.071] _slurm_rpc_kill_job: REQUEST_KILL_JOB JobId=43719 uid 548200019
[2022-06-14T20:40:40.788] _slurm_rpc_submit_batch_job: JobId=43785 InitPrio=20277 usec=492
[2022-06-14T20:40:41.493] sched: Allocate JobId=43785 NodeList=cpu05 #CPUs=64 Partition=cpu-opteron
[2022-06-14T20:42:05.580] _slurm_rpc_kill_job: REQUEST_KILL_JOB JobId=43721 uid 548200019
[2022-06-14T20:43:08.624] _slurm_rpc_kill_job: REQUEST_KILL_JOB JobId=43723 uid 548200019
[2022-06-14T20:45:27.365] _slurm_rpc_kill_job: REQUEST_KILL_JOB JobId=43722 uid 548200019
[2022-06-14T20:46:38.625] _slurm_rpc_submit_batch_job: JobId=43786 InitPrio=20277 usec=470
[2022-06-14T20:46:39.136] sched: Allocate JobId=43786 NodeList=cpu09 #CPUs=64 Partition=cpu-opteron
[2022-06-14T20:47:47.447] _slurm_rpc_submit_batch_job: JobId=43787 InitPrio=20551 usec=459
[2022-06-14T20:47:48.320] sched: Allocate JobId=43787 NodeList=cpu08 #CPUs=32 Partition=cpu-opteron
[2022-06-14T20:49:58.026] _slurm_rpc_submit_batch_job: JobId=43788 InitPrio=20551 usec=481
[2022-06-14T20:49:58.507] sched: Allocate JobId=43788 NodeList=cpu13 #CPUs=32 Partition=cpu-epyc
[2022-06-14T22:38:41.127] sched: _slurm_rpc_allocate_resources JobId=43789 NodeList=cpu03 usec=15604
[2022-06-14T23:53:30.375] _slurm_rpc_submit_batch_job: JobId=43790 InitPrio=20280 usec=428
[2022-06-14T23:53:31.024] sched: Allocate JobId=43790 NodeList=cpu10 #CPUs=32 Partition=cpu-opteron
[2022-06-15T00:05:20.348] _slurm_rpc_kill_job: REQUEST_KILL_JOB JobId=43779 uid 548200021
[2022-06-15T00:05:23.152] sched: Allocate JobId=43780 NodeList=gpu02 #CPUs=32 Partition=gpu-titan
[2022-06-15T00:06:24.555] _job_complete: JobId=43789 WEXITSTATUS 0
[2022-06-15T00:06:24.555] _job_complete: JobId=43789 done
[2022-06-15T00:08:58.320] _job_complete: JobId=43780 WEXITSTATUS 1
[2022-06-15T00:08:58.320] _job_complete: JobId=43780 done
[2022-06-15T00:11:26.116] _slurm_rpc_submit_batch_job: JobId=43791 InitPrio=20280 usec=387
[2022-06-15T00:11:26.997] sched: Allocate JobId=43791 NodeList=gpu02 #CPUs=32 Partition=gpu-titan
[2022-06-15T00:11:31.331] _slurm_rpc_submit_batch_job: JobId=43792 InitPrio=20280 usec=429
[2022-06-15T00:11:35.686] _job_complete: JobId=43791 WEXITSTATUS 1
[2022-06-15T00:11:35.686] _job_complete: JobId=43791 done
[2022-06-15T00:11:36.010] sched: Allocate JobId=43792 NodeList=gpu02 #CPUs=32 Partition=gpu-titan
[2022-06-15T00:12:57.612] _slurm_rpc_submit_batch_job: JobId=43793 InitPrio=20280 usec=544
[2022-06-15T00:15:03.579] _job_complete: JobId=43792 WEXITSTATUS 1
[2022-06-15T00:15:03.579] _job_complete: JobId=43792 done
[2022-06-15T00:15:03.888] sched: Allocate JobId=43793 NodeList=gpu02 #CPUs=32 Partition=gpu-titan
[2022-06-15T00:18:14.087] _slurm_rpc_submit_batch_job: JobId=43794 InitPrio=20551 usec=498
[2022-06-15T00:18:14.731] sched: Allocate JobId=43794 NodeList=cpu11 #CPUs=32 Partition=cpu-opteron
[2022-06-15T00:30:50.438] _slurm_rpc_kill_job: REQUEST_KILL_JOB JobId=43793 uid 548200021
[2022-06-15T00:30:58.946] _slurm_rpc_submit_batch_job: JobId=43795 InitPrio=20280 usec=402
[2022-06-15T00:30:59.030] sched: Allocate JobId=43795 NodeList=gpu02 #CPUs=32 Partition=gpu-titan
[2022-06-15T00:31:07.657] _slurm_rpc_submit_batch_job: JobId=43796 InitPrio=20280 usec=485
[2022-06-15T00:31:07.703] _job_complete: JobId=43795 WEXITSTATUS 1
[2022-06-15T00:31:07.703] _job_complete: JobId=43795 done
[2022-06-15T00:31:08.026] sched: Allocate JobId=43796 NodeList=gpu02 #CPUs=32 Partition=gpu-titan
[2022-06-15T00:33:05.920] _slurm_rpc_kill_job: REQUEST_KILL_JOB JobId=43796 uid 548200021
[2022-06-15T00:33:10.040] _slurm_rpc_submit_batch_job: JobId=43797 InitPrio=20280 usec=511
[2022-06-15T00:33:10.321] sched: Allocate JobId=43797 NodeList=gpu02 #CPUs=32 Partition=gpu-titan
[2022-06-15T00:33:59.737] _slurm_rpc_submit_batch_job: JobId=43798 InitPrio=20280 usec=427
[2022-06-15T00:43:17.381] _slurm_rpc_kill_job: REQUEST_KILL_JOB JobId=43422 uid 548300516
[2022-06-15T00:43:22.587] _slurm_rpc_kill_job: REQUEST_KILL_JOB JobId=43424 uid 548300516
[2022-06-15T00:43:28.293] _slurm_rpc_kill_job: REQUEST_KILL_JOB JobId=43425 uid 548300516
[2022-06-15T00:46:52.592] _slurm_rpc_submit_batch_job: JobId=43799 InitPrio=20010 usec=413
[2022-06-15T00:54:41.608] _slurm_rpc_submit_batch_job: JobId=43800 InitPrio=20010 usec=436
[2022-06-15T00:55:35.495] _job_complete: JobId=43790 WEXITSTATUS 0
[2022-06-15T00:55:35.495] _job_complete: JobId=43790 done
[2022-06-15T00:56:09.339] _slurm_rpc_submit_batch_job: JobId=43801 InitPrio=20010 usec=350
[2022-06-15T01:15:16.849] Time limit exhausted for JobId=43698
[2022-06-15T01:16:28.381] _job_complete: JobId=43797 WEXITSTATUS 1
[2022-06-15T01:16:28.381] _job_complete: JobId=43797 done
[2022-06-15T01:16:28.711] sched: Allocate JobId=43798 NodeList=gpu02 #CPUs=32 Partition=gpu-titan
[2022-06-15T01:16:37.105] _job_complete: JobId=43798 WEXITSTATUS 1
[2022-06-15T01:16:37.105] _job_complete: JobId=43798 done
[2022-06-15T01:20:46.445] Time limit exhausted for JobId=43700
[2022-06-15T01:20:48.364] sched: Allocate JobId=43591 NodeList=cpu15 #CPUs=48 Partition=cpu-epyc
[2022-06-15T07:37:52.072] _slurm_rpc_kill_job: REQUEST_KILL_JOB JobId=43677 uid 548300547
[2022-06-15T08:29:46.012] Time limit exhausted for JobId=43718
[2022-06-15T08:29:47.905] sched: Allocate JobId=43799 NodeList=cpu14 #CPUs=32 Partition=cpu-epyc
[2022-06-15T09:47:10.448] _slurm_rpc_submit_batch_job: JobId=43802 InitPrio=20280 usec=557
[2022-06-15T09:47:10.543] sched: Allocate JobId=43802 NodeList=gpu02 #CPUs=32 Partition=gpu-titan
[2022-06-15T09:47:14.179] _slurm_rpc_submit_batch_job: JobId=43803 InitPrio=20280 usec=502
[2022-06-15T09:52:48.339] _slurm_rpc_submit_batch_job: JobId=43804 InitPrio=25956 usec=479
[2022-06-15T09:52:48.425] sched: Allocate JobId=43804 NodeList=cpu10 #CPUs=32 Partition=cpu-opteron
[2022-06-15T09:53:19.716] _job_complete: JobId=43804 WEXITSTATUS 0
[2022-06-15T09:53:19.716] _job_complete: JobId=43804 done
[2022-06-15T09:57:39.811] _job_complete: JobId=43802 WEXITSTATUS 1
[2022-06-15T09:57:39.811] _job_complete: JobId=43802 done
[2022-06-15T09:57:40.109] sched: Allocate JobId=43803 NodeList=gpu02 #CPUs=32 Partition=gpu-titan
[2022-06-15T09:57:48.455] _job_complete: JobId=43803 WEXITSTATUS 1
[2022-06-15T09:57:48.455] _job_complete: JobId=43803 done
[2022-06-15T10:32:54.907] _slurm_rpc_submit_batch_job: JobId=43805 InitPrio=20821 usec=469
[2022-06-15T10:32:55.892] sched: Allocate JobId=43805 NodeList=cpu10 #CPUs=32 Partition=cpu-opteron
[2022-06-15T10:33:04.987] _slurm_rpc_submit_batch_job: JobId=43806 InitPrio=19945 usec=555
[2022-06-15T10:33:05.903] sched: Allocate JobId=43806 NodeList=gpu02 #CPUs=8 Partition=gpu-titan
[2022-06-15T10:35:01.400] _slurm_rpc_kill_job: REQUEST_KILL_JOB JobId=43806 uid 548200045
[2022-06-15T10:35:51.613] _slurm_rpc_submit_batch_job: JobId=43807 InitPrio=19945 usec=490
[2022-06-15T10:35:52.128] sched: Allocate JobId=43807 NodeList=gpu02 #CPUs=8 Partition=gpu-titan
[2022-06-15T10:46:14.660] _slurm_rpc_submit_batch_job: JobId=43808 InitPrio=20958 usec=417
[2022-06-15T10:46:15.270] sched: Allocate JobId=43808 NodeList=cpu03 #CPUs=16 Partition=cpu-opteron
[2022-06-15T10:46:22.146] _job_complete: JobId=43808 WEXITSTATUS 0
[2022-06-15T10:46:22.146] _job_complete: JobId=43808 done
[2022-06-15T10:49:36.237] _slurm_rpc_submit_batch_job: JobId=43809 InitPrio=20821 usec=436
[2022-06-15T10:49:36.632] sched: Allocate JobId=43809 NodeList=cpu03 #CPUs=32 Partition=cpu-opteron
[2022-06-15T10:49:59.258] _job_complete: JobId=43809 WEXITSTATUS 1
[2022-06-15T10:49:59.259] _job_complete: JobId=43809 done
[2022-06-15T10:50:14.334] _slurm_rpc_kill_job: REQUEST_KILL_JOB JobId=43805 uid 548200023
[2022-06-15T11:11:55.962] _slurm_rpc_submit_batch_job: JobId=43810 InitPrio=20280 usec=461
[2022-06-15T11:12:53.291] _slurm_rpc_submit_batch_job: JobId=43811 InitPrio=20280 usec=378
[2022-06-15T11:12:54.269] sched: Allocate JobId=43811 NodeList=gpu03 #CPUs=32 Partition=gpu-k10
[2022-06-15T11:13:09.196] _slurm_rpc_kill_job: REQUEST_KILL_JOB JobId=43810 uid 548200021
[2022-06-15T11:13:13.317] _job_complete: JobId=43811 WEXITSTATUS 1
[2022-06-15T11:13:13.317] _job_complete: JobId=43811 done
[2022-06-15T11:19:02.325] _job_complete: JobId=42981 WEXITSTATUS 0
[2022-06-15T11:19:02.329] _job_complete: JobId=42981 done
[2022-06-15T11:20:17.437] _slurm_rpc_submit_batch_job: JobId=43812 InitPrio=20280 usec=446
[2022-06-15T11:20:18.051] sched: Allocate JobId=43812 NodeList=gpu03 #CPUs=32 Partition=gpu-k10
[2022-06-15T11:20:38.002] _job_complete: JobId=43812 WEXITSTATUS 1
[2022-06-15T11:20:38.002] _job_complete: JobId=43812 done
[2022-06-15T11:23:16.831] _slurm_rpc_submit_batch_job: JobId=43813 InitPrio=20280 usec=501
[2022-06-15T11:23:17.439] sched: Allocate JobId=43813 NodeList=gpu03 #CPUs=32 Partition=gpu-k10
[2022-06-15T11:23:37.494] _job_complete: JobId=43813 WEXITSTATUS 1
[2022-06-15T11:23:37.494] _job_complete: JobId=43813 done
[2022-06-15T11:27:09.283] _slurm_rpc_submit_batch_job: JobId=43814 InitPrio=20280 usec=403
[2022-06-15T11:27:09.778] sched: Allocate JobId=43814 NodeList=gpu03 #CPUs=32 Partition=gpu-k10
[2022-06-15T11:35:07.987] _job_complete: JobId=43814 WEXITSTATUS 0
[2022-06-15T11:35:07.987] _job_complete: JobId=43814 done
[2022-06-15T11:38:00.893] _slurm_rpc_submit_batch_job: JobId=43815 InitPrio=20546 usec=456
[2022-06-15T11:38:01.154] sched: Allocate JobId=43815 NodeList=cpu03 #CPUs=1 Partition=cpu-opteron
[2022-06-15T11:38:03.922] _job_complete: JobId=43815 WEXITSTATUS 0
[2022-06-15T11:38:03.922] _job_complete: JobId=43815 done
[2022-06-15T11:39:36.844] _slurm_rpc_submit_batch_job: JobId=43816 InitPrio=20280 usec=591
[2022-06-15T11:39:37.294] sched: Allocate JobId=43816 NodeList=cpu11 #CPUs=32 Partition=cpu-opteron
[2022-06-15T11:39:43.964] _job_complete: JobId=43816 WEXITSTATUS 1
[2022-06-15T11:39:43.964] _job_complete: JobId=43816 done
[2022-06-15T11:40:49.687] _slurm_rpc_submit_batch_job: JobId=43817 InitPrio=20546 usec=493
[2022-06-15T11:40:50.402] sched: Allocate JobId=43817 NodeList=cpu03 #CPUs=1 Partition=cpu-opteron
[2022-06-15T11:40:53.273] _job_complete: JobId=43817 WEXITSTATUS 0
[2022-06-15T11:40:53.273] _job_complete: JobId=43817 done
[2022-06-15T11:41:02.860] _slurm_rpc_submit_batch_job: JobId=43818 InitPrio=20280 usec=474
[2022-06-15T11:41:03.421] sched: Allocate JobId=43818 NodeList=cpu11 #CPUs=32 Partition=cpu-opteron
[2022-06-15T11:41:10.936] _job_complete: JobId=43818 WEXITSTATUS 1
[2022-06-15T11:41:10.936] _job_complete: JobId=43818 done
[2022-06-15T11:44:36.249] _slurm_rpc_submit_batch_job: JobId=43819 InitPrio=20546 usec=446
[2022-06-15T11:44:36.845] sched: Allocate JobId=43819 NodeList=cpu03 #CPUs=1 Partition=cpu-opteron
[2022-06-15T11:44:39.506] _job_complete: JobId=43819 WEXITSTATUS 0
[2022-06-15T11:44:39.507] _job_complete: JobId=43819 done
[2022-06-15T11:44:50.392] _slurm_rpc_submit_batch_job: JobId=43820 InitPrio=20280 usec=438
[2022-06-15T11:44:50.864] sched: Allocate JobId=43820 NodeList=cpu11 #CPUs=32 Partition=cpu-opteron
[2022-06-15T11:44:58.316] _job_complete: JobId=43820 WEXITSTATUS 1
[2022-06-15T11:44:58.316] _job_complete: JobId=43820 done
[2022-06-15T11:45:51.467] _slurm_rpc_submit_batch_job: JobId=43821 InitPrio=25956 usec=602
[2022-06-15T11:46:39.337] _slurm_rpc_kill_job: REQUEST_KILL_JOB JobId=43821 uid 548200084
[2022-06-15T11:47:17.816] _slurm_rpc_submit_batch_job: JobId=43822 InitPrio=26093 usec=501
[2022-06-15T11:47:58.204] _slurm_rpc_kill_job: REQUEST_KILL_JOB JobId=43822 uid 548200084
[2022-06-15T11:49:00.671] _slurm_rpc_submit_batch_job: JobId=43823 InitPrio=25956 usec=418
[2022-06-15T11:58:28.343] _slurm_rpc_submit_batch_job: JobId=43824 InitPrio=20280 usec=426
[2022-06-15T11:58:28.374] sched: Allocate JobId=43824 NodeList=gpu03 #CPUs=32 Partition=gpu-k10
[2022-06-15T11:59:52.821] sched: _slurm_rpc_allocate_resources JobId=43825 NodeList=cpu03 usec=1186
[2022-06-15T12:00:20.587] _job_complete: JobId=43824 WEXITSTATUS 0
[2022-06-15T12:00:20.587] _job_complete: JobId=43824 done
[2022-06-15T12:18:43.646] _slurm_rpc_kill_job: REQUEST_KILL_JOB JobId=43823 uid 548200084
[2022-06-15T12:19:06.542] _slurm_rpc_submit_batch_job: JobId=43826 InitPrio=26093 usec=576
[2022-06-15T12:19:39.764] _slurm_rpc_kill_job: REQUEST_KILL_JOB JobId=43826 uid 548200084
[2022-06-15T12:19:47.924] _get_job_parts: invalid partition specified: cpu-opter
[2022-06-15T12:19:47.924] _slurm_rpc_submit_batch_job: Invalid partition name specified
[2022-06-15T12:20:42.670] _slurm_rpc_submit_batch_job: JobId=43827 InitPrio=25956 usec=659
[2022-06-15T12:20:42.785] sched: Allocate JobId=43827 NodeList=cpu04 #CPUs=32 Partition=cpu-opteron
[2022-06-15T12:28:57.800] _job_complete: JobId=43827 WEXITSTATUS 0
[2022-06-15T12:28:57.800] _job_complete: JobId=43827 done
[2022-06-15T12:37:34.398] Requeuing JobId=43799
[2022-06-15T12:37:34.413] sched: Allocate JobId=43800 NodeList=cpu14 #CPUs=32 Partition=cpu-epyc
[2022-06-15T12:39:47.504] _slurm_rpc_requeue: Requeue of JobId=43801 returned an error: Job is pending execution
[2022-06-15T12:39:50.635] Requeuing JobId=43800
[2022-06-15T12:39:50.636] sched: Allocate JobId=43801 NodeList=cpu14 #CPUs=32 Partition=cpu-epyc
[2022-06-15T12:39:52.877] sched: _hold_job_rec: hold on JobId=43801 by uid 548200003
[2022-06-15T12:39:52.877] sched: _update_job: set priority to 0 for JobId=43801
[2022-06-15T12:39:52.877] _update_job: updating accounting
[2022-06-15T12:39:52.877] _slurm_rpc_update_job: complete JobId=43801 uid=548200003 usec=913
[2022-06-15T12:40:01.369] Requeuing JobId=43801
[2022-06-15T13:14:12.159] _slurm_rpc_submit_batch_job: JobId=43828 InitPrio=20280 usec=581
[2022-06-15T13:14:12.692] sched: Allocate JobId=43828 NodeList=gpu03 #CPUs=32 Partition=gpu-k10
[2022-06-15T13:58:37.163] _slurm_rpc_submit_batch_job: JobId=43829 InitPrio=20280 usec=545
[2022-06-15T13:58:37.726] sched: Allocate JobId=43829 NodeList=cpu10 #CPUs=32 Partition=cpu-opteron
[2022-06-15T14:04:25.670] _job_complete: JobId=43829 WEXITSTATUS 0
[2022-06-15T14:04:25.671] _job_complete: JobId=43829 done
[2022-06-15T14:30:51.974] _slurm_rpc_kill_job: REQUEST_KILL_JOB JobId=43799 uid 548300516
[2022-06-15T14:30:56.408] _slurm_rpc_kill_job: REQUEST_KILL_JOB JobId=43800 uid 548300516
[2022-06-15T14:31:01.275] _slurm_rpc_kill_job: REQUEST_KILL_JOB JobId=43811 uid 548300516
[2022-06-15T14:31:01.275] job_str_signal(3): invalid JobId=43811
[2022-06-15T14:31:01.275] _slurm_rpc_kill_job: job_str_signal() uid=548300516 JobId=43811 sig=9 returned: Invalid job id specified
[2022-06-15T14:31:06.299] _slurm_rpc_kill_job: REQUEST_KILL_JOB JobId=43801 uid 548300516
[2022-06-15T15:05:20.351] _slurm_rpc_submit_batch_job: JobId=43830 InitPrio=25956 usec=536
[2022-06-15T15:05:20.717] sched: Allocate JobId=43830 NodeList=cpu04 #CPUs=32 Partition=cpu-opteron
[2022-06-15T15:05:45.185] _job_complete: JobId=43830 WEXITSTATUS 0
[2022-06-15T15:05:45.185] _job_complete: JobId=43830 done
[2022-06-15T15:19:14.971] _slurm_rpc_submit_batch_job: JobId=43831 InitPrio=25956 usec=542
[2022-06-15T15:19:15.291] sched: Allocate JobId=43831 NodeList=cpu04 #CPUs=32 Partition=cpu-opteron
[2022-06-15T15:26:43.961] _slurm_rpc_submit_batch_job: JobId=43832 InitPrio=20551 usec=438
[2022-06-15T15:26:44.062] sched: Allocate JobId=43832 NodeList=cpu14 #CPUs=32 Partition=cpu-epyc
[2022-06-15T15:27:46.188] _job_complete: JobId=43831 WEXITSTATUS 0
[2022-06-15T15:27:46.188] _job_complete: JobId=43831 done
[2022-06-15T15:46:33.358] _slurm_rpc_submit_batch_job: JobId=43833 InitPrio=20551 usec=424
[2022-06-15T15:46:34.261] sched: Allocate JobId=43833 NodeList=cpu04 #CPUs=32 Partition=cpu-opteron
[2022-06-15T15:46:49.698] _slurm_rpc_submit_batch_job: JobId=43834 InitPrio=20958 usec=443
[2022-06-15T15:46:50.294] sched: Allocate JobId=43834 NodeList=cpu03 #CPUs=16 Partition=cpu-opteron
[2022-06-15T15:51:01.365] _slurm_rpc_submit_batch_job: JobId=43835 InitPrio=20546 usec=410
[2022-06-15T15:51:01.761] sched: Allocate JobId=43835 NodeList=cpu03 #CPUs=1 Partition=cpu-opteron
[2022-06-15T15:51:04.791] _job_complete: JobId=43835 WEXITSTATUS 0
[2022-06-15T15:51:04.792] _job_complete: JobId=43835 done
[2022-06-15T15:51:38.724] _slurm_rpc_submit_batch_job: JobId=43836 InitPrio=20280 usec=434
[2022-06-15T15:51:38.804] sched: Allocate JobId=43836 NodeList=cpu11 #CPUs=32 Partition=cpu-opteron
[2022-06-15T15:52:18.459] _slurm_rpc_submit_batch_job: JobId=43837 InitPrio=25956 usec=429
[2022-06-15T15:52:18.866] sched: Allocate JobId=43837 NodeList=cpu10 #CPUs=32 Partition=cpu-opteron
[2022-06-15T15:52:20.133] _job_complete: JobId=43837 WEXITSTATUS 1
[2022-06-15T15:52:20.133] _job_complete: JobId=43837 done
[2022-06-15T15:52:49.172] _job_complete: JobId=43832 OOM failure
[2022-06-15T15:52:49.172] _job_complete: JobId=43832 done
[2022-06-15T15:52:58.812] _slurm_rpc_submit_batch_job: JobId=43838 InitPrio=25956 usec=407
[2022-06-15T15:52:59.026] sched: Allocate JobId=43838 NodeList=cpu10 #CPUs=32 Partition=cpu-opteron
[2022-06-15T15:54:05.867] _slurm_rpc_submit_batch_job: JobId=43839 InitPrio=20551 usec=462
[2022-06-15T15:54:27.814] _slurm_rpc_submit_batch_job: JobId=43840 InitPrio=20551 usec=575
[2022-06-15T15:54:28.155] sched: Allocate JobId=43840 NodeList=cpu14 #CPUs=32 Partition=cpu-epyc
[2022-06-15T15:54:54.137] _job_complete: JobId=43838 WEXITSTATUS 0
[2022-06-15T15:54:54.138] _job_complete: JobId=43838 done
[2022-06-15T15:54:54.625] sched: Allocate JobId=43839 NodeList=cpu10 #CPUs=32 Partition=cpu-opteron
[2022-06-15T16:11:37.875] _slurm_rpc_submit_batch_job: JobId=43841 InitPrio=25956 usec=475
[2022-06-15T16:12:41.438] _job_complete: JobId=43781 WEXITSTATUS 0
[2022-06-15T16:12:41.443] _job_complete: JobId=43781 done
[2022-06-15T16:15:02.085] _job_complete: JobId=43836 WEXITSTATUS 0
[2022-06-15T16:15:02.085] _job_complete: JobId=43836 done
[2022-06-15T16:15:02.623] sched: Allocate JobId=43841 NodeList=cpu11 #CPUs=32 Partition=cpu-opteron
[2022-06-15T16:15:04.066] _job_complete: JobId=43841 WEXITSTATUS 1
[2022-06-15T16:15:04.066] _job_complete: JobId=43841 done
[2022-06-15T16:20:26.154] _slurm_rpc_submit_batch_job: JobId=43842 InitPrio=25956 usec=506
[2022-06-15T16:20:26.974] sched: Allocate JobId=43842 NodeList=cpu11 #CPUs=32 Partition=cpu-opteron
[2022-06-15T16:20:46.461] _job_complete: JobId=43842 WEXITSTATUS 0
[2022-06-15T16:20:46.461] _job_complete: JobId=43842 done
[2022-06-15T16:35:24.937] _slurm_rpc_submit_batch_job: JobId=43843 InitPrio=25956 usec=432
[2022-06-15T16:35:25.572] sched: Allocate JobId=43843 NodeList=cpu11 #CPUs=32 Partition=cpu-opteron
[2022-06-15T16:37:21.219] _job_complete: JobId=43843 WEXITSTATUS 0
[2022-06-15T16:37:21.219] _job_complete: JobId=43843 done
[2022-06-15T16:52:41.831] _slurm_rpc_submit_batch_job: JobId=43844 InitPrio=25956 usec=507
[2022-06-15T16:52:42.626] sched: Allocate JobId=43844 NodeList=cpu11 #CPUs=32 Partition=cpu-opteron
[2022-06-15T16:54:44.168] _job_complete: JobId=43844 WEXITSTATUS 0
[2022-06-15T16:54:44.168] _job_complete: JobId=43844 done
[2022-06-15T16:56:41.457] _slurm_rpc_submit_batch_job: JobId=43845 InitPrio=19469 usec=417
[2022-06-15T16:56:41.984] sched: Allocate JobId=43845 NodeList=cpu13 #CPUs=32 Partition=cpu-epyc
[2022-06-15T16:58:07.198] _job_complete: JobId=43591 WEXITSTATUS 1
[2022-06-15T16:58:07.199] _job_complete: JobId=43591 done
[2022-06-15T17:24:07.025] _job_complete: JobId=43828 WEXITSTATUS 1
[2022-06-15T17:24:07.025] _job_complete: JobId=43828 done
[2022-06-15T17:41:40.869] _slurm_rpc_submit_batch_job: JobId=43846 InitPrio=25956 usec=460
[2022-06-15T17:41:41.885] sched: Allocate JobId=43846 NodeList=cpu11 #CPUs=32 Partition=cpu-opteron
[2022-06-15T17:41:57.627] _job_complete: JobId=43846 WEXITSTATUS 0
[2022-06-15T17:41:57.627] _job_complete: JobId=43846 done
[2022-06-15T18:16:04.651] _job_complete: JobId=43840 WEXITSTATUS 0
[2022-06-15T18:16:04.652] _job_complete: JobId=43840 done
[2022-06-15T18:51:13.255] _slurm_rpc_submit_batch_job: JobId=43847 InitPrio=25956 usec=493
[2022-06-15T18:51:13.704] sched: Allocate JobId=43847 NodeList=cpu11 #CPUs=32 Partition=cpu-opteron
[2022-06-15T18:53:16.816] _job_complete: JobId=43847 WEXITSTATUS 0
[2022-06-15T18:53:16.816] _job_complete: JobId=43847 done
[2022-06-15T19:07:08.918] _job_complete: JobId=43825 WEXITSTATUS 0
[2022-06-15T19:07:08.918] _job_complete: JobId=43825 done
[2022-06-15T19:12:09.542] cleanup_completing: JobId=43825 completion process took 301 seconds
[2022-06-15T19:20:17.715] _slurm_rpc_submit_batch_job: JobId=43848 InitPrio=25956 usec=537
[2022-06-15T19:20:18.099] sched: Allocate JobId=43848 NodeList=cpu11 #CPUs=32 Partition=cpu-opteron
[2022-06-15T19:20:20.432] _job_complete: JobId=43848 WEXITSTATUS 1
[2022-06-15T19:20:20.432] _job_complete: JobId=43848 done
[2022-06-15T19:35:52.358] _slurm_rpc_submit_batch_job: JobId=43849 InitPrio=25956 usec=444
[2022-06-15T19:35:52.920] sched: Allocate JobId=43849 NodeList=cpu11 #CPUs=32 Partition=cpu-opteron
[2022-06-15T19:36:11.414] _job_complete: JobId=43849 WEXITSTATUS 0
[2022-06-15T19:36:11.414] _job_complete: JobId=43849 done
[2022-06-15T19:46:05.752] _slurm_rpc_submit_batch_job: JobId=43850 InitPrio=25956 usec=551
[2022-06-15T19:46:06.274] sched: Allocate JobId=43850 NodeList=cpu11 #CPUs=32 Partition=cpu-opteron
[2022-06-15T19:47:57.669] _job_complete: JobId=43850 WEXITSTATUS 0
[2022-06-15T19:47:57.669] _job_complete: JobId=43850 done
[2022-06-15T20:09:48.512] _slurm_rpc_submit_batch_job: JobId=43851 InitPrio=25956 usec=527
[2022-06-15T20:09:48.855] sched: Allocate JobId=43851 NodeList=cpu11 #CPUs=32 Partition=cpu-opteron
[2022-06-15T20:10:11.316] _job_complete: JobId=43851 WEXITSTATUS 0
[2022-06-15T20:10:11.316] _job_complete: JobId=43851 done
[2022-06-15T20:21:55.250] _slurm_rpc_submit_batch_job: JobId=43852 InitPrio=25956 usec=502
[2022-06-15T20:21:56.104] sched: Allocate JobId=43852 NodeList=cpu11 #CPUs=32 Partition=cpu-opteron
[2022-06-15T20:23:52.522] _job_complete: JobId=43852 WEXITSTATUS 0
[2022-06-15T20:23:52.522] _job_complete: JobId=43852 done
[2022-06-15T20:35:46.132] Time limit exhausted for JobId=43784
[2022-06-15T20:40:46.733] Time limit exhausted for JobId=43785
[2022-06-15T20:46:46.860] Time limit exhausted for JobId=43786
[2022-06-15T20:48:16.104] Time limit exhausted for JobId=43787
[2022-06-15T20:50:16.283] Time limit exhausted for JobId=43788
[2022-06-15T20:50:38.865] _slurm_rpc_submit_batch_job: JobId=43853 InitPrio=20684 usec=607
[2022-06-15T20:50:39.332] sched: Allocate JobId=43853 NodeList=cpu15 #CPUs=48 Partition=cpu-epyc
[2022-06-15T20:54:56.568] _slurm_rpc_submit_batch_job: JobId=43854 InitPrio=20684 usec=818
[2022-06-15T20:54:56.833] sched: Allocate JobId=43854 NodeList=cpu15 #CPUs=48 Partition=cpu-epyc
[2022-06-15T20:55:12.655] _slurm_rpc_submit_batch_job: JobId=43855 InitPrio=20280 usec=418
[2022-06-15T20:55:12.865] sched: Allocate JobId=43855 NodeList=cpu13 #CPUs=32 Partition=cpu-epyc
[2022-06-15T20:55:57.736] _slurm_rpc_submit_batch_job: JobId=43856 InitPrio=20143 usec=496
[2022-06-15T20:56:50.899] _slurm_rpc_submit_batch_job: JobId=43857 InitPrio=20280 usec=593
[2022-06-15T20:56:50.998] sched: Allocate JobId=43857 NodeList=cpu14 #CPUs=32 Partition=cpu-epyc
[2022-06-15T20:57:39.722] _slurm_rpc_kill_job: REQUEST_KILL_JOB JobId=43856 uid 548200019
[2022-06-15T20:58:35.642] _slurm_rpc_submit_batch_job: JobId=43858 InitPrio=20006 usec=467
[2022-06-15T20:58:36.232] sched: Allocate JobId=43858 NodeList=cpu05 #CPUs=64 Partition=cpu-opteron
[2022-06-15T20:59:43.698] _slurm_rpc_submit_batch_job: JobId=43859 InitPrio=20006 usec=547
[2022-06-15T20:59:44.329] sched: Allocate JobId=43859 NodeList=cpu08 #CPUs=64 Partition=cpu-opteron
[2022-06-15T21:00:39.226] _slurm_rpc_submit_batch_job: JobId=43860 InitPrio=20821 usec=416
[2022-06-15T21:00:39.413] sched: Allocate JobId=43860 NodeList=cpu11 #CPUs=32 Partition=cpu-opteron
[2022-06-15T21:01:54.732] _slurm_rpc_submit_batch_job: JobId=43861 InitPrio=20821 usec=453
[2022-06-15T21:01:55.518] sched: Allocate JobId=43861 NodeList=cpu09 #CPUs=32 Partition=cpu-opteron
[2022-06-15T21:03:03.753] _slurm_rpc_submit_batch_job: JobId=43862 InitPrio=20006 usec=454
[2022-06-15T21:03:58.563] _slurm_rpc_kill_job: REQUEST_KILL_JOB JobId=43862 uid 548200019
[2022-06-15T21:03:59.910] _slurm_rpc_submit_batch_job: JobId=43863 InitPrio=20821 usec=424
[2022-06-15T21:04:00.794] sched: Allocate JobId=43863 NodeList=cpu09 #CPUs=32 Partition=cpu-opteron
[2022-06-15T21:04:13.376] _slurm_rpc_submit_batch_job: JobId=43864 InitPrio=20280 usec=414
[2022-06-15T21:04:41.592] _job_complete: JobId=43853 WEXITSTATUS 0
[2022-06-15T21:04:41.592] _job_complete: JobId=43853 done
[2022-06-15T21:05:20.372] _slurm_rpc_submit_batch_job: JobId=43865 InitPrio=20684 usec=485
[2022-06-15T21:05:20.908] sched: Allocate JobId=43865 NodeList=cpu15 #CPUs=48 Partition=cpu-epyc
[2022-06-15T21:20:19.983] _slurm_rpc_submit_batch_job: JobId=43866 InitPrio=20551 usec=542
[2022-06-15T21:20:20.673] sched: Allocate JobId=43866 NodeList=gpu03 #CPUs=32 Partition=gpu-k10
[2022-06-15T21:50:39.808] _job_complete: JobId=43860 WEXITSTATUS 0
[2022-06-15T21:50:39.808] _job_complete: JobId=43860 done
[2022-06-15T21:50:41.890] sched: Allocate JobId=43864 NodeList=cpu11 #CPUs=32 Partition=cpu-opteron
[2022-06-15T21:53:04.044] _job_complete: JobId=43863 WEXITSTATUS 0
[2022-06-15T21:53:04.045] _job_complete: JobId=43863 done
[2022-06-15T22:18:41.663] _job_complete: JobId=43854 WEXITSTATUS 0
[2022-06-15T22:18:41.664] _job_complete: JobId=43854 done
[2022-06-15T22:25:33.087] _job_complete: JobId=43865 WEXITSTATUS 0
[2022-06-15T22:25:33.087] _job_complete: JobId=43865 done
[2022-06-15T22:32:05.502] _job_complete: JobId=43866 WEXITSTATUS 1
[2022-06-15T22:32:05.502] _job_complete: JobId=43866 done
[2022-06-15T22:52:08.862] _slurm_rpc_submit_batch_job: JobId=43867 InitPrio=21357 usec=489
[2022-06-15T22:52:09.025] sched: Allocate JobId=43867 NodeList=cpu15 #CPUs=1 Partition=cpu-epyc
[2022-06-15T22:52:29.452] _job_complete: JobId=43867 WEXITSTATUS 0
[2022-06-15T22:52:29.452] _job_complete: JobId=43867 done
[2022-06-15T22:53:44.474] _slurm_rpc_submit_batch_job: JobId=43868 InitPrio=21357 usec=405
[2022-06-15T22:53:45.282] sched: Allocate JobId=43868 NodeList=cpu15 #CPUs=1 Partition=cpu-epyc
[2022-06-15T22:54:05.791] _job_complete: JobId=43868 WEXITSTATUS 0
[2022-06-15T22:54:05.792] _job_complete: JobId=43868 done
[2022-06-15T22:54:29.944] _slurm_rpc_submit_batch_job: JobId=43869 InitPrio=21357 usec=408
[2022-06-15T22:54:30.345] sched: Allocate JobId=43869 NodeList=cpu15 #CPUs=1 Partition=cpu-epyc
[2022-06-15T22:54:50.732] _job_complete: JobId=43869 WEXITSTATUS 0
[2022-06-15T22:54:50.732] _job_complete: JobId=43869 done
[2022-06-15T23:22:12.343] _slurm_rpc_submit_batch_job: JobId=43870 InitPrio=23120 usec=469
[2022-06-15T23:56:08.742] _slurm_rpc_submit_batch_job: JobId=43871 InitPrio=20684 usec=570
[2022-06-15T23:56:09.307] sched: Allocate JobId=43871 NodeList=cpu15 #CPUs=48 Partition=cpu-epyc
[2022-06-15T23:58:39.199] _slurm_rpc_submit_batch_job: JobId=43872 InitPrio=20684 usec=442
[2022-06-16T00:01:56.351] _slurm_rpc_submit_batch_job: JobId=43873 InitPrio=20684 usec=417
[2022-06-16T00:03:41.865] _slurm_rpc_submit_batch_job: JobId=43874 InitPrio=20684 usec=408
[2022-06-16T00:05:15.871] _job_complete: JobId=43871 WEXITSTATUS 0
[2022-06-16T00:05:15.872] _job_complete: JobId=43871 done
[2022-06-16T00:05:16.601] sched: Allocate JobId=43872 NodeList=cpu15 #CPUs=48 Partition=cpu-epyc
[2022-06-16T00:05:16.602] sched: Allocate JobId=43873 NodeList=cpu15 #CPUs=48 Partition=cpu-epyc
[2022-06-16T00:18:16.971] Time limit exhausted for JobId=43794
[2022-06-16T00:19:13.620] _job_complete: JobId=43873 WEXITSTATUS 0
[2022-06-16T00:19:13.620] _job_complete: JobId=43873 done
[2022-06-16T00:19:13.944] sched: Allocate JobId=43874 NodeList=cpu15 #CPUs=48 Partition=cpu-epyc
[2022-06-16T00:21:45.939] _slurm_rpc_submit_batch_job: JobId=43875 InitPrio=20551 usec=472
[2022-06-16T00:21:46.293] sched: Allocate JobId=43875 NodeList=gpu03 #CPUs=32 Partition=gpu-k10
[2022-06-16T00:21:54.023] _slurm_rpc_submit_batch_job: JobId=43876 InitPrio=20010 usec=465
[2022-06-16T00:21:54.304] sched: Allocate JobId=43876 NodeList=cpu09 #CPUs=32 Partition=cpu-opteron
[2022-06-16T00:23:38.923] _job_complete: JobId=43875 WEXITSTATUS 0
[2022-06-16T00:23:38.923] _job_complete: JobId=43875 done
[2022-06-16T00:33:30.787] _slurm_rpc_submit_batch_job: JobId=43877 InitPrio=20551 usec=572
[2022-06-16T00:33:31.566] sched: Allocate JobId=43877 NodeList=gpu03 #CPUs=32 Partition=gpu-k10
[2022-06-16T01:29:49.751] _job_complete: JobId=43872 WEXITSTATUS 0
[2022-06-16T01:29:49.751] _job_complete: JobId=43872 done
[2022-06-16T01:42:18.054] _job_complete: JobId=43874 WEXITSTATUS 0
[2022-06-16T01:42:18.055] _job_complete: JobId=43874 done
[2022-06-16T02:51:13.324] _job_complete: JobId=43861 WEXITSTATUS 0
[2022-06-16T02:51:13.324] _job_complete: JobId=43861 done
[2022-06-16T07:43:53.149] _job_complete: JobId=43777 WEXITSTATUS 1
[2022-06-16T07:43:53.154] _job_complete: JobId=43777 done
[2022-06-16T07:48:11.774] _job_complete: JobId=43877 WEXITSTATUS 1
[2022-06-16T07:48:11.774] _job_complete: JobId=43877 done
[2022-06-16T09:08:04.423] _slurm_rpc_submit_batch_job: JobId=43878 InitPrio=21632 usec=396
[2022-06-16T09:08:05.325] sched: Allocate JobId=43878 NodeList=cpu09 #CPUs=32 Partition=cpu-opteron
[2022-06-16T09:10:11.749] _slurm_rpc_submit_batch_job: JobId=43879 InitPrio=22039 usec=461
[2022-06-16T09:10:12.511] sched: Allocate JobId=43879 NodeList=gpu04 #CPUs=16 Partition=gpu-k40c
[2022-06-16T09:17:27.989] _slurm_rpc_submit_batch_job: JobId=43880 InitPrio=25956 usec=406
[2022-06-16T09:17:28.532] sched: Allocate JobId=43880 NodeList=cpu11 #CPUs=32 Partition=cpu-opteron
[2022-06-16T09:19:05.482] _job_complete: JobId=43880 WEXITSTATUS 0
[2022-06-16T09:19:05.482] _job_complete: JobId=43880 done
[2022-06-16T09:37:57.232] _job_complete: JobId=43878 WEXITSTATUS 0
[2022-06-16T09:37:57.233] _job_complete: JobId=43878 done
[2022-06-16T10:06:13.471] _slurm_rpc_submit_batch_job: JobId=43881 InitPrio=20551 usec=589
[2022-06-16T10:06:14.472] sched: Allocate JobId=43881 NodeList=gpu03 #CPUs=32 Partition=gpu-k10
[2022-06-16T10:22:48.753] sched: _slurm_rpc_allocate_resources JobId=43882 NodeList=cpu03 usec=4651
[2022-06-16T10:31:03.729] _job_complete: JobId=43833 WEXITSTATUS 0
[2022-06-16T10:31:03.729] _job_complete: JobId=43833 done
[2022-06-16T10:34:40.439] _slurm_rpc_submit_batch_job: JobId=43883 InitPrio=23661 usec=389
[2022-06-16T10:34:40.873] sched: Allocate JobId=43883 NodeList=cpu04 #CPUs=16 Partition=cpu-opteron
[2022-06-16T10:34:43.702] _slurm_rpc_submit_batch_job: JobId=43884 InitPrio=23661 usec=398
[2022-06-16T10:34:43.859] sched: Allocate JobId=43884 NodeList=cpu04 #CPUs=16 Partition=cpu-opteron
[2022-06-16T10:36:20.999] Time limit exhausted for JobId=43807
[2022-06-16T10:48:46.025] _slurm_rpc_submit_batch_job: JobId=43885 InitPrio=19945 usec=416
[2022-06-16T10:48:46.616] sched: Allocate JobId=43885 NodeList=gpu02 #CPUs=8 Partition=gpu-titan
[2022-06-16T10:49:10.506] _slurm_rpc_kill_job: REQUEST_KILL_JOB JobId=43885 uid 548200045
[2022-06-16T10:49:28.283] _slurm_rpc_submit_batch_job: JobId=43886 InitPrio=19945 usec=379
[2022-06-16T10:49:28.663] sched: Allocate JobId=43886 NodeList=gpu02 #CPUs=8 Partition=gpu-titan
[2022-06-16T10:53:05.618] _slurm_rpc_kill_job: REQUEST_KILL_JOB JobId=43884 uid 548300558
[2022-06-16T10:53:09.020] _slurm_rpc_kill_job: REQUEST_KILL_JOB JobId=43883 uid 548300558
[2022-06-16T11:07:20.827] _slurm_rpc_kill_job: REQUEST_KILL_JOB JobId=43773 uid 548200017
[2022-06-16T11:07:45.169] _slurm_rpc_submit_batch_job: JobId=43887 InitPrio=19196 usec=374
[2022-06-16T11:07:45.725] sched: Allocate JobId=43887 NodeList=cpu15 #CPUs=64 Partition=cpu-epyc
[2022-06-16T11:09:41.119] _slurm_rpc_kill_job: REQUEST_KILL_JOB JobId=43783 uid 548200017
[2022-06-16T11:10:04.262] _slurm_rpc_submit_batch_job: JobId=43888 InitPrio=19332 usec=374
[2022-06-16T11:10:04.918] sched: Allocate JobId=43888 NodeList=cpu12 #CPUs=48 Partition=cpu-epyc
[2022-06-16T11:11:58.223] _slurm_rpc_submit_batch_job: JobId=43889 InitPrio=23524 usec=435
[2022-06-16T11:11:59.090] sched: Allocate JobId=43889 NodeList=cpu04 #CPUs=32 Partition=cpu-opteron
[2022-06-16T11:12:06.535] _slurm_rpc_submit_batch_job: JobId=43890 InitPrio=23524 usec=500
[2022-06-16T11:12:07.099] sched: Allocate JobId=43890 NodeList=cpu09 #CPUs=32 Partition=cpu-opteron
[2022-06-16T11:16:43.194] _slurm_rpc_kill_job: REQUEST_KILL_JOB JobId=43887 uid 548200017
[2022-06-16T11:17:06.863] _slurm_rpc_submit_batch_job: JobId=43891 InitPrio=19196 usec=426
[2022-06-16T11:17:07.647] sched: Allocate JobId=43891 NodeList=cpu15 #CPUs=64 Partition=cpu-epyc
[2022-06-16T11:29:58.912] _slurm_rpc_submit_batch_job: JobId=43892 InitPrio=19469 usec=349
[2022-06-16T11:29:59.069] sched: Allocate JobId=43892 NodeList=cpu13 #CPUs=32 Partition=cpu-epyc
[2022-06-16T11:42:13.481] _slurm_rpc_submit_batch_job: JobId=43893 InitPrio=21498 usec=826
[2022-06-16T11:42:46.453] _slurm_rpc_kill_job: REQUEST_KILL_JOB JobId=43893 uid 548200029
[2022-06-16T11:43:17.539] _slurm_rpc_submit_batch_job: JobId=43894 InitPrio=21498 usec=837
[2022-06-16T11:43:17.703] sched: Allocate JobId=43894 NodeList=gpu02 #CPUs=16 Partition=gpu-titan
[2022-06-16T11:43:40.025] _slurm_rpc_submit_batch_job: JobId=43895 InitPrio=25956 usec=507
[2022-06-16T11:43:40.738] sched: Allocate JobId=43895 NodeList=cpu11 #CPUs=32 Partition=cpu-opteron
[2022-06-16T11:44:56.659] _job_complete: JobId=43895 WEXITSTATUS 0
[2022-06-16T11:44:56.659] _job_complete: JobId=43895 done
[2022-06-16T12:09:03.935] _job_complete: JobId=43771 WEXITSTATUS 0
[2022-06-16T12:09:03.936] _job_complete: JobId=43771 done
[2022-06-16T12:10:36.671] _slurm_rpc_submit_batch_job: JobId=43896 InitPrio=25956 usec=535
[2022-06-16T12:10:36.685] sched: Allocate JobId=43896 NodeList=cpu15 #CPUs=32 Partition=cpu-epyc
[2022-06-16T12:25:09.436] _slurm_rpc_submit_batch_job: JobId=43897 InitPrio=25956 usec=405
[2022-06-16T12:25:09.617] sched: Allocate JobId=43897 NodeList=cpu11 #CPUs=32 Partition=cpu-opteron
[2022-06-16T12:25:27.666] _slurm_rpc_submit_batch_job: JobId=43898 InitPrio=20551 usec=545
[2022-06-16T12:25:28.845] _job_complete: JobId=43897 WEXITSTATUS 0
[2022-06-16T12:25:28.845] _job_complete: JobId=43897 done
[2022-06-16T12:25:29.294] sched: Allocate JobId=43898 NodeList=cpu11 #CPUs=32 Partition=cpu-opteron
[2022-06-16T12:26:29.230] _job_complete: JobId=43898 WEXITSTATUS 0
[2022-06-16T12:26:29.230] _job_complete: JobId=43898 done
[2022-06-16T12:43:16.256] _slurm_rpc_submit_batch_job: JobId=43899 InitPrio=25956 usec=405
[2022-06-16T12:43:16.671] sched: Allocate JobId=43899 NodeList=cpu11 #CPUs=32 Partition=cpu-opteron
[2022-06-16T12:44:32.766] _job_complete: JobId=43899 WEXITSTATUS 0
[2022-06-16T12:44:32.766] _job_complete: JobId=43899 done
[2022-06-16T12:53:28.098] _job_complete: JobId=43896 WEXITSTATUS 0
[2022-06-16T12:53:28.098] _job_complete: JobId=43896 done
[2022-06-16T12:57:28.030] _slurm_rpc_submit_batch_job: JobId=43900 InitPrio=20816 usec=428
[2022-06-16T12:57:28.404] sched: Allocate JobId=43900 NodeList=cpu03 #CPUs=1 Partition=cpu-opteron
[2022-06-16T12:57:29.850] _job_complete: JobId=43900 WEXITSTATUS 1
[2022-06-16T12:57:29.851] _job_complete: JobId=43900 done
[2022-06-16T12:58:06.330] _slurm_rpc_submit_batch_job: JobId=43901 InitPrio=20816 usec=508
[2022-06-16T12:58:06.499] sched: Allocate JobId=43901 NodeList=cpu03 #CPUs=1 Partition=cpu-opteron
[2022-06-16T12:58:08.375] _job_complete: JobId=43901 WEXITSTATUS 0
[2022-06-16T12:58:08.375] _job_complete: JobId=43901 done
[2022-06-16T12:58:09.348] _slurm_rpc_submit_batch_job: JobId=43902 InitPrio=25956 usec=391
[2022-06-16T12:58:09.507] sched: Allocate JobId=43902 NodeList=cpu11 #CPUs=32 Partition=cpu-opteron
[2022-06-16T12:59:58.069] _slurm_rpc_kill_job: REQUEST_KILL_JOB JobId=43902 uid 548200084
[2022-06-16T13:16:28.484] Requeuing JobId=43889
[2022-06-16T13:16:29.464] Requeuing JobId=43890
[2022-06-16T13:19:22.257] _slurm_rpc_submit_batch_job: JobId=43903 InitPrio=20010 usec=441
[2022-06-16T13:19:22.863] sched: Allocate JobId=43903 NodeList=cpu15 #CPUs=32 Partition=cpu-epyc
[2022-06-16T13:20:58.651] _slurm_rpc_submit_batch_job: JobId=43904 InitPrio=19469 usec=371
[2022-06-16T13:20:59.121] _slurm_rpc_submit_batch_job: JobId=43905 InitPrio=20010 usec=436
[2022-06-16T13:21:01.993] sched: Allocate JobId=43905 NodeList=cpu04 #CPUs=32 Partition=cpu-opteron
[2022-06-16T13:21:53.014] _slurm_rpc_kill_job: REQUEST_KILL_JOB JobId=43904 uid 548200017
[2022-06-16T13:21:56.649] _slurm_rpc_submit_batch_job: JobId=43906 InitPrio=19469 usec=441
[2022-06-16T13:21:57.085] sched: Allocate JobId=43906 NodeList=cpu09 #CPUs=32 Partition=cpu-opteron
[2022-06-16T13:22:49.689] _slurm_rpc_submit_batch_job: JobId=43907 InitPrio=20551 usec=388
[2022-06-16T13:22:50.309] sched: Allocate JobId=43907 NodeList=cpu11 #CPUs=32 Partition=cpu-opteron
[2022-06-16T13:23:38.864] sched: _slurm_rpc_allocate_resources JobId=43908 NodeList=cpu03 usec=17201
[2022-06-16T13:27:17.209] _slurm_rpc_kill_job: REQUEST_KILL_JOB JobId=43889 uid 548300558
[2022-06-16T13:27:30.612] _slurm_rpc_kill_job: REQUEST_KILL_JOB JobId=43890 uid 548300558
[2022-06-16T13:44:31.349] _slurm_rpc_submit_batch_job: JobId=43909 InitPrio=25956 usec=415
[2022-06-16T13:45:10.855] _slurm_rpc_submit_batch_job: JobId=43910 InitPrio=25956 usec=442
[2022-06-16T13:55:03.195] _job_complete: JobId=43908 WEXITSTATUS 1
[2022-06-16T13:55:03.195] _job_complete: JobId=43908 done
[2022-06-16T13:59:11.663] _slurm_rpc_submit_batch_job: JobId=43911 InitPrio=28255 usec=438
[2022-06-16T14:22:06.222] _job_complete: JobId=43907 WEXITSTATUS 0
[2022-06-16T14:22:06.222] _job_complete: JobId=43907 done
[2022-06-16T14:22:06.750] sched: Allocate JobId=43910 NodeList=cpu11 #CPUs=32 Partition=cpu-opteron
[2022-06-16T14:31:31.261] _slurm_rpc_submit_batch_job: JobId=43912 InitPrio=25951 usec=365
[2022-06-16T14:31:32.117] sched: Allocate JobId=43912 NodeList=cpu12 #CPUs=1 Partition=cpu-epyc
[2022-06-16T14:31:39.741] _slurm_rpc_kill_job: REQUEST_KILL_JOB JobId=43912 uid 548300543
[2022-06-16T14:36:57.914] _slurm_rpc_submit_batch_job: JobId=43913 InitPrio=25891 usec=417
[2022-06-16T14:36:58.701] sched: Allocate JobId=43913 NodeList=cpu12 #CPUs=8 Partition=cpu-epyc
[2022-06-16T14:37:46.550] _slurm_rpc_kill_job: REQUEST_KILL_JOB JobId=43913 uid 548300543
[2022-06-16T14:41:13.889] _slurm_rpc_submit_batch_job: JobId=43914 InitPrio=25891 usec=316
[2022-06-16T14:41:14.181] sched: Allocate JobId=43914 NodeList=cpu12 #CPUs=8 Partition=cpu-epyc
[2022-06-16T14:41:41.715] _slurm_rpc_kill_job: REQUEST_KILL_JOB JobId=43914 uid 548300543
[2022-06-16T14:49:25.039] _slurm_rpc_submit_batch_job: JobId=43915 InitPrio=25891 usec=387
[2022-06-16T14:49:25.128] sched: Allocate JobId=43915 NodeList=cpu12 #CPUs=8 Partition=cpu-epyc
[2022-06-16T14:51:23.254] _slurm_rpc_kill_job: REQUEST_KILL_JOB JobId=43915 uid 548300543
[2022-06-16T14:54:39.162] _slurm_rpc_submit_batch_job: JobId=43916 InitPrio=20816 usec=432
[2022-06-16T14:54:39.710] sched: Allocate JobId=43916 NodeList=cpu03 #CPUs=1 Partition=cpu-opteron
[2022-06-16T14:54:42.830] _job_complete: JobId=43916 WEXITSTATUS 1
[2022-06-16T14:54:42.830] _job_complete: JobId=43916 done
[2022-06-16T14:55:33.009] _slurm_rpc_submit_batch_job: JobId=43917 InitPrio=20816 usec=455
[2022-06-16T14:55:33.774] sched: Allocate JobId=43917 NodeList=cpu03 #CPUs=1 Partition=cpu-opteron
[2022-06-16T14:55:36.969] _job_complete: JobId=43917 WEXITSTATUS 1
[2022-06-16T14:55:36.970] _job_complete: JobId=43917 done
[2022-06-16T14:56:13.192] _slurm_rpc_submit_batch_job: JobId=43918 InitPrio=25891 usec=357
[2022-06-16T14:56:13.831] sched: Allocate JobId=43918 NodeList=cpu12 #CPUs=8 Partition=cpu-epyc
[2022-06-16T14:57:54.101] _slurm_rpc_submit_batch_job: JobId=43919 InitPrio=20816 usec=468
[2022-06-16T14:57:55.090] sched: Allocate JobId=43919 NodeList=cpu03 #CPUs=1 Partition=cpu-opteron
[2022-06-16T14:57:58.257] _job_complete: JobId=43919 WEXITSTATUS 1
[2022-06-16T14:57:58.257] _job_complete: JobId=43919 done
[2022-06-16T14:58:45.604] _slurm_rpc_submit_batch_job: JobId=43920 InitPrio=20807 usec=383
[2022-06-16T14:58:46.162] sched: Allocate JobId=43920 NodeList=cpu03 #CPUs=2 Partition=cpu-opteron
[2022-06-16T14:58:48.817] _job_complete: JobId=43920 WEXITSTATUS 1
[2022-06-16T14:58:48.817] _job_complete: JobId=43920 done
[2022-06-16T14:59:26.368] _slurm_rpc_kill_job: REQUEST_KILL_JOB JobId=43918 uid 548300543
[2022-06-16T14:59:28.794] _job_complete: JobId=43882 WEXITSTATUS 0
[2022-06-16T14:59:28.794] _job_complete: JobId=43882 done
[2022-06-16T15:00:17.209] _slurm_rpc_submit_batch_job: JobId=43921 InitPrio=25891 usec=376
[2022-06-16T15:00:17.285] sched: Allocate JobId=43921 NodeList=cpu12 #CPUs=8 Partition=cpu-epyc
[2022-06-16T15:00:44.574] sched: _slurm_rpc_allocate_resources JobId=43922 NodeList=cpu03 usec=1471
[2022-06-16T15:02:05.716] _slurm_rpc_kill_job: REQUEST_KILL_JOB JobId=43921 uid 548300543
[2022-06-16T15:02:12.616] _job_complete: JobId=43731 WEXITSTATUS 1
[2022-06-16T15:02:12.622] _job_complete: JobId=43731 done
[2022-06-16T15:02:40.167] _slurm_rpc_submit_batch_job: JobId=43923 InitPrio=25891 usec=400
[2022-06-16T15:02:40.568] sched: Allocate JobId=43923 NodeList=cpu12 #CPUs=8 Partition=cpu-epyc
[2022-06-16T15:03:18.983] _slurm_rpc_kill_job: REQUEST_KILL_JOB JobId=43923 uid 548300543
[2022-06-16T15:03:22.300] _slurm_rpc_submit_batch_job: JobId=43924 InitPrio=25891 usec=370
[2022-06-16T15:03:22.631] sched: Allocate JobId=43924 NodeList=cpu12 #CPUs=8 Partition=cpu-epyc
[2022-06-16T15:04:51.201] _slurm_rpc_kill_job: REQUEST_KILL_JOB JobId=43924 uid 548300543
[2022-06-16T15:08:36.348] _slurm_rpc_submit_batch_job: JobId=43925 InitPrio=25891 usec=368
[2022-06-16T15:08:37.199] sched: Allocate JobId=43925 NodeList=cpu03 #CPUs=8 Partition=cpu-opteron
[2022-06-16T15:12:57.175] _slurm_rpc_kill_job: REQUEST_KILL_JOB JobId=43925 uid 548300543
[2022-06-16T15:23:30.407] _slurm_rpc_submit_batch_job: JobId=43926 InitPrio=25891 usec=461
[2022-06-16T15:23:30.922] sched: Allocate JobId=43926 NodeList=cpu12 #CPUs=8 Partition=cpu-epyc
[2022-06-16T15:25:05.452] _job_complete: JobId=43926 WEXITSTATUS 1
[2022-06-16T15:25:05.453] _job_complete: JobId=43926 done
[2022-06-16T15:39:11.830] _slurm_rpc_submit_batch_job: JobId=43927 InitPrio=23661 usec=390
[2022-06-16T15:39:12.755] sched: Allocate JobId=43927 NodeList=cpu12 #CPUs=16 Partition=cpu-epyc
[2022-06-16T15:39:14.594] _slurm_rpc_submit_batch_job: JobId=43928 InitPrio=23524 usec=416
[2022-06-16T15:39:15.740] sched: Allocate JobId=43928 NodeList=gpu01 #CPUs=32 Partition=gpu-k10
[2022-06-16T15:39:24.988] _job_complete: JobId=43927 WEXITSTATUS 1
[2022-06-16T15:39:24.989] _job_complete: JobId=43927 done
[2022-06-16T15:39:25.109] _job_complete: JobId=43928 WEXITSTATUS 1
[2022-06-16T15:39:25.109] _job_complete: JobId=43928 done
[2022-06-16T15:43:27.112] _slurm_rpc_submit_batch_job: JobId=43929 InitPrio=23661 usec=315
[2022-06-16T15:43:28.303] sched: Allocate JobId=43929 NodeList=cpu12 #CPUs=16 Partition=cpu-epyc
[2022-06-16T15:43:29.822] _slurm_rpc_submit_batch_job: JobId=43930 InitPrio=23524 usec=451
[2022-06-16T15:43:31.307] sched: Allocate JobId=43930 NodeList=gpu01 #CPUs=32 Partition=gpu-k10
[2022-06-16T15:46:50.594] Time limit exhausted for JobId=43834
[2022-06-16T15:54:27.392] _job_complete: JobId=43929 WEXITSTATUS 0
[2022-06-16T15:54:27.393] _job_complete: JobId=43929 done
[2022-06-16T15:55:20.573] Time limit exhausted for JobId=43839
[2022-06-16T16:00:36.238] _job_complete: JobId=43930 WEXITSTATUS 0
[2022-06-16T16:00:36.238] _job_complete: JobId=43930 done
[2022-06-16T16:14:13.139] _slurm_rpc_submit_batch_job: JobId=43931 InitPrio=21498 usec=757
[2022-06-16T16:14:13.703] sched: Allocate JobId=43931 NodeList=gpu01 #CPUs=16 Partition=gpu-k10
[2022-06-16T16:14:59.360] _job_complete: JobId=43910 WEXITSTATUS 0
[2022-06-16T16:14:59.360] _job_complete: JobId=43910 done
[2022-06-16T16:18:25.752] _slurm_rpc_submit_batch_job: JobId=43932 InitPrio=23661 usec=455
[2022-06-16T16:18:28.688] _slurm_rpc_submit_batch_job: JobId=43933 InitPrio=23661 usec=412
[2022-06-16T16:44:36.462] _slurm_rpc_submit_batch_job: JobId=43934 InitPrio=20816 usec=474
[2022-06-16T16:44:37.055] sched: Allocate JobId=43934 NodeList=cpu03 #CPUs=1 Partition=cpu-opteron
[2022-06-16T16:44:38.747] _job_complete: JobId=43934 WEXITSTATUS 1
[2022-06-16T16:44:38.747] _job_complete: JobId=43934 done
[2022-06-16T16:47:14.865] _slurm_rpc_submit_batch_job: JobId=43935 InitPrio=20816 usec=407
[2022-06-16T16:47:15.274] sched: Allocate JobId=43935 NodeList=cpu03 #CPUs=1 Partition=cpu-opteron
[2022-06-16T16:47:18.168] _job_complete: JobId=43935 WEXITSTATUS 0
[2022-06-16T16:47:18.168] _job_complete: JobId=43935 done
[2022-06-16T16:48:54.913] _slurm_rpc_submit_batch_job: JobId=43936 InitPrio=20551 usec=451
[2022-06-16T16:48:55.592] sched: Allocate JobId=43936 NodeList=cpu11 #CPUs=32 Partition=cpu-opteron
[2022-06-16T16:53:59.440] _slurm_rpc_kill_job: REQUEST_KILL_JOB JobId=43936 uid 548200021
[2022-06-16T16:55:20.754] _slurm_rpc_submit_batch_job: JobId=43937 InitPrio=20816 usec=421
[2022-06-16T16:55:21.250] sched: Allocate JobId=43937 NodeList=cpu03 #CPUs=1 Partition=cpu-opteron
[2022-06-16T16:55:24.132] _job_complete: JobId=43937 WEXITSTATUS 0
[2022-06-16T16:55:24.132] _job_complete: JobId=43937 done
[2022-06-16T16:55:29.385] _slurm_rpc_submit_batch_job: JobId=43938 InitPrio=20551 usec=462
[2022-06-16T16:55:30.259] sched: Allocate JobId=43938 NodeList=cpu11 #CPUs=32 Partition=cpu-opteron
[2022-06-16T17:15:17.235] _slurm_rpc_submit_batch_job: JobId=43939 InitPrio=25686 usec=479
[2022-06-16T17:15:17.467] sched: Allocate JobId=43939 NodeList=cpu10 #CPUs=32 Partition=cpu-opteron
[2022-06-16T17:15:36.506] _job_complete: JobId=43939 WEXITSTATUS 0
[2022-06-16T17:15:36.507] _job_complete: JobId=43939 done
[2022-06-16T17:31:19.600] _slurm_rpc_submit_batch_job: JobId=43940 InitPrio=20010 usec=506
[2022-06-16T17:31:20.242] sched: Allocate JobId=43940 NodeList=cpu10 #CPUs=32 Partition=cpu-opteron
[2022-06-16T17:36:02.526] _slurm_rpc_submit_batch_job: JobId=43941 InitPrio=25686 usec=471
[2022-06-16T17:41:44.960] _slurm_rpc_submit_batch_job: JobId=43942 InitPrio=21361 usec=387
[2022-06-16T17:41:57.419] _slurm_rpc_submit_batch_job: JobId=43943 InitPrio=21361 usec=378
[2022-06-16T17:42:10.098] _slurm_rpc_submit_batch_job: JobId=43944 InitPrio=21361 usec=479
[2022-06-16T17:42:25.832] _slurm_rpc_submit_batch_job: JobId=43945 InitPrio=21361 usec=372
[2022-06-16T17:42:34.673] _slurm_rpc_submit_batch_job: JobId=43946 InitPrio=21361 usec=469
[2022-06-16T17:55:11.844] _slurm_rpc_submit_batch_job: JobId=43947 InitPrio=25686 usec=595
[2022-06-16T18:06:15.357] _job_complete: JobId=43681 WEXITSTATUS 0
[2022-06-16T18:06:15.362] _job_complete: JobId=43681 done
[2022-06-16T18:06:20.335] sched: Allocate JobId=43941 NodeList=cpu03 #CPUs=32 Partition=cpu-opteron
[2022-06-16T18:06:37.349] _job_complete: JobId=43941 WEXITSTATUS 0
[2022-06-16T18:06:37.349] _job_complete: JobId=43941 done
[2022-06-16T18:06:37.711] sched: Allocate JobId=43947 NodeList=cpu03 #CPUs=32 Partition=cpu-opteron
[2022-06-16T18:07:50.159] _job_complete: JobId=43947 WEXITSTATUS 0
[2022-06-16T18:07:50.159] _job_complete: JobId=43947 done
[2022-06-16T18:07:50.542] sched: Allocate JobId=43942 NodeList=cpu03 #CPUs=32 Partition=cpu-opteron
[2022-06-16T18:07:53.148] _job_complete: JobId=43942 WEXITSTATUS 1
[2022-06-16T18:07:53.148] _job_complete: JobId=43942 done
[2022-06-16T18:07:53.515] sched: Allocate JobId=43943 NodeList=cpu03 #CPUs=32 Partition=cpu-opteron
[2022-06-16T18:07:55.764] _job_complete: JobId=43943 WEXITSTATUS 1
[2022-06-16T18:07:55.764] _job_complete: JobId=43943 done
[2022-06-16T18:07:56.123] sched: Allocate JobId=43944 NodeList=cpu03 #CPUs=32 Partition=cpu-opteron
[2022-06-16T18:07:58.397] _job_complete: JobId=43944 WEXITSTATUS 1
[2022-06-16T18:07:58.397] _job_complete: JobId=43944 done
[2022-06-16T18:07:58.761] sched: Allocate JobId=43945 NodeList=cpu03 #CPUs=32 Partition=cpu-opteron
[2022-06-16T18:08:01.017] _job_complete: JobId=43945 WEXITSTATUS 1
[2022-06-16T18:08:01.017] _job_complete: JobId=43945 done
[2022-06-16T18:08:01.375] sched: Allocate JobId=43946 NodeList=cpu03 #CPUs=32 Partition=cpu-opteron
[2022-06-16T18:08:03.619] _job_complete: JobId=43946 WEXITSTATUS 1
[2022-06-16T18:08:03.620] _job_complete: JobId=43946 done
[2022-06-16T18:18:53.450] _slurm_rpc_submit_batch_job: JobId=43948 InitPrio=21361 usec=430
[2022-06-16T18:18:53.599] sched: Allocate JobId=43948 NodeList=cpu03 #CPUs=32 Partition=cpu-opteron
[2022-06-16T18:18:56.024] _job_complete: JobId=43948 WEXITSTATUS 1
[2022-06-16T18:18:56.025] _job_complete: JobId=43948 done
[2022-06-16T18:19:07.733] _slurm_rpc_submit_batch_job: JobId=43949 InitPrio=21361 usec=362
[2022-06-16T18:19:08.618] sched: Allocate JobId=43949 NodeList=cpu03 #CPUs=32 Partition=cpu-opteron
[2022-06-16T18:19:10.870] _job_complete: JobId=43949 WEXITSTATUS 1
[2022-06-16T18:19:10.871] _job_complete: JobId=43949 done
[2022-06-16T18:20:05.585] _slurm_rpc_submit_batch_job: JobId=43950 InitPrio=20019 usec=503
[2022-06-16T18:20:05.706] sched: Allocate JobId=43950 NodeList=cpu03 #CPUs=31 Partition=cpu-opteron
[2022-06-16T18:20:46.073] _slurm_rpc_submit_batch_job: JobId=43951 InitPrio=21361 usec=436
[2022-06-16T18:20:46.767] sched: Allocate JobId=43951 NodeList=cpu03 #CPUs=32 Partition=cpu-opteron
[2022-06-16T18:20:49.200] _job_complete: JobId=43951 WEXITSTATUS 1
[2022-06-16T18:20:49.200] _job_complete: JobId=43951 done
[2022-06-16T18:21:40.759] _slurm_rpc_submit_batch_job: JobId=43952 InitPrio=21361 usec=489
[2022-06-16T18:21:40.847] sched: Allocate JobId=43952 NodeList=cpu03 #CPUs=32 Partition=cpu-opteron
[2022-06-16T18:21:43.201] _job_complete: JobId=43952 WEXITSTATUS 1
[2022-06-16T18:21:43.202] _job_complete: JobId=43952 done
[2022-06-16T18:23:19.596] _slurm_rpc_submit_batch_job: JobId=43953 InitPrio=21361 usec=360
[2022-06-16T18:23:20.080] sched: Allocate JobId=43953 NodeList=cpu03 #CPUs=32 Partition=cpu-opteron
[2022-06-16T18:23:22.536] _job_complete: JobId=43953 WEXITSTATUS 1
[2022-06-16T18:23:22.536] _job_complete: JobId=43953 done
[2022-06-16T18:33:09.749] _slurm_rpc_submit_batch_job: JobId=43954 InitPrio=21361 usec=380
[2022-06-16T18:33:10.173] sched: Allocate JobId=43954 NodeList=cpu03 #CPUs=32 Partition=cpu-opteron
[2022-06-16T18:33:12.785] _job_complete: JobId=43954 WEXITSTATUS 1
[2022-06-16T18:33:12.786] _job_complete: JobId=43954 done
[2022-06-16T18:34:22.051] _slurm_rpc_submit_batch_job: JobId=43955 InitPrio=21361 usec=410
[2022-06-16T18:34:22.279] sched: Allocate JobId=43955 NodeList=cpu03 #CPUs=32 Partition=cpu-opteron
[2022-06-16T18:34:24.736] _job_complete: JobId=43955 WEXITSTATUS 1
[2022-06-16T18:34:24.737] _job_complete: JobId=43955 done
[2022-06-16T18:34:54.402] _slurm_rpc_submit_batch_job: JobId=43956 InitPrio=21361 usec=476
[2022-06-16T18:34:55.326] sched: Allocate JobId=43956 NodeList=cpu03 #CPUs=32 Partition=cpu-opteron
[2022-06-16T18:34:57.737] _job_complete: JobId=43956 WEXITSTATUS 1
[2022-06-16T18:34:57.738] _job_complete: JobId=43956 done
[2022-06-16T18:35:51.358] _slurm_rpc_submit_batch_job: JobId=43957 InitPrio=21361 usec=505
[2022-06-16T18:35:51.414] sched: Allocate JobId=43957 NodeList=cpu03 #CPUs=32 Partition=cpu-opteron
[2022-06-16T18:35:53.854] _job_complete: JobId=43957 WEXITSTATUS 1
[2022-06-16T18:35:53.854] _job_complete: JobId=43957 done
[2022-06-16T18:47:55.302] _slurm_rpc_submit_batch_job: JobId=43958 InitPrio=20147 usec=454
[2022-06-16T18:47:55.872] sched: Allocate JobId=43958 NodeList=cpu12 #CPUs=16 Partition=cpu-epyc
[2022-06-16T18:58:19.561] _slurm_rpc_submit_batch_job: JobId=43959 InitPrio=25686 usec=403
[2022-06-16T18:58:20.024] sched: Allocate JobId=43959 NodeList=cpu03 #CPUs=32 Partition=cpu-opteron
[2022-06-16T19:22:19.993] _slurm_rpc_submit_batch_job: JobId=43960 InitPrio=25686 usec=479
[2022-06-16T20:00:30.427] _job_complete: JobId=43938 WEXITSTATUS 0
[2022-06-16T20:00:30.428] _job_complete: JobId=43938 done
[2022-06-16T20:00:30.945] sched: Allocate JobId=43960 NodeList=cpu11 #CPUs=32 Partition=cpu-opteron
[2022-06-16T20:01:47.001] _job_complete: JobId=43960 WEXITSTATUS 0
[2022-06-16T20:01:47.001] _job_complete: JobId=43960 done
[2022-06-16T20:30:06.868] _slurm_rpc_submit_batch_job: JobId=43961 InitPrio=25686 usec=512
[2022-06-16T20:30:07.273] sched: Allocate JobId=43961 NodeList=cpu11 #CPUs=32 Partition=cpu-opteron
[2022-06-16T20:51:34.635] _job_complete: JobId=43959 WEXITSTATUS 0
[2022-06-16T20:51:34.635] _job_complete: JobId=43959 done
[2022-06-16T20:52:18.390] _slurm_rpc_kill_job: REQUEST_KILL_JOB JobId=43909 uid 548200084
[2022-06-16T20:53:19.233] _slurm_rpc_submit_batch_job: JobId=43962 InitPrio=25686 usec=432
[2022-06-16T20:53:20.048] sched: Allocate JobId=43962 NodeList=cpu03 #CPUs=32 Partition=cpu-opteron
[2022-06-16T20:55:21.226] Time limit exhausted for JobId=43855
[2022-06-16T20:56:51.355] Time limit exhausted for JobId=43857
[2022-06-16T20:58:51.660] Time limit exhausted for JobId=43858
[2022-06-16T20:59:51.748] Time limit exhausted for JobId=43859
[2022-06-16T21:09:47.072] _slurm_rpc_submit_batch_job: JobId=43963 InitPrio=21361 usec=345
[2022-06-16T21:09:47.898] sched: Allocate JobId=43963 NodeList=cpu05 #CPUs=32 Partition=cpu-opteron
[2022-06-16T21:09:54.681] _job_complete: JobId=43963 WEXITSTATUS 0
[2022-06-16T21:09:54.681] _job_complete: JobId=43963 done
[2022-06-16T21:15:29.989] _slurm_rpc_submit_batch_job: JobId=43964 InitPrio=21361 usec=469
[2022-06-16T21:15:30.499] sched: Allocate JobId=43964 NodeList=cpu05 #CPUs=32 Partition=cpu-opteron
[2022-06-16T21:15:42.948] _job_complete: JobId=43964 WEXITSTATUS 0
[2022-06-16T21:15:42.948] _job_complete: JobId=43964 done
[2022-06-16T21:25:31.804] _slurm_rpc_submit_batch_job: JobId=43965 InitPrio=21361 usec=387
[2022-06-16T21:25:32.668] sched: Allocate JobId=43965 NodeList=cpu05 #CPUs=32 Partition=cpu-opteron
[2022-06-16T21:25:40.591] _job_complete: JobId=43965 WEXITSTATUS 0
[2022-06-16T21:25:40.591] _job_complete: JobId=43965 done
[2022-06-16T21:29:23.181] _slurm_rpc_submit_batch_job: JobId=43966 InitPrio=20816 usec=427
[2022-06-16T21:29:24.164] sched: Allocate JobId=43966 NodeList=cpu05 #CPUs=1 Partition=cpu-opteron
[2022-06-16T21:29:27.009] _job_complete: JobId=43966 WEXITSTATUS 0
[2022-06-16T21:29:27.009] _job_complete: JobId=43966 done
[2022-06-16T21:31:23.627] _slurm_rpc_submit_batch_job: JobId=43967 InitPrio=20277 usec=462
[2022-06-16T21:31:24.330] sched: Allocate JobId=43967 NodeList=cpu05 #CPUs=64 Partition=cpu-opteron
[2022-06-16T21:33:58.219] _slurm_rpc_submit_batch_job: JobId=43968 InitPrio=21361 usec=392
[2022-06-16T21:33:58.678] sched: Allocate JobId=43968 NodeList=cpu08 #CPUs=32 Partition=cpu-opteron
[2022-06-16T21:34:14.216] _job_complete: JobId=43968 WEXITSTATUS 0
[2022-06-16T21:34:14.217] _job_complete: JobId=43968 done
[2022-06-16T21:50:51.700] Time limit exhausted for JobId=43864
[2022-06-16T21:59:53.109] _slurm_rpc_submit_batch_job: JobId=43969 InitPrio=25686 usec=516
[2022-06-16T21:59:53.738] sched: Allocate JobId=43969 NodeList=cpu11 #CPUs=32 Partition=cpu-opteron
[2022-06-16T22:00:23.985] _job_complete: JobId=43969 WEXITSTATUS 0
[2022-06-16T22:00:23.985] _job_complete: JobId=43969 done
[2022-06-16T22:00:37.599] _slurm_rpc_submit_batch_job: JobId=43970 InitPrio=25686 usec=479
[2022-06-16T22:00:37.800] sched: Allocate JobId=43970 NodeList=cpu11 #CPUs=32 Partition=cpu-opteron
[2022-06-16T22:00:52.492] _job_complete: JobId=43970 WEXITSTATUS 0
[2022-06-16T22:00:52.492] _job_complete: JobId=43970 done
[2022-06-16T22:01:32.951] _slurm_rpc_submit_batch_job: JobId=43971 InitPrio=25686 usec=573
[2022-06-16T22:01:33.888] sched: Allocate JobId=43971 NodeList=cpu11 #CPUs=32 Partition=cpu-opteron
[2022-06-16T22:02:01.619] _job_complete: JobId=43971 WEXITSTATUS 0
[2022-06-16T22:02:01.619] _job_complete: JobId=43971 done
[2022-06-16T22:02:22.224] _slurm_rpc_submit_batch_job: JobId=43972 InitPrio=25686 usec=411
[2022-06-16T22:02:23.041] sched: Allocate JobId=43972 NodeList=cpu11 #CPUs=32 Partition=cpu-opteron
[2022-06-16T22:02:37.311] _job_complete: JobId=43972 WEXITSTATUS 0
[2022-06-16T22:02:37.311] _job_complete: JobId=43972 done
[2022-06-16T22:04:42.727] _job_complete: JobId=43881 WEXITSTATUS 0
[2022-06-16T22:04:42.727] _job_complete: JobId=43881 done
[2022-06-16T22:17:52.473] _slurm_rpc_submit_batch_job: JobId=43973 InitPrio=19736 usec=449
[2022-06-16T22:18:28.287] _slurm_rpc_submit_batch_job: JobId=43974 InitPrio=20010 usec=409
[2022-06-16T22:18:28.948] sched: Allocate JobId=43974 NodeList=cpu11 #CPUs=32 Partition=cpu-opteron
[2022-06-16T22:18:38.905] _slurm_rpc_kill_job: REQUEST_KILL_JOB JobId=43973 uid 548200019
[2022-06-16T22:19:13.434] _slurm_rpc_submit_batch_job: JobId=43975 InitPrio=19736 usec=386
[2022-06-16T22:19:14.002] sched: Allocate JobId=43975 NodeList=cpu08 #CPUs=64 Partition=cpu-opteron
[2022-06-16T22:20:47.263] _slurm_rpc_submit_batch_job: JobId=43976 InitPrio=20010 usec=465
[2022-06-16T22:20:48.138] sched: Allocate JobId=43976 NodeList=cpu13 #CPUs=32 Partition=cpu-epyc
[2022-06-16T22:22:05.894] _slurm_rpc_submit_batch_job: JobId=43977 InitPrio=20010 usec=411
[2022-06-16T22:22:06.253] sched: Allocate JobId=43977 NodeList=cpu14 #CPUs=32 Partition=cpu-epyc
[2022-06-16T22:23:38.227] _job_complete: JobId=43922 WEXITSTATUS 0
[2022-06-16T22:23:38.228] _job_complete: JobId=43922 done
[2022-06-16T22:24:01.825] _job_complete: JobId=43961 WEXITSTATUS 0
[2022-06-16T22:24:01.825] _job_complete: JobId=43961 done
[2022-06-16T22:28:39.028] cleanup_completing: JobId=43922 completion process took 301 seconds
[2022-06-16T22:32:25.278] _slurm_rpc_submit_batch_job: JobId=43978 InitPrio=19469 usec=475
[2022-06-16T22:32:25.518] sched: Allocate JobId=43978 NodeList=cpu11 #CPUs=32 Partition=cpu-opteron
[2022-06-16T22:45:01.665] _job_complete: JobId=43962 WEXITSTATUS 0
[2022-06-16T22:45:01.665] _job_complete: JobId=43962 done
[2022-06-16T23:01:01.437] _job_complete: JobId=43845 WEXITSTATUS 0
[2022-06-16T23:01:01.438] _job_complete: JobId=43845 done
[2022-06-17T00:22:21.708] Time limit exhausted for JobId=43876
[2022-06-17T07:39:30.423] _slurm_rpc_submit_batch_job: JobId=43979 InitPrio=25686 usec=468
[2022-06-17T07:39:30.561] sched: Allocate JobId=43979 NodeList=cpu09 #CPUs=32 Partition=cpu-opteron
[2022-06-17T07:40:19.964] _slurm_rpc_submit_batch_job: JobId=43980 InitPrio=25686 usec=401
[2022-06-17T07:40:20.619] sched: Allocate JobId=43980 NodeList=cpu03 #CPUs=32 Partition=cpu-opteron
[2022-06-17T07:40:49.283] _job_complete: JobId=43979 WEXITSTATUS 0
[2022-06-17T07:40:49.283] _job_complete: JobId=43979 done
[2022-06-17T07:41:30.662] _slurm_rpc_submit_batch_job: JobId=43981 InitPrio=25686 usec=390
[2022-06-17T07:41:30.724] sched: Allocate JobId=43981 NodeList=cpu09 #CPUs=32 Partition=cpu-opteron
[2022-06-17T07:41:37.012] _job_complete: JobId=43980 WEXITSTATUS 0
[2022-06-17T07:41:37.012] _job_complete: JobId=43980 done
[2022-06-17T07:42:25.176] _slurm_rpc_submit_batch_job: JobId=43982 InitPrio=25686 usec=392
[2022-06-17T07:42:25.899] sched: Allocate JobId=43982 NodeList=cpu03 #CPUs=32 Partition=cpu-opteron
[2022-06-17T07:42:50.447] _job_complete: JobId=43981 WEXITSTATUS 0
[2022-06-17T07:42:50.447] _job_complete: JobId=43981 done
[2022-06-17T07:43:42.697] _job_complete: JobId=43982 WEXITSTATUS 0
[2022-06-17T07:43:42.697] _job_complete: JobId=43982 done
[2022-06-17T09:16:56.719] _slurm_rpc_submit_batch_job: JobId=43983 InitPrio=26161 usec=379
[2022-06-17T09:16:57.662] sched: Allocate JobId=43983 NodeList=cpu13 #CPUs=8 Partition=cpu-epyc
[2022-06-17T09:18:03.368] _job_complete: JobId=43983 WEXITSTATUS 1
[2022-06-17T09:18:03.368] _job_complete: JobId=43983 done
[2022-06-17T09:34:05.763] _slurm_rpc_submit_batch_job: JobId=43984 InitPrio=24600 usec=564
[2022-06-17T09:34:06.761] sched: Allocate JobId=43984 NodeList=cpu09 #CPUs=1 Partition=cpu-opteron
[2022-06-17T09:34:07.079] _job_complete: JobId=43984 WEXITSTATUS 127
[2022-06-17T09:34:07.079] _job_complete: JobId=43984 done
[2022-06-17T09:34:09.477] _slurm_rpc_kill_job: REQUEST_KILL_JOB JobId=43984 uid 548200003
[2022-06-17T09:34:11.879] _slurm_rpc_submit_batch_job: JobId=43985 InitPrio=24600 usec=450
[2022-06-17T09:34:12.743] sched: Allocate JobId=43985 NodeList=cpu09 #CPUs=1 Partition=cpu-opteron
[2022-06-17T09:34:13.338] _job_complete: JobId=43985 WEXITSTATUS 127
[2022-06-17T09:34:13.338] _job_complete: JobId=43985 done
[2022-06-17T09:34:17.479] _slurm_rpc_kill_job: REQUEST_KILL_JOB JobId=43985 uid 548200003
[2022-06-17T10:02:33.568] _slurm_rpc_submit_batch_job: JobId=43986 InitPrio=25686 usec=414
[2022-06-17T10:02:33.733] sched: Allocate JobId=43986 NodeList=cpu09 #CPUs=32 Partition=cpu-opteron
[2022-06-17T10:03:34.219] _slurm_rpc_submit_batch_job: JobId=43987 InitPrio=25686 usec=482
[2022-06-17T10:03:34.810] sched: Allocate JobId=43987 NodeList=cpu03 #CPUs=32 Partition=cpu-opteron
[2022-06-17T10:04:41.512] _slurm_rpc_submit_batch_job: JobId=43988 InitPrio=25686 usec=455
[2022-06-17T10:04:41.907] sched: Allocate JobId=43988 NodeList=cpu13 #CPUs=32 Partition=cpu-epyc
[2022-06-17T10:05:36.674] _slurm_rpc_submit_batch_job: JobId=43989 InitPrio=25686 usec=579
[2022-06-17T10:11:45.891] _slurm_rpc_submit_batch_job: JobId=43990 InitPrio=19469 usec=378
[2022-06-17T10:39:13.689] _job_complete: JobId=43931 WEXITSTATUS 1
[2022-06-17T10:39:13.693] _job_complete: JobId=43931 done
[2022-06-17T10:39:55.007] _job_complete: JobId=43988 WEXITSTATUS 0
[2022-06-17T10:39:55.007] _job_complete: JobId=43988 done
[2022-06-17T10:39:55.261] sched: Allocate JobId=43990 NodeList=cpu13 #CPUs=32 Partition=cpu-epyc
[2022-06-17T11:26:46.983] _slurm_rpc_submit_batch_job: JobId=43991 InitPrio=28255 usec=393
[2022-06-17T11:56:19.762] _job_complete: JobId=43986 WEXITSTATUS 0
[2022-06-17T11:56:19.762] _job_complete: JobId=43986 done
[2022-06-17T11:56:20.303] sched: Allocate JobId=43989 NodeList=cpu09 #CPUs=32 Partition=cpu-opteron
[2022-06-17T11:57:40.132] _job_complete: JobId=43987 WEXITSTATUS 0
[2022-06-17T11:57:40.132] _job_complete: JobId=43987 done
[2022-06-17T12:26:13.844] _job_complete: JobId=43894 WEXITSTATUS 1
[2022-06-17T12:26:13.848] _job_complete: JobId=43894 done
[2022-06-17T13:19:24.787] Time limit exhausted for JobId=43903
[2022-06-17T13:21:24.961] Time limit exhausted for JobId=43905
[2022-06-17T13:40:34.316] _job_complete: JobId=43782 WEXITSTATUS 0
[2022-06-17T13:40:34.320] _job_complete: JobId=43782 done
[2022-06-17T13:50:29.567] _job_complete: JobId=43989 WEXITSTATUS 0
[2022-06-17T13:50:29.567] _job_complete: JobId=43989 done
[2022-06-17T14:18:55.877] _job_complete: JobId=43967 WEXITSTATUS 0
[2022-06-17T14:18:55.878] _job_complete: JobId=43967 done
[2022-06-17T14:22:09.944] _slurm_rpc_submit_batch_job: JobId=43992 InitPrio=19736 usec=492
[2022-06-17T14:22:10.691] sched: Allocate JobId=43992 NodeList=cpu05 #CPUs=64 Partition=cpu-opteron
[2022-06-17T14:23:46.818] _slurm_rpc_submit_batch_job: JobId=43993 InitPrio=20010 usec=409
[2022-06-17T14:23:46.971] sched: Allocate JobId=43993 NodeList=cpu15 #CPUs=32 Partition=cpu-epyc
[2022-06-17T14:25:15.581] _slurm_rpc_submit_batch_job: JobId=43994 InitPrio=20147 usec=435
[2022-06-17T14:25:16.100] sched: Allocate JobId=43994 NodeList=cpu09 #CPUs=16 Partition=cpu-opteron
[2022-06-17T14:25:58.477] _slurm_rpc_kill_job: REQUEST_KILL_JOB JobId=43993 uid 548200019
[2022-06-17T14:26:28.779] _slurm_rpc_submit_batch_job: JobId=43995 InitPrio=20010 usec=405
[2022-06-17T14:26:30.206] sched: Allocate JobId=43995 NodeList=cpu15 #CPUs=32 Partition=cpu-epyc
[2022-06-17T14:28:54.745] _slurm_rpc_submit_batch_job: JobId=43996 InitPrio=20147 usec=455
[2022-06-17T14:28:55.547] sched: Allocate JobId=43996 NodeList=cpu09 #CPUs=16 Partition=cpu-opteron
[2022-06-17T14:29:09.322] _slurm_rpc_kill_job: REQUEST_KILL_JOB JobId=43996 uid 548200019
[2022-06-17T14:29:12.186] _slurm_rpc_submit_batch_job: JobId=43997 InitPrio=19469 usec=401
[2022-06-17T14:29:12.585] sched: Allocate JobId=43997 NodeList=cpu01 #CPUs=32 Partition=cpu-opteron
[2022-06-17T14:29:35.546] _slurm_rpc_submit_batch_job: JobId=43998 InitPrio=20147 usec=695
[2022-06-17T14:29:35.607] sched: Allocate JobId=43998 NodeList=cpu09 #CPUs=16 Partition=cpu-opteron
[2022-06-17T15:47:12.179] _job_complete: JobId=43998 WEXITSTATUS 1
[2022-06-17T15:47:12.179] _job_complete: JobId=43998 done
[2022-06-17T15:53:33.053] _slurm_rpc_submit_batch_job: JobId=43999 InitPrio=25686 usec=449
[2022-06-17T15:53:33.527] sched: Allocate JobId=43999 NodeList=cpu04 #CPUs=32 Partition=cpu-opteron
[2022-06-17T15:54:05.886] _job_complete: JobId=43999 WEXITSTATUS 0
[2022-06-17T15:54:05.887] _job_complete: JobId=43999 done
[2022-06-17T15:58:41.067] _slurm_rpc_submit_batch_job: JobId=44000 InitPrio=26432 usec=520
[2022-06-17T15:58:42.059] sched: Allocate JobId=44000 NodeList=cpu09 #CPUs=8 Partition=cpu-opteron
[2022-06-17T15:58:56.376] _job_complete: JobId=44000 WEXITSTATUS 0
[2022-06-17T15:58:56.376] _job_complete: JobId=44000 done
[2022-06-17T15:59:01.913] _slurm_rpc_submit_batch_job: JobId=44001 InitPrio=25686 usec=461
[2022-06-17T15:59:02.074] sched: Allocate JobId=44001 NodeList=cpu04 #CPUs=32 Partition=cpu-opteron
[2022-06-17T15:59:33.575] _job_complete: JobId=44001 WEXITSTATUS 0
[2022-06-17T15:59:33.575] _job_complete: JobId=44001 done
[2022-06-17T16:00:21.800] _slurm_rpc_submit_batch_job: JobId=44002 InitPrio=25686 usec=453
[2022-06-17T16:00:22.191] sched: Allocate JobId=44002 NodeList=cpu04 #CPUs=32 Partition=cpu-opteron
[2022-06-17T16:00:54.458] _job_complete: JobId=44002 WEXITSTATUS 0
[2022-06-17T16:00:54.458] _job_complete: JobId=44002 done
[2022-06-17T16:01:06.954] _slurm_rpc_submit_batch_job: JobId=44003 InitPrio=26432 usec=436
[2022-06-17T16:01:07.255] sched: Allocate JobId=44003 NodeList=cpu09 #CPUs=8 Partition=cpu-opteron
[2022-06-17T16:01:12.713] _job_complete: JobId=44003 WEXITSTATUS 0
[2022-06-17T16:01:12.713] _job_complete: JobId=44003 done
[2022-06-17T16:01:13.075] _slurm_rpc_submit_batch_job: JobId=44004 InitPrio=25686 usec=476
[2022-06-17T16:01:13.120] sched: Allocate JobId=44004 NodeList=cpu04 #CPUs=32 Partition=cpu-opteron
[2022-06-17T16:01:46.228] _job_complete: JobId=44004 WEXITSTATUS 0
[2022-06-17T16:01:46.228] _job_complete: JobId=44004 done
[2022-06-17T16:04:13.261] _slurm_rpc_submit_batch_job: JobId=44005 InitPrio=26432 usec=381
[2022-06-17T16:04:13.636] sched: Allocate JobId=44005 NodeList=cpu09 #CPUs=8 Partition=cpu-opteron
[2022-06-17T16:04:19.254] _job_complete: JobId=44005 WEXITSTATUS 0
[2022-06-17T16:04:19.254] _job_complete: JobId=44005 done
[2022-06-17T16:05:09.183] _slurm_rpc_submit_batch_job: JobId=44006 InitPrio=26432 usec=481
[2022-06-17T16:05:09.717] sched: Allocate JobId=44006 NodeList=cpu09 #CPUs=8 Partition=cpu-opteron
[2022-06-17T16:05:14.820] _job_complete: JobId=44006 WEXITSTATUS 0
[2022-06-17T16:05:14.820] _job_complete: JobId=44006 done
[2022-06-17T16:07:20.423] _slurm_rpc_submit_batch_job: JobId=44007 InitPrio=26432 usec=456
[2022-06-17T16:07:20.905] sched: Allocate JobId=44007 NodeList=cpu09 #CPUs=8 Partition=cpu-opteron
[2022-06-17T16:07:26.332] _job_complete: JobId=44007 WEXITSTATUS 0
[2022-06-17T16:07:26.332] _job_complete: JobId=44007 done
[2022-06-17T16:08:45.542] _slurm_rpc_submit_batch_job: JobId=44008 InitPrio=26432 usec=491
[2022-06-17T16:08:46.106] sched: Allocate JobId=44008 NodeList=cpu09 #CPUs=8 Partition=cpu-opteron
[2022-06-17T16:08:51.644] _job_complete: JobId=44008 WEXITSTATUS 0
[2022-06-17T16:08:51.644] _job_complete: JobId=44008 done
[2022-06-17T16:11:40.632] _slurm_rpc_submit_batch_job: JobId=44009 InitPrio=26432 usec=438
[2022-06-17T16:11:41.349] sched: Allocate JobId=44009 NodeList=cpu09 #CPUs=8 Partition=cpu-opteron
[2022-06-17T16:11:51.280] _job_complete: JobId=44009 WEXITSTATUS 0
[2022-06-17T16:11:51.280] _job_complete: JobId=44009 done
[2022-06-17T16:13:08.090] _slurm_rpc_submit_batch_job: JobId=44010 InitPrio=26432 usec=988
[2022-06-17T16:13:08.592] sched: Allocate JobId=44010 NodeList=cpu09 #CPUs=8 Partition=cpu-opteron
[2022-06-17T16:13:17.680] _job_complete: JobId=44010 WEXITSTATUS 0
[2022-06-17T16:13:17.680] _job_complete: JobId=44010 done
[2022-06-17T16:14:25.379] _slurm_rpc_submit_batch_job: JobId=44011 InitPrio=26432 usec=431
[2022-06-17T16:14:25.704] sched: Allocate JobId=44011 NodeList=cpu09 #CPUs=8 Partition=cpu-opteron
[2022-06-17T16:14:34.471] _job_complete: JobId=44011 WEXITSTATUS 0
[2022-06-17T16:14:34.472] _job_complete: JobId=44011 done
[2022-06-17T16:16:34.303] _slurm_rpc_submit_batch_job: JobId=44012 InitPrio=26432 usec=426
[2022-06-17T16:16:34.888] sched: Allocate JobId=44012 NodeList=cpu09 #CPUs=8 Partition=cpu-opteron
[2022-06-17T16:16:44.519] _job_complete: JobId=44012 WEXITSTATUS 0
[2022-06-17T16:16:44.519] _job_complete: JobId=44012 done
[2022-06-17T16:18:01.942] _slurm_rpc_submit_batch_job: JobId=44013 InitPrio=26432 usec=600
[2022-06-17T16:18:02.118] sched: Allocate JobId=44013 NodeList=cpu09 #CPUs=8 Partition=cpu-opteron
[2022-06-17T16:21:48.468] _job_complete: JobId=44013 WEXITSTATUS 0
[2022-06-17T16:21:48.468] _job_complete: JobId=44013 done
[2022-06-17T16:30:06.413] _slurm_rpc_submit_batch_job: JobId=44014 InitPrio=26432 usec=495
[2022-06-17T16:30:07.416] sched: Allocate JobId=44014 NodeList=cpu09 #CPUs=8 Partition=cpu-opteron
[2022-06-17T16:30:12.690] _job_complete: JobId=44014 WEXITSTATUS 0
[2022-06-17T16:30:12.690] _job_complete: JobId=44014 done
[2022-06-17T16:31:03.805] _slurm_rpc_submit_batch_job: JobId=44015 InitPrio=26432 usec=394
[2022-06-17T16:31:04.497] sched: Allocate JobId=44015 NodeList=cpu09 #CPUs=8 Partition=cpu-opteron
[2022-06-17T16:31:09.190] _job_complete: JobId=44015 WEXITSTATUS 0
[2022-06-17T16:31:09.190] _job_complete: JobId=44015 done
[2022-06-17T16:31:57.556] _slurm_rpc_submit_batch_job: JobId=44016 InitPrio=26432 usec=519
[2022-06-17T16:31:57.571] sched: Allocate JobId=44016 NodeList=cpu09 #CPUs=8 Partition=cpu-opteron
[2022-06-17T16:32:02.440] _job_complete: JobId=44016 WEXITSTATUS 0
[2022-06-17T16:32:02.440] _job_complete: JobId=44016 done
[2022-06-17T16:32:03.523] error: This association 204(account='free', user='lin0618', partition='(null)') does not have access to qos normal
[2022-06-17T16:32:03.523] _slurm_rpc_submit_batch_job: Invalid qos specification
[2022-06-17T16:33:16.503] _slurm_rpc_submit_batch_job: JobId=44017 InitPrio=26432 usec=847
[2022-06-17T16:33:16.816] sched: Allocate JobId=44017 NodeList=cpu09 #CPUs=8 Partition=cpu-opteron
[2022-06-17T16:33:43.440] error: Invalid qos (normal*)
[2022-06-17T16:33:43.440] _slurm_rpc_submit_batch_job: Invalid qos specification
[2022-06-17T16:34:10.765] _slurm_rpc_submit_batch_job: JobId=44018 InitPrio=68384 usec=456
[2022-06-17T16:34:10.982] sched: Allocate JobId=44018 NodeList=cpu09 #CPUs=1 Partition=cpu-opteron
[2022-06-17T16:34:11.931] _job_complete: JobId=44018 WEXITSTATUS 2
[2022-06-17T16:34:11.932] _job_complete: JobId=44018 done
[2022-06-17T16:36:55.003] _job_complete: JobId=44017 WEXITSTATUS 0
[2022-06-17T16:36:55.003] _job_complete: JobId=44017 done
[2022-06-17T16:40:26.583] _slurm_rpc_submit_batch_job: JobId=44019 InitPrio=26432 usec=486
[2022-06-17T16:40:27.529] sched: Allocate JobId=44019 NodeList=cpu09 #CPUs=8 Partition=cpu-opteron
[2022-06-17T16:42:00.612] sched: _slurm_rpc_allocate_resources JobId=44020 NodeList=cpu09 usec=1100
[2022-06-17T16:42:45.786] _slurm_rpc_submit_batch_job: JobId=44021 InitPrio=26432 usec=537
[2022-06-17T16:42:45.855] sched: Allocate JobId=44021 NodeList=cpu04 #CPUs=8 Partition=cpu-opteron
[2022-06-17T16:42:59.661] _slurm_rpc_kill_job: REQUEST_KILL_JOB JobId=44019 uid 548200132
[2022-06-17T16:46:07.357] _job_complete: JobId=44021 WEXITSTATUS 0
[2022-06-17T16:46:07.357] _job_complete: JobId=44021 done
[2022-06-17T16:49:11.653] sched: _slurm_rpc_allocate_resources JobId=44022 NodeList=(null) usec=884
[2022-06-17T16:49:22.429] _slurm_rpc_submit_batch_job: JobId=44023 InitPrio=26432 usec=459
[2022-06-17T16:49:22.516] sched: Allocate JobId=44023 NodeList=cpu09 #CPUs=8 Partition=cpu-opteron
[2022-06-17T16:49:27.678] _job_complete: JobId=44023 WEXITSTATUS 0
[2022-06-17T16:49:27.678] _job_complete: JobId=44023 done
[2022-06-17T16:49:31.584] _job_complete: JobId=44022 WTERMSIG 126
[2022-06-17T16:49:31.584] _job_complete: JobId=44022 cancelled by interactive user
[2022-06-17T16:49:31.584] _job_complete: JobId=44022 done
[2022-06-17T16:50:26.785] sched: _slurm_rpc_allocate_resources JobId=44024 NodeList=(null) usec=894
[2022-06-17T16:51:43.839] _job_complete: JobId=44024 WTERMSIG 126
[2022-06-17T16:51:43.839] _job_complete: JobId=44024 cancelled by interactive user
[2022-06-17T16:51:43.839] _job_complete: JobId=44024 done
[2022-06-17T16:51:47.512] sched: _slurm_rpc_allocate_resources JobId=44025 NodeList=(null) usec=1209
[2022-06-17T16:51:54.737] _job_complete: JobId=44025 WTERMSIG 126
[2022-06-17T16:51:54.737] _job_complete: JobId=44025 cancelled by interactive user
[2022-06-17T16:51:54.737] _job_complete: JobId=44025 done
[2022-06-17T16:52:46.079] sched: _slurm_rpc_allocate_resources JobId=44026 NodeList=(null) usec=866
[2022-06-17T16:53:22.160] _slurm_rpc_submit_batch_job: JobId=44027 InitPrio=26432 usec=444
[2022-06-17T16:53:22.945] sched: Allocate JobId=44027 NodeList=cpu09 #CPUs=8 Partition=cpu-opteron
[2022-06-17T16:53:55.478] _job_complete: JobId=44026 WTERMSIG 126
[2022-06-17T16:53:55.478] _job_complete: JobId=44026 cancelled by interactive user
[2022-06-17T16:53:55.478] _job_complete: JobId=44026 done
[2022-06-17T16:55:59.994] _slurm_rpc_submit_batch_job: JobId=44028 InitPrio=30816 usec=446
[2022-06-17T16:56:44.894] _slurm_rpc_kill_job: REQUEST_KILL_JOB JobId=44020 uid 548300576
[2022-06-17T16:56:45.299] sched: Allocate JobId=44028 NodeList=cpu09 #CPUs=1 Partition=cpu-opteron
[2022-06-17T16:56:45.971] _job_complete: JobId=44028 WEXITSTATUS 2
[2022-06-17T16:56:45.971] _job_complete: JobId=44028 done
[2022-06-17T16:57:15.653] _job_complete: JobId=44027 WEXITSTATUS 0
[2022-06-17T16:57:15.653] _job_complete: JobId=44027 done
[2022-06-17T16:59:02.303] sched: _slurm_rpc_allocate_resources JobId=44029 NodeList=cpu09 usec=3941
[2022-06-17T17:03:43.776] _slurm_rpc_submit_batch_job: JobId=44030 InitPrio=26432 usec=455
[2022-06-17T17:03:44.038] sched: Allocate JobId=44030 NodeList=cpu09 #CPUs=8 Partition=cpu-opteron
[2022-06-17T17:03:49.278] _job_complete: JobId=44030 WEXITSTATUS 0
[2022-06-17T17:03:49.278] _job_complete: JobId=44030 done
[2022-06-17T17:05:38.581] _slurm_rpc_submit_batch_job: JobId=44031 InitPrio=22850 usec=499
[2022-06-17T17:05:39.216] sched: Allocate JobId=44031 NodeList=cpu04 #CPUs=16 Partition=cpu-opteron
[2022-06-17T17:05:44.092] _slurm_rpc_submit_batch_job: JobId=44032 InitPrio=22850 usec=429
[2022-06-17T17:05:44.212] sched: Allocate JobId=44032 NodeList=cpu04 #CPUs=16 Partition=cpu-opteron
[2022-06-17T17:05:49.196] _slurm_rpc_submit_batch_job: JobId=44033 InitPrio=22850 usec=404
[2022-06-17T17:05:49.222] sched: Allocate JobId=44033 NodeList=cpu03 #CPUs=16 Partition=cpu-opteron
[2022-06-17T17:05:53.069] _slurm_rpc_submit_batch_job: JobId=44034 InitPrio=22850 usec=439
[2022-06-17T17:05:53.227] sched: Allocate JobId=44034 NodeList=cpu03 #CPUs=16 Partition=cpu-opteron
[2022-06-17T17:05:58.020] _slurm_rpc_submit_batch_job: JobId=44035 InitPrio=22850 usec=420
[2022-06-17T17:06:01.245] _slurm_rpc_submit_batch_job: JobId=44036 InitPrio=22850 usec=447
[2022-06-17T17:06:07.132] _slurm_rpc_submit_batch_job: JobId=44037 InitPrio=22850 usec=390
[2022-06-17T17:06:11.070] _slurm_rpc_submit_batch_job: JobId=44038 InitPrio=22850 usec=501
[2022-06-17T17:06:15.022] _slurm_rpc_submit_batch_job: JobId=44039 InitPrio=22850 usec=559
[2022-06-17T17:06:18.726] _slurm_rpc_submit_batch_job: JobId=44040 InitPrio=22850 usec=452
[2022-06-17T17:06:23.324] _slurm_rpc_submit_batch_job: JobId=44041 InitPrio=22850 usec=471
[2022-06-17T17:06:27.029] _slurm_rpc_submit_batch_job: JobId=44042 InitPrio=22850 usec=642
[2022-06-17T17:06:30.085] _slurm_rpc_submit_batch_job: JobId=44043 InitPrio=22850 usec=538
[2022-06-17T17:06:32.853] _slurm_rpc_submit_batch_job: JobId=44044 InitPrio=22850 usec=480
[2022-06-17T17:06:35.717] _slurm_rpc_submit_batch_job: JobId=44045 InitPrio=22850 usec=409
[2022-06-17T17:06:38.541] _slurm_rpc_submit_batch_job: JobId=44046 InitPrio=22850 usec=432
[2022-06-17T17:06:41.389] _slurm_rpc_submit_batch_job: JobId=44047 InitPrio=22850 usec=397
[2022-06-17T17:06:44.277] _slurm_rpc_submit_batch_job: JobId=44048 InitPrio=22850 usec=496
[2022-06-17T17:06:47.047] _slurm_rpc_submit_batch_job: JobId=44049 InitPrio=22850 usec=412
[2022-06-17T17:06:50.933] _slurm_rpc_submit_batch_job: JobId=44050 InitPrio=22850 usec=444
[2022-06-17T17:06:54.096] _slurm_rpc_submit_batch_job: JobId=44051 InitPrio=22850 usec=419
[2022-06-17T17:10:13.110] _slurm_rpc_submit_batch_job: JobId=44052 InitPrio=29735 usec=520
[2022-06-17T17:10:25.763] _slurm_rpc_submit_batch_job: JobId=44053 InitPrio=26432 usec=495
[2022-06-17T17:10:26.728] sched: Allocate JobId=44053 NodeList=cpu09 #CPUs=8 Partition=cpu-opteron
[2022-06-17T17:10:31.937] _job_complete: JobId=44053 WEXITSTATUS 0
[2022-06-17T17:10:31.937] _job_complete: JobId=44053 done
[2022-06-17T17:10:44.273] _job_complete: JobId=44029 WEXITSTATUS 127
[2022-06-17T17:10:44.273] _job_complete: JobId=44029 done
[2022-06-17T17:10:45.289] sched: Allocate JobId=44052 NodeList=cpu03 #CPUs=1 Partition=cpu-opteron
[2022-06-17T17:10:45.290] sched: Allocate JobId=44035 NodeList=cpu09 #CPUs=16 Partition=cpu-opteron
[2022-06-17T17:10:55.211] _job_complete: JobId=44052 WEXITSTATUS 2
[2022-06-17T17:10:55.212] _job_complete: JobId=44052 done
[2022-06-17T17:13:00.550] _slurm_rpc_submit_batch_job: JobId=44054 InitPrio=26432 usec=449
[2022-06-17T17:14:09.219] _slurm_rpc_submit_batch_job: JobId=44055 InitPrio=26432 usec=437
[2022-06-17T17:14:09.238] sched: Allocate JobId=44055 NodeList=gpu05 #CPUs=8 Partition=gpu-v100s
[2022-06-17T17:14:15.218] _job_complete: JobId=44055 WEXITSTATUS 0
[2022-06-17T17:14:15.219] _job_complete: JobId=44055 done
[2022-06-17T17:17:27.410] _slurm_rpc_submit_batch_job: JobId=44056 InitPrio=26432 usec=523
[2022-06-17T17:17:27.607] sched: Allocate JobId=44056 NodeList=gpu05 #CPUs=8 Partition=gpu-v100s
[2022-06-17T17:17:31.058] _job_complete: JobId=44056 WEXITSTATUS 0
[2022-06-17T17:17:31.059] _job_complete: JobId=44056 done
[2022-06-17T17:17:32.671] _slurm_rpc_submit_batch_job: JobId=44057 InitPrio=29735 usec=465
[2022-06-17T17:17:33.657] sched: Allocate JobId=44057 NodeList=cpu03 #CPUs=1 Partition=cpu-opteron
[2022-06-17T17:17:34.561] _job_complete: JobId=44057 WEXITSTATUS 2
[2022-06-17T17:17:34.561] _job_complete: JobId=44057 done
[2022-06-17T17:19:27.023] _slurm_rpc_submit_batch_job: JobId=44058 InitPrio=29735 usec=486
[2022-06-17T17:19:27.827] sched: Allocate JobId=44058 NodeList=cpu03 #CPUs=1 Partition=cpu-opteron
[2022-06-17T17:19:29.373] _job_complete: JobId=44058 WEXITSTATUS 1
[2022-06-17T17:19:29.374] _job_complete: JobId=44058 done
[2022-06-17T17:19:37.481] _slurm_rpc_submit_batch_job: JobId=44059 InitPrio=26432 usec=456
[2022-06-17T17:19:37.840] sched: Allocate JobId=44059 NodeList=gpu05 #CPUs=8 Partition=gpu-v100s
[2022-06-17T17:19:41.337] _job_complete: JobId=44059 WEXITSTATUS 0
[2022-06-17T17:19:41.337] _job_complete: JobId=44059 done
[2022-06-17T17:22:08.141] _slurm_rpc_submit_batch_job: JobId=44060 InitPrio=26432 usec=476
[2022-06-17T17:22:09.052] sched: Allocate JobId=44060 NodeList=gpu05 #CPUs=8 Partition=gpu-v100s
[2022-06-17T17:22:12.607] _job_complete: JobId=44060 WEXITSTATUS 0
[2022-06-17T17:22:12.607] _job_complete: JobId=44060 done
[2022-06-17T17:23:24.960] _slurm_rpc_submit_batch_job: JobId=44061 InitPrio=26432 usec=559
[2022-06-17T17:23:25.310] sched: Allocate JobId=44061 NodeList=gpu05 #CPUs=8 Partition=gpu-v100s
[2022-06-17T17:23:28.890] _job_complete: JobId=44061 WEXITSTATUS 0
[2022-06-17T17:23:28.890] _job_complete: JobId=44061 done
[2022-06-17T17:24:51.850] _slurm_rpc_submit_batch_job: JobId=44062 InitPrio=26432 usec=659
[2022-06-17T17:24:52.435] sched: Allocate JobId=44062 NodeList=gpu05 #CPUs=8 Partition=gpu-v100s
[2022-06-17T17:24:55.769] _job_complete: JobId=44062 WEXITSTATUS 0
[2022-06-17T17:24:55.769] _job_complete: JobId=44062 done
[2022-06-17T17:26:15.544] _slurm_rpc_submit_batch_job: JobId=44063 InitPrio=26432 usec=632
[2022-06-17T17:26:15.552] sched: Allocate JobId=44063 NodeList=gpu05 #CPUs=8 Partition=gpu-v100s
[2022-06-17T17:26:18.914] _job_complete: JobId=44063 WEXITSTATUS 0
[2022-06-17T17:26:18.914] _job_complete: JobId=44063 done
[2022-06-17T17:31:20.084] _slurm_rpc_submit_batch_job: JobId=44064 InitPrio=26432 usec=433
[2022-06-17T17:31:20.089] sched: Allocate JobId=44064 NodeList=gpu05 #CPUs=8 Partition=gpu-v100s
[2022-06-17T17:31:24.106] _job_complete: JobId=44064 WEXITSTATUS 0
[2022-06-17T17:31:24.106] _job_complete: JobId=44064 done
[2022-06-17T17:31:25.096] Time limit exhausted for JobId=43940
[2022-06-17T17:31:27.093] sched: Allocate JobId=44054 NodeList=cpu10 #CPUs=8 Partition=cpu-opteron
[2022-06-17T17:31:27.098] sched: Allocate JobId=44036 NodeList=cpu10 #CPUs=16 Partition=cpu-opteron
[2022-06-17T17:31:37.638] _job_complete: JobId=44054 WEXITSTATUS 0
[2022-06-17T17:31:37.638] _job_complete: JobId=44054 done
[2022-06-17T17:31:38.705] sched: Allocate JobId=44037 NodeList=cpu10 #CPUs=16 Partition=cpu-opteron
[2022-06-17T17:42:25.932] _slurm_rpc_submit_batch_job: JobId=44065 InitPrio=26432 usec=419
[2022-06-17T17:42:26.429] sched: Allocate JobId=44065 NodeList=gpu05 #CPUs=8 Partition=gpu-v100s
[2022-06-17T17:42:29.859] _job_complete: JobId=44065 WEXITSTATUS 0
[2022-06-17T17:42:29.859] _job_complete: JobId=44065 done
[2022-06-17T17:42:39.501] sched: _slurm_rpc_allocate_resources JobId=44066 NodeList=gpu01 usec=13760
[2022-06-17T17:43:46.176] _slurm_rpc_submit_batch_job: JobId=44067 InitPrio=26432 usec=479
[2022-06-17T17:43:46.585] sched: Allocate JobId=44067 NodeList=gpu05 #CPUs=8 Partition=gpu-v100s
[2022-06-17T17:43:49.709] _job_complete: JobId=44067 WEXITSTATUS 0
[2022-06-17T17:43:49.709] _job_complete: JobId=44067 done
[2022-06-17T17:45:00.326] _slurm_rpc_submit_batch_job: JobId=44068 InitPrio=26432 usec=452
[2022-06-17T17:45:00.691] sched: Allocate JobId=44068 NodeList=gpu05 #CPUs=8 Partition=gpu-v100s
[2022-06-17T17:45:03.990] _job_complete: JobId=44068 WEXITSTATUS 0
[2022-06-17T17:45:03.990] _job_complete: JobId=44068 done
[2022-06-17T17:45:44.090] _slurm_rpc_submit_batch_job: JobId=44069 InitPrio=26432 usec=481
[2022-06-17T17:45:44.752] sched: Allocate JobId=44069 NodeList=gpu05 #CPUs=8 Partition=gpu-v100s
[2022-06-17T17:45:47.584] _job_complete: JobId=44069 WEXITSTATUS 0
[2022-06-17T17:45:47.584] _job_complete: JobId=44069 done
[2022-06-17T17:46:51.146] _slurm_rpc_submit_batch_job: JobId=44070 InitPrio=26432 usec=416
[2022-06-17T17:46:51.849] sched: Allocate JobId=44070 NodeList=gpu05 #CPUs=8 Partition=gpu-v100s
[2022-06-17T17:48:44.816] _job_complete: JobId=44070 WEXITSTATUS 0
[2022-06-17T17:48:44.816] _job_complete: JobId=44070 done
[2022-06-17T18:07:35.503] _slurm_rpc_submit_batch_job: JobId=44071 InitPrio=25686 usec=536
[2022-06-17T18:20:25.897] Time limit exhausted for JobId=43950
[2022-06-17T18:20:26.918] sched: Allocate JobId=44071 NodeList=cpu03 #CPUs=32 Partition=cpu-opteron
[2022-06-17T18:20:58.752] _job_complete: JobId=44071 WEXITSTATUS 0
[2022-06-17T18:20:58.752] _job_complete: JobId=44071 done
[2022-06-17T18:20:59.229] sched: Allocate JobId=44038 NodeList=cpu03 #CPUs=16 Partition=cpu-opteron
[2022-06-17T18:20:59.229] sched: Allocate JobId=44039 NodeList=cpu03 #CPUs=16 Partition=cpu-opteron
[2022-06-17T18:21:45.041] _slurm_rpc_kill_job: REQUEST_KILL_JOB JobId=44066 uid 548300564
[2022-06-17T18:21:51.938] _slurm_rpc_kill_job: REQUEST_KILL_JOB JobId=44066 uid 548300564
[2022-06-17T18:26:50.678] cleanup_completing: JobId=44066 completion process took 305 seconds
[2022-06-17T18:31:12.878] sched: _slurm_rpc_allocate_resources JobId=44072 NodeList=gpu01 usec=4819
[2022-06-17T18:41:44.278] _slurm_rpc_submit_batch_job: JobId=44073 InitPrio=25686 usec=393
[2022-06-17T18:41:56.868] _slurm_rpc_kill_job: REQUEST_KILL_JOB JobId=44072 uid 548300564
[2022-06-17T18:42:25.162] _slurm_rpc_submit_batch_job: JobId=44074 InitPrio=25686 usec=530
[2022-06-17T18:46:58.503] cleanup_completing: JobId=44072 completion process took 302 seconds
[2022-06-17T18:47:56.085] Time limit exhausted for JobId=43958
[2022-06-17T20:15:29.335] _get_job_parts: invalid partition specified: gpu-k10c
[2022-06-17T20:15:29.335] _slurm_rpc_submit_batch_job: Invalid partition name specified
[2022-06-17T20:15:44.808] _slurm_rpc_submit_batch_job: JobId=44075 InitPrio=29066 usec=490
[2022-06-17T20:15:45.784] sched: Allocate JobId=44075 NodeList=gpu01 #CPUs=16 Partition=gpu-k10
[2022-06-17T20:15:46.195] _job_complete: JobId=44075 WEXITSTATUS 1
[2022-06-17T20:15:46.196] _job_complete: JobId=44075 done
[2022-06-17T20:17:01.550] _slurm_rpc_submit_batch_job: JobId=44076 InitPrio=29066 usec=542
[2022-06-17T20:17:01.852] sched: Allocate JobId=44076 NodeList=gpu01 #CPUs=16 Partition=gpu-k10
[2022-06-17T20:17:42.404] _job_complete: JobId=44076 WEXITSTATUS 1
[2022-06-17T20:17:42.404] _job_complete: JobId=44076 done
[2022-06-17T20:22:48.254] _slurm_rpc_submit_batch_job: JobId=44077 InitPrio=29066 usec=415
[2022-06-17T20:56:37.387] sched: _slurm_rpc_allocate_resources JobId=44078 NodeList=gpu01 usec=4681
[2022-06-17T20:57:13.920] _job_complete: JobId=44078 WEXITSTATUS 0
[2022-06-17T20:57:13.920] _job_complete: JobId=44078 done
[2022-06-17T20:58:34.946] sched: _slurm_rpc_allocate_resources JobId=44079 NodeList=gpu01 usec=1012
[2022-06-17T21:16:22.172] _slurm_rpc_submit_batch_job: JobId=44080 InitPrio=22039 usec=636
[2022-06-17T21:16:22.571] sched: Allocate JobId=44080 NodeList=gpu02 #CPUs=16 Partition=gpu-titan
[2022-06-17T21:16:33.580] _job_complete: JobId=44080 WEXITSTATUS 1
[2022-06-17T21:16:33.580] _job_complete: JobId=44080 done
[2022-06-17T21:18:07.700] _slurm_rpc_submit_batch_job: JobId=44081 InitPrio=22039 usec=462
[2022-06-17T21:18:07.851] sched: Allocate JobId=44081 NodeList=gpu02 #CPUs=16 Partition=gpu-titan
[2022-06-17T21:18:10.725] _job_complete: JobId=44081 WEXITSTATUS 1
[2022-06-17T21:18:10.726] _job_complete: JobId=44081 done
[2022-06-17T21:19:39.715] _slurm_rpc_submit_batch_job: JobId=44082 InitPrio=20280 usec=582
[2022-06-17T21:19:40.001] sched: Allocate JobId=44082 NodeList=gpu03 #CPUs=32 Partition=gpu-k10
[2022-06-17T21:23:22.287] _job_complete: JobId=44079 WEXITSTATUS 127
[2022-06-17T21:23:22.287] _job_complete: JobId=44079 done
[2022-06-17T21:24:42.074] _slurm_rpc_submit_batch_job: JobId=44083 InitPrio=30005 usec=324
[2022-06-17T21:24:48.238] _slurm_rpc_submit_batch_job: JobId=44084 InitPrio=22039 usec=370
[2022-06-17T21:24:48.583] sched: Allocate JobId=44084 NodeList=gpu02 #CPUs=16 Partition=gpu-titan
[2022-06-17T21:24:52.444] _job_complete: JobId=44084 WEXITSTATUS 1
[2022-06-17T21:24:52.444] _job_complete: JobId=44084 done
[2022-06-17T21:25:10.838] _slurm_rpc_submit_batch_job: JobId=44085 InitPrio=28659 usec=515
[2022-06-17T21:26:27.702] _slurm_rpc_submit_batch_job: JobId=44086 InitPrio=20537 usec=467
[2022-06-17T21:32:21.181] _slurm_rpc_submit_batch_job: JobId=44087 InitPrio=20537 usec=400
[2022-06-17T21:32:21.332] sched: Allocate JobId=44087 NodeList=cpu12 #CPUs=2 Partition=cpu-epyc
[2022-06-17T21:32:23.668] _job_complete: JobId=44087 WEXITSTATUS 1
[2022-06-17T21:32:23.668] _job_complete: JobId=44087 done
[2022-06-17T21:32:46.734] _slurm_rpc_kill_job: REQUEST_KILL_JOB JobId=44086 uid 548200021
[2022-06-17T21:33:01.592] sched: _slurm_rpc_allocate_resources JobId=44088 NodeList=(null) usec=844
[2022-06-17T21:33:22.412] _slurm_rpc_submit_batch_job: JobId=44089 InitPrio=20537 usec=406
[2022-06-17T21:33:22.527] sched: Allocate JobId=44089 NodeList=cpu12 #CPUs=2 Partition=cpu-epyc
[2022-06-17T21:33:30.932] _job_complete: JobId=44088 WTERMSIG 126
[2022-06-17T21:33:30.932] _job_complete: JobId=44088 cancelled by interactive user
[2022-06-17T21:33:30.932] _job_complete: JobId=44088 done
[2022-06-17T21:34:06.309] sched: _slurm_rpc_allocate_resources JobId=44090 NodeList=(null) usec=860
[2022-06-17T21:34:56.683] _slurm_rpc_submit_batch_job: JobId=44091 InitPrio=22039 usec=379
[2022-06-17T21:34:57.668] sched: Allocate JobId=44091 NodeList=gpu02 #CPUs=16 Partition=gpu-titan
[2022-06-17T21:35:02.168] _job_complete: JobId=44091 WEXITSTATUS 1
[2022-06-17T21:35:02.169] _job_complete: JobId=44091 done
[2022-06-17T21:35:43.593] _job_complete: JobId=44090 WTERMSIG 126
[2022-06-17T21:35:43.593] _job_complete: JobId=44090 cancelled by interactive user
[2022-06-17T21:35:43.593] _job_complete: JobId=44090 done
[2022-06-17T21:36:54.053] _slurm_rpc_submit_batch_job: JobId=44092 InitPrio=22039 usec=558
[2022-06-17T21:36:54.833] sched: Allocate JobId=44092 NodeList=gpu02 #CPUs=16 Partition=gpu-titan
[2022-06-17T21:37:13.190] _job_complete: JobId=44092 WEXITSTATUS 139
[2022-06-17T21:37:13.191] _job_complete: JobId=44092 done
[2022-06-17T21:43:59.975] _slurm_rpc_submit_batch_job: JobId=44093 InitPrio=22039 usec=396
[2022-06-17T21:44:00.661] sched: Allocate JobId=44093 NodeList=gpu02 #CPUs=16 Partition=gpu-titan
[2022-06-17T21:44:04.451] _job_complete: JobId=44093 WEXITSTATUS 1
[2022-06-17T21:44:04.452] _job_complete: JobId=44093 done
[2022-06-17T21:44:21.362] _job_complete: JobId=44089 WEXITSTATUS 0
[2022-06-17T21:44:21.362] _job_complete: JobId=44089 done
[2022-06-17T21:44:38.514] _slurm_rpc_submit_batch_job: JobId=44094 InitPrio=22039 usec=493
[2022-06-17T21:44:38.719] sched: Allocate JobId=44094 NodeList=gpu02 #CPUs=16 Partition=gpu-titan
[2022-06-17T21:44:41.330] _job_complete: JobId=44094 WEXITSTATUS 1
[2022-06-17T21:44:41.331] _job_complete: JobId=44094 done
[2022-06-17T21:46:42.810] error: This association 204(account='free', user='lin0618', partition='(null)') does not have access to qos normal
[2022-06-17T21:46:42.811] _slurm_rpc_submit_batch_job: Invalid qos specification
[2022-06-17T21:47:08.834] error: Invalid qos (normal*)
[2022-06-17T21:47:08.834] _slurm_rpc_submit_batch_job: Invalid qos specification
[2022-06-17T21:48:05.273] error: Invalid qos (normal*)
[2022-06-17T21:48:05.273] _slurm_rpc_submit_batch_job: Invalid qos specification
[2022-06-17T21:48:08.964] _job_create: exceeded association/QOS limit for user 548300576: AssocGrpMemLimit
[2022-06-17T21:48:08.964] _slurm_rpc_submit_batch_job: Job violates accounting/QOS policy (job submit limit, user's size and/or time limits)
[2022-06-17T21:49:57.120] _slurm_rpc_submit_batch_job: JobId=44095 InitPrio=30005 usec=379
[2022-06-17T21:51:33.191] _slurm_rpc_submit_batch_job: JobId=44096 InitPrio=22039 usec=512
[2022-06-17T21:51:33.460] sched: Allocate JobId=44096 NodeList=gpu02 #CPUs=16 Partition=gpu-titan
[2022-06-17T21:51:37.272] _job_complete: JobId=44096 WEXITSTATUS 1
[2022-06-17T21:51:37.273] _job_complete: JobId=44096 done
[2022-06-17T21:57:45.138] _slurm_rpc_submit_batch_job: JobId=44097 InitPrio=22039 usec=402
[2022-06-17T21:57:45.226] sched: Allocate JobId=44097 NodeList=gpu02 #CPUs=16 Partition=gpu-titan
[2022-06-17T21:58:02.238] _job_complete: JobId=44097 WEXITSTATUS 1
[2022-06-17T21:58:02.238] _job_complete: JobId=44097 done
[2022-06-17T22:01:51.135] _slurm_rpc_submit_batch_job: JobId=44098 InitPrio=22039 usec=531
[2022-06-17T22:01:51.580] sched: Allocate JobId=44098 NodeList=gpu02 #CPUs=16 Partition=gpu-titan
[2022-06-17T22:02:03.482] _job_complete: JobId=44098 WEXITSTATUS 1
[2022-06-17T22:02:03.483] _job_complete: JobId=44098 done
[2022-06-17T22:03:37.755] _slurm_rpc_submit_batch_job: JobId=44099 InitPrio=22039 usec=404
[2022-06-17T22:03:37.853] sched: Allocate JobId=44099 NodeList=gpu02 #CPUs=16 Partition=gpu-titan
[2022-06-17T22:03:50.915] _job_complete: JobId=44099 WEXITSTATUS 1
[2022-06-17T22:03:50.916] _job_complete: JobId=44099 done
[2022-06-17T22:06:04.611] _job_complete: JobId=43888 WEXITSTATUS 0
[2022-06-17T22:06:04.652] _job_complete: JobId=43888 done
[2022-06-17T22:09:24.970] _slurm_rpc_submit_batch_job: JobId=44100 InitPrio=22039 usec=450
[2022-06-17T22:09:25.526] sched: Allocate JobId=44100 NodeList=gpu02 #CPUs=16 Partition=gpu-titan
[2022-06-17T22:09:41.575] _job_complete: JobId=44100 WEXITSTATUS 1
[2022-06-17T22:09:41.576] _job_complete: JobId=44100 done
[2022-06-17T22:11:08.929] _job_create: exceeded association/QOS limit for user 548300576: AssocGrpMemLimit
[2022-06-17T22:11:08.929] _slurm_rpc_submit_batch_job: Job violates accounting/QOS policy (job submit limit, user's size and/or time limits)
[2022-06-17T22:12:20.378] _job_create: exceeded association/QOS limit for user 548300576: AssocGrpMemLimit
[2022-06-17T22:12:20.378] _slurm_rpc_submit_batch_job: Job violates accounting/QOS policy (job submit limit, user's size and/or time limits)
[2022-06-17T22:12:43.877] _job_create: exceeded association/QOS limit for user 548300576: AssocGrpMemLimit
[2022-06-17T22:12:43.878] _slurm_rpc_submit_batch_job: Job violates accounting/QOS policy (job submit limit, user's size and/or time limits)
[2022-06-17T22:13:22.428] _slurm_rpc_submit_batch_job: JobId=44101 InitPrio=22039 usec=522
[2022-06-17T22:13:22.996] sched: Allocate JobId=44101 NodeList=gpu02 #CPUs=16 Partition=gpu-titan
[2022-06-17T22:13:27.095] _job_create: exceeded association/QOS limit for user 548300576: AssocGrpCpuLimit
[2022-06-17T22:13:27.095] _slurm_rpc_submit_batch_job: Job violates accounting/QOS policy (job submit limit, user's size and/or time limits)
[2022-06-17T22:13:38.854] _job_complete: JobId=44101 WEXITSTATUS 1
[2022-06-17T22:13:38.855] _job_complete: JobId=44101 done
[2022-06-17T22:15:14.308] _job_create: exceeded association/QOS limit for user 548300576: AssocGrpCpuLimit
[2022-06-17T22:15:14.309] _slurm_rpc_submit_batch_job: Job violates accounting/QOS policy (job submit limit, user's size and/or time limits)
[2022-06-17T22:15:44.601] _job_create: exceeded association/QOS limit for user 548300576: AssocGrpCpuLimit
[2022-06-17T22:15:44.601] _slurm_rpc_submit_batch_job: Job violates accounting/QOS policy (job submit limit, user's size and/or time limits)
[2022-06-17T22:16:39.787] _slurm_rpc_submit_batch_job: JobId=44102 InitPrio=22039 usec=520
[2022-06-17T22:16:40.130] sched/backfill: _start_job: Started JobId=44102 in gpu-titan on gpu02
[2022-06-17T22:16:55.134] _job_complete: JobId=44102 WEXITSTATUS 1
[2022-06-17T22:16:55.134] _job_complete: JobId=44102 done
[2022-06-17T22:18:54.265] _slurm_rpc_submit_batch_job: JobId=44103 InitPrio=22039 usec=383
[2022-06-17T22:18:54.597] sched: Allocate JobId=44103 NodeList=gpu02 #CPUs=16 Partition=gpu-titan
[2022-06-17T22:18:57.599] Time limit exhausted for JobId=43974
[2022-06-17T22:18:58.150] sched: Allocate JobId=44083 NodeList=cpu11 #CPUs=1 Partition=cpu-opteron
[2022-06-17T22:18:58.152] sched: Allocate JobId=44095 NodeList=cpu11 #CPUs=1 Partition=cpu-opteron
[2022-06-17T22:18:58.164] sched: Allocate JobId=44040 NodeList=cpu11 #CPUs=16 Partition=cpu-opteron
[2022-06-17T22:18:58.415] _job_complete: JobId=44103 WEXITSTATUS 1
[2022-06-17T22:18:58.416] _job_complete: JobId=44103 done
[2022-06-17T22:19:00.534] _job_complete: JobId=44083 WEXITSTATUS 1
[2022-06-17T22:19:00.534] _job_complete: JobId=44083 done
[2022-06-17T22:19:27.641] Time limit exhausted for JobId=43975
[2022-06-17T22:19:29.695] sched: Allocate JobId=44073 NodeList=cpu08 #CPUs=32 Partition=cpu-opteron
[2022-06-17T22:19:29.696] sched: Allocate JobId=44074 NodeList=cpu08 #CPUs=32 Partition=cpu-opteron
[2022-06-17T22:19:50.243] _slurm_rpc_submit_batch_job: JobId=44104 InitPrio=22039 usec=456
[2022-06-17T22:19:50.679] sched: Allocate JobId=44104 NodeList=gpu02 #CPUs=16 Partition=gpu-titan
[2022-06-17T22:19:53.399] _job_complete: JobId=44104 WEXITSTATUS 1
[2022-06-17T22:19:53.400] _job_complete: JobId=44104 done
[2022-06-17T22:20:03.110] _job_complete: JobId=44074 WEXITSTATUS 0
[2022-06-17T22:20:03.110] _job_complete: JobId=44074 done
[2022-06-17T22:20:03.540] sched: Allocate JobId=44041 NodeList=cpu08 #CPUs=16 Partition=cpu-opteron
[2022-06-17T22:20:03.540] sched: Allocate JobId=44042 NodeList=cpu08 #CPUs=16 Partition=cpu-opteron
[2022-06-17T22:20:04.459] _job_complete: JobId=44073 WEXITSTATUS 0
[2022-06-17T22:20:04.460] _job_complete: JobId=44073 done
[2022-06-17T22:20:04.866] sched: Allocate JobId=44043 NodeList=cpu08 #CPUs=16 Partition=cpu-opteron
[2022-06-17T22:20:04.867] sched: Allocate JobId=44044 NodeList=cpu08 #CPUs=16 Partition=cpu-opteron
[2022-06-17T22:20:34.900] _slurm_rpc_submit_batch_job: JobId=44105 InitPrio=22039 usec=391
[2022-06-17T22:20:35.741] sched: Allocate JobId=44105 NodeList=gpu02 #CPUs=16 Partition=gpu-titan
[2022-06-17T22:20:38.588] _job_complete: JobId=44105 WEXITSTATUS 1
[2022-06-17T22:20:38.589] _job_complete: JobId=44105 done
[2022-06-17T22:20:57.772] Time limit exhausted for JobId=43976
[2022-06-17T22:21:20.285] _slurm_rpc_submit_batch_job: JobId=44106 InitPrio=22039 usec=485
[2022-06-17T22:21:20.808] sched: Allocate JobId=44106 NodeList=gpu02 #CPUs=16 Partition=gpu-titan
[2022-06-17T22:21:23.296] _job_complete: JobId=44106 WEXITSTATUS 1
[2022-06-17T22:21:23.297] _job_complete: JobId=44106 done
[2022-06-17T22:21:44.899] _job_complete: JobId=43892 WEXITSTATUS 0
[2022-06-17T22:21:44.900] _job_complete: JobId=43892 done
[2022-06-17T22:22:20.120] _slurm_rpc_submit_batch_job: JobId=44107 InitPrio=22039 usec=453
[2022-06-17T22:22:20.899] sched: Allocate JobId=44107 NodeList=gpu02 #CPUs=16 Partition=gpu-titan
[2022-06-17T22:22:27.960] Time limit exhausted for JobId=43977
[2022-06-17T22:22:45.622] _slurm_rpc_submit_batch_job: JobId=44108 InitPrio=20537 usec=524
[2022-06-17T22:22:46.035] sched: Allocate JobId=44108 NodeList=cpu14 #CPUs=2 Partition=cpu-epyc
[2022-06-17T22:24:15.298] _slurm_rpc_kill_job: REQUEST_KILL_JOB JobId=44107 uid 548300547
[2022-06-17T22:25:22.753] _slurm_rpc_kill_job: REQUEST_KILL_JOB JobId=44107 uid 548300547
[2022-06-17T22:25:59.464] _slurm_rpc_submit_batch_job: JobId=44109 InitPrio=22039 usec=418
[2022-06-17T22:26:00.322] sched: Allocate JobId=44109 NodeList=gpu02 #CPUs=16 Partition=gpu-titan
[2022-06-17T22:26:13.516] _job_complete: JobId=44109 WEXITSTATUS 1
[2022-06-17T22:26:13.516] _job_complete: JobId=44109 done
[2022-06-17T22:29:09.341] _slurm_rpc_submit_batch_job: JobId=44110 InitPrio=22039 usec=417
[2022-06-17T22:29:09.725] sched: Allocate JobId=44110 NodeList=gpu02 #CPUs=16 Partition=gpu-titan
[2022-06-17T22:30:36.806] _slurm_rpc_kill_job: REQUEST_KILL_JOB JobId=44110 uid 548300547
[2022-06-17T22:30:44.952] _slurm_rpc_submit_batch_job: JobId=44111 InitPrio=21628 usec=447
[2022-06-17T22:31:43.863] _slurm_rpc_kill_job: REQUEST_KILL_JOB JobId=44111 uid 548300547
[2022-06-17T22:31:45.951] _slurm_rpc_submit_batch_job: JobId=44112 InitPrio=21628 usec=489
[2022-06-17T22:32:05.651] _job_complete: JobId=44108 WEXITSTATUS 0
